Workbook

Sheet 처방전양식
B1: No. | F1: 총용량 | G1: 1g 금액 | H1: 1첩 금액 | I1: 총 금액 | J1: 1일당 | K1: 기본 정보
B2: 1 | C2: 향부자 | E2: 10 | F2: =E2*$L$15 -> 100 | G2: =VLOOKUP($C2,[1]약재관리!$A:$J,10,FALSE) -> 14.7 | H2: =G2*E2 -> 147 | I2: =G2*F2 -> 1470 | J2: =F2/$L$14 -> 10 | K2: UNIT | L2: 186
B3: 2 | C3: 백출 | E3: 4 | F3: =E3*$L$15 -> 40 | G3: =VLOOKUP($C3,[1]약재관리!$A:$J,10,FALSE) -> 27.8 | H3: =G3*E3 -> 111.2 | I3: =G3*F3 -> 1112 | J3: =F3/$L$14 -> 4 | K3: 처방명 | L3: 개울화담전
B4: 3 | C4: 진피1 | E4: 4 | F4: =E4*$L$15 -> 40 | G4: =VLOOKUP($C4,[1]약재관리!$A:$J,10,FALSE) -> 17.6 | H4: =G4*E4 -> 70.4 | I4: =G4*F4 -> 704 | J4: =F4/$L$14 -> 4 | K4: 날짜 | L4: 46055
B5: 4 | C5: 후박 | E5: 4 | F5: =E5*$L$15 -> 40 | G5: =VLOOKUP($C5,[1]약재관리!$A:$J,10,FALSE) -> 8.8 | H5: =G5*E5 -> 35.2 | I5: =G5*F5 -> 352 | J5: =F5/$L$14 -> 4 | K5: 이름 | L5: 박선영
B6: 5 | C6: 반하 | E6: 4 | F6: =E6*$L$15 -> 40 | G6: =VLOOKUP($C6,[1]약재관리!$A:$J,10,FALSE) -> 41 | H6: =G6*E6 -> 164 | I6: =G6*F6 -> 1640 | J6: =F6/$L$14 -> 4 | K6: 나이 | L6: 28
B7: 6 | C7: 복령 | E7: 4 | F7: =E7*$L$15 -> 40 | G7: =VLOOKUP($C7,[1]약재관리!$A:$J,10,FALSE) -> 8.7 | H7: =G7*E7 -> 34.8 | I7: =G7*F7 -> 348 | J7: =F7/$L$14 -> 4 | K7: 성별 | L7: F
B8: 7 | C8: 연교 | E8: 4 | F8: =E8*$L$15 -> 40 | G8: =VLOOKUP($C8,[1]약재관리!$A:$J,10,FALSE) -> 28 | H8: =G8*E8 -> 112 | I8: =G8*F8 -> 1120 | J8: =F8/$L$14 -> 4 | K8: 메모
B9: 8 | C9: 나복자 | E9: 4 | F9: =E9*$L$15 -> 40 | G9: =VLOOKUP($C9,[1]약재관리!$A:$J,10,FALSE) -> 6 | H9: =G9*E9 -> 24 | I9: =G9*F9 -> 240 | J9: =F9/$L$14 -> 4 | K9: 개울화담전 + 길경 백작약 현호색
B10: 9 | C10: 지실 | E10: 4 | F10: =E10*$L$15 -> 40 | G10: =VLOOKUP($C10,[1]약재관리!$A:$J,10,FALSE) -> 16.7 | H10: =G10*E10 -> 66.8 | I10: =G10*F10 -> 668 | J10: =F10/$L$14 -> 4
B11: 10 | C11: 신곡 | E11: 4 | F11: =E11*$L$15 -> 40 | G11: =VLOOKUP($C11,[1]약재관리!$A:$J,10,FALSE) -> 8 | H11: =G11*E11 -> 32 | I11: =G11*F11 -> 320 | J11: =F11/$L$14 -> 4
B12: 11 | C12: 목향 | E12: 3 | F12: =E12*$L$15 -> 30 | G12: =VLOOKUP($C12,[1]약재관리!$A:$J,10,FALSE) -> 12.2 | H12: =G12*E12 -> 36.6 | I12: =G12*F12 -> 366 | J12: =F12/$L$14 -> 3
B13: 12 | C13: 황금 | E13: 2 | F13: =E13*$L$15 -> 20 | G13: =VLOOKUP($C13,[1]약재관리!$A:$J,10,FALSE) -> 22.5 | H13: =G13*E13 -> 45 | I13: =G13*F13 -> 450 | J13: =F13/$L$14 -> 2
B14: 13 | C14: 황련 | E14: 2 | F14: =E14*$L$15 -> 20 | G14: =VLOOKUP($C14,[1]약재관리!$A:$J,10,FALSE) -> 136.8 | H14: =G14*E14 -> 273.6 | I14: =G14*F14 -> 2736 | J14: =F14/$L$14 -> 2 | K14: 총 일수 | L14: 10 | M14: 일분
B15: 14 | C15: 생강 | E15: 4 | F15: =E15*$L$15 -> 40 | G15: =VLOOKUP($C15,[1]약재관리!$A:$J,10,FALSE) -> 20 | H15: =G15*E15 -> 80 | I15: =G15*F15 -> 800 | J15: =F15/$L$14 -> 4 | K15: 첩수 | L15: 10 | M15: 첩
B16: 15 | C16: 길경 | E16: 4 | F16: =E16*$L$15 -> 40 | G16: =VLOOKUP($C16,[1]약재관리!$A:$J,10,FALSE) -> 11.5 | H16: =G16*E16 -> 46 | I16: =G16*F16 -> 460 | J16: =F16/$L$14 -> 4 | K16: 총 팩수 | L16: 20 | M16: 팩
B17: 16 | C17: 백작약 | E17: 4 | F17: =E17*$L$15 -> 40 | G17: =VLOOKUP($C17,[1]약재관리!$A:$J,10,FALSE) -> 19.6 | H17: =G17*E17 -> 78.4 | I17: =G17*F17 -> 784 | J17: =F17/$L$14 -> 4 | K17: 팩당 물량 | L17: 70 | M17: cc
B18: 17 | C18: 현호색 | E18: 4 | F18: =E18*$L$15 -> 40 | G18: =VLOOKUP($C18,[1]약재관리!$A:$J,10,FALSE) -> 59.7 | H18: =G18*E18 -> 238.8 | I18: =G18*F18 -> 2388 | J18: =F18/$L$14 -> 4 | K18: 1첩당약재 | L18: =SUM(E2:E31) -> 69 | M18: g
B19: 18 | F19: =E19*$L$15 -> 0 | H19: =G19*E19 -> 0 | I19: =G19*F19 -> 0 | K19: 약재총량 | L19: =L15*L18 -> 690 | M19: g
B20: 19 | F20: =E20*$L$15 -> 0 | H20: =G20*E20 -> 0 | I20: =G20*F20 -> 0 | K20: 총 물 양 | L20: =L16*L17+L19 -> 2090 | M20: cc
B21: 20 | F21: =E21*$L$15 -> 0 | H21: =G21*E21 -> 0 | I21: =G21*F21 -> 0
B22: 21 | F22: =E22*$L$15 -> 0 | H22: =G22*E22 -> 0 | I22: =G22*F22 -> 0 | K22: 참고치
B23: 22 | F23: =E23*$L$15 -> 0 | H23: =G23*E23 -> 0 | I23: =G23*F23 -> 0 | K23: cross chk | L23: =SUM(F2:F31) -> 690 | M23: g
B24: 23 | F24: =E24*$L$15 -> 0 | H24: =G24*E24 -> 0 | I24: =G24*F24 -> 0 | K24: 20첩물양 | L24: 5000 | M24: cc
B25: 24 | F25: =E25*$L$15 -> 0 | H25: =G25*E25 -> 0 | I25: =G25*F25 -> 0 | K25: 1첩당 | L25: 80-120 | M25: g
B26: 25 | F26: =E26*$L$15 -> 0 | H26: =G26*E26 -> 0 | I26: =G26*F26 -> 0 | K26: 20첩당 | L26: 1600 | M26: g
B27: 26 | F27: =E27*$L$15 -> 0 | H27: =G27*E27 -> 0 | I27: =G27*F27 -> 0 | K27: 1돈 환산 | L27: 4 | M27: g
B28: 27 | F28: =E28*$L$15 -> 0 | H28: =G28*E28 -> 0 | I28: =G28*F28 -> 0
B29: 28 | F29: =E29*$L$15 -> 0 | H29: =G29*E29 -> 0 | I29: =G29*F29 -> 0 | K29: 금액
B30: 29 | F30: =E30*$L$15 -> 0 | H30: =G30*E30 -> 0 | I30: =G30*F30 -> 0 | K30: 1첩당 | L30: =SUM(H2:H31) -> 1595.8 | M30: 원
B31: 30 | F31: =E31*$L$15 -> 0 | H31: =G31*E31 -> 0 | I31: =G31*F31 -> 0 | K31: 총 | L31: =SUM(I2:I31) -> 15958 | M31: 원

Sheet 약재관리
A1: 약재 이름 | B1: 옴니허브 | C1: 한퓨어 | D1: 신우한방 | E1: 바른한약 | F1: 옴니허브 | G1: 한퓨어 | H1: 신우한방 | I1: 바른한약 | J1: 최종 | K1: 옴니허브 | L1: 한퓨어 | M1: 신우한방 | N1: 바른한약
A2: 45902 | B2: 구입단가 | C2: 구입단가 | D2: 구입단가 | E2: 구입단가 | F2: 1g | G2: 1g | H2: 1g | I2: 1g | J2: 1g | K2: 500g | L2: 500g | M2: 600g | N2: 600g
A3: 갈근 | B3: 9900 | C3: 9000 | D3: 11000 | E3: 9900 | F3: =B3/500 -> 19.8 | G3: =C3/500 -> 18 | H3: =D3/600 -> 18.333333 | I3: =E3/600 -> 16.5 | J3: 16.5 | L3: 선일국산 | M3: 토 | N3: 퓨어마인드국산
A4: 감국 | C4: 10000 | E4: 11700 | F4: =B4/500 -> 0 | G4: =C4/500 -> 20 | H4: =D4/600 -> 0 | I4: =E4/600 -> 19.5
A5: 감수 | C5: 23400 | E5: 27100 | F5: =B5/500 -> 0 | G5: =C5/600 -> 39 | H5: =D5/600 -> 0 | I5: =E5/600 -> 45.166667 | J5: 45.2 | L5: 600g씨케이중국 | N5: 씨케이중국
A6: 감초 | B6: 17500 | D6: 17000 | E6: 25500 | F6: =B6/500 -> 35 | G6: =C6/500 -> 0 | H6: =D6/600 -> 28.333333 | I6: =E6/600 -> 42.5 | J6: 28.3 | M6: 양외2 | N6: 양외1
A7: 강활1 | B7: 27200 | C7: 24000 | D7: 24000 | F7: =B7/500 -> 54.4 | G7: =C7/500 -> 48 | H7: =D7/600 -> 40 | I7: =E7/600 -> 0 | J7: 40 | L7: 선일국산 | M7: 토
A8: 강활2 | C8: 23000 | D8: 21000 | E8: 27400 | F8: =B8/500 -> 0 | G8: =C8/500 -> 46 | H8: =D8/600 -> 35 | I8: =E8/600 -> 45.666667 | J8: 45.7 | L8: 태극인국산 | N8: 선일국산
A9: 강황 | C9: 3300 | D9: 5000 | F9: =B9/500 -> 0 | G9: =C9/500 -> 6.6 | H9: =D9/600 -> 8.3333333 | I9: =E9/600 -> 0 | J9: 8.3 | M9: 인도
A10: 건강 | C10: 5200 | D10: 8000 | E10: 5900 | F10: =B10/500 -> 0 | G10: =C10/500 -> 10.4 | H10: =D10/600 -> 13.333333 | I10: =E10/600 -> 9.8333333 | J10: 9.5 | L10: 페루 | N10: 페루
A11: 건율 | C11: 16800 | D11: 16500 | E11: 20800 | F11: =B11/500 -> 0 | G11: =C11/500 -> 33.6 | H11: =D11/600 -> 27.5 | I11: =E11/600 -> 34.666667 | J11: 34.7 | M11: 토 | N11: (절, 토)
A12: 건지황 | B12: 19900 | C12: 5600 | D12: 11000 | E12: 8900 | F12: =B12/500 -> 39.8 | G12: =C12/500 -> 11.2 | H12: =D12/600 -> 18.333333 | I12: =E12/600 -> 14.833333 | J12: 14.4 | L12: 허브팜중국
A13: 결명자 | F13: =B13/500 -> 0 | G13: =C13/500 -> 0 | H13: =D13/600 -> 0 | I13: =E13/600 -> 0
A14: 계자황(난황)
A15: 계지 | B15: 4500 | C15: 2000 | D15: 3500 | E15: 2900 | F15: =B15/500 -> 9 | G15: =C15/500 -> 4 | H15: =D15/600 -> 5.8333333 | I15: =E15/600 -> 4.8333333 | J15: 4.8 | L15: 씨케이베트남 | M15: 세 | N15: 엔탭베트남
A16: 계혈등
A17: 고량강 | C17: 10200 | E17: 11100 | F17: =B17/500 -> 0 | G17: =C17/600 -> 17 | H17: =D17/600 -> 0 | I17: =E17/600 -> 18.5 | J17: 17 | L17: 600g 씨케이중국 | N17: 씨케이중국
A18: 고본 | C18: 32000 | E18: 41600 | F18: =B18/500 -> 0 | G18: =C18/500 -> 64 | H18: =D18/600 -> 0 | I18: =E18/600 -> 69.333333 | J18: 64 | L18: 선일국산 | N18: 퓨어마인드국산
A19: 고삼 | C19: 4500 | F19: =B19/500 -> 0 | G19: =C19/500 -> 9 | H19: =D19/600 -> 0 | I19: =E19/600 -> 0 | J19: 9 | L19: 한솔중국
A20: 골쇄보 | F20: =B20/500 -> 0 | G20: =C20/500 -> 0 | H20: =D20/600 -> 0 | I20: =E20/600 -> 0
A21: 과루인 | C21: 3500 | D21: 6500 | F21: =B21/500 -> 0 | G21: =C21/500 -> 7 | H21: =D21/600 -> 10.833333 | I21: =E21/600 -> 0 | J21: 10.8 | M21: (추)
A22: 곽향1 | B22: 6900 | C22: 5600 | E22: 6900 | F22: =B22/500 -> 13.8 | G22: =C22/500 -> 11.2 | H22: =D22/600 -> 0 | I22: =E22/600 -> 11.5 | J22: 13.8 | L22: 선일국산 | N22: 씨케이국산
A23: 곽향2 | B23: 4600 | C23: 3500 | E23: 4800 | F23: =B23/500 -> 9.2 | G23: =C23/500 -> 7 | H23: =D23/600 -> 0 | I23: =E23/600 -> 8 | J23: 7 | K23: 인도네시아 | L23: 올본인도네시아 | N23: 엔탭인도네시아
A24: 관동화 | C24: 46000 | D24: 73000 | E24: 75400 | F24: =B24/500 -> 0 | G24: =C24/300 -> 153.33333 | H24: =D24/600 -> 121.66667 | I24: =E24/600 -> 125.66667 | J24: 121.7 | L24: 300g | N24: 엔탭중국
A25: 괴화 | F25: =B25/500 -> 0 | G25: =C25/500 -> 0 | H25: =D25/600 -> 0 | I25: =E25/600 -> 0
A26: 교이 | F26: =B26/500 -> 0 | G26: =C26/500 -> 0 | H26: =D26/600 -> 0 | I26: =E26/600 -> 0 | J26: 5.3
A27: 구기자 | B27: 14900 | C27: 8700 | D27: 9000 | E27: 8200 | F27: =B27/500 -> 29.8 | G27: =C27/500 -> 17.4 | H27: =D27/600 -> 15 | I27: =E27/600 -> 13.666667 | J27: 13.7 | N27: 엔탭중국영하
A28: 구맥 | F28: =B28/500 -> 0 | G28: =C28/500 -> 0 | H28: =D28/600 -> 0 | I28: =E28/600 -> 0
A29: 구척 | C29: 12000 | E29: 14300 | F29: =B29/500 -> 0 | G29: =C29/500 -> 24 | H29: =D29/600 -> 0 | I29: =E29/600 -> 23.833333
A30: 귀판 | C30: 20500 | D30: 19000 | F30: =B30/500 -> 0 | G30: =C30/600 -> 34.166667 | H30: =D30/600 -> 31.666667 | I30: =E30/600 -> 0 | J30: 31.7 | L30: 600g추말/자연세상인도네시아
A31: 금은화 | C31: 21500 | E31: 30800 | F31: =B31/500 -> 0 | G31: =C31/500 -> 43 | H31: =D31/600 -> 0 | I31: =E31/600 -> 51.333333 | J31: 43 | L31: 한솔중국 | N31: 엔탭중국
A32: 길경 | B32: 11500 | C32: 12900 | D32: 7500 | E32: 6900 | F32: =B32/500 -> 23 | G32: =C32/500 -> 25.8 | H32: =D32/600 -> 12.5 | I32: =E32/600 -> 11.5 | J32: 11.5 | K32: (중국4-5년) | L32: 선일국산 | M32: (편) | N32: 엔탭중국야생3년
A33: 나복자 | C33: 3000 | D33: 4000 | E33: 4000 | F33: =B33/500 -> 0 | G33: =C33/500 -> 6 | H33: =D33/600 -> 6.6666667 | I33: =E33/600 -> 6.6666667 | J33: 6 | L33: 올본인도/추말 | M33: 추
A34: 남성 | C34: 13000 | D34: 13000 | F34: =B34/500 -> 0 | G34: =C34/500 -> 26 | H34: =D34/500 -> 26 | I34: =E34/600 -> 0 | J34: 26 | L34: 생강백반제/신흥중국 | M34: 500g생강백반제/신흥중국
A35: 녹각교
A36: 녹용 | C36: 278000 | F36: =B36/500 -> 0 | G36: =C36/600 -> 463.33333 | H36: =D36/600 -> 0 | I36: =E36/600 -> 0 | J36: 463.3 | L36: 600g
A37: 단삼 | C37: 6600 | E37: 8900 | F37: =B37/500 -> 0 | G37: =C37/500 -> 13.2 | H37: =D37/600 -> 0 | I37: =E37/600 -> 14.833333 | J37: 14.8 | L37: 허브팜중국 | N37: 엔탭중국
A38: 담두시 | D38: 8000 | F38: =B38/500 -> 0 | G38: =C38/500 -> 0 | H38: =D38/600 -> 13.333333 | I38: =E38/600 -> 0 | J38: 13.3
A39: 당귀1 | B39: 14900 | C39: 12700 | D39: 15000 | E39: 16300 | F39: =B39/500 -> 29.8 | G39: =C39/500 -> 25.4 | H39: =D39/600 -> 25 | I39: =E39/600 -> 27.166667 | J39: 27.2 | L39: 선일국산 | N39: 선일국산
A40: 당귀2 | C40: 12700 | E40: 13800 | F40: =B40/500 -> 0 | G40: =C40/500 -> 25.4 | H40: =D40/600 -> 0 | I40: =E40/600 -> 23 | J40: 23 | L40: 선일국산 | N40: 선일국산
...
