Workbook

Sheet 청상보하탕 14차
B1: No. | C1: 약재명 | D1: 수치 | E1: 그램 | F1: 총용량 | G1: 1g 금액 | H1: 1첩 금액 | I1: 총 금액 | K1: 기본 정보
B2: 1 | C2: 사삼 | E2: 10 | F2: =E2*$L$15 -> 200 | G2: =VLOOKUP($C2,약재관리!A:J,10,FALSE) -> 27.2 | H2: =G2*E2 -> 272 | I2: =G2*F2 -> 5440 | K2: UNIT | L2: 19
B3: 2 | C3: 맥문동 | E3: 10 | F3: =E3*$L$15 -> 200 | G3: =VLOOKUP($C3,약재관리!A:J,10,FALSE) -> 44.3 | H3: =G3*E3 -> 443 | I3: =G3*F3 -> 8860 | K3: 처방명 | L3: 양진한치-기관지확장증방
B4: 3 | C4: 백합 | E4: 6 | F4: =E4*$L$15 -> 120 | G4: =VLOOKUP($C4,약재관리!A:J,10,FALSE) -> 16.7 | H4: =G4*E4 -> 100.2 | I4: =G4*F4 -> 2004 | K4: 날짜 | L4: 45765
B5: 4 | C5: 건지황 | E5: 6 | F5: =E5*$L$15 -> 120 | G5: =VLOOKUP($C5,약재관리!A:J,10,FALSE) -> 14.4 | H5: =G5*E5 -> 86.4 | I5: =G5*F5 -> 1728 | K5: 이름 | L5: 오명옥
B6: 5 | C6: 상백피 | E6: 6 | F6: =E6*$L$15 -> 120 | G6: =VLOOKUP($C6,약재관리!A:J,10,FALSE) -> 35 | H6: =G6*E6 -> 210 | I6: =G6*F6 -> 4200 | K6: 나이 | L6: F
B7: 6 | C7: 지골피 | E7: 6 | F7: =E7*$L$15 -> 120 | G7: =VLOOKUP($C7,약재관리!A:J,10,FALSE) -> 21.7 | H7: =G7*E7 -> 130.2 | I7: =G7*F7 -> 2604 | K7: 성별 | L7: 58
B8: 7 | C8: 패모 | E8: 4.5 | F8: =E8*$L$15 -> 90 | G8: =VLOOKUP($C8,약재관리!A:J,10,FALSE) -> 32 | H8: =G8*E8 -> 144 | I8: =G8*F8 -> 2880 | K8: 메모
B9: 8 | C9: 지각 | E9: 6 | F9: =E9*$L$15 -> 120 | G9: =VLOOKUP($C9,약재관리!A:J,10,FALSE) -> 10 | H9: =G9*E9 -> 60 | I9: =G9*F9 -> 1200 | K9: 기관지확장증방3 + 치자, 평위산
B10: 9 | C10: 단삼 | E10: 6 | F10: =E10*$L$15 -> 120 | G10: =VLOOKUP($C10,약재관리!A:J,10,FALSE) -> 14.8 | H10: =G10*E10 -> 88.8 | I10: =G10*F10 -> 1776
B11: 10 | C11: 당귀1 | E11: 4 | F11: =E11*$L$15 -> 80 | G11: =VLOOKUP($C11,약재관리!A:J,10,FALSE) -> 27.2 | H11: =G11*E11 -> 108.8 | I11: =G11*F11 -> 2176
B12: 11 | C12: 치자 | E12: 4 | F12: =E12*$L$15 -> 80 | G12: =VLOOKUP($C12,약재관리!A:J,10,FALSE) -> 26 | H12: =G12*E12 -> 104 | I12: =G12*F12 -> 2080
B13: 12 | C13: 백출 | E13: 4 | F13: =E13*$L$15 -> 80 | G13: =VLOOKUP($C13,약재관리!A:J,10,FALSE) -> 30.3 | H13: =G13*E13 -> 121.2 | I13: =G13*F13 -> 2424
B14: 13 | C14: 후박 | E14: 4 | F14: =E14*$L$15 -> 80 | G14: =VLOOKUP($C14,약재관리!A:J,10,FALSE) -> 9 | H14: =G14*E14 -> 36 | I14: =G14*F14 -> 720 | K14: 총 일수 | L14: 15 | M14: 일분
B15: 14 | C15: 진피1 | E15: 4 | F15: =E15*$L$15 -> 80 | G15: =VLOOKUP($C15,약재관리!A:J,10,FALSE) -> 17.6 | H15: =G15*E15 -> 70.4 | I15: =G15*F15 -> 1408 | K15: 첩수 | L15: 20 | M15: 첩
B16: 15 | C16: 감초 | E16: 4 | F16: =E16*$L$15 -> 80 | G16: =VLOOKUP($C16,약재관리!A:J,10,FALSE) -> 28.3 | H16: =G16*E16 -> 113.2 | I16: =G16*F16 -> 2264 | K16: 총 팩수 | L16: 45 | M16: 팩
B17: 16 | F17: =E17*$L$15 -> 0 | H17: =G17*E17 -> 0 | I17: =G17*F17 -> 0 | K17: 팩당 물량 | L17: 90 | M17: cc
B18: 17 | F18: =E18*$L$15 -> 0 | H18: =G18*E18 -> 0 | I18: =G18*F18 -> 0 | K18: 1첩당약재 | L18: =SUM(E2:E31) -> 84.5 | M18: g
B19: 18 | F19: =E19*$L$15 -> 0 | H19: =G19*E19 -> 0 | I19: =G19*F19 -> 0 | K19: 약재총량 | L19: =L15*L18 -> 1690 | M19: g
B20: 19 | F20: =E20*$L$15 -> 0 | H20: =G20*E20 -> 0 | I20: =G20*F20 -> 0 | K20: 총 물 양 | L20: =L16*L17+L19 -> 5740 | M20: cc
B21: 20 | F21: =E21*$L$15 -> 0 | H21: =G21*E21 -> 0 | I21: =G21*F21 -> 0
B22: 21 | F22: =E22*$L$15 -> 0 | H22: =G22*E22 -> 0 | I22: =G22*F22 -> 0 | K22: 참고치
B23: 22 | F23: =E23*$L$15 -> 0 | H23: =G23*E23 -> 0 | I23: =G23*F23 -> 0 | K23: cross chk | L23: =SUM(F2:F31) -> 1690 | M23: g
B24: 23 | F24: =E24*$L$15 -> 0 | H24: =G24*E24 -> 0 | I24: =G24*F24 -> 0 | K24: 20첩물양 | L24: 5000 | M24: cc
B25: 24 | F25: =E25*$L$15 -> 0 | H25: =G25*E25 -> 0 | I25: =G25*F25 -> 0 | K25: 1첩당 | L25: 80-120 | M25: g
B26: 25 | F26: =E26*$L$15 -> 0 | H26: =G26*E26 -> 0 | I26: =G26*F26 -> 0 | K26: 20첩당 | L26: 1600 | M26: g
B27: 26 | F27: =E27*$L$15 -> 0 | H27: =G27*E27 -> 0 | I27: =G27*F27 -> 0 | K27: 1돈 환산 | L27: 4 | M27: g
B28: 27 | F28: =E28*$L$15 -> 0 | H28: =G28*E28 -> 0 | I28: =G28*F28 -> 0
B29: 28 | F29: =E29*$L$15 -> 0 | H29: =G29*E29 -> 0 | I29: =G29*F29 -> 0 | K29: 금액
B30: 29 | F30: =E30*$L$15 -> 0 | H30: =G30*E30 -> 0 | I30: =G30*F30 -> 0 | K30: 1첩당 | L30: =SUM(H2:H31) -> 2088.2 | M30: 원
B31: 30 | F31: =E31*$L$15 -> 0 | H31: =G31*E31 -> 0 | I31: =G31*F31 -> 0 | K31: 총 | L31: =SUM(I2:I31) -> 41764 | M31: 원

Sheet 청상보하탕 13차
B1: No. | C1: 약재명 | D1: 수치 | E1: 그램 | F1: 총용량 | G1: 1g 금액 | H1: 1첩 금액 | I1: 총 금액 | K1: 기본 정보
B2: 1 | C2: 숙지황 | E2: 4 | F2: =E2*$L$15 -> 80 | G2: =VLOOKUP($C2,약재관리!A:J,10,FALSE) -> 20 | H2: =G2*E2 -> 80 | I2: =G2*F2 -> 1600 | K2: UNIT | L2: 19
B3: 2 | C3: 산약 | E3: 4 | F3: =E3*$L$15 -> 80 | G3: =VLOOKUP($C3,약재관리!A:J,10,FALSE) -> 18.3 | H3: =G3*E3 -> 73.2 | I3: =G3*F3 -> 1464 | K3: 처방명 | L3: 청상보하탕
B4: 3 | C4: 산수유 | E4: 4 | F4: =E4*$L$15 -> 80 | G4: =VLOOKUP($C4,약재관리!A:J,10,FALSE) -> 27.7 | H4: =G4*E4 -> 110.8 | I4: =G4*F4 -> 2216 | K4: 날짜 | L4: 45765
B5: 4 | C5: 복령 | E5: 4 | F5: =E5*$L$15 -> 80 | G5: =VLOOKUP($C5,약재관리!A:J,10,FALSE) -> 9.8 | H5: =G5*E5 -> 39.2 | I5: =G5*F5 -> 784 | K5: 이름 | L5: 오명옥
B6: 5 | C6: 택사1 | E6: 4 | F6: =E6*$L$15 -> 80 | G6: =VLOOKUP($C6,약재관리!A:J,10,FALSE) -> 23.7 | H6: =G6*E6 -> 94.8 | I6: =G6*F6 -> 1896 | K6: 나이 | L6: F
B7: 6 | C7: 목단피 | E7: 4 | F7: =E7*$L$15 -> 80 | G7: =VLOOKUP($C7,약재관리!A:J,10,FALSE) -> 28 | H7: =G7*E7 -> 112 | I7: =G7*F7 -> 2240 | K7: 성별 | L7: 58
B8: 7 | C8: 자완 | E8: 4 | F8: =E8*$L$15 -> 80 | G8: =VLOOKUP($C8,약재관리!A:J,10,FALSE) -> 38 | H8: =G8*E8 -> 152 | I8: =G8*F8 -> 3040 | K8: 메모
B9: 8 | C9: 백부근 | E9: 4 | F9: =E9*$L$15 -> 80 | G9: =VLOOKUP($C9,약재관리!A:J,10,FALSE) -> 23.3 | H9: =G9*E9 -> 93.2 | I9: =G9*F9 -> 1864 | K9: 청상보하탕 + 사삼 지골피 금은화 관동화
B10: 9 | C10: 지실 | E10: 4 | F10: =E10*$L$15 -> 80 | G10: =VLOOKUP($C10,약재관리!A:J,10,FALSE) -> 16.7 | H10: =G10*E10 -> 66.8 | I10: =G10*F10 -> 1336
B11: 10 | C11: 맥문동 | E11: 3 | F11: =E11*$L$15 -> 60 | G11: =VLOOKUP($C11,약재관리!A:J,10,FALSE) -> 44.3 | H11: =G11*E11 -> 132.9 | I11: =G11*F11 -> 2658
B12: 11 | C12: 천문동 | E12: 3 | F12: =E12*$L$15 -> 60 | G12: =VLOOKUP($C12,약재관리!A:J,10,FALSE) -> 28.5 | H12: =G12*E12 -> 85.5 | I12: =G12*F12 -> 1710
B13: 12 | C13: 오미자 | E13: 3 | F13: =E13*$L$15 -> 60 | G13: =VLOOKUP($C13,약재관리!A:J,10,FALSE) -> 23.5 | H13: =G13*E13 -> 70.5 | I13: =G13*F13 -> 1410
B14: 13 | C14: 과루인 | E14: 3 | F14: =E14*$L$15 -> 60 | G14: =VLOOKUP($C14,약재관리!A:J,10,FALSE) -> 10.8 | H14: =G14*E14 -> 32.4 | I14: =G14*F14 -> 648 | K14: 총 일수 | L14: 15 | M14: 일분
B15: 14 | C15: 반하 | E15: 3 | F15: =E15*$L$15 -> 60 | G15: =VLOOKUP($C15,약재관리!A:J,10,FALSE) -> 41 | H15: =G15*E15 -> 123 | I15: =G15*F15 -> 2460 | K15: 첩수 | L15: 20 | M15: 첩
B16: 15 | C16: 황금 | E16: 3 | F16: =E16*$L$15 -> 60 | G16: =VLOOKUP($C16,약재관리!A:J,10,FALSE) -> 22.5 | H16: =G16*E16 -> 67.5 | I16: =G16*F16 -> 1350 | K16: 총 팩수 | L16: 45 | M16: 팩
B17: 16 | C17: 황련 | E17: 3 | F17: =E17*$L$15 -> 60 | G17: =VLOOKUP($C17,약재관리!A:J,10,FALSE) -> 136.8 | H17: =G17*E17 -> 410.4 | I17: =G17*F17 -> 8208 | K17: 팩당 물량 | L17: 100 | M17: cc
B18: 17 | C18: 패모 | E18: 3 | F18: =E18*$L$15 -> 60 | G18: =VLOOKUP($C18,약재관리!A:J,10,FALSE) -> 32 | H18: =G18*E18 -> 96 | I18: =G18*F18 -> 1920 | K18: 1첩당약재 | L18: =SUM(E2:E31) -> 84 | M18: g
B19: 18 | C19: 길경 | E19: 4 | F19: =E19*$L$15 -> 80 | G19: =VLOOKUP($C19,약재관리!A:J,10,FALSE) -> 11.5 | H19: =G19*E19 -> 46 | I19: =G19*F19 -> 920 | K19: 약재총량 | L19: =L15*L18 -> 1680 | M19: g
B20: 19 | C20: 행인 | E20: 3 | F20: =E20*$L$15 -> 60 | G20: =VLOOKUP($C20,약재관리!A:J,10,FALSE) -> 12 | H20: =G20*E20 -> 36 | I20: =G20*F20 -> 720 | K20: 총 물 양 | L20: =L16*L17+L19 -> 6180 | M20: cc
B21: 20 | C21: 사삼 | E21: 3 | F21: =E21*$L$15 -> 60 | G21: =VLOOKUP($C21,약재관리!A:J,10,FALSE) -> 27.2 | H21: =G21*E21 -> 81.6 | I21: =G21*F21 -> 1632
B22: 21 | C22: 지골피 | E22: 4 | F22: =E22*$L$15 -> 80 | G22: =VLOOKUP($C22,약재관리!A:J,10,FALSE) -> 21.7 | H22: =G22*E22 -> 86.8 | I22: =G22*F22 -> 1736 | K22: 참고치
B23: 22 | C23: 금은화 | E23: 6 | F23: =E23*$L$15 -> 120 | G23: =VLOOKUP($C23,약재관리!A:J,10,FALSE) -> 43 | H23: =G23*E23 -> 258 | I23: =G23*F23 -> 5160 | K23: cross chk | L23: =SUM(F2:F31) -> 1680 | M23: g
B24: 23 | C24: 치자 | E24: 4 | F24: =E24*$L$15 -> 80 | G24: =VLOOKUP($C24,약재관리!A:J,10,FALSE) -> 26 | H24: =G24*E24 -> 104 | I24: =G24*F24 -> 2080 | K24: 20첩물양 | L24: 5000 | M24: cc
B25: 24 | F25: =E25*$L$15 -> 0 | H25: =G25*E25 -> 0 | I25: =G25*F25 -> 0 | K25: 1첩당 | L25: 80-120 | M25: g
B26: 25 | F26: =E26*$L$15 -> 0 | H26: =G26*E26 -> 0 | I26: =G26*F26 -> 0 | K26: 20첩당 | L26: 1600 | M26: g
B27: 26 | F27: =E27*$L$15 -> 0 | H27: =G27*E27 -> 0 | I27: =G27*F27 -> 0 | K27: 1돈 환산 | L27: 4 | M27: g
B28: 27 | F28: =E28*$L$15 -> 0 | H28: =G28*E28 -> 0 | I28: =G28*F28 -> 0
B29: 28 | F29: =E29*$L$15 -> 0 | H29: =G29*E29 -> 0 | I29: =G29*F29 -> 0 | K29: 금액
B30: 29 | F30: =E30*$L$15 -> 0 | H30: =G30*E30 -> 0 | I30: =G30*F30 -> 0 | K30: 1첩당 | L30: =SUM(H2:H31) -> 2452.6 | M30: 원
B31: 30 | F31: =E31*$L$15 -> 0 | H31: =G31*E31 -> 0 | I31: =G31*F31 -> 0 | K31: 총 | L31: =SUM(I2:I31) -> 49052 | M31: 원

Sheet 청상보하탕 12차
B1: No. | C1: 약재명 | D1: 수치 | E1: 그램 | F1: 총용량 | G1: 1g 금액 | H1: 1첩 금액 | I1: 총 금액 | K1: 기본 정보
B2: 1 | C2: 숙지황 | E2: 4 | F2: =E2*$L$15 -> 80 | G2: =VLOOKUP($C2,#REF!,10,FALSE) -> #REF! | H2: =G2*E2 -> #REF! | I2: =G2*F2 -> #REF! | K2: UNIT | L2: 19
B3: 2 | C3: 산약 | E3: 4 | F3: =E3*$L$15 -> 80 | G3: =VLOOKUP($C3,#REF!,10,FALSE) -> #REF! | H3: =G3*E3 -> #REF! | I3: =G3*F3 -> #REF! | K3: 처방명 | L3: 청상보하탕
B4: 3 | C4: 산수유 | E4: 4 | F4: =E4*$L$15 -> 80 | G4: =VLOOKUP($C4,#REF!,10,FALSE) -> #REF! | H4: =G4*E4 -> #REF! | I4: =G4*F4 -> #REF! | K4: 날짜 | L4: 45737
B5: 4 | C5: 복령 | E5: 4 | F5: =E5*$L$15 -> 80 | G5: =VLOOKUP($C5,#REF!,10,FALSE) -> #REF! | H5: =G5*E5 -> #REF! | I5: =G5*F5 -> #REF! | K5: 이름 | L5: 오명옥
B6: 5 | C6: 택사1 | E6: 4 | F6: =E6*$L$15 -> 80 | G6: =VLOOKUP($C6,#REF!,10,FALSE) -> #REF! | H6: =G6*E6 -> #REF! | I6: =G6*F6 -> #REF! | K6: 나이 | L6: F
B7: 6 | C7: 목단피 | E7: 4 | F7: =E7*$L$15 -> 80 | G7: =VLOOKUP($C7,#REF!,10,FALSE) -> #REF! | H7: =G7*E7 -> #REF! | I7: =G7*F7 -> #REF! | K7: 성별 | L7: 58
B8: 7 | C8: 자완 | E8: 4 | F8: =E8*$L$15 -> 80 | G8: =VLOOKUP($C8,#REF!,10,FALSE) -> #REF! | H8: =G8*E8 -> #REF! | I8: =G8*F8 -> #REF! | K8: 메모
B9: 8 | C9: 백부근 | E9: 4 | F9: =E9*$L$15 -> 80 | G9: =VLOOKUP($C9,#REF!,10,FALSE) -> #REF! | H9: =G9*E9 -> #REF! | I9: =G9*F9 -> #REF! | K9: 천문동 대 천화분
B10: 9 | C10: 지실 | E10: 4 | F10: =E10*$L$15 -> 80 | G10: =VLOOKUP($C10,#REF!,10,FALSE) -> #REF! | H10: =G10*E10 -> #REF! | I10: =G10*F10 -> #REF!
B11: 10 | C11: 맥문동 | E11: 3 | F11: =E11*$L$15 -> 60 | G11: =VLOOKUP($C11,#REF!,10,FALSE) -> #REF! | H11: =G11*E11 -> #REF! | I11: =G11*F11 -> #REF!
B12: 11 | C12: 천화분 | E12: 3 | F12: =E12*$L$15 -> 60 | G12: =VLOOKUP($C12,#REF!,10,FALSE) -> #REF! | H12: =G12*E12 -> #REF! | I12: =G12*F12 -> #REF!
B13: 12 | C13: 오미자 | E13: 3 | F13: =E13*$L$15 -> 60 | G13: =VLOOKUP($C13,#REF!,10,FALSE) -> #REF! | H13: =G13*E13 -> #REF! | I13: =G13*F13 -> #REF!
B14: 13 | C14: 과루인 | E14: 3 | F14: =E14*$L$15 -> 60 | G14: =VLOOKUP($C14,#REF!,10,FALSE) -> #REF! | H14: =G14*E14 -> #REF! | I14: =G14*F14 -> #REF! | K14: 총 일수 | L14: 15 | M14: 일분
B15: 14 | C15: 반하 | E15: 6 | F15: =E15*$L$15 -> 120 | G15: =VLOOKUP($C15,#REF!,10,FALSE) -> #REF! | H15: =G15*E15 -> #REF! | I15: =G15*F15 -> #REF! | K15: 첩수 | L15: 20 | M15: 첩
B16: 15 | C16: 황금 | E16: 4 | F16: =E16*$L$15 -> 80 | G16: =VLOOKUP($C16,#REF!,10,FALSE) -> #REF! | H16: =G16*E16 -> #REF! | I16: =G16*F16 -> #REF! | K16: 총 팩수 | L16: 45 | M16: 팩
B17: 16 | C17: 황련 | E17: 4 | F17: =E17*$L$15 -> 80 | G17: =VLOOKUP($C17,#REF!,10,FALSE) -> #REF! | H17: =G17*E17 -> #REF! | I17: =G17*F17 -> #REF! | K17: 팩당 물량 | L17: 100 | M17: cc
B18: 17 | C18: 패모 | E18: 6 | F18: =E18*$L$15 -> 120 | G18: =VLOOKUP($C18,#REF!,10,FALSE) -> #REF! | H18: =G18*E18 -> #REF! | I18: =G18*F18 -> #REF! | K18: 1첩당약재 | L18: =SUM(E2:E31) -> 102 | M18: g
B19: 18 | C19: 길경 | E19: 6 | F19: =E19*$L$15 -> 120 | G19: =VLOOKUP($C19,#REF!,10,FALSE) -> #REF! | H19: =G19*E19 -> #REF! | I19: =G19*F19 -> #REF! | K19: 약재총량 | L19: =L15*L18 -> 2040 | M19: g
B20: 19 | C20: 행인 | E20: 4 | F20: =E20*$L$15 -> 80 | G20: =VLOOKUP($C20,#REF!,10,FALSE) -> #REF! | H20: =G20*E20 -> #REF! | I20: =G20*F20 -> #REF! | K20: 총 물 양 | L20: =L16*L17+L19 -> 6540 | M20: cc
B21: 20 | C21: 관동화 | E21: 4 | F21: =E21*$L$15 -> 80 | G21: =VLOOKUP($C21,#REF!,10,FALSE) -> #REF! | H21: =G21*E21 -> #REF! | I21: =G21*F21 -> #REF!
B22: 21 | C22: 창출1 | E22: 6 | F22: =E22*$L$15 -> 120 | G22: =VLOOKUP($C22,#REF!,10,FALSE) -> #REF! | H22: =G22*E22 -> #REF! | I22: =G22*F22 -> #REF! | K22: 참고치
B23: 22 | C23: 나복자 | E23: 4 | F23: =E23*$L$15 -> 80 | G23: =VLOOKUP($C23,#REF!,10,FALSE) -> #REF! | H23: =G23*E23 -> #REF! | I23: =G23*F23 -> #REF! | K23: cross chk | L23: =SUM(F2:F31) -> 2040 | M23: g
B24: 23 | C24: 전호 | E24: 6 | F24: =E24*$L$15 -> 120 | G24: =VLOOKUP($C24,#REF!,10,FALSE) -> #REF! | H24: =G24*E24 -> #REF! | I24: =G24*F24 -> #REF! | K24: 20첩물양 | L24: 5000 | M24: cc
B25: 24 | C25: 신곡 | E25: 4 | F25: =E25*$L$15 -> 80 | G25: =VLOOKUP($C25,#REF!,10,FALSE) -> #REF! | H25: =G25*E25 -> #REF! | I25: =G25*F25 -> #REF! | K25: 1첩당 | L25: 80-120 | M25: g
B26: 25 | F26: =E26*$L$15 -> 0 | H26: =G26*E26 -> 0 | I26: =G26*F26 -> 0 | K26: 20첩당 | L26: 1600 | M26: g
B27: 26 | F27: =E27*$L$15 -> 0 | H27: =G27*E27 -> 0 | I27: =G27*F27 -> 0 | K27: 1돈 환산 | L27: 4 | M27: g
B28: 27 | F28: =E28*$L$15 -> 0 | H28: =G28*E28 -> 0 | I28: =G28*F28 -> 0
B29: 28 | F29: =E29*$L$15 -> 0 | H29: =G29*E29 -> 0 | I29: =G29*F29 -> 0 | K29: 금액
B30: 29 | F30: =E30*$L$15 -> 0 | H30: =G30*E30 -> 0 | I30: =G30*F30 -> 0 | K30: 1첩당 | L30: =SUM(H2:H31) -> #REF! | M30: 원
B31: 30 | F31: =E31*$L$15 -> 0 | H31: =G31*E31 -> 0 | I31: =G31*F31 -> 0 | K31: 총 | L31: =SUM(I2:I31) -> #REF! | M31: 원

Sheet 청상보하탕 11차
B1: No. | C1: 약재명 | D1: 수치 | E1: 그램 | F1: 총용량 | G1: 1g 금액 | H1: 1첩 금액 | I1: 총 금액 | K1: 기본 정보
B2: 1 | C2: 숙지황 | E2: 4 | F2: =E2*$L$15 -> 80 | G2: =VLOOKUP($C2,#REF!,10,FALSE) -> #REF! | H2: =G2*E2 -> #REF! | I2: =G2*F2 -> #REF! | K2: UNIT | L2: 19
B3: 2 | C3: 산약 | E3: 4 | F3: =E3*$L$15 -> 80 | G3: =VLOOKUP($C3,#REF!,10,FALSE) -> #REF! | H3: =G3*E3 -> #REF! | I3: =G3*F3 -> #REF! | K3: 처방명 | L3: 청상보하탕
B4: 3 | C4: 산수유 | E4: 4 | F4: =E4*$L$15 -> 80 | G4: =VLOOKUP($C4,#REF!,10,FALSE) -> #REF! | H4: =G4*E4 -> #REF! | I4: =G4*F4 -> #REF! | K4: 날짜 | L4: 45737
B5: 4 | C5: 복령 | E5: 4 | F5: =E5*$L$15 -> 80 | G5: =VLOOKUP($C5,#REF!,10,FALSE) -> #REF! | H5: =G5*E5 -> #REF! | I5: =G5*F5 -> #REF! | K5: 이름 | L5: 오명옥
B6: 5 | C6: 택사1 | E6: 4 | F6: =E6*$L$15 -> 80 | G6: =VLOOKUP($C6,#REF!,10,FALSE) -> #REF! | H6: =G6*E6 -> #REF! | I6: =G6*F6 -> #REF! | K6: 나이 | L6: F
B7: 6 | C7: 목단피 | E7: 4 | F7: =E7*$L$15 -> 80 | G7: =VLOOKUP($C7,#REF!,10,FALSE) -> #REF! | H7: =G7*E7 -> #REF! | I7: =G7*F7 -> #REF! | K7: 성별 | L7: 58
B8: 7 | C8: 자완 | E8: 4 | F8: =E8*$L$15 -> 80 | G8: =VLOOKUP($C8,#REF!,10,FALSE) -> #REF! | H8: =G8*E8 -> #REF! | I8: =G8*F8 -> #REF! | K8: 메모
B9: 8 | C9: 백부근 | E9: 4 | F9: =E9*$L$15 -> 80 | G9: =VLOOKUP($C9,#REF!,10,FALSE) -> #REF! | H9: =G9*E9 -> #REF! | I9: =G9*F9 -> #REF! | K9: 육미감량
B10: 9 | C10: 지실 | E10: 4 | F10: =E10*$L$15 -> 80 | G10: =VLOOKUP($C10,#REF!,10,FALSE) -> #REF! | H10: =G10*E10 -> #REF! | I10: =G10*F10 -> #REF!
B11: 10 | C11: 맥문동 | E11: 3 | F11: =E11*$L$15 -> 60 | G11: =VLOOKUP($C11,#REF!,10,FALSE) -> #REF! | H11: =G11*E11 -> #REF! | I11: =G11*F11 -> #REF!
B12: 11 | C12: 천문동 | E12: 3 | F12: =E12*$L$15 -> 60 | G12: =VLOOKUP($C12,#REF!,10,FALSE) -> #REF! | H12: =G12*E12 -> #REF! | I12: =G12*F12 -> #REF!
B13: 12 | C13: 오미자 | E13: 3 | F13: =E13*$L$15 -> 60 | G13: =VLOOKUP($C13,#REF!,10,FALSE) -> #REF! | H13: =G13*E13 -> #REF! | I13: =G13*F13 -> #REF!
B14: 13 | C14: 과루인 | E14: 3 | F14: =E14*$L$15 -> 60 | G14: =VLOOKUP($C14,#REF!,10,FALSE) -> #REF! | H14: =G14*E14 -> #REF! | I14: =G14*F14 -> #REF! | K14: 총 일수 | L14: 15 | M14: 일분
B15: 14 | C15: 반하 | E15: 4 | F15: =E15*$L$15 -> 80 | G15: =VLOOKUP($C15,#REF!,10,FALSE) -> #REF! | H15: =G15*E15 -> #REF! | I15: =G15*F15 -> #REF! | K15: 첩수 | L15: 20 | M15: 첩
B16: 15 | C16: 황금 | E16: 4 | F16: =E16*$L$15 -> 80 | G16: =VLOOKUP($C16,#REF!,10,FALSE) -> #REF! | H16: =G16*E16 -> #REF! | I16: =G16*F16 -> #REF! | K16: 총 팩수 | L16: 45 | M16: 팩
B17: 16 | C17: 황련 | E17: 4 | F17: =E17*$L$15 -> 80 | G17: =VLOOKUP($C17,#REF!,10,FALSE) -> #REF! | H17: =G17*E17 -> #REF! | I17: =G17*F17 -> #REF! | K17: 팩당 물량 | L17: 100 | M17: cc
B18: 17 | C18: 패모 | E18: 4 | F18: =E18*$L$15 -> 80 | G18: =VLOOKUP($C18,#REF!,10,FALSE) -> #REF! | H18: =G18*E18 -> #REF! | I18: =G18*F18 -> #REF! | K18: 1첩당약재 | L18: =SUM(E2:E31) -> 94 | M18: g
B19: 18 | C19: 길경 | E19: 6 | F19: =E19*$L$15 -> 120 | G19: =VLOOKUP($C19,#REF!,10,FALSE) -> #REF! | H19: =G19*E19 -> #REF! | I19: =G19*F19 -> #REF! | K19: 약재총량 | L19: =L15*L18 -> 1880 | M19: g
B20: 19 | C20: 행인 | E20: 4 | F20: =E20*$L$15 -> 80 | G20: =VLOOKUP($C20,#REF!,10,FALSE) -> #REF! | H20: =G20*E20 -> #REF! | I20: =G20*F20 -> #REF! | K20: 총 물 양 | L20: =L16*L17+L19 -> 6380 | M20: cc
B21: 20 | C21: 관동화 | E21: 4 | F21: =E21*$L$15 -> 80 | G21: =VLOOKUP($C21,#REF!,10,FALSE) -> #REF! | H21: =G21*E21 -> #REF! | I21: =G21*F21 -> #REF!
B22: 21 | C22: 금은화 | E22: 6 | F22: =E22*$L$15 -> 120 | G22: =VLOOKUP($C22,#REF!,10,FALSE) -> #REF! | H22: =G22*E22 -> #REF! | I22: =G22*F22 -> #REF! | K22: 참고치
B23: 22 | C23: 나복자 | E23: 4 | F23: =E23*$L$15 -> 80 | G23: =VLOOKUP($C23,#REF!,10,FALSE) -> #REF! | H23: =G23*E23 -> #REF! | I23: =G23*F23 -> #REF! | K23: cross chk | L23: =SUM(F2:F31) -> 1880 | M23: g
B24: 23 | C24: 소자 | E24: 4 | F24: =E24*$L$15 -> 80 | G24: =VLOOKUP($C24,#REF!,10,FALSE) -> #REF! | H24: =G24*E24 -> #REF! | I24: =G24*F24 -> #REF! | K24: 20첩물양 | L24: 5000 | M24: cc
B25: 24 | C25: 백개자 | E25: 2 | F25: =E25*$L$15 -> 40 | G25: =VLOOKUP($C25,#REF!,10,FALSE) -> #REF! | H25: =G25*E25 -> #REF! | I25: =G25*F25 -> #REF! | K25: 1첩당 | L25: 80-120 | M25: g
B26: 25 | F26: =E26*$L$15 -> 0 | H26: =G26*E26 -> 0 | I26: =G26*F26 -> 0 | K26: 20첩당 | L26: 1600 | M26: g
B27: 26 | F27: =E27*$L$15 -> 0 | H27: =G27*E27 -> 0 | I27: =G27*F27 -> 0 | K27: 1돈 환산 | L27: 4 | M27: g
B28: 27 | F28: =E28*$L$15 -> 0 | H28: =G28*E28 -> 0 | I28: =G28*F28 -> 0
B29: 28 | F29: =E29*$L$15 -> 0 | H29: =G29*E29 -> 0 | I29: =G29*F29 -> 0 | K29: 금액
B30: 29 | F30: =E30*$L$15 -> 0 | H30: =G30*E30 -> 0 | I30: =G30*F30 -> 0 | K30: 1첩당 | L30: =SUM(H2:H31) -> #REF! | M30: 원
B31: 30 | F31: =E31*$L$15 -> 0 | H31: =G31*E31 -> 0 | I31: =G31*F31 -> 0 | K31: 총 | L31: =SUM(I2:I31) -> #REF! | M31: 원

Sheet 청상보하탕 10차
B1: No. | C1: 약재명 | D1: 수치 | E1: 그램 | F1: 총용량 | G1: 1g 금액 | H1: 1첩 금액 | I1: 총 금액 | K1: 기본 정보
B2: 1 | C2: 숙지황 | E2: 6 | F2: =E2*$L$15 -> 240 | G2: =VLOOKUP($C2,#REF!,10,FALSE) -> #REF! | H2: =G2*E2 -> #REF! | I2: =G2*F2 -> #REF! | K2: UNIT | L2: 19
B3: 2 | C3: 산약 | E3: 6 | F3: =E3*$L$15 -> 240 | G3: =VLOOKUP($C3,#REF!,10,FALSE) -> #REF! | H3: =G3*E3 -> #REF! | I3: =G3*F3 -> #REF! | K3: 처방명 | L3: 청상보하탕
B4: 3 | C4: 산수유 | E4: 6 | F4: =E4*$L$15 -> 240 | G4: =VLOOKUP($C4,#REF!,10,FALSE) -> #REF! | H4: =G4*E4 -> #REF! | I4: =G4*F4 -> #REF! | K4: 날짜 | L4: 45721
B5: 4 | C5: 복령 | E5: 4 | F5: =E5*$L$15 -> 160 | G5: =VLOOKUP($C5,#REF!,10,FALSE) -> #REF! | H5: =G5*E5 -> #REF! | I5: =G5*F5 -> #REF! | K5: 이름 | L5: 오명옥
B6: 5 | C6: 택사1 | E6: 4 | F6: =E6*$L$15 -> 160 | G6: =VLOOKUP($C6,#REF!,10,FALSE) -> #REF! | H6: =G6*E6 -> #REF! | I6: =G6*F6 -> #REF! | K6: 나이 | L6: F
B7: 6 | C7: 목단피 | E7: 4 | F7: =E7*$L$15 -> 160 | G7: =VLOOKUP($C7,#REF!,10,FALSE) -> #REF! | H7: =G7*E7 -> #REF! | I7: =G7*F7 -> #REF! | K7: 성별 | L7: 58
B8: 7 | C8: 자완 | E8: 4 | F8: =E8*$L$15 -> 160 | G8: =VLOOKUP($C8,#REF!,10,FALSE) -> #REF! | H8: =G8*E8 -> #REF! | I8: =G8*F8 -> #REF! | K8: 메모
B9: 8 | C9: 백부근 | E9: 4 | F9: =E9*$L$15 -> 160 | G9: =VLOOKUP($C9,#REF!,10,FALSE) -> #REF! | H9: =G9*E9 -> #REF! | I9: =G9*F9 -> #REF! | K9: 9차약과 동일
B10: 9 | C10: 지실 | E10: 3 | F10: =E10*$L$15 -> 120 | G10: =VLOOKUP($C10,#REF!,10,FALSE) -> #REF! | H10: =G10*E10 -> #REF! | I10: =G10*F10 -> #REF!
B11: 10 | C11: 맥문동 | E11: 3 | F11: =E11*$L$15 -> 120 | G11: =VLOOKUP($C11,#REF!,10,FALSE) -> #REF! | H11: =G11*E11 -> #REF! | I11: =G11*F11 -> #REF!
B12: 11 | C12: 천문동 | E12: 3 | F12: =E12*$L$15 -> 120 | G12: =VLOOKUP($C12,#REF!,10,FALSE) -> #REF! | H12: =G12*E12 -> #REF! | I12: =G12*F12 -> #REF!
B13: 12 | C13: 오미자 | E13: 3 | F13: =E13*$L$15 -> 120 | G13: =VLOOKUP($C13,#REF!,10,FALSE) -> #REF! | H13: =G13*E13 -> #REF! | I13: =G13*F13 -> #REF!
B14: 13 | C14: 과루인 | E14: 3 | F14: =E14*$L$15 -> 120 | G14: =VLOOKUP($C14,#REF!,10,FALSE) -> #REF! | H14: =G14*E14 -> #REF! | I14: =G14*F14 -> #REF! | K14: 총 일수 | L14: 30 | M14: 일분
B15: 14 | C15: 반하 | E15: 4 | F15: =E15*$L$15 -> 160 | G15: =VLOOKUP($C15,#REF!,10,FALSE) -> #REF! | H15: =G15*E15 -> #REF! | I15: =G15*F15 -> #REF! | K15: 첩수 | L15: 40 | M15: 첩
B16: 15 | C16: 황금 | E16: 3 | F16: =E16*$L$15 -> 120 | G16: =VLOOKUP($C16,#REF!,10,FALSE) -> #REF! | H16: =G16*E16 -> #REF! | I16: =G16*F16 -> #REF! | K16: 총 팩수 | L16: 90 | M16: 팩
B17: 16 | C17: 황련 | E17: 3 | F17: =E17*$L$15 -> 120 | G17: =VLOOKUP($C17,#REF!,10,FALSE) -> #REF! | H17: =G17*E17 -> #REF! | I17: =G17*F17 -> #REF! | K17: 팩당 물량 | L17: 100 | M17: cc
B18: 17 | C18: 패모 | E18: 4 | F18: =E18*$L$15 -> 160 | G18: =VLOOKUP($C18,#REF!,10,FALSE) -> #REF! | H18: =G18*E18 -> #REF! | I18: =G18*F18 -> #REF! | K18: 1첩당약재 | L18: =SUM(E2:E31) -> 89 | M18: g
B19: 18 | C19: 길경 | E19: 4 | F19: =E19*$L$15 -> 160 | G19: =VLOOKUP($C19,#REF!,10,FALSE) -> #REF! | H19: =G19*E19 -> #REF! | I19: =G19*F19 -> #REF! | K19: 약재총량 | L19: =L15*L18 -> 3560 | M19: g
B20: 19 | C20: 행인 | E20: 4 | F20: =E20*$L$15 -> 160 | G20: =VLOOKUP($C20,#REF!,10,FALSE) -> #REF! | H20: =G20*E20 -> #REF! | I20: =G20*F20 -> #REF! | K20: 총 물 양 | L20: =L16*L17+L19 -> 12560 | M20: cc
B21: 20 | C21: 감초 | E21: 2 | F21: =E21*$L$15 -> 80 | G21: =VLOOKUP($C21,#REF!,10,FALSE) -> #REF! | H21: =G21*E21 -> #REF! | I21: =G21*F21 -> #REF!
B22: 21 | C22: 죽여1 | E22: 4 | F22: =E22*$L$15 -> 160 | G22: =VLOOKUP($C22,#REF!,10,FALSE) -> #REF! | H22: =G22*E22 -> #REF! | I22: =G22*F22 -> #REF! | K22: 참고치
B23: 22 | C23: 생강 | E23: 4 | F23: =E23*$L$15 -> 160 | G23: =VLOOKUP($C23,#REF!,10,FALSE) -> #REF! | H23: =G23*E23 -> #REF! | I23: =G23*F23 -> #REF! | K23: cross chk | L23: =SUM(F2:F31) -> 3560 | M23: g
B24: 23 | C24: 치자 | D24: 초 | E24: 4 | F24: =E24*$L$15 -> 160 | G24: =VLOOKUP($C24,#REF!,10,FALSE) -> #REF! | H24: =G24*E24 -> #REF! | I24: =G24*F24 -> #REF! | K24: 20첩물양 | L24: 5000 | M24: cc
B25: 24 | F25: =E25*$L$15 -> 0 | H25: =G25*E25 -> 0 | I25: =G25*F25 -> 0 | K25: 1첩당 | L25: 80-120 | M25: g
B26: 25 | F26: =E26*$L$15 -> 0 | H26: =G26*E26 -> 0 | I26: =G26*F26 -> 0 | K26: 20첩당 | L26: 1600 | M26: g
B27: 26 | F27: =E27*$L$15 -> 0 | H27: =G27*E27 -> 0 | I27: =G27*F27 -> 0 | K27: 1돈 환산 | L27: 4 | M27: g
B28: 27 | F28: =E28*$L$15 -> 0 | H28: =G28*E28 -> 0 | I28: =G28*F28 -> 0
B29: 28 | F29: =E29*$L$15 -> 0 | H29: =G29*E29 -> 0 | I29: =G29*F29 -> 0 | K29: 금액
B30: 29 | F30: =E30*$L$15 -> 0 | H30: =G30*E30 -> 0 | I30: =G30*F30 -> 0 | K30: 1첩당 | L30: =SUM(H2:H31) -> #REF! | M30: 원
B31: 30 | F31: =E31*$L$15 -> 0 | H31: =G31*E31 -> 0 | I31: =G31*F31 -> 0 | K31: 총 | L31: =SUM(I2:I31) -> #REF! | M31: 원

Sheet 청상보하탕 9차
B1: No. | C1: 약재명 | D1: 수치 | E1: 그램 | F1: 총용량 | G1: 1g 금액 | H1: 1첩 금액 | I1: 총 금액 | K1: 기본 정보
B2: 1 | C2: 숙지황 | E2: 6 | F2: =E2*$L$15 -> 150 | G2: =VLOOKUP($C2,#REF!,10,FALSE) -> #REF! | H2: =G2*E2 -> #REF! | I2: =G2*F2 -> #REF! | K2: UNIT | L2: 19
B3: 2 | C3: 산약 | E3: 6 | F3: =E3*$L$15 -> 150 | G3: =VLOOKUP($C3,#REF!,10,FALSE) -> #REF! | H3: =G3*E3 -> #REF! | I3: =G3*F3 -> #REF! | K3: 처방명 | L3: 청상보하탕
B4: 3 | C4: 산수유 | E4: 6 | F4: =E4*$L$15 -> 150 | G4: =VLOOKUP($C4,#REF!,10,FALSE) -> #REF! | H4: =G4*E4 -> #REF! | I4: =G4*F4 -> #REF! | K4: 날짜 | L4: 45696
B5: 4 | C5: 복령 | E5: 4 | F5: =E5*$L$15 -> 100 | G5: =VLOOKUP($C5,#REF!,10,FALSE) -> #REF! | H5: =G5*E5 -> #REF! | I5: =G5*F5 -> #REF! | K5: 이름 | L5: 오명옥
B6: 5 | C6: 택사1 | E6: 4 | F6: =E6*$L$15 -> 100 | G6: =VLOOKUP($C6,#REF!,10,FALSE) -> #REF! | H6: =G6*E6 -> #REF! | I6: =G6*F6 -> #REF! | K6: 나이 | L6: F
B7: 6 | C7: 목단피 | E7: 4 | F7: =E7*$L$15 -> 100 | G7: =VLOOKUP($C7,#REF!,10,FALSE) -> #REF! | H7: =G7*E7 -> #REF! | I7: =G7*F7 -> #REF! | K7: 성별 | L7: 58
B8: 7 | C8: 자완 | E8: 4 | F8: =E8*$L$15 -> 100 | G8: =VLOOKUP($C8,#REF!,10,FALSE) -> #REF! | H8: =G8*E8 -> #REF! | I8: =G8*F8 -> #REF! | K8: 메모
B9: 8 | C9: 백부근 | E9: 4 | F9: =E9*$L$15 -> 100 | G9: =VLOOKUP($C9,#REF!,10,FALSE) -> #REF! | H9: =G9*E9 -> #REF! | I9: =G9*F9 -> #REF! | K9: 3차약 - 과루인감량 진피대생강 #흉민, 담다
B10: 9 | C10: 지실 | E10: 3 | F10: =E10*$L$15 -> 75 | G10: =VLOOKUP($C10,#REF!,10,FALSE) -> #REF! | H10: =G10*E10 -> #REF! | I10: =G10*F10 -> #REF!
B11: 10 | C11: 맥문동 | E11: 3 | F11: =E11*$L$15 -> 75 | G11: =VLOOKUP($C11,#REF!,10,FALSE) -> #REF! | H11: =G11*E11 -> #REF! | I11: =G11*F11 -> #REF!
B12: 11 | C12: 천문동 | E12: 3 | F12: =E12*$L$15 -> 75 | G12: =VLOOKUP($C12,#REF!,10,FALSE) -> #REF! | H12: =G12*E12 -> #REF! | I12: =G12*F12 -> #REF!
B13: 12 | C13: 오미자 | E13: 3 | F13: =E13*$L$15 -> 75 | G13: =VLOOKUP($C13,#REF!,10,FALSE) -> #REF! | H13: =G13*E13 -> #REF! | I13: =G13*F13 -> #REF!
B14: 13 | C14: 과루인 | E14: 3 | F14: =E14*$L$15 -> 75 | G14: =VLOOKUP($C14,#REF!,10,FALSE) -> #REF! | H14: =G14*E14 -> #REF! | I14: =G14*F14 -> #REF! | K14: 총 일수 | L14: 20 | M14: 일분
B15: 14 | C15: 반하 | E15: 4 | F15: =E15*$L$15 -> 100 | G15: =VLOOKUP($C15,#REF!,10,FALSE) -> #REF! | H15: =G15*E15 -> #REF! | I15: =G15*F15 -> #REF! | K15: 첩수 | L15: 25 | M15: 첩
B16: 15 | C16: 황금 | E16: 3 | F16: =E16*$L$15 -> 75 | G16: =VLOOKUP($C16,#REF!,10,FALSE) -> #REF! | H16: =G16*E16 -> #REF! | I16: =G16*F16 -> #REF! | K16: 총 팩수 | L16: 60 | M16: 팩
B17: 16 | C17: 황련 | E17: 3 | F17: =E17*$L$15 -> 75 | G17: =VLOOKUP($C17,#REF!,10,FALSE) -> #REF! | H17: =G17*E17 -> #REF! | I17: =G17*F17 -> #REF! | K17: 팩당 물량 | L17: 100 | M17: cc
B18: 17 | C18: 패모 | E18: 4 | F18: =E18*$L$15 -> 100 | G18: =VLOOKUP($C18,#REF!,10,FALSE) -> #REF! | H18: =G18*E18 -> #REF! | I18: =G18*F18 -> #REF! | K18: 1첩당약재 | L18: =SUM(E2:E31) -> 89 | M18: g
B19: 18 | C19: 길경 | E19: 4 | F19: =E19*$L$15 -> 100 | G19: =VLOOKUP($C19,#REF!,10,FALSE) -> #REF! | H19: =G19*E19 -> #REF! | I19: =G19*F19 -> #REF! | K19: 약재총량 | L19: =L15*L18 -> 2225 | M19: g
B20: 19 | C20: 행인 | E20: 4 | F20: =E20*$L$15 -> 100 | G20: =VLOOKUP($C20,#REF!,10,FALSE) -> #REF! | H20: =G20*E20 -> #REF! | I20: =G20*F20 -> #REF! | K20: 총 물 양 | L20: =L16*L17+L19 -> 8225 | M20: cc
B21: 20 | C21: 감초 | E21: 2 | F21: =E21*$L$15 -> 50 | G21: =VLOOKUP($C21,#REF!,10,FALSE) -> #REF! | H21: =G21*E21 -> #REF! | I21: =G21*F21 -> #REF!
B22: 21 | C22: 죽여1 | E22: 4 | F22: =E22*$L$15 -> 100 | G22: =VLOOKUP($C22,#REF!,10,FALSE) -> #REF! | H22: =G22*E22 -> #REF! | I22: =G22*F22 -> #REF! | K22: 참고치
B23: 22 | C23: 생강 | E23: 4 | F23: =E23*$L$15 -> 100 | G23: =VLOOKUP($C23,#REF!,10,FALSE) -> #REF! | H23: =G23*E23 -> #REF! | I23: =G23*F23 -> #REF! | K23: cross chk | L23: =SUM(F2:F31) -> 2225 | M23: g
B24: 23 | C24: 치자 | D24: 초 | E24: 4 | F24: =E24*$L$15 -> 100 | G24: =VLOOKUP($C24,#REF!,10,FALSE) -> #REF! | H24: =G24*E24 -> #REF! | I24: =G24*F24 -> #REF! | K24: 20첩물양 | L24: 5000 | M24: cc
B25: 24 | F25: =E25*$L$15 -> 0 | H25: =G25*E25 -> 0 | I25: =G25*F25 -> 0 | K25: 1첩당 | L25: 80-120 | M25: g
B26: 25 | F26: =E26*$L$15 -> 0 | H26: =G26*E26 -> 0 | I26: =G26*F26 -> 0 | K26: 20첩당 | L26: 1600 | M26: g
B27: 26 | F27: =E27*$L$15 -> 0 | H27: =G27*E27 -> 0 | I27: =G27*F27 -> 0 | K27: 1돈 환산 | L27: 4 | M27: g
B28: 27 | F28: =E28*$L$15 -> 0 | H28: =G28*E28 -> 0 | I28: =G28*F28 -> 0
B29: 28 | F29: =E29*$L$15 -> 0 | H29: =G29*E29 -> 0 | I29: =G29*F29 -> 0 | K29: 금액
B30: 29 | F30: =E30*$L$15 -> 0 | H30: =G30*E30 -> 0 | I30: =G30*F30 -> 0 | K30: 1첩당 | L30: =SUM(H2:H31) -> #REF! | M30: 원
B31: 30 | F31: =E31*$L$15 -> 0 | H31: =G31*E31 -> 0 | I31: =G31*F31 -> 0 | K31: 총 | L31: =SUM(I2:I31) -> #REF! | M31: 원

Sheet 청상보하탕 8차
B1: No. | C1: 약재명 | D1: 수치 | E1: 그램 | F1: 총용량 | G1: 1g 금액 | H1: 1첩 금액 | I1: 총 금액 | K1: 기본 정보
B2: 1 | C2: 숙지황 | E2: 8 | F2: =E2*$L$15 -> 160 | G2: =VLOOKUP($C2,#REF!,10,FALSE) -> #REF! | H2: =G2*E2 -> #REF! | I2: =G2*F3 -> #REF! | K2: UNIT | L2: 19
B3: 2 | C3: 진피1 | E3: 4 | F3: =E3*$L$15 -> 80 | G3: =VLOOKUP($C3,#REF!,10,FALSE) -> #REF! | H3: =G3*E3 -> #REF! | I3: =G3*F4 -> #REF! | K3: 처방명 | L3: 청상보하탕
B4: 3 | C4: 산수유 | E4: 6 | F4: =E4*$L$15 -> 120 | G4: =VLOOKUP($C4,#REF!,10,FALSE) -> #REF! | H4: =G4*E4 -> #REF! | I4: =G4*F4 -> #REF! | K4: 날짜 | L4: 45677
B5: 4 | C5: 복령 | E5: 6 | F5: =E5*$L$15 -> 120 | G5: =VLOOKUP($C5,#REF!,10,FALSE) -> #REF! | H5: =G5*E5 -> #REF! | I5: =G5*F5 -> #REF! | K5: 이름 | L5: 오명옥
B6: 5 | C6: 택사1 | E6: 6 | F6: =E6*$L$15 -> 120 | G6: =VLOOKUP($C6,#REF!,10,FALSE) -> #REF! | H6: =G6*E6 -> #REF! | I6: =G6*F6 -> #REF! | K6: 나이 | L6: F
B7: 6 | C7: 목단피 | E7: 6 | F7: =E7*$L$15 -> 120 | G7: =VLOOKUP($C7,#REF!,10,FALSE) -> #REF! | H7: =G7*E7 -> #REF! | I7: =G7*F7 -> #REF! | K7: 성별 | L7: 58
B8: 7 | C8: 자완 | E8: 4 | F8: =E8*$L$15 -> 80 | G8: =VLOOKUP($C8,#REF!,10,FALSE) -> #REF! | H8: =G8*E8 -> #REF! | I8: =G8*F8 -> #REF! | K8: 메모
B9: 8 | C9: 백부근 | E9: 4 | F9: =E9*$L$15 -> 80 | G9: =VLOOKUP($C9,#REF!,10,FALSE) -> #REF! | H9: =G9*E9 -> #REF! | I9: =G9*F9 -> #REF! | K9: 7차약 - 치자 + 황련, 숙지황 증량 + 진피
B10: 9 | C10: 지실 | E10: 4 | F10: =E10*$L$15 -> 80 | G10: =VLOOKUP($C10,#REF!,10,FALSE) -> #REF! | H10: =G10*E10 -> #REF! | I10: =G10*F10 -> #REF!
B11: 10 | C11: 맥문동 | E11: 3 | F11: =E11*$L$15 -> 60 | G11: =VLOOKUP($C11,#REF!,10,FALSE) -> #REF! | H11: =G11*E11 -> #REF! | I11: =G11*F11 -> #REF!
B12: 11 | C12: 천문동 | E12: 3 | F12: =E12*$L$15 -> 60 | G12: =VLOOKUP($C12,#REF!,10,FALSE) -> #REF! | H12: =G12*E12 -> #REF! | I12: =G12*F12 -> #REF!
B13: 12 | C13: 오미자 | E13: 3 | F13: =E13*$L$15 -> 60 | G13: =VLOOKUP($C13,#REF!,10,FALSE) -> #REF! | H13: =G13*E13 -> #REF! | I13: =G13*F13 -> #REF!
B14: 13 | C14: 과루인 | E14: 3 | F14: =E14*$L$15 -> 60 | G14: =VLOOKUP($C14,#REF!,10,FALSE) -> #REF! | H14: =G14*E14 -> #REF! | I14: =G14*F14 -> #REF! | K14: 총 일수 | L14: 15 | M14: 일분
B15: 14 | C15: 반하 | E15: 2 | F15: =E15*$L$15 -> 40 | G15: =VLOOKUP($C15,#REF!,10,FALSE) -> #REF! | H15: =G15*E15 -> #REF! | I15: =G15*F15 -> #REF! | K15: 첩수 | L15: 20 | M15: 첩
B16: 15 | C16: 황금 | E16: 3 | F16: =E16*$L$15 -> 60 | G16: =VLOOKUP($C16,#REF!,10,FALSE) -> #REF! | H16: =G16*E16 -> #REF! | I16: =G16*F16 -> #REF! | K16: 총 팩수 | L16: 45 | M16: 팩
B17: 16 | C17: 황련 | E17: 3 | F17: =E17*$L$15 -> 60 | G17: =VLOOKUP($C17,#REF!,10,FALSE) -> #REF! | H17: =G17*E17 -> #REF! | I17: =G17*F17 -> #REF! | K17: 팩당 물량 | L17: 100 | M17: cc
B18: 17 | C18: 패모 | E18: 3 | F18: =E18*$L$15 -> 60 | G18: =VLOOKUP($C18,#REF!,10,FALSE) -> #REF! | H18: =G18*E18 -> #REF! | I18: =G18*F18 -> #REF! | K18: 1첩당약재 | L18: =SUM(E2:E31) -> 92 | M18: g
B19: 18 | C19: 길경 | E19: 3 | F19: =E19*$L$15 -> 60 | G19: =VLOOKUP($C19,#REF!,10,FALSE) -> #REF! | H19: =G19*E19 -> #REF! | I19: =G19*F19 -> #REF! | K19: 약재총량 | L19: =L15*L18 -> 1840 | M19: g
B20: 19 | C20: 행인 | E20: 4 | F20: =E20*$L$15 -> 80 | G20: =VLOOKUP($C20,#REF!,10,FALSE) -> #REF! | H20: =G20*E20 -> #REF! | I20: =G20*F20 -> #REF! | K20: 총 물 양 | L20: =L16*L17+L19 -> 6340 | M20: cc
B21: 20 | C21: 감초 | E21: 2 | F21: =E21*$L$15 -> 40 | G21: =VLOOKUP($C21,#REF!,10,FALSE) -> #REF! | H21: =G21*E21 -> #REF! | I21: =G21*F21 -> #REF!
B22: 21 | C22: 마자인 | E22: 6 | F22: =E22*$L$15 -> 120 | G22: =VLOOKUP($C22,#REF!,10,FALSE) -> #REF! | H22: =G22*E22 -> #REF! | I22: =G22*F22 -> #REF! | K22: 참고치
B23: 22 | C23: 신곡 | E23: 3 | F23: =E23*$L$15 -> 60 | G23: =VLOOKUP($C23,#REF!,10,FALSE) -> #REF! | H23: =G23*E23 -> #REF! | I23: =G23*F23 -> #REF! | K23: cross chk | L23: =SUM(F3:F31) -> 1680 | M23: g
B24: 23 | C24: 맥아 | E24: 3 | F24: =E24*$L$15 -> 60 | G24: =VLOOKUP($C24,#REF!,10,FALSE) -> #REF! | H24: =G24*E24 -> #REF! | I24: =G24*F24 -> #REF! | K24: 20첩물양 | L24: 5000 | M24: cc
B25: 24 | F25: =E25*$L$15 -> 0 | H25: =G25*E25 -> 0 | I25: =G25*F25 -> 0 | K25: 1첩당 | L25: 80-120 | M25: g
B26: 25 | F26: =E26*$L$15 -> 0 | H26: =G26*E26 -> 0 | I26: =G26*F26 -> 0 | K26: 20첩당 | L26: 1600 | M26: g
B27: 26 | F27: =E27*$L$15 -> 0 | H27: =G27*E27 -> 0 | I27: =G27*F27 -> 0 | K27: 1돈 환산 | L27: 4 | M27: g
B28: 27 | F28: =E28*$L$15 -> 0 | H28: =G28*E28 -> 0 | I28: =G28*F28 -> 0
B29: 28 | F29: =E29*$L$15 -> 0 | H29: =G29*E29 -> 0 | I29: =G29*F29 -> 0 | K29: 금액
B30: 29 | F30: =E30*$L$15 -> 0 | H30: =G30*E30 -> 0 | I30: =G30*F30 -> 0 | K30: 1첩당 | L30: =SUM(H2:H31) -> #REF! | M30: 원
B31: 30 | F31: =E31*$L$15 -> 0 | H31: =G31*E31 -> 0 | I31: =G31*F31 -> 0 | K31: 총 | L31: =SUM(I2:I31) -> #REF! | M31: 원

Sheet 청상보하탕 7차
B1: No. | C1: 약재명 | D1: 수치 | E1: 그램 | F1: 총용량 | G1: 1g 금액 | H1: 1첩 금액 | I1: 총 금액 | K1: 기본 정보
B2: 1 | C2: 숙지황 | E2: 6 | F2: =E2*$L$15 -> 120 | G2: =VLOOKUP($C2,#REF!,10,FALSE) -> #REF! | H2: =G2*E2 -> #REF! | I2: =G2*F3 -> #REF! | K2: UNIT | L2: 19
B3: 2 | C3: 치자 | D3: 초 | E3: 4 | F3: =E3*$L$15 -> 80 | G3: =VLOOKUP($C3,#REF!,10,FALSE) -> #REF! | H3: =G3*E3 -> #REF! | I3: =G3*F4 -> #REF! | K3: 처방명 | L3: 청상보하탕
B4: 3 | C4: 산수유 | E4: 6 | F4: =E4*$L$15 -> 120 | G4: =VLOOKUP($C4,#REF!,10,FALSE) -> #REF! | H4: =G4*E4 -> #REF! | I4: =G4*F4 -> #REF! | K4: 날짜 | L4: 45666
B5: 4 | C5: 복령 | E5: 6 | F5: =E5*$L$15 -> 120 | G5: =VLOOKUP($C5,#REF!,10,FALSE) -> #REF! | H5: =G5*E5 -> #REF! | I5: =G5*F5 -> #REF! | K5: 이름 | L5: 오명옥
B6: 5 | C6: 택사1 | E6: 6 | F6: =E6*$L$15 -> 120 | G6: =VLOOKUP($C6,#REF!,10,FALSE) -> #REF! | H6: =G6*E6 -> #REF! | I6: =G6*F6 -> #REF! | K6: 나이 | L6: F
B7: 6 | C7: 목단피 | E7: 6 | F7: =E7*$L$15 -> 120 | G7: =VLOOKUP($C7,#REF!,10,FALSE) -> #REF! | H7: =G7*E7 -> #REF! | I7: =G7*F7 -> #REF! | K7: 성별 | L7: 58
B8: 7 | C8: 자완 | E8: 4 | F8: =E8*$L$15 -> 80 | G8: =VLOOKUP($C8,#REF!,10,FALSE) -> #REF! | H8: =G8*E8 -> #REF! | I8: =G8*F8 -> #REF! | K8: 메모
B9: 8 | C9: 백부근 | E9: 4 | F9: =E9*$L$15 -> 80 | G9: =VLOOKUP($C9,#REF!,10,FALSE) -> #REF! | H9: =G9*E9 -> #REF! | I9: =G9*F9 -> #REF! | K9: 6차약 - 산약 + 치자초 + 마자인 증량 #변비
B10: 9 | C10: 지실 | E10: 4 | F10: =E10*$L$15 -> 80 | G10: =VLOOKUP($C10,#REF!,10,FALSE) -> #REF! | H10: =G10*E10 -> #REF! | I10: =G10*F10 -> #REF!
B11: 10 | C11: 맥문동 | E11: 3 | F11: =E11*$L$15 -> 60 | G11: =VLOOKUP($C11,#REF!,10,FALSE) -> #REF! | H11: =G11*E11 -> #REF! | I11: =G11*F11 -> #REF!
B12: 11 | C12: 천문동 | E12: 3 | F12: =E12*$L$15 -> 60 | G12: =VLOOKUP($C12,#REF!,10,FALSE) -> #REF! | H12: =G12*E12 -> #REF! | I12: =G12*F12 -> #REF!
B13: 12 | C13: 오미자 | E13: 3 | F13: =E13*$L$15 -> 60 | G13: =VLOOKUP($C13,#REF!,10,FALSE) -> #REF! | H13: =G13*E13 -> #REF! | I13: =G13*F13 -> #REF!
B14: 13 | C14: 과루인 | E14: 3 | F14: =E14*$L$15 -> 60 | G14: =VLOOKUP($C14,#REF!,10,FALSE) -> #REF! | H14: =G14*E14 -> #REF! | I14: =G14*F14 -> #REF! | K14: 총 일수 | L14: 15 | M14: 일분
B15: 14 | C15: 반하 | E15: 2 | F15: =E15*$L$15 -> 40 | G15: =VLOOKUP($C15,#REF!,10,FALSE) -> #REF! | H15: =G15*E15 -> #REF! | I15: =G15*F15 -> #REF! | K15: 첩수 | L15: 20 | M15: 첩
B16: 15 | C16: 황금 | E16: 3 | F16: =E16*$L$15 -> 60 | G16: =VLOOKUP($C16,#REF!,10,FALSE) -> #REF! | H16: =G16*E16 -> #REF! | I16: =G16*F16 -> #REF! | K16: 총 팩수 | L16: 45 | M16: 팩
B17: 16 | C17: 황련 | E17: 2 | F17: =E17*$L$15 -> 40 | G17: =VLOOKUP($C17,#REF!,10,FALSE) -> #REF! | H17: =G17*E17 -> #REF! | I17: =G17*F17 -> #REF! | K17: 팩당 물량 | L17: 100 | M17: cc
B18: 17 | C18: 패모 | E18: 3 | F18: =E18*$L$15 -> 60 | G18: =VLOOKUP($C18,#REF!,10,FALSE) -> #REF! | H18: =G18*E18 -> #REF! | I18: =G18*F18 -> #REF! | K18: 1첩당약재 | L18: =SUM(E2:E31) -> 89 | M18: g
B19: 18 | C19: 길경 | E19: 3 | F19: =E19*$L$15 -> 60 | G19: =VLOOKUP($C19,#REF!,10,FALSE) -> #REF! | H19: =G19*E19 -> #REF! | I19: =G19*F19 -> #REF! | K19: 약재총량 | L19: =L15*L18 -> 1780 | M19: g
B20: 19 | C20: 행인 | E20: 4 | F20: =E20*$L$15 -> 80 | G20: =VLOOKUP($C20,#REF!,10,FALSE) -> #REF! | H20: =G20*E20 -> #REF! | I20: =G20*F20 -> #REF! | K20: 총 물 양 | L20: =L16*L17+L19 -> 6280 | M20: cc
B21: 20 | C21: 감초 | E21: 2 | F21: =E21*$L$15 -> 40 | G21: =VLOOKUP($C21,#REF!,10,FALSE) -> #REF! | H21: =G21*E21 -> #REF! | I21: =G21*F21 -> #REF!
B22: 21 | C22: 마자인 | E22: 6 | F22: =E22*$L$15 -> 120 | G22: =VLOOKUP($C22,#REF!,10,FALSE) -> #REF! | H22: =G22*E22 -> #REF! | I22: =G22*F22 -> #REF! | K22: 참고치
B23: 22 | C23: 신곡 | E23: 3 | F23: =E23*$L$15 -> 60 | G23: =VLOOKUP($C23,#REF!,10,FALSE) -> #REF! | H23: =G23*E23 -> #REF! | I23: =G23*F23 -> #REF! | K23: cross chk | L23: =SUM(F3:F31) -> 1660 | M23: g
B24: 23 | C24: 맥아 | E24: 3 | F24: =E24*$L$15 -> 60 | G24: =VLOOKUP($C24,#REF!,10,FALSE) -> #REF! | H24: =G24*E24 -> #REF! | I24: =G24*F24 -> #REF! | K24: 20첩물양 | L24: 5000 | M24: cc
B25: 24 | F25: =E25*$L$15 -> 0 | H25: =G25*E25 -> 0 | I25: =G25*F25 -> 0 | K25: 1첩당 | L25: 80-120 | M25: g
B26: 25 | F26: =E26*$L$15 -> 0 | H26: =G26*E26 -> 0 | I26: =G26*F26 -> 0 | K26: 20첩당 | L26: 1600 | M26: g
B27: 26 | F27: =E27*$L$15 -> 0 | H27: =G27*E27 -> 0 | I27: =G27*F27 -> 0 | K27: 1돈 환산 | L27: 4 | M27: g
B28: 27 | F28: =E28*$L$15 -> 0 | H28: =G28*E28 -> 0 | I28: =G28*F28 -> 0
B29: 28 | F29: =E29*$L$15 -> 0 | H29: =G29*E29 -> 0 | I29: =G29*F29 -> 0 | K29: 금액
B30: 29 | F30: =E30*$L$15 -> 0 | H30: =G30*E30 -> 0 | I30: =G30*F30 -> 0 | K30: 1첩당 | L30: =SUM(H2:H31) -> #REF! | M30: 원
B31: 30 | F31: =E31*$L$15 -> 0 | H31: =G31*E31 -> 0 | I31: =G31*F31 -> 0 | K31: 총 | L31: =SUM(I2:I31) -> #REF! | M31: 원

Sheet 청상보하탕 6차
B1: No. | C1: 약재명 | D1: 수치 | E1: 그램 | F1: 총용량 | G1: 1g 금액 | H1: 1첩 금액 | I1: 총 금액 | K1: 기본 정보
B2: 1 | C2: 숙지황 | E2: 6 | F2: =E2*$L$15 -> 120 | G2: =VLOOKUP($C2,#REF!,10,FALSE) -> #REF! | H2: =G2*E2 -> #REF! | I2: =G2*F2 -> #REF! | K2: UNIT | L2: 19
B3: 2 | C3: 산약 | E3: 6 | F3: =E3*$L$15 -> 120 | G3: =VLOOKUP($C3,#REF!,10,FALSE) -> #REF! | H3: =G3*E3 -> #REF! | I3: =G3*F3 -> #REF! | K3: 처방명 | L3: 청상보하탕
B4: 3 | C4: 산수유 | E4: 6 | F4: =E4*$L$15 -> 120 | G4: =VLOOKUP($C4,#REF!,10,FALSE) -> #REF! | H4: =G4*E4 -> #REF! | I4: =G4*F4 -> #REF! | K4: 날짜 | L4: 45637
B5: 4 | C5: 복령 | E5: 6 | F5: =E5*$L$15 -> 120 | G5: =VLOOKUP($C5,#REF!,10,FALSE) -> #REF! | H5: =G5*E5 -> #REF! | I5: =G5*F5 -> #REF! | K5: 이름 | L5: 오명옥
B6: 5 | C6: 택사1 | E6: 6 | F6: =E6*$L$15 -> 120 | G6: =VLOOKUP($C6,#REF!,10,FALSE) -> #REF! | H6: =G6*E6 -> #REF! | I6: =G6*F6 -> #REF! | K6: 나이 | L6: F
B7: 6 | C7: 목단피 | E7: 6 | F7: =E7*$L$15 -> 120 | G7: =VLOOKUP($C7,#REF!,10,FALSE) -> #REF! | H7: =G7*E7 -> #REF! | I7: =G7*F7 -> #REF! | K7: 성별 | L7: 58
B8: 7 | C8: 자완 | E8: 4 | F8: =E8*$L$15 -> 80 | G8: =VLOOKUP($C8,#REF!,10,FALSE) -> #REF! | H8: =G8*E8 -> #REF! | I8: =G8*F8 -> #REF! | K8: 메모
B9: 8 | C9: 백부근 | E9: 4 | F9: =E9*$L$15 -> 80 | G9: =VLOOKUP($C9,#REF!,10,FALSE) -> #REF! | H9: =G9*E9 -> #REF! | I9: =G9*F9 -> #REF! | K9: 4차약 - 육미, 반하 감량 + 패모, 길경, 행인 + 신곡 맥아 + 마자인 #변비
B10: 9 | C10: 지실 | E10: 4 | F10: =E10*$L$15 -> 80 | G10: =VLOOKUP($C10,#REF!,10,FALSE) -> #REF! | H10: =G10*E10 -> #REF! | I10: =G10*F10 -> #REF!
B11: 10 | C11: 맥문동 | E11: 3 | F11: =E11*$L$15 -> 60 | G11: =VLOOKUP($C11,#REF!,10,FALSE) -> #REF! | H11: =G11*E11 -> #REF! | I11: =G11*F11 -> #REF!
B12: 11 | C12: 천문동 | E12: 3 | F12: =E12*$L$15 -> 60 | G12: =VLOOKUP($C12,#REF!,10,FALSE) -> #REF! | H12: =G12*E12 -> #REF! | I12: =G12*F12 -> #REF!
B13: 12 | C13: 오미자 | E13: 3 | F13: =E13*$L$15 -> 60 | G13: =VLOOKUP($C13,#REF!,10,FALSE) -> #REF! | H13: =G13*E13 -> #REF! | I13: =G13*F13 -> #REF!
B14: 13 | C14: 과루인 | E14: 3 | F14: =E14*$L$15 -> 60 | G14: =VLOOKUP($C14,#REF!,10,FALSE) -> #REF! | H14: =G14*E14 -> #REF! | I14: =G14*F14 -> #REF! | K14: 총 일수 | L14: 15 | M14: 일분
B15: 14 | C15: 반하 | E15: 2 | F15: =E15*$L$15 -> 40 | G15: =VLOOKUP($C15,#REF!,10,FALSE) -> #REF! | H15: =G15*E15 -> #REF! | I15: =G15*F15 -> #REF! | K15: 첩수 | L15: 20 | M15: 첩
B16: 15 | C16: 황금 | E16: 3 | F16: =E16*$L$15 -> 60 | G16: =VLOOKUP($C16,#REF!,10,FALSE) -> #REF! | H16: =G16*E16 -> #REF! | I16: =G16*F16 -> #REF! | K16: 총 팩수 | L16: 45 | M16: 팩
B17: 16 | C17: 황련 | E17: 2 | F17: =E17*$L$15 -> 40 | G17: =VLOOKUP($C17,#REF!,10,FALSE) -> #REF! | H17: =G17*E17 -> #REF! | I17: =G17*F17 -> #REF! | K17: 팩당 물량 | L17: 100 | M17: cc
B18: 17 | C18: 패모 | E18: 3 | F18: =E18*$L$15 -> 60 | G18: =VLOOKUP($C18,#REF!,10,FALSE) -> #REF! | H18: =G18*E18 -> #REF! | I18: =G18*F18 -> #REF! | K18: 1첩당약재 | L18: =SUM(E2:E31) -> 89 | M18: g
B19: 18 | C19: 길경 | E19: 3 | F19: =E19*$L$15 -> 60 | G19: =VLOOKUP($C19,#REF!,10,FALSE) -> #REF! | H19: =G19*E19 -> #REF! | I19: =G19*F19 -> #REF! | K19: 약재총량 | L19: =L15*L18 -> 1780 | M19: g
B20: 19 | C20: 행인 | E20: 4 | F20: =E20*$L$15 -> 80 | G20: =VLOOKUP($C20,#REF!,10,FALSE) -> #REF! | H20: =G20*E20 -> #REF! | I20: =G20*F20 -> #REF! | K20: 총 물 양 | L20: =L16*L17+L19 -> 6280 | M20: cc
B21: 20 | C21: 감초 | E21: 2 | F21: =E21*$L$15 -> 40 | G21: =VLOOKUP($C21,#REF!,10,FALSE) -> #REF! | H21: =G21*E21 -> #REF! | I21: =G21*F21 -> #REF!
B22: 21 | C22: 마자인 | E22: 4 | F22: =E22*$L$15 -> 80 | G22: =VLOOKUP($C22,#REF!,10,FALSE) -> #REF! | H22: =G22*E22 -> #REF! | I22: =G22*F22 -> #REF! | K22: 참고치
B23: 22 | C23: 신곡 | E23: 3 | F23: =E23*$L$15 -> 60 | G23: =VLOOKUP($C23,#REF!,10,FALSE) -> #REF! | H23: =G23*E23 -> #REF! | I23: =G23*F23 -> #REF! | K23: cross chk | L23: =SUM(F2:F31) -> 1780 | M23: g
B24: 23 | C24: 맥아 | E24: 3 | F24: =E24*$L$15 -> 60 | G24: =VLOOKUP($C24,#REF!,10,FALSE) -> #REF! | H24: =G24*E24 -> #REF! | I24: =G24*F24 -> #REF! | K24: 20첩물양 | L24: 5000 | M24: cc
B25: 24 | F25: =E25*$L$15 -> 0 | H25: =G25*E25 -> 0 | I25: =G25*F25 -> 0 | K25: 1첩당 | L25: 80-120 | M25: g
B26: 25 | F26: =E26*$L$15 -> 0 | H26: =G26*E26 -> 0 | I26: =G26*F26 -> 0 | K26: 20첩당 | L26: 1600 | M26: g
B27: 26 | F27: =E27*$L$15 -> 0 | H27: =G27*E27 -> 0 | I27: =G27*F27 -> 0 | K27: 1돈 환산 | L27: 4 | M27: g
B28: 27 | F28: =E28*$L$15 -> 0 | H28: =G28*E28 -> 0 | I28: =G28*F28 -> 0
B29: 28 | F29: =E29*$L$15 -> 0 | H29: =G29*E29 -> 0 | I29: =G29*F29 -> 0 | K29: 금액
B30: 29 | F30: =E30*$L$15 -> 0 | H30: =G30*E30 -> 0 | I30: =G30*F30 -> 0 | K30: 1첩당 | L30: =SUM(H2:H31) -> #REF! | M30: 원
B31: 30 | F31: =E31*$L$15 -> 0 | H31: =G31*E31 -> 0 | I31: =G31*F31 -> 0 | K31: 총 | L31: =SUM(I2:I31) -> #REF! | M31: 원

Sheet 청상보하탕 5차
B1: No. | C1: 약재명 | D1: 수치 | E1: 그램 | F1: 총용량 | G1: 1g 금액 | H1: 1첩 금액 | I1: 총 금액 | K1: 기본 정보
B2: 1 | C2: 숙지황 | E2: 6 | F2: =E2*$L$15 -> 120 | G2: =VLOOKUP($C2,#REF!,10,FALSE) -> #REF! | H2: =G2*E2 -> #REF! | I2: =G2*F2 -> #REF! | K2: UNIT | L2: 19
B3: 2 | C3: 산약 | E3: 6 | F3: =E3*$L$15 -> 120 | G3: =VLOOKUP($C3,#REF!,10,FALSE) -> #REF! | H3: =G3*E3 -> #REF! | I3: =G3*F3 -> #REF! | K3: 처방명 | L3: 청상보하탕
B4: 3 | C4: 산수유 | E4: 6 | F4: =E4*$L$15 -> 120 | G4: =VLOOKUP($C4,#REF!,10,FALSE) -> #REF! | H4: =G4*E4 -> #REF! | I4: =G4*F4 -> #REF! | K4: 날짜 | L4: 45637
B5: 4 | C5: 복령 | E5: 6 | F5: =E5*$L$15 -> 120 | G5: =VLOOKUP($C5,#REF!,10,FALSE) -> #REF! | H5: =G5*E5 -> #REF! | I5: =G5*F5 -> #REF! | K5: 이름 | L5: 오명옥
B6: 5 | C6: 택사1 | E6: 6 | F6: =E6*$L$15 -> 120 | G6: =VLOOKUP($C6,#REF!,10,FALSE) -> #REF! | H6: =G6*E6 -> #REF! | I6: =G6*F6 -> #REF! | K6: 나이 | L6: F
B7: 6 | C7: 목단피 | E7: 6 | F7: =E7*$L$15 -> 120 | G7: =VLOOKUP($C7,#REF!,10,FALSE) -> #REF! | H7: =G7*E7 -> #REF! | I7: =G7*F7 -> #REF! | K7: 성별 | L7: 58
B8: 7 | C8: 자완 | E8: 4 | F8: =E8*$L$15 -> 80 | G8: =VLOOKUP($C8,#REF!,10,FALSE) -> #REF! | H8: =G8*E8 -> #REF! | I8: =G8*F8 -> #REF! | K8: 메모
B9: 8 | C9: 백부근 | E9: 4 | F9: =E9*$L$15 -> 80 | G9: =VLOOKUP($C9,#REF!,10,FALSE) -> #REF! | H9: =G9*E9 -> #REF! | I9: =G9*F9 -> #REF! | K9: 2차약 - 육미 감량 + 반하, 패모, 길경, 행인 + 치자초 + 신곡 맥아 #흉민
B10: 9 | C10: 지실 | E10: 4 | F10: =E10*$L$15 -> 80 | G10: =VLOOKUP($C10,#REF!,10,FALSE) -> #REF! | H10: =G10*E10 -> #REF! | I10: =G10*F10 -> #REF!
B11: 10 | C11: 맥문동 | E11: 3 | F11: =E11*$L$15 -> 60 | G11: =VLOOKUP($C11,#REF!,10,FALSE) -> #REF! | H11: =G11*E11 -> #REF! | I11: =G11*F11 -> #REF!
B12: 11 | C12: 천문동 | E12: 3 | F12: =E12*$L$15 -> 60 | G12: =VLOOKUP($C12,#REF!,10,FALSE) -> #REF! | H12: =G12*E12 -> #REF! | I12: =G12*F12 -> #REF!
B13: 12 | C13: 오미자 | E13: 3 | F13: =E13*$L$15 -> 60 | G13: =VLOOKUP($C13,#REF!,10,FALSE) -> #REF! | H13: =G13*E13 -> #REF! | I13: =G13*F13 -> #REF!
B14: 13 | C14: 과루인 | E14: 3 | F14: =E14*$L$15 -> 60 | G14: =VLOOKUP($C14,#REF!,10,FALSE) -> #REF! | H14: =G14*E14 -> #REF! | I14: =G14*F14 -> #REF! | K14: 총 일수 | L14: 15 | M14: 일분
B15: 14 | C15: 반하 | E15: 3 | F15: =E15*$L$15 -> 60 | G15: =VLOOKUP($C15,#REF!,10,FALSE) -> #REF! | H15: =G15*E15 -> #REF! | I15: =G15*F15 -> #REF! | K15: 첩수 | L15: 20 | M15: 첩
B16: 15 | C16: 황금 | E16: 3 | F16: =E16*$L$15 -> 60 | G16: =VLOOKUP($C16,#REF!,10,FALSE) -> #REF! | H16: =G16*E16 -> #REF! | I16: =G16*F16 -> #REF! | K16: 총 팩수 | L16: 45 | M16: 팩
B17: 16 | C17: 황련 | E17: 2 | F17: =E17*$L$15 -> 40 | G17: =VLOOKUP($C17,#REF!,10,FALSE) -> #REF! | H17: =G17*E17 -> #REF! | I17: =G17*F17 -> #REF! | K17: 팩당 물량 | L17: 100 | M17: cc
B18: 17 | C18: 패모 | E18: 3 | F18: =E18*$L$15 -> 60 | G18: =VLOOKUP($C18,#REF!,10,FALSE) -> #REF! | H18: =G18*E18 -> #REF! | I18: =G18*F18 -> #REF! | K18: 1첩당약재 | L18: =SUM(E2:E31) -> 88 | M18: g
B19: 18 | C19: 길경 | E19: 3 | F19: =E19*$L$15 -> 60 | G19: =VLOOKUP($C19,#REF!,10,FALSE) -> #REF! | H19: =G19*E19 -> #REF! | I19: =G19*F19 -> #REF! | K19: 약재총량 | L19: =L15*L18 -> 1760 | M19: g
B20: 19 | C20: 행인 | E20: 3 | F20: =E20*$L$15 -> 60 | G20: =VLOOKUP($C20,#REF!,10,FALSE) -> #REF! | H20: =G20*E20 -> #REF! | I20: =G20*F20 -> #REF! | K20: 총 물 양 | L20: =L16*L17+L19 -> 6260 | M20: cc
B21: 20 | C21: 감초 | E21: 2 | F21: =E21*$L$15 -> 40 | G21: =VLOOKUP($C21,#REF!,10,FALSE) -> #REF! | H21: =G21*E21 -> #REF! | I21: =G21*F21 -> #REF!
B22: 21 | C22: 나복자 | E22: 3 | F22: =E22*$L$15 -> 60 | G22: =VLOOKUP($C22,#REF!,10,FALSE) -> #REF! | H22: =G22*E22 -> #REF! | I22: =G22*F22 -> #REF! | K22: 참고치
B23: 22 | C23: 신곡 | E23: 3 | F23: =E23*$L$15 -> 60 | G23: =VLOOKUP($C23,#REF!,10,FALSE) -> #REF! | H23: =G23*E23 -> #REF! | I23: =G23*F23 -> #REF! | K23: cross chk | L23: =SUM(F2:F31) -> 1760 | M23: g
B24: 23 | C24: 맥아 | E24: 3 | F24: =E24*$L$15 -> 60 | G24: =VLOOKUP($C24,#REF!,10,FALSE) -> #REF! | H24: =G24*E24 -> #REF! | I24: =G24*F24 -> #REF! | K24: 20첩물양 | L24: 5000 | M24: cc
B25: 24 | F25: =E25*$L$15 -> 0 | H25: =G25*E25 -> 0 | I25: =G25*F25 -> 0 | K25: 1첩당 | L25: 80-120 | M25: g
B26: 25 | F26: =E26*$L$15 -> 0 | H26: =G26*E26 -> 0 | I26: =G26*F26 -> 0 | K26: 20첩당 | L26: 1600 | M26: g
B27: 26 | F27: =E27*$L$15 -> 0 | H27: =G27*E27 -> 0 | I27: =G27*F27 -> 0 | K27: 1돈 환산 | L27: 4 | M27: g
B28: 27 | F28: =E28*$L$15 -> 0 | H28: =G28*E28 -> 0 | I28: =G28*F28 -> 0
B29: 28 | F29: =E29*$L$15 -> 0 | H29: =G29*E29 -> 0 | I29: =G29*F29 -> 0 | K29: 금액
B30: 29 | F30: =E30*$L$15 -> 0 | H30: =G30*E30 -> 0 | I30: =G30*F30 -> 0 | K30: 1첩당 | L30: =SUM(H2:H31) -> #REF! | M30: 원
B31: 30 | F31: =E31*$L$15 -> 0 | H31: =G31*E31 -> 0 | I31: =G31*F31 -> 0 | K31: 총 | L31: =SUM(I2:I31) -> #REF! | M31: 원

Sheet 청상보하탕 4차
B1: No. | C1: 약재명 | D1: 수치 | E1: 그램 | F1: 총용량 | G1: 1g 금액 | H1: 1첩 금액 | I1: 총 금액 | K1: 기본 정보
B2: 1 | C2: 숙지황 | E2: 6 | F2: =E2*$L$15 -> 120 | G2: =VLOOKUP($C2,#REF!,10,FALSE) -> #REF! | H2: =G2*E2 -> #REF! | I2: =G2*F2 -> #REF! | K2: UNIT | L2: 19
B3: 2 | C3: 산약 | E3: 6 | F3: =E3*$L$15 -> 120 | G3: =VLOOKUP($C3,#REF!,10,FALSE) -> #REF! | H3: =G3*E3 -> #REF! | I3: =G3*F3 -> #REF! | K3: 처방명 | L3: 청상보하탕
B4: 3 | C4: 산수유 | E4: 6 | F4: =E4*$L$15 -> 120 | G4: =VLOOKUP($C4,#REF!,10,FALSE) -> #REF! | H4: =G4*E4 -> #REF! | I4: =G4*F4 -> #REF! | K4: 날짜 | L4: 45604
B5: 4 | C5: 복령 | E5: 6 | F5: =E5*$L$15 -> 120 | G5: =VLOOKUP($C5,#REF!,10,FALSE) -> #REF! | H5: =G5*E5 -> #REF! | I5: =G5*F5 -> #REF! | K5: 이름 | L5: 오명옥
B6: 5 | C6: 택사1 | E6: 6 | F6: =E6*$L$15 -> 120 | G6: =VLOOKUP($C6,#REF!,10,FALSE) -> #REF! | H6: =G6*E6 -> #REF! | I6: =G6*F6 -> #REF! | K6: 나이 | L6: F
B7: 6 | C7: 목단피 | E7: 6 | F7: =E7*$L$15 -> 120 | G7: =VLOOKUP($C7,#REF!,10,FALSE) -> #REF! | H7: =G7*E7 -> #REF! | I7: =G7*F7 -> #REF! | K7: 성별 | L7: 58
B8: 7 | C8: 자완 | E8: 4 | F8: =E8*$L$15 -> 80 | G8: =VLOOKUP($C8,#REF!,10,FALSE) -> #REF! | H8: =G8*E8 -> #REF! | I8: =G8*F8 -> #REF! | K8: 메모
B9: 8 | C9: 백부근 | E9: 4 | F9: =E9*$L$15 -> 80 | G9: =VLOOKUP($C9,#REF!,10,FALSE) -> #REF! | H9: =G9*E9 -> #REF! | I9: =G9*F9 -> #REF! | K9: 2차약 - 육미 감량 + 반하, 패모, 길경, 행인 증량 + 치자초 #흉민, 담다
B10: 9 | C10: 지실 | E10: 4 | F10: =E10*$L$15 -> 80 | G10: =VLOOKUP($C10,#REF!,10,FALSE) -> #REF! | H10: =G10*E10 -> #REF! | I10: =G10*F10 -> #REF!
B11: 10 | C11: 맥문동 | E11: 3 | F11: =E11*$L$15 -> 60 | G11: =VLOOKUP($C11,#REF!,10,FALSE) -> #REF! | H11: =G11*E11 -> #REF! | I11: =G11*F11 -> #REF!
B12: 11 | C12: 천문동 | E12: 3 | F12: =E12*$L$15 -> 60 | G12: =VLOOKUP($C12,#REF!,10,FALSE) -> #REF! | H12: =G12*E12 -> #REF! | I12: =G12*F12 -> #REF!
B13: 12 | C13: 오미자 | E13: 3 | F13: =E13*$L$15 -> 60 | G13: =VLOOKUP($C13,#REF!,10,FALSE) -> #REF! | H13: =G13*E13 -> #REF! | I13: =G13*F13 -> #REF!
B14: 13 | C14: 과루인 | E14: 3 | F14: =E14*$L$15 -> 60 | G14: =VLOOKUP($C14,#REF!,10,FALSE) -> #REF! | H14: =G14*E14 -> #REF! | I14: =G14*F14 -> #REF! | K14: 총 일수 | L14: 15 | M14: 일분
B15: 14 | C15: 반하 | E15: 3 | F15: =E15*$L$15 -> 60 | G15: =VLOOKUP($C15,#REF!,10,FALSE) -> #REF! | H15: =G15*E15 -> #REF! | I15: =G15*F15 -> #REF! | K15: 첩수 | L15: 20 | M15: 첩
B16: 15 | C16: 황금 | E16: 3 | F16: =E16*$L$15 -> 60 | G16: =VLOOKUP($C16,#REF!,10,FALSE) -> #REF! | H16: =G16*E16 -> #REF! | I16: =G16*F16 -> #REF! | K16: 총 팩수 | L16: 45 | M16: 팩
B17: 16 | C17: 황련 | E17: 2 | F17: =E17*$L$15 -> 40 | G17: =VLOOKUP($C17,#REF!,10,FALSE) -> #REF! | H17: =G17*E17 -> #REF! | I17: =G17*F17 -> #REF! | K17: 팩당 물량 | L17: 100 | M17: cc
B18: 17 | C18: 패모 | E18: 3 | F18: =E18*$L$15 -> 60 | G18: =VLOOKUP($C18,#REF!,10,FALSE) -> #REF! | H18: =G18*E18 -> #REF! | I18: =G18*F18 -> #REF! | K18: 1첩당약재 | L18: =SUM(E2:E31) -> 82 | M18: g
B19: 18 | C19: 길경 | E19: 3 | F19: =E19*$L$15 -> 60 | G19: =VLOOKUP($C19,#REF!,10,FALSE) -> #REF! | H19: =G19*E19 -> #REF! | I19: =G19*F19 -> #REF! | K19: 약재총량 | L19: =L15*L18 -> 1640 | M19: g
B20: 19 | C20: 행인 | E20: 3 | F20: =E20*$L$15 -> 60 | G20: =VLOOKUP($C20,#REF!,10,FALSE) -> #REF! | H20: =G20*E20 -> #REF! | I20: =G20*F20 -> #REF! | K20: 총 물 양 | L20: =L16*L17+L19 -> 6140 | M20: cc
B21: 20 | C21: 감초 | E21: 2 | F21: =E21*$L$15 -> 40 | G21: =VLOOKUP($C21,#REF!,10,FALSE) -> #REF! | H21: =G21*E21 -> #REF! | I21: =G21*F21 -> #REF!
B22: 21 | C22: 나복자 | E22: 3 | F22: =E22*$L$15 -> 60 | G22: =VLOOKUP($C22,#REF!,10,FALSE) -> #REF! | H22: =G22*E22 -> #REF! | I22: =G22*F22 -> #REF! | K22: 참고치
B23: 22 | K23: cross chk | L23: =SUM(F2:F31) -> 1640 | M23: g
B24: 23 | K24: 20첩물양 | L24: 5000 | M24: cc
B25: 24 | F25: =E25*$L$15 -> 0 | H25: =G25*E25 -> 0 | I25: =G25*F25 -> 0 | K25: 1첩당 | L25: 80-120 | M25: g
B26: 25 | F26: =E26*$L$15 -> 0 | H26: =G26*E26 -> 0 | I26: =G26*F26 -> 0 | K26: 20첩당 | L26: 1600 | M26: g
B27: 26 | F27: =E27*$L$15 -> 0 | H27: =G27*E27 -> 0 | I27: =G27*F27 -> 0 | K27: 1돈 환산 | L27: 4 | M27: g
B28: 27 | F28: =E28*$L$15 -> 0 | H28: =G28*E28 -> 0 | I28: =G28*F28 -> 0
B29: 28 | F29: =E29*$L$15 -> 0 | H29: =G29*E29 -> 0 | I29: =G29*F29 -> 0 | K29: 금액
B30: 29 | F30: =E30*$L$15 -> 0 | H30: =G30*E30 -> 0 | I30: =G30*F30 -> 0 | K30: 1첩당 | L30: =SUM(H2:H31) -> #REF! | M30: 원
B31: 30 | F31: =E31*$L$15 -> 0 | H31: =G31*E31 -> 0 | I31: =G31*F31 -> 0 | K31: 총 | L31: =SUM(I2:I31) -> #REF! | M31: 원

Sheet 청상보하탕 3차
B1: No. | C1: 약재명 | D1: 수치 | E1: 그램 | F1: 총용량 | G1: 1g 금액 | H1: 1첩 금액 | I1: 총 금액 | K1: 기본 정보
B2: 1 | C2: 숙지황 | E2: 6 | F2: =E2*$L$15 -> 120 | G2: =VLOOKUP($C2,#REF!,10,FALSE) -> #REF! | H2: =G2*E2 -> #REF! | I2: =G2*F2 -> #REF! | K2: UNIT | L2: 19
B3: 2 | C3: 산약 | E3: 6 | F3: =E3*$L$15 -> 120 | G3: =VLOOKUP($C3,#REF!,10,FALSE) -> #REF! | H3: =G3*E3 -> #REF! | I3: =G3*F3 -> #REF! | K3: 처방명 | L3: 청상보하탕
B4: 3 | C4: 산수유 | E4: 6 | F4: =E4*$L$15 -> 120 | G4: =VLOOKUP($C4,#REF!,10,FALSE) -> #REF! | H4: =G4*E4 -> #REF! | I4: =G4*F4 -> #REF! | K4: 날짜 | L4: 45573
B5: 4 | C5: 복령 | E5: 4 | F5: =E5*$L$15 -> 80 | G5: =VLOOKUP($C5,#REF!,10,FALSE) -> #REF! | H5: =G5*E5 -> #REF! | I5: =G5*F5 -> #REF! | K5: 이름 | L5: 오명옥
B6: 5 | C6: 택사1 | E6: 4 | F6: =E6*$L$15 -> 80 | G6: =VLOOKUP($C6,#REF!,10,FALSE) -> #REF! | H6: =G6*E6 -> #REF! | I6: =G6*F6 -> #REF! | K6: 나이 | L6: F
B7: 6 | C7: 목단피 | E7: 4 | F7: =E7*$L$15 -> 80 | G7: =VLOOKUP($C7,#REF!,10,FALSE) -> #REF! | H7: =G7*E7 -> #REF! | I7: =G7*F7 -> #REF! | K7: 성별 | L7: 58
B8: 7 | C8: 자완 | E8: 4 | F8: =E8*$L$15 -> 80 | G8: =VLOOKUP($C8,#REF!,10,FALSE) -> #REF! | H8: =G8*E8 -> #REF! | I8: =G8*F8 -> #REF! | K8: 메모
B9: 8 | C9: 백부근 | E9: 4 | F9: =E9*$L$15 -> 80 | G9: =VLOOKUP($C9,#REF!,10,FALSE) -> #REF! | H9: =G9*E9 -> #REF! | I9: =G9*F9 -> #REF! | K9: 2차약 - 육미 감량 + 반하, 패모, 길경, 행인 증량 + 치자초 #흉민, 담다
B10: 9 | C10: 지실 | E10: 3 | F10: =E10*$L$15 -> 60 | G10: =VLOOKUP($C10,#REF!,10,FALSE) -> #REF! | H10: =G10*E10 -> #REF! | I10: =G10*F10 -> #REF!
B11: 10 | C11: 맥문동 | E11: 3 | F11: =E11*$L$15 -> 60 | G11: =VLOOKUP($C11,#REF!,10,FALSE) -> #REF! | H11: =G11*E11 -> #REF! | I11: =G11*F11 -> #REF!
B12: 11 | C12: 천문동 | E12: 3 | F12: =E12*$L$15 -> 60 | G12: =VLOOKUP($C12,#REF!,10,FALSE) -> #REF! | H12: =G12*E12 -> #REF! | I12: =G12*F12 -> #REF!
B13: 12 | C13: 오미자 | E13: 3 | F13: =E13*$L$15 -> 60 | G13: =VLOOKUP($C13,#REF!,10,FALSE) -> #REF! | H13: =G13*E13 -> #REF! | I13: =G13*F13 -> #REF!
B14: 13 | C14: 과루인 | E14: 4 | F14: =E14*$L$15 -> 80 | G14: =VLOOKUP($C14,#REF!,10,FALSE) -> #REF! | H14: =G14*E14 -> #REF! | I14: =G14*F14 -> #REF! | K14: 총 일수 | L14: 15 | M14: 일분
B15: 14 | C15: 반하 | E15: 4 | F15: =E15*$L$15 -> 80 | G15: =VLOOKUP($C15,#REF!,10,FALSE) -> #REF! | H15: =G15*E15 -> #REF! | I15: =G15*F15 -> #REF! | K15: 첩수 | L15: 20 | M15: 첩
B16: 15 | C16: 황금 | E16: 3 | F16: =E16*$L$15 -> 60 | G16: =VLOOKUP($C16,#REF!,10,FALSE) -> #REF! | H16: =G16*E16 -> #REF! | I16: =G16*F16 -> #REF! | K16: 총 팩수 | L16: 45 | M16: 팩
B17: 16 | C17: 황련 | E17: 3 | F17: =E17*$L$15 -> 60 | G17: =VLOOKUP($C17,#REF!,10,FALSE) -> #REF! | H17: =G17*E17 -> #REF! | I17: =G17*F17 -> #REF! | K17: 팩당 물량 | L17: 100 | M17: cc
B18: 17 | C18: 패모 | E18: 4 | F18: =E18*$L$15 -> 80 | G18: =VLOOKUP($C18,#REF!,10,FALSE) -> #REF! | H18: =G18*E18 -> #REF! | I18: =G18*F18 -> #REF! | K18: 1첩당약재 | L18: =SUM(E2:E31) -> 90 | M18: g
B19: 18 | C19: 길경 | E19: 4 | F19: =E19*$L$15 -> 80 | G19: =VLOOKUP($C19,#REF!,10,FALSE) -> #REF! | H19: =G19*E19 -> #REF! | I19: =G19*F19 -> #REF! | K19: 약재총량 | L19: =L15*L18 -> 1800 | M19: g
B20: 19 | C20: 행인 | E20: 4 | F20: =E20*$L$15 -> 80 | G20: =VLOOKUP($C20,#REF!,10,FALSE) -> #REF! | H20: =G20*E20 -> #REF! | I20: =G20*F20 -> #REF! | K20: 총 물 양 | L20: =L16*L17+L19 -> 6300 | M20: cc
B21: 20 | C21: 감초 | E21: 2 | F21: =E21*$L$15 -> 40 | G21: =VLOOKUP($C21,#REF!,10,FALSE) -> #REF! | H21: =G21*E21 -> #REF! | I21: =G21*F21 -> #REF!
B22: 21 | C22: 죽여1 | E22: 4 | F22: =E22*$L$15 -> 80 | G22: =VLOOKUP($C22,#REF!,10,FALSE) -> #REF! | H22: =G22*E22 -> #REF! | I22: =G22*F22 -> #REF! | K22: 참고치
B23: 22 | C23: 진피1 | E23: 4 | F23: =E23*$L$15 -> 80 | G23: =VLOOKUP($C23,#REF!,10,FALSE) -> #REF! | H23: =G23*E23 -> #REF! | I23: =G23*F23 -> #REF! | K23: cross chk | L23: =SUM(F2:F31) -> 1800 | M23: g
B24: 23 | C24: 치자 | D24: 초 | E24: 4 | F24: =E24*$L$15 -> 80 | G24: =VLOOKUP($C24,#REF!,10,FALSE) -> #REF! | H24: =G24*E24 -> #REF! | I24: =G24*F24 -> #REF! | K24: 20첩물양 | L24: 5000 | M24: cc
B25: 24 | F25: =E25*$L$15 -> 0 | H25: =G25*E25 -> 0 | I25: =G25*F25 -> 0 | K25: 1첩당 | L25: 80-120 | M25: g
B26: 25 | F26: =E26*$L$15 -> 0 | H26: =G26*E26 -> 0 | I26: =G26*F26 -> 0 | K26: 20첩당 | L26: 1600 | M26: g
B27: 26 | F27: =E27*$L$15 -> 0 | H27: =G27*E27 -> 0 | I27: =G27*F27 -> 0 | K27: 1돈 환산 | L27: 4 | M27: g
B28: 27 | F28: =E28*$L$15 -> 0 | H28: =G28*E28 -> 0 | I28: =G28*F28 -> 0
B29: 28 | F29: =E29*$L$15 -> 0 | H29: =G29*E29 -> 0 | I29: =G29*F29 -> 0 | K29: 금액
B30: 29 | F30: =E30*$L$15 -> 0 | H30: =G30*E30 -> 0 | I30: =G30*F30 -> 0 | K30: 1첩당 | L30: =SUM(H2:H31) -> #REF! | M30: 원
B31: 30 | F31: =E31*$L$15 -> 0 | H31: =G31*E31 -> 0 | I31: =G31*F31 -> 0 | K31: 총 | L31: =SUM(I2:I31) -> #REF! | M31: 원

Sheet 청상보하탕 2차
B1: No. | C1: 약재명 | D1: 수치 | E1: 그램 | F1: 총용량 | G1: 1g 금액 | H1: 1첩 금액 | I1: 총 금액 | K1: 기본 정보
B2: 1 | C2: 숙지황 | E2: 8 | F2: =E2*$L$15 -> 160 | G2: =VLOOKUP($C2,#REF!,10,FALSE) -> #REF! | H2: =G2*E2 -> #REF! | I2: =G2*F2 -> #REF! | K2: UNIT | L2: 19
B3: 2 | C3: 산약 | E3: 8 | F3: =E3*$L$15 -> 160 | G3: =VLOOKUP($C3,#REF!,10,FALSE) -> #REF! | H3: =G3*E3 -> #REF! | I3: =G3*F3 -> #REF! | K3: 처방명 | L3: 청상보하탕
B4: 3 | C4: 산수유 | E4: 8 | F4: =E4*$L$15 -> 160 | G4: =VLOOKUP($C4,#REF!,10,FALSE) -> #REF! | H4: =G4*E4 -> #REF! | I4: =G4*F4 -> #REF! | K4: 날짜 | L4: 45573
B5: 4 | C5: 복령 | E5: 6 | F5: =E5*$L$15 -> 120 | G5: =VLOOKUP($C5,#REF!,10,FALSE) -> #REF! | H5: =G5*E5 -> #REF! | I5: =G5*F5 -> #REF! | K5: 이름 | L5: 오명옥
B6: 5 | C6: 택사1 | E6: 6 | F6: =E6*$L$15 -> 120 | G6: =VLOOKUP($C6,#REF!,10,FALSE) -> #REF! | H6: =G6*E6 -> #REF! | I6: =G6*F6 -> #REF! | K6: 나이 | L6: F
B7: 6 | C7: 목단피 | E7: 6 | F7: =E7*$L$15 -> 120 | G7: =VLOOKUP($C7,#REF!,10,FALSE) -> #REF! | H7: =G7*E7 -> #REF! | I7: =G7*F7 -> #REF! | K7: 성별 | L7: 58
B8: 7 | C8: 자완 | E8: 4 | F8: =E8*$L$15 -> 80 | G8: =VLOOKUP($C8,#REF!,10,FALSE) -> #REF! | H8: =G8*E8 -> #REF! | I8: =G8*F8 -> #REF! | K8: 메모
B9: 8 | C9: 백부근 | E9: 4 | F9: =E9*$L$15 -> 80 | G9: =VLOOKUP($C9,#REF!,10,FALSE) -> #REF! | H9: =G9*E9 -> #REF! | I9: =G9*F9 -> #REF! | K9: 2차약 - 육미 감량 + 반하, 패모, 길경, 행인 증량 + 치자초 #흉민, 담다
B10: 9 | C10: 지실 | E10: 4 | F10: =E10*$L$15 -> 80 | G10: =VLOOKUP($C10,#REF!,10,FALSE) -> #REF! | H10: =G10*E10 -> #REF! | I10: =G10*F10 -> #REF!
B11: 10 | C11: 맥문동 | E11: 4 | F11: =E11*$L$15 -> 80 | G11: =VLOOKUP($C11,#REF!,10,FALSE) -> #REF! | H11: =G11*E11 -> #REF! | I11: =G11*F11 -> #REF!
B12: 11 | C12: 천문동 | E12: 4 | F12: =E12*$L$15 -> 80 | G12: =VLOOKUP($C12,#REF!,10,FALSE) -> #REF! | H12: =G12*E12 -> #REF! | I12: =G12*F12 -> #REF!
B13: 12 | C13: 오미자 | E13: 4 | F13: =E13*$L$15 -> 80 | G13: =VLOOKUP($C13,#REF!,10,FALSE) -> #REF! | H13: =G13*E13 -> #REF! | I13: =G13*F13 -> #REF!
B14: 13 | C14: 과루인 | E14: 3 | F14: =E14*$L$15 -> 60 | G14: =VLOOKUP($C14,#REF!,10,FALSE) -> #REF! | H14: =G14*E14 -> #REF! | I14: =G14*F14 -> #REF! | K14: 총 일수 | L14: 15 | M14: 일분
B15: 14 | C15: 반하 | E15: 3 | F15: =E15*$L$15 -> 60 | G15: =VLOOKUP($C15,#REF!,10,FALSE) -> #REF! | H15: =G15*E15 -> #REF! | I15: =G15*F15 -> #REF! | K15: 첩수 | L15: 20 | M15: 첩
B16: 15 | C16: 황금 | E16: 3 | F16: =E16*$L$15 -> 60 | G16: =VLOOKUP($C16,#REF!,10,FALSE) -> #REF! | H16: =G16*E16 -> #REF! | I16: =G16*F16 -> #REF! | K16: 총 팩수 | L16: 45 | M16: 팩
B17: 16 | C17: 황련 | E17: 3 | F17: =E17*$L$15 -> 60 | G17: =VLOOKUP($C17,#REF!,10,FALSE) -> #REF! | H17: =G17*E17 -> #REF! | I17: =G17*F17 -> #REF! | K17: 팩당 물량 | L17: 100 | M17: cc
B18: 17 | C18: 패모 | E18: 3 | F18: =E18*$L$15 -> 60 | G18: =VLOOKUP($C18,#REF!,10,FALSE) -> #REF! | H18: =G18*E18 -> #REF! | I18: =G18*F18 -> #REF! | K18: 1첩당약재 | L18: =SUM(E2:E31) -> 93 | M18: g
B19: 18 | C19: 길경 | E19: 3 | F19: =E19*$L$15 -> 60 | G19: =VLOOKUP($C19,#REF!,10,FALSE) -> #REF! | H19: =G19*E19 -> #REF! | I19: =G19*F19 -> #REF! | K19: 약재총량 | L19: =L15*L18 -> 1860 | M19: g
B20: 19 | C20: 행인 | E20: 3 | F20: =E20*$L$15 -> 60 | G20: =VLOOKUP($C20,#REF!,10,FALSE) -> #REF! | H20: =G20*E20 -> #REF! | I20: =G20*F20 -> #REF! | K20: 총 물 양 | L20: =L16*L17+L19 -> 6360 | M20: cc
B21: 20 | C21: 감초 | E21: 2 | F21: =E21*$L$15 -> 40 | G21: =VLOOKUP($C21,#REF!,10,FALSE) -> #REF! | H21: =G21*E21 -> #REF! | I21: =G21*F21 -> #REF!
B22: 21 | C22: 죽여1 | E22: 4 | F22: =E22*$L$15 -> 80 | G22: =VLOOKUP($C22,#REF!,10,FALSE) -> #REF! | H22: =G22*E22 -> #REF! | I22: =G22*F22 -> #REF! | K22: 참고치
B23: 22 | F23: =E23*$L$15 -> 0 | H23: =G23*E23 -> 0 | I23: =G23*F23 -> 0 | K23: cross chk | L23: =SUM(F2:F31) -> 1860 | M23: g
B24: 23 | F24: =E24*$L$15 -> 0 | H24: =G24*E24 -> 0 | I24: =G24*F24 -> 0 | K24: 20첩물양 | L24: 5000 | M24: cc
B25: 24 | F25: =E25*$L$15 -> 0 | H25: =G25*E25 -> 0 | I25: =G25*F25 -> 0 | K25: 1첩당 | L25: 80-120 | M25: g
B26: 25 | F26: =E26*$L$15 -> 0 | H26: =G26*E26 -> 0 | I26: =G26*F26 -> 0 | K26: 20첩당 | L26: 1600 | M26: g
B27: 26 | F27: =E27*$L$15 -> 0 | H27: =G27*E27 -> 0 | I27: =G27*F27 -> 0 | K27: 1돈 환산 | L27: 4 | M27: g
B28: 27 | F28: =E28*$L$15 -> 0 | H28: =G28*E28 -> 0 | I28: =G28*F28 -> 0
B29: 28 | F29: =E29*$L$15 -> 0 | H29: =G29*E29 -> 0 | I29: =G29*F29 -> 0 | K29: 금액
B30: 29 | F30: =E30*$L$15 -> 0 | H30: =G30*E30 -> 0 | I30: =G30*F30 -> 0 | K30: 1첩당 | L30: =SUM(H2:H31) -> #REF! | M30: 원
B31: 30 | F31: =E31*$L$15 -> 0 | H31: =G31*E31 -> 0 | I31: =G31*F31 -> 0 | K31: 총 | L31: =SUM(I2:I31) -> #REF! | M31: 원

Sheet 청상보하탕1차
B1: No. | C1: 약재명 | D1: 수치 | E1: 그램 | F1: 총용량 | G1: 1g 금액 | H1: 1첩 금액 | I1: 총 금액 | K1: 기본 정보
B2: 1 | C2: 숙지황 | E2: 8 | F2: =E2*$L$15 -> 160 | G2: =VLOOKUP($C2,#REF!,10,FALSE) -> #REF! | H2: =G2*E2 -> #REF! | I2: =G2*F2 -> #REF! | K2: UNIT | L2: 19
B3: 2 | C3: 자완 | E3: 4 | F3: =E3*$L$15 -> 80 | G3: =VLOOKUP($C3,#REF!,10,FALSE) -> #REF! | H3: =G3*E3 -> #REF! | I3: =G3*F3 -> #REF! | K3: 처방명 | L3: 청상보하탕
