Workbook

Sheet 청심온담탕2차-2
B1: No. | C1: 약재명 | D1: 수치 | E1: 그램 | F1: 총용량 | G1: 1g 금액 | H1: 1첩 금액 | I1: 총 금액 | K1: 기본 정보
B2: 1 | C2: 향부자 | E2: 10 | F2: =E2*$L$15 -> 140 | G2: =VLOOKUP($C2,약재관리!A:J,10,FALSE) -> 14.4 | H2: =G2*E2 -> 144 | I2: =G2*F2 -> 2016 | K2: UNIT | L2: 20
B3: 2 | C3: 진피1 | E3: 6 | F3: =E3*$L$15 -> 84 | G3: =VLOOKUP($C3,약재관리!A:J,10,FALSE) -> 17.6 | H3: =G3*E3 -> 105.6 | I3: =G3*F3 -> 1478.4 | K3: 처방명 | L3: 청심온담탕
B4: 3 | C4: 반하 | E4: 4 | F4: =E4*$L$15 -> 56 | G4: =VLOOKUP($C4,약재관리!A:J,10,FALSE) -> 53 | H4: =G4*E4 -> 212 | I4: =G4*F4 -> 2968 | K4: 날짜 | L4: 45617
B5: 4 | C5: 복령 | E5: 6 | F5: =E5*$L$15 -> 84 | G5: =VLOOKUP($C5,약재관리!A:J,10,FALSE) -> 11 | H5: =G5*E5 -> 66 | I5: =G5*F5 -> 924 | K5: 이름 | L5: 권광희
B6: 5 | C6: 창출2 | E6: 4 | F6: =E6*$L$15 -> 56 | G6: =VLOOKUP($C6,약재관리!A:J,10,FALSE) -> 24 | H6: =G6*E6 -> 96 | I6: =G6*F6 -> 1344 | K6: 나이 | L6: 79
B7: 6 | C7: 지각 | E7: 4 | F7: =E7*$L$15 -> 56 | G7: =VLOOKUP($C7,약재관리!A:J,10,FALSE) -> 10 | H7: =G7*E7 -> 40 | I7: =G7*F7 -> 560 | K7: 성별 | L7: F
B8: 7 | C8: 죽여1 | E8: 4 | F8: =E8*$L$15 -> 56 | G8: =VLOOKUP($C8,약재관리!A:J,10,FALSE) -> 15.4 | H8: =G8*E8 -> 61.6 | I8: =G8*F8 -> 862.4 | K8: 메모
B9: 8 | C9: 황금 | D9: 주초 | E9: 2 | F9: =E9*$L$15 -> 28 | G9: =VLOOKUP($C9,약재관리!A:J,10,FALSE) -> 22.5 | H9: =G9*E9 -> 45 | I9: =G9*F9 -> 630 | K9: 청심온담탕 + 신곡 황련 연교 + 원육 당귀
B10: 9 | C10: 감초 | E10: 2 | F10: =E10*$L$15 -> 28 | G10: =VLOOKUP($C10,약재관리!A:J,10,FALSE) -> 28.3 | H10: =G10*E10 -> 56.6 | I10: =G10*F10 -> 792.4
B11: 10 | C11: 생강 | E11: 4 | F11: =E11*$L$15 -> 56 | G11: =VLOOKUP($C11,약재관리!A:J,10,FALSE) -> 18 | H11: =G11*E11 -> 72 | I11: =G11*F11 -> 1008
B12: 11 | C12: 대추 | E12: 4 | F12: =E12*$L$15 -> 56 | G12: =VLOOKUP($C12,약재관리!A:J,10,FALSE) -> 20.8 | H12: =G12*E12 -> 83.2 | I12: =G12*F12 -> 1164.8
B13: 12 | C13: 황련 | D13: 주초 | E13: 2 | F13: =E13*$L$15 -> 28 | G13: =VLOOKUP($C13,약재관리!A:J,10,FALSE) -> 134.3 | H13: =G13*E13 -> 268.6 | I13: =G13*F13 -> 3760.4
B14: 13 | C14: 당귀1 | E14: 4 | F14: =E14*$L$15 -> 56 | G14: =VLOOKUP($C14,약재관리!A:J,10,FALSE) -> 25 | H14: =G14*E14 -> 100 | I14: =G14*F14 -> 1400 | K14: 총 일수 | L14: 10 | M14: 일분
B15: 14 | C15: 원육 | E15: 6 | F15: =E15*$L$15 -> 84 | G15: =VLOOKUP($C15,약재관리!A:J,10,FALSE) -> 19.2 | H15: =G15*E15 -> 115.2 | I15: =G15*F15 -> 1612.8 | K15: 첩수 | L15: 14 | M15: 첩
B16: 15 | C16: 신곡 | D16: 초 | E16: 4 | F16: =E16*$L$15 -> 56 | G16: =VLOOKUP($C16,약재관리!A:J,10,FALSE) -> 8 | H16: =G16*E16 -> 32 | I16: =G16*F16 -> 448 | K16: 총 팩수 | L16: 30 | M16: 팩
B17: 16 | C17: 연교 | E17: 4 | F17: =E17*$L$15 -> 56 | G17: =VLOOKUP($C17,약재관리!A:J,10,FALSE) -> 28 | H17: =G17*E17 -> 112 | I17: =G17*F17 -> 1568 | K17: 팩당 물량 | L17: 100 | M17: cc
B18: 17 | K18: 1첩당약재 | L18: =SUM(E2:E31) -> 70 | M18: g
B19: 18 | K19: 약재총량 | L19: =L15*L18 -> 980 | M19: g
B20: 19 | K20: 총 물 양 | L20: =L16*L17+L19 -> 3980 | M20: cc
B21: 20
B22: 21 | F22: =E22*$L$15 -> 0 | H22: =G22*E22 -> 0 | I22: =G22*F22 -> 0 | K22: 참고치
B23: 22 | F23: =E23*$L$15 -> 0 | H23: =G23*E23 -> 0 | I23: =G23*F23 -> 0 | K23: cross chk | L23: =SUM(F2:F31) -> 980 | M23: g
B24: 23 | F24: =E24*$L$15 -> 0 | H24: =G24*E24 -> 0 | I24: =G24*F24 -> 0 | K24: 20첩물양 | L24: 5000 | M24: cc
B25: 24 | F25: =E25*$L$15 -> 0 | H25: =G25*E25 -> 0 | I25: =G25*F25 -> 0 | K25: 1첩당 | L25: 80-120 | M25: g
B26: 25 | F26: =E26*$L$15 -> 0 | H26: =G26*E26 -> 0 | I26: =G26*F26 -> 0 | K26: 20첩당 | L26: 1600 | M26: g
B27: 26 | F27: =E27*$L$15 -> 0 | H27: =G27*E27 -> 0 | I27: =G27*F27 -> 0 | K27: 1돈 환산 | L27: 4 | M27: g
B28: 27 | F28: =E28*$L$15 -> 0 | H28: =G28*E28 -> 0 | I28: =G28*F28 -> 0
B29: 28 | F29: =E29*$L$15 -> 0 | H29: =G29*E29 -> 0 | I29: =G29*F29 -> 0 | K29: 금액
B30: 29 | F30: =E30*$L$15 -> 0 | H30: =G30*E30 -> 0 | I30: =G30*F30 -> 0 | K30: 1첩당 | L30: =SUM(H2:H31) -> 1609.8 | M30: 원
B31: 30 | F31: =E31*$L$15 -> 0 | H31: =G31*E31 -> 0 | I31: =G31*F31 -> 0 | K31: 총 | L31: =SUM(I2:I31) -> 22537.2 | M31: 원

Sheet 청심온담탕2차
B1: No. | C1: 약재명 | D1: 수치 | E1: 그램 | F1: 총용량 | G1: 1g 금액 | H1: 1첩 금액 | I1: 총 금액 | K1: 기본 정보
B2: 1 | C2: 향부자 | E2: 10 | F2: =E2*$L$15 -> 200 | G2: =VLOOKUP($C2,약재관리!A:J,10,FALSE) -> 14.4 | H2: =G2*E2 -> 144 | I2: =G2*F2 -> 2880 | K2: UNIT | L2: 20
B3: 2 | C3: 진피1 | E3: 6 | F3: =E3*$L$15 -> 120 | G3: =VLOOKUP($C3,약재관리!A:J,10,FALSE) -> 17.6 | H3: =G3*E3 -> 105.6 | I3: =G3*F3 -> 2112 | K3: 처방명 | L3: 청심온담탕
B4: 3 | C4: 반하 | E4: 4 | F4: =E4*$L$15 -> 80 | G4: =VLOOKUP($C4,약재관리!A:J,10,FALSE) -> 53 | H4: =G4*E4 -> 212 | I4: =G4*F4 -> 4240 | K4: 날짜 | L4: 45594
B5: 4 | C5: 복령 | E5: 6 | F5: =E5*$L$15 -> 120 | G5: =VLOOKUP($C5,약재관리!A:J,10,FALSE) -> 11 | H5: =G5*E5 -> 66 | I5: =G5*F5 -> 1320 | K5: 이름 | L5: 권광희
B6: 5 | C6: 창출2 | E6: 4 | F6: =E6*$L$15 -> 80 | G6: =VLOOKUP($C6,약재관리!A:J,10,FALSE) -> 24 | H6: =G6*E6 -> 96 | I6: =G6*F6 -> 1920 | K6: 나이 | L6: 79
B7: 6 | C7: 지각 | E7: 4 | F7: =E7*$L$15 -> 80 | G7: =VLOOKUP($C7,약재관리!A:J,10,FALSE) -> 10 | H7: =G7*E7 -> 40 | I7: =G7*F7 -> 800 | K7: 성별 | L7: F
B8: 7 | C8: 죽여1 | E8: 4 | F8: =E8*$L$15 -> 80 | G8: =VLOOKUP($C8,약재관리!A:J,10,FALSE) -> 15.4 | H8: =G8*E8 -> 61.6 | I8: =G8*F8 -> 1232 | K8: 메모
B9: 8 | C9: 황금 | D9: 주초 | E9: 2 | F9: =E9*$L$15 -> 40 | G9: =VLOOKUP($C9,약재관리!A:J,10,FALSE) -> 22.5 | H9: =G9*E9 -> 45 | I9: =G9*F9 -> 900 | K9: 청심온담탕 + 사물탕(숙지황 대 원육) + 신곡 목향 사인+ 길경 현삼 + 황련 오미자 맥문동
B10: 9 | C10: 감초 | E10: 2 | F10: =E10*$L$15 -> 40 | G10: =VLOOKUP($C10,약재관리!A:J,10,FALSE) -> 28.3 | H10: =G10*E10 -> 56.6 | I10: =G10*F10 -> 1132
B11: 10 | C11: 생강 | E11: 4 | F11: =E11*$L$15 -> 80 | G11: =VLOOKUP($C11,약재관리!A:J,10,FALSE) -> 18 | H11: =G11*E11 -> 72 | I11: =G11*F11 -> 1440
B12: 11 | C12: 대추 | E12: 4 | F12: =E12*$L$15 -> 80 | G12: =VLOOKUP($C12,약재관리!A:J,10,FALSE) -> 20.8 | H12: =G12*E12 -> 83.2 | I12: =G12*F12 -> 1664
B13: 12 | C13: 당귀1 | E13: 4 | F13: =E13*$L$15 -> 80 | G13: =VLOOKUP($C13,약재관리!A:J,10,FALSE) -> 25 | H13: =G13*E13 -> 100 | I13: =G13*F13 -> 2000
B14: 13 | C14: 사인 | E14: 2 | F14: =E14*$L$15 -> 40 | G14: =VLOOKUP($C14,약재관리!A:J,10,FALSE) -> 21.8 | H14: =G14*E14 -> 43.6 | I14: =G14*F14 -> 872 | K14: 총 일수 | L14: 15 | M14: 일분
B15: 14 | C15: 원육 | E15: 6 | F15: =E15*$L$15 -> 120 | G15: =VLOOKUP($C15,약재관리!A:J,10,FALSE) -> 19.2 | H15: =G15*E15 -> 115.2 | I15: =G15*F15 -> 2304 | K15: 첩수 | L15: 20 | M15: 첩
B16: 15 | C16: 백작약 | E16: 4 | F16: =E16*$L$15 -> 80 | G16: =VLOOKUP($C16,약재관리!A:J,10,FALSE) -> 19.6 | H16: =G16*E16 -> 78.4 | I16: =G16*F16 -> 1568 | K16: 총 팩수 | L16: 45 | M16: 팩
B17: 16 | C17: 신곡 | D17: 초 | E17: 4 | F17: =E17*$L$15 -> 80 | G17: =VLOOKUP($C17,약재관리!A:J,10,FALSE) -> 8 | H17: =G17*E17 -> 32 | I17: =G17*F17 -> 640 | K17: 팩당 물량 | L17: 100 | M17: cc
B18: 17 | C18: 길경 | E18: 4 | F18: =E18*$L$15 -> 80 | G18: =VLOOKUP($C18,약재관리!A:J,10,FALSE) -> 11.2 | H18: =G18*E18 -> 44.8 | I18: =G18*F18 -> 896 | K18: 1첩당약재 | L18: =SUM(E2:E31) -> 88 | M18: g
B19: 18 | C19: 현삼 | E19: 4 | F19: =E19*$L$15 -> 80 | G19: =VLOOKUP($C19,약재관리!A:J,10,FALSE) -> 24 | H19: =G19*E19 -> 96 | I19: =G19*F19 -> 1920 | K19: 약재총량 | L19: =L15*L18 -> 1760 | M19: g
B20: 19 | C20: 황련 | D20: 주초 | E20: 2 | F20: =E20*$L$15 -> 40 | G20: =VLOOKUP($C20,약재관리!A:J,10,FALSE) -> 134.3 | H20: =G20*E20 -> 268.6 | I20: =G20*F20 -> 5372 | K20: 총 물 양 | L20: =L16*L17+L19 -> 6260 | M20: cc
B21: 20 | C21: 목향 | E21: 2 | F21: =E21*$L$15 -> 40 | G21: =VLOOKUP($C21,약재관리!A:J,10,FALSE) -> 9.8 | H21: =G21*E21 -> 19.6 | I21: =G21*F21 -> 392
B22: 21 | C22: 오미자 | E22: 2 | F22: =E22*$L$15 -> 40 | G22: =VLOOKUP($C22,약재관리!A:J,10,FALSE) -> 25.2 | H22: =G22*E22 -> 50.4 | I22: =G22*F22 -> 1008 | K22: 참고치
B23: 22 | C23: 맥문동 | E23: 4 | F23: =E23*$L$15 -> 80 | G23: =VLOOKUP($C23,약재관리!A:J,10,FALSE) -> 44.3 | H23: =G23*E23 -> 177.2 | I23: =G23*F23 -> 3544 | K23: cross chk | L23: =SUM(F2:F31) -> 1760 | M23: g
B24: 23 | F24: =E24*$L$15 -> 0 | H24: =G24*E24 -> 0 | I24: =G24*F24 -> 0 | K24: 20첩물양 | L24: 5000 | M24: cc
B25: 24 | F25: =E25*$L$15 -> 0 | H25: =G25*E25 -> 0 | I25: =G25*F25 -> 0 | K25: 1첩당 | L25: 80-120 | M25: g
B26: 25 | F26: =E26*$L$15 -> 0 | H26: =G26*E26 -> 0 | I26: =G26*F26 -> 0 | K26: 20첩당 | L26: 1600 | M26: g
B27: 26 | F27: =E27*$L$15 -> 0 | H27: =G27*E27 -> 0 | I27: =G27*F27 -> 0 | K27: 1돈 환산 | L27: 4 | M27: g
B28: 27 | F28: =E28*$L$15 -> 0 | H28: =G28*E28 -> 0 | I28: =G28*F28 -> 0
B29: 28 | F29: =E29*$L$15 -> 0 | H29: =G29*E29 -> 0 | I29: =G29*F29 -> 0 | K29: 금액
B30: 29 | F30: =E30*$L$15 -> 0 | H30: =G30*E30 -> 0 | I30: =G30*F30 -> 0 | K30: 1첩당 | L30: =SUM(H2:H31) -> 2007.8 | M30: 원
B31: 30 | F31: =E31*$L$15 -> 0 | H31: =G31*E31 -> 0 | I31: =G31*F31 -> 0 | K31: 총 | L31: =SUM(I2:I31) -> 40156 | M31: 원

Sheet 청심온담탕1차
B1: No. | C1: 약재명 | D1: 수치 | E1: 그램 | F1: 총용량 | G1: 1g 금액 | H1: 1첩 금액 | I1: 총 금액 | K1: 기본 정보
B2: 1 | C2: 향부자 | E2: 10 | F2: =E2*$L$15 -> 200 | G2: =VLOOKUP($C2,약재관리!A:J,10,FALSE) -> 14.4 | H2: =G2*E2 -> 144 | I2: =G2*F2 -> 2880 | K2: UNIT | L2: 20
B3: 2 | C3: 진피1 | E3: 6 | F3: =E3*$L$15 -> 120 | G3: =VLOOKUP($C3,약재관리!A:J,10,FALSE) -> 17.6 | H3: =G3*E3 -> 105.6 | I3: =G3*F3 -> 2112 | K3: 처방명 | L3: 청심온담탕
B4: 3 | C4: 반하 | E4: 4 | F4: =E4*$L$15 -> 80 | G4: =VLOOKUP($C4,약재관리!A:J,10,FALSE) -> 53 | H4: =G4*E4 -> 212 | I4: =G4*F4 -> 4240 | K4: 날짜 | L4: 45575
B5: 4 | C5: 복령 | E5: 6 | F5: =E5*$L$15 -> 120 | G5: =VLOOKUP($C5,약재관리!A:J,10,FALSE) -> 11 | H5: =G5*E5 -> 66 | I5: =G5*F5 -> 1320 | K5: 이름 | L5: 권광희
B6: 5 | C6: 창출2 | E6: 4 | F6: =E6*$L$15 -> 80 | G6: =VLOOKUP($C6,약재관리!A:J,10,FALSE) -> 24 | H6: =G6*E6 -> 96 | I6: =G6*F6 -> 1920 | K6: 나이 | L6: 79
B7: 6 | C7: 지각 | E7: 4 | F7: =E7*$L$15 -> 80 | G7: =VLOOKUP($C7,약재관리!A:J,10,FALSE) -> 10 | H7: =G7*E7 -> 40 | I7: =G7*F7 -> 800 | K7: 성별 | L7: F
B8: 7 | C8: 죽여1 | E8: 4 | F8: =E8*$L$15 -> 80 | G8: =VLOOKUP($C8,약재관리!A:J,10,FALSE) -> 15.4 | H8: =G8*E8 -> 61.6 | I8: =G8*F8 -> 1232 | K8: 메모
B9: 8 | C9: 황금 | D9: 주초 | E9: 2 | F9: =E9*$L$15 -> 40 | G9: =VLOOKUP($C9,약재관리!A:J,10,FALSE) -> 22.5 | H9: =G9*E9 -> 45 | I9: =G9*F9 -> 900 | K9: 청심온담탕 + 사물탕(숙지황 대 원육) + 신곡 목향 + 길경 현삼 + 황기
B10: 9 | C10: 감초 | E10: 2 | F10: =E10*$L$15 -> 40 | G10: =VLOOKUP($C10,약재관리!A:J,10,FALSE) -> 28.3 | H10: =G10*E10 -> 56.6 | I10: =G10*F10 -> 1132
B11: 10 | C11: 생강 | E11: 4 | F11: =E11*$L$15 -> 80 | G11: =VLOOKUP($C11,약재관리!A:J,10,FALSE) -> 18 | H11: =G11*E11 -> 72 | I11: =G11*F11 -> 1440
B12: 11 | C12: 대추 | E12: 4 | F12: =E12*$L$15 -> 80 | G12: =VLOOKUP($C12,약재관리!A:J,10,FALSE) -> 20.8 | H12: =G12*E12 -> 83.2 | I12: =G12*F12 -> 1664
B13: 12 | C13: 당귀1 | E13: 4 | F13: =E13*$L$15 -> 80 | G13: =VLOOKUP($C13,약재관리!A:J,10,FALSE) -> 25 | H13: =G13*E13 -> 100 | I13: =G13*F13 -> 2000
B14: 13 | C14: 천궁1 | E14: 4 | F14: =E14*$L$15 -> 80 | G14: =VLOOKUP($C14,약재관리!A:J,10,FALSE) -> 10.8 | H14: =G14*E14 -> 43.2 | I14: =G14*F14 -> 864 | K14: 총 일수 | L14: 15 | M14: 일분
B15: 14 | C15: 원육 | E15: 4 | F15: =E15*$L$15 -> 80 | G15: =VLOOKUP($C15,약재관리!A:J,10,FALSE) -> 19.2 | H15: =G15*E15 -> 76.8 | I15: =G15*F15 -> 1536 | K15: 첩수 | L15: 20 | M15: 첩
B16: 15 | C16: 백작약 | E16: 4 | F16: =E16*$L$15 -> 80 | G16: =VLOOKUP($C16,약재관리!A:J,10,FALSE) -> 19.6 | H16: =G16*E16 -> 78.4 | I16: =G16*F16 -> 1568 | K16: 총 팩수 | L16: 45 | M16: 팩
B17: 16 | C17: 신곡 | D17: 초 | E17: 4 | F17: =E17*$L$15 -> 80 | G17: =VLOOKUP($C17,약재관리!A:J,10,FALSE) -> 8 | H17: =G17*E17 -> 32 | I17: =G17*F17 -> 640 | K17: 팩당 물량 | L17: 100 | M17: cc
B18: 17 | C18: 길경 | E18: 4 | F18: =E18*$L$15 -> 80 | G18: =VLOOKUP($C18,약재관리!A:J,10,FALSE) -> 11.2 | H18: =G18*E18 -> 44.8 | I18: =G18*F18 -> 896 | K18: 1첩당약재 | L18: =SUM(E2:E31) -> 86 | M18: g
B19: 18 | C19: 현삼 | E19: 4 | F19: =E19*$L$15 -> 80 | G19: =VLOOKUP($C19,약재관리!A:J,10,FALSE) -> 24 | H19: =G19*E19 -> 96 | I19: =G19*F19 -> 1920 | K19: 약재총량 | L19: =L15*L18 -> 1720 | M19: g
B20: 19 | C20: 황기 | E20: 6 | F20: =E20*$L$15 -> 120 | G20: =VLOOKUP($C20,약재관리!A:J,10,FALSE) -> 22 | H20: =G20*E20 -> 132 | I20: =G20*F20 -> 2640 | K20: 총 물 양 | L20: =L16*L17+L19 -> 6220 | M20: cc
B21: 20 | C21: 목향 | E21: 2 | F21: =E21*$L$15 -> 40 | G21: =VLOOKUP($C21,약재관리!A:J,10,FALSE) -> 9.8 | H21: =G21*E21 -> 19.6 | I21: =G21*F21 -> 392
B22: 21 | F22: =E22*$L$15 -> 0 | H22: =G22*E22 -> 0 | I22: =G22*F22 -> 0 | K22: 참고치
B23: 22 | F23: =E23*$L$15 -> 0 | H23: =G23*E23 -> 0 | I23: =G23*F23 -> 0 | K23: cross chk | L23: =SUM(F2:F31) -> 1720 | M23: g
B24: 23 | F24: =E24*$L$15 -> 0 | H24: =G24*E24 -> 0 | I24: =G24*F24 -> 0 | K24: 20첩물양 | L24: 5000 | M24: cc
B25: 24 | F25: =E25*$L$15 -> 0 | H25: =G25*E25 -> 0 | I25: =G25*F25 -> 0 | K25: 1첩당 | L25: 80-120 | M25: g
B26: 25 | F26: =E26*$L$15 -> 0 | H26: =G26*E26 -> 0 | I26: =G26*F26 -> 0 | K26: 20첩당 | L26: 1600 | M26: g
B27: 26 | F27: =E27*$L$15 -> 0 | H27: =G27*E27 -> 0 | I27: =G27*F27 -> 0 | K27: 1돈 환산 | L27: 4 | M27: g
B28: 27 | F28: =E28*$L$15 -> 0 | H28: =G28*E28 -> 0 | I28: =G28*F28 -> 0
B29: 28 | F29: =E29*$L$15 -> 0 | H29: =G29*E29 -> 0 | I29: =G29*F29 -> 0 | K29: 금액
B30: 29 | F30: =E30*$L$15 -> 0 | H30: =G30*E30 -> 0 | I30: =G30*F30 -> 0 | K30: 1첩당 | L30: =SUM(H2:H31) -> 1604.8 | M30: 원
B31: 30 | F31: =E31*$L$15 -> 0 | H31: =G31*E31 -> 0 | I31: =G31*F31 -> 0 | K31: 총 | L31: =SUM(I2:I31) -> 32096 | M31: 원

Sheet 약재관리
A1: 약재 이름 | B1: 옴니허브 | C1: 한퓨어 | D1: 신우한방 | E1: 바른한약 | F1: 옴니허브 | G1: 한퓨어 | H1: 신우한방 | I1: 바른한약 | J1: 최종 | K1: 옴니허브 | L1: 한퓨어 | M1: 신우한방 | N1: 바른한약
A2: 45566 | B2: 구입단가 | C2: 구입단가 | D2: 구입단가 | E2: 구입단가 | F2: 1g | G2: 1g | H2: 1g | I2: 1g | J2: 1g | K2: 500g | L2: 500g | M2: 600g | N2: 600g
A3: 갈근1 | B3: 9900 | C3: 9000 | D3: 10500 | E3: 9900 | F3: =B3/500 -> 19.8 | G3: =C3/500 -> 18 | H3: =D3/600 -> 17.5 | I3: =E3/600 -> 16.5 | J3: 16.5 | L3: 선일국산 | M3: 토 | N3: 퓨어마인드국산
A4: 갈근2 | C4: 2700 | F4: =B4/500 -> 0 | G4: =C4/500 -> 5.4 | H4: =D4/600 -> 0 | I4: =E4/600 -> 0 | L4: 이풀잎중국
A5: 감국 | F5: =B5/500 -> 0 | G5: =C5/500 -> 0 | H5: =D5/600 -> 0 | I5: =E5/600 -> 0
A6: 감수 | C6: 23400 | E6: 27100 | F6: =B6/500 -> 0 | G6: =C6/600 -> 39 | H6: =D6/600 -> 0 | I6: =E6/600 -> 45.166667 | J6: 45.2 | L6: 600g씨케이중국 | N6: 씨케이중국
A7: 감초 | D7: 17000 | E7: 25500 | F7: =B7/500 -> 0 | G7: =C7/500 -> 0 | H7: =D7/600 -> 28.333333 | I7: =E7/600 -> 42.5 | J7: 28.3 | M7: 양외2 | N7: 양외1
A8: 강활1 | B8: 27200 | C8: 20500 | D8: 24000 | F8: =B8/500 -> 54.4 | G8: =C8/500 -> 41 | H8: =D8/600 -> 40 | I8: =E8/600 -> 0 | L8: 선일국산 | M8: 토
A9: 강활2 | C9: 18700 | D9: 21000 | E9: 23300 | F9: =B9/500 -> 0 | G9: =C9/500 -> 37.4 | H9: =D9/600 -> 35 | I9: =E9/600 -> 38.833333 | J9: 38.8 | L9: 태극인국산 | N9: 선일국산
A10: 강황 | C10: 3300 | D10: 5000 | F10: =B10/500 -> 0 | G10: =C10/500 -> 6.6 | H10: =D10/600 -> 8.3333333 | I10: =E10/600 -> 0 | J10: 8.3 | M10: 인도
A11: 건강 | C11: 4500 | D11: 8000 | F11: =B11/500 -> 0 | G11: =C11/500 -> 9 | H11: =D11/600 -> 13.333333 | I11: =E11/600 -> 0 | J11: 13.3
A12: 건율 | C12: 13500 | D12: 16500 | E12: 16700 | F12: =B12/500 -> 0 | G12: =C12/500 -> 27 | H12: =D12/600 -> 27.5 | I12: =E12/600 -> 27.833333 | J12: 27.5 | M12: 토 | N12: (절, 토)
A13: 건지황 | B13: 19900 | C13: 7200 | D13: 11000 | E13: 8900 | F13: =B13/500 -> 39.8 | G13: =C13/500 -> 14.4 | H13: =D13/600 -> 18.333333 | I13: =E13/600 -> 14.833333 | J13: 14.4 | L13: 허브팜중국
A14: 검인 | F14: =B14/500 -> 0 | G14: =C14/500 -> 0 | H14: =D14/600 -> 0 | I14: =E14/600 -> 0
A15: 결명자 | F15: =B15/500 -> 0 | G15: =C15/500 -> 0 | H15: =D15/600 -> 0 | I15: =E15/600 -> 0
A16: 계지 | B16: 4500 | C16: 2000 | D16: 3500 | E16: 2900 | F16: =B16/500 -> 9 | G16: =C16/500 -> 4 | H16: =D16/600 -> 5.8333333 | I16: =E16/600 -> 4.8333333 | J16: 4.8 | L16: 씨케이베트남 | M16: 세 | N16: 엔탭베트남
A17: 고량강 | C17: 10200 | E17: 11100 | F17: =B17/500 -> 0 | G17: =C17/600 -> 17 | H17: =D17/600 -> 0 | I17: =E17/600 -> 18.5 | J17: 17 | L17: 600g 씨케이중국 | N17: 씨케이중국
A18: 고본 | C18: 32000 | E18: 36800 | F18: =B18/500 -> 0 | G18: =C18/500 -> 64 | H18: =D18/600 -> 0 | I18: =E18/600 -> 61.333333 | J18: 61.3 | N18: 퓨어마인드국산
A19: 고삼 | C19: 4500 | F19: =B19/500 -> 0 | G19: =C19/500 -> 9 | H19: =D19/600 -> 0 | I19: =E19/600 -> 0 | J19: 9 | L19: 한솔중국
A20: 골쇄보 | F20: =B20/500 -> 0 | G20: =C20/500 -> 0 | H20: =D20/600 -> 0 | I20: =E20/600 -> 0
A21: 과루인 | C21: 3500 | D21: 6500 | F21: =B21/500 -> 0 | G21: =C21/500 -> 7 | H21: =D21/600 -> 10.833333 | I21: =E21/600 -> 0 | J21: 10.8 | M21: (추)
A22: 곽향1 | B22: 6900 | C22: 5600 | E22: 6900 | F22: =B22/500 -> 13.8 | G22: =C22/500 -> 11.2 | H22: =D22/600 -> 0 | I22: =E22/600 -> 11.5 | J22: 13.8 | L22: 선일국산 | N22: 씨케이국산
A23: 곽향2 | B23: 4600 | C23: 3500 | E23: 4800 | F23: =B23/500 -> 9.2 | G23: =C23/500 -> 7 | H23: =D23/600 -> 0 | I23: =E23/600 -> 8 | J23: 7 | K23: 인도네시아 | L23: 올본인도네시아 | N23: 엔탭인도네시아
A24: 관동화 | C24: 46000 | D24: 70000 | E24: 75400 | F24: =B24/500 -> 0 | G24: =C24/300 -> 153.33333 | H24: =D24/600 -> 116.66667 | I24: =E24/600 -> 125.66667 | J24: 116.7 | L24: 300g | N24: 엔탭중국
A25: 괴화 | F25: =B25/500 -> 0 | G25: =C25/500 -> 0 | H25: =D25/600 -> 0 | I25: =E25/600 -> 0
A26: 구기자 | B26: 14900 | C26: 8700 | D26: 9000 | E26: 8000 | F26: =B26/500 -> 29.8 | G26: =C26/500 -> 17.4 | H26: =D26/600 -> 15 | I26: =E26/600 -> 13.333333 | J26: 13.3 | N26: 엔탭중국영하
A27: 구맥 | F27: =B27/500 -> 0 | G27: =C27/500 -> 0 | H27: =D27/600 -> 0 | I27: =E27/600 -> 0
A28: 구척 | F28: =B28/500 -> 0 | G28: =C28/500 -> 0 | H28: =D28/600 -> 0 | I28: =E28/600 -> 0
A29: 귀판 | C29: 20500 | D29: 19000 | F29: =B29/500 -> 0 | G29: =C29/600 -> 34.166667 | H29: =D29/600 -> 31.666667 | I29: =E29/600 -> 0 | J29: 31.7 | L29: 600g추말/자연세상인도네시아
A30: 금은화 | C30: 22000 | E30: 30800 | F30: =B30/500 -> 0 | G30: =C30/500 -> 44 | H30: =D30/600 -> 0 | I30: =E30/600 -> 51.333333 | J30: 44 | L30: 한솔중국 | N30: 엔탭중국
A31: 길경 | B31: 11500 | C31: 12900 | D31: 7500 | E31: 6700 | F31: =B31/500 -> 23 | G31: =C31/500 -> 25.8 | H31: =D31/600 -> 12.5 | I31: =E31/600 -> 11.166667 | J31: 11.2 | K31: (중국4-5년) | L31: 선일국산 | M31: (편) | N31: 엔탭중국야생3년
A32: 나복자 | C32: 3000 | D32: 4000 | F32: =B32/500 -> 0 | G32: =C32/500 -> 6 | H32: =D32/600 -> 6.6666667 | I32: =E32/600 -> 0 | J32: 6.7 | L32: 올본인도/추말 | M32: 추
A33: 남성 | C33: 13000 | D33: 13000 | F33: =B33/500 -> 0 | G33: =C33/500 -> 26 | H33: =D33/500 -> 26 | I33: =E33/600 -> 0 | J33: 26 | L33: 생강백반제/신흥중국 | M33: 500g생강백반제/신흥중국
A34: 녹용 | C34: 278000 | F34: =B34/500 -> 0 | G34: =C34/600 -> 463.33333 | H34: =D34/600 -> 0 | I34: =E34/600 -> 0 | J34: 463.3 | L34: 600g
A35: 단삼 | C35: 6600 | E35: 8900 | F35: =B35/500 -> 0 | G35: =C35/500 -> 13.2 | H35: =D35/600 -> 0 | I35: =E35/600 -> 14.833333 | J35: 14.8 | L35: 허브팜중국 | N35: 엔탭중국
A36: 담두시 | D36: 8000 | F36: =B36/500 -> 0 | G36: =C36/500 -> 0 | H36: =D36/600 -> 13.333333 | I36: =E36/600 -> 0 | J36: 13.3
A37: 당귀1 | B37: 14900 | C37: 12000 | D37: 15000 | E37: 15000 | F37: =B37/500 -> 29.8 | G37: =C37/500 -> 24 | H37: =D37/600 -> 25 | I37: =E37/600 -> 25 | J37: 25 | L37: 선일국산 | N37: 선일국산
A38: 당귀2 | C38: 12700 | E38: 13800 | F38: =B38/500 -> 0 | G38: =C38/500 -> 25.4 | H38: =D38/600 -> 0 | I38: =E38/600 -> 23 | J38: 23 | L38: 선일국산 | N38: 선일국산
A39: 당삼 | C39: 26500 | D39: 32000 | F39: =B39/500 -> 0 | G39: =C39/500 -> 53 | H39: =D39/600 -> 53.333333 | I39: =E39/600 -> 0 | J39: 53.3
A40: 대두황권 | C40: 13000 | E40: 15800 | F40: =B40/500 -> 0 | G40: =C40/500 -> 26 | H40: =D40/600 -> 0 | I40: =E40/600 -> 26.333333 | J40: 26 | L40: 씨케이중국 | N40: 씨케이중국
...
