Workbook

Sheet 처방전양식 (12)
B1: No. | C1: 약재명 | D1: 수치 | E1: 그램 | F1: 총용량 | G1: 1g 금액 | H1: 1첩 금액 | I1: 총 금액 | K1: 기본 정보
B2: 1 | C2: 반하 | E2: 12 | F2: =E2*$L$15 -> 240 | G2: =VLOOKUP($C2,약재관리!A:J,10,FALSE) -> 47 | H2: =G2*E2 -> 564 | I2: =G2*F2 -> 11280 | K2: UNIT | L2: 47
B3: 2 | C3: 감초 | E3: 8 | F3: =E3*$L$15 -> 160 | G3: =VLOOKUP($C3,약재관리!A:J,10,FALSE) -> 28.3 | H3: =G3*E3 -> 226.4 | I3: =G3*F3 -> 4528 | K3: 처방명 | L3: 감사거삼탕가감
B4: 3 | C4: 대추 | E4: 8 | F4: =E4*$L$15 -> 160 | G4: =VLOOKUP($C4,약재관리!A:J,10,FALSE) -> 20.8 | H4: =G4*E4 -> 166.4 | I4: =G4*F4 -> 3328 | K4: 날짜 | L4: 45813
B5: 4 | C5: 황금 | E5: 6 | F5: =E5*$L$15 -> 120 | G5: =VLOOKUP($C5,약재관리!A:J,10,FALSE) -> 22.5 | H5: =G5*E5 -> 135 | I5: =G5*F5 -> 2700 | K5: 이름 | L5: 박효진
B6: 5 | C6: 건강 | E6: 6 | F6: =E6*$L$15 -> 120 | G6: =VLOOKUP($C6,약재관리!A:J,10,FALSE) -> 9.5 | H6: =G6*E6 -> 57 | I6: =G6*F6 -> 1140 | K6: 나이 | L6: 41
B7: 6 | C7: 황련 | E7: 4 | F7: =E7*$L$15 -> 80 | G7: =VLOOKUP($C7,약재관리!A:J,10,FALSE) -> 136.7 | H7: =G7*E7 -> 546.8 | I7: =G7*F7 -> 10936 | K7: 성별 | L7: F
B8: 7 | C8: 당귀1 | E8: 6 | F8: =E8*$L$15 -> 120 | G8: =VLOOKUP($C8,약재관리!A:J,10,FALSE) -> 25 | H8: =G8*E8 -> 150 | I8: =G8*F8 -> 3000 | K8: 메모
B9: 8 | C9: 천궁1 | E9: 4 | F9: =E9*$L$15 -> 80 | G9: =VLOOKUP($C9,약재관리!A:J,10,FALSE) -> 10.8 | H9: =G9*E9 -> 43.2 | I9: =G9*F9 -> 864 | K9: 감사거삼탕 + 사물탕 + 홍화 목단피 자충
B10: 9 | C10: 백작약 | E10: 6 | F10: =E10*$L$15 -> 120 | G10: =VLOOKUP($C10,약재관리!A:J,10,FALSE) -> 19.6 | H10: =G10*E10 -> 117.6 | I10: =G10*F10 -> 2352
B11: 10 | C11: 건지황 | E11: 6 | F11: =E11*$L$15 -> 120 | G11: =VLOOKUP($C11,약재관리!A:J,10,FALSE) -> 14.4 | H11: =G11*E11 -> 86.4 | I11: =G11*F11 -> 1728
B12: 11 | C12: 홍화 | E12: 2 | F12: =E12*$L$15 -> 40 | G12: =VLOOKUP($C12,약재관리!A:J,10,FALSE) -> 44.2 | H12: =G12*E12 -> 88.4 | I12: =G12*F12 -> 1768
B13: 12 | C13: 목단피 | E13: 4 | F13: =E13*$L$15 -> 80 | G13: =VLOOKUP($C13,약재관리!A:J,10,FALSE) -> 31.5 | H13: =G13*E13 -> 126 | I13: =G13*F13 -> 2520
B14: 13 | C14: 자충 | E14: 10 | F14: =E14*$L$15 -> 200 | G14: =VLOOKUP($C14,약재관리!A:J,10,FALSE) -> 52 | H14: =G14*E14 -> 520 | I14: =G14*F14 -> 10400 | K14: 총 일수 | L14: 15 | M14: 일분
B15: 14 | H15: =G15*E15 -> 0 | I15: =G15*F15 -> 0 | K15: 첩수 | L15: 20 | M15: 첩
B16: 15 | H16: =G16*E16 -> 0 | I16: =G16*F16 -> 0 | K16: 총 팩수 | L16: 45 | M16: 팩
B17: 16 | F17: =E17*$L$15 -> 0 | H17: =G17*E17 -> 0 | I17: =G17*F17 -> 0 | K17: 팩당 물량 | L17: 100 | M17: cc
B18: 17 | F18: =E18*$L$15 -> 0 | H18: =G18*E18 -> 0 | I18: =G18*F18 -> 0 | K18: 1첩당약재 | L18: =SUM(E2:E31) -> 82 | M18: g
B19: 18 | F19: =E19*$L$15 -> 0 | H19: =G19*E19 -> 0 | I19: =G19*F19 -> 0 | K19: 약재총량 | L19: =L15*L18 -> 1640 | M19: g
B20: 19 | F20: =E20*$L$15 -> 0 | H20: =G20*E20 -> 0 | I20: =G20*F20 -> 0 | K20: 총 물 양 | L20: =L16*L17+L19 -> 6140 | M20: cc
B21: 20 | F21: =E21*$L$15 -> 0 | H21: =G21*E21 -> 0 | I21: =G21*F21 -> 0
B22: 21 | F22: =E22*$L$15 -> 0 | H22: =G22*E22 -> 0 | I22: =G22*F22 -> 0 | K22: 참고치
B23: 22 | F23: =E23*$L$15 -> 0 | H23: =G23*E23 -> 0 | I23: =G23*F23 -> 0 | K23: cross chk | L23: =SUM(F2:F31) -> 1640 | M23: g
B24: 23 | F24: =E24*$L$15 -> 0 | H24: =G24*E24 -> 0 | I24: =G24*F24 -> 0 | K24: 20첩물양 | L24: 5000 | M24: cc
B25: 24 | F25: =E25*$L$15 -> 0 | H25: =G25*E25 -> 0 | I25: =G25*F25 -> 0 | K25: 1첩당 | L25: 80-120 | M25: g
B26: 25 | F26: =E26*$L$15 -> 0 | H26: =G26*E26 -> 0 | I26: =G26*F26 -> 0 | K26: 20첩당 | L26: 1600 | M26: g
B27: 26 | F27: =E27*$L$15 -> 0 | H27: =G27*E27 -> 0 | I27: =G27*F27 -> 0 | K27: 1돈 환산 | L27: 4 | M27: g
B28: 27 | F28: =E28*$L$15 -> 0 | H28: =G28*E28 -> 0 | I28: =G28*F28 -> 0
B29: 28 | F29: =E29*$L$15 -> 0 | H29: =G29*E29 -> 0 | I29: =G29*F29 -> 0 | K29: 금액
B30: 29 | F30: =E30*$L$15 -> 0 | H30: =G30*E30 -> 0 | I30: =G30*F30 -> 0 | K30: 1첩당 | L30: =SUM(H2:H31) -> 2827.2 | M30: 원
B31: 30 | F31: =E31*$L$15 -> 0 | H31: =G31*E31 -> 0 | I31: =G31*F31 -> 0 | K31: 총 | L31: =SUM(I2:I31) -> 56544 | M31: 원

Sheet 처방전양식 (11)
B1: No. | C1: 약재명 | D1: 수치 | E1: 그램 | F1: 총용량 | G1: 1g 금액 | H1: 1첩 금액 | I1: 총 금액 | K1: 기본 정보
B2: 1 | C2: 백작약 | E2: 4 | F2: =E2*$L$15 -> 80 | G2: =VLOOKUP($C2,약재관리!A:J,10,FALSE) -> 19.6 | H2: =G2*E2 -> 78.4 | I2: =G2*F2 -> 1568 | K2: UNIT | L2: 47
B3: 2 | C3: 창출1 | E3: 6 | F3: =E3*$L$15 -> 120 | G3: =VLOOKUP($C3,약재관리!A:J,10,FALSE) -> 24 | H3: =G3*E3 -> 144 | I3: =G3*F3 -> 2880 | K3: 처방명 | L3: 소요산 가감
B4: 3 | C4: 당귀1 | E4: 8 | F4: =E4*$L$15 -> 160 | G4: =VLOOKUP($C4,약재관리!A:J,10,FALSE) -> 25 | H4: =G4*E4 -> 200 | I4: =G4*F4 -> 4000 | K4: 날짜 | L4: 45793
B5: 4 | C5: 복령 | E5: 6 | F5: =E5*$L$15 -> 120 | G5: =VLOOKUP($C5,약재관리!A:J,10,FALSE) -> 11 | H5: =G5*E5 -> 66 | I5: =G5*F5 -> 1320 | K5: 이름 | L5: 박효진
B6: 5 | C6: 맥문동 | E6: 4 | F6: =E6*$L$15 -> 80 | G6: =VLOOKUP($C6,약재관리!A:J,10,FALSE) -> 44.3 | H6: =G6*E6 -> 177.2 | I6: =G6*F6 -> 3544 | K6: 나이 | L6: 41
B7: 6 | C7: 건지황 | E7: 6 | F7: =E7*$L$15 -> 120 | G7: =VLOOKUP($C7,약재관리!A:J,10,FALSE) -> 14.4 | H7: =G7*E7 -> 86.4 | I7: =G7*F7 -> 1728 | K7: 성별 | L7: F
B8: 7 | C8: 치자 | D8: 초 | E8: 4 | F8: =E8*$L$15 -> 80 | G8: =VLOOKUP($C8,약재관리!A:J,10,FALSE) -> 21.3 | H8: =G8*E8 -> 85.2 | I8: =G8*F8 -> 1704 | K8: 메모
B9: 8 | C9: 진피1 | E9: 4 | F9: =E9*$L$15 -> 80 | G9: =VLOOKUP($C9,약재관리!A:J,10,FALSE) -> 17.6 | H9: =G9*E9 -> 70.4 | I9: =G9*F9 -> 1408 | K9: 단치소요산 + 황련 지골피 + 홍화 자충 삼릉 봉출 + 사인 건강 익지인 반하 진피
B10: 9 | C10: 건강 | E10: 4 | F10: =E10*$L$15 -> 80 | G10: =VLOOKUP($C10,약재관리!A:J,10,FALSE) -> 9.5 | H10: =G10*E10 -> 38 | I10: =G10*F10 -> 760
B11: 10 | C11: 감초 | E11: 2 | F11: =E11*$L$15 -> 40 | G11: =VLOOKUP($C11,약재관리!A:J,10,FALSE) -> 28.3 | H11: =G11*E11 -> 56.6 | I11: =G11*F11 -> 1132
B12: 11 | C12: 지골피 | E12: 4 | F12: =E12*$L$15 -> 80 | G12: =VLOOKUP($C12,약재관리!A:J,10,FALSE) -> 21.7 | H12: =G12*E12 -> 86.8 | I12: =G12*F12 -> 1736
B13: 12 | C13: 목단피 | E13: 4 | F13: =E13*$L$15 -> 80 | G13: =VLOOKUP($C13,약재관리!A:J,10,FALSE) -> 31.5 | H13: =G13*E13 -> 126 | I13: =G13*F13 -> 2520
B14: 13 | C14: 황련 | D14: 주초 | E14: 3 | F14: =E14*$L$15 -> 60 | G14: =VLOOKUP($C14,약재관리!A:J,10,FALSE) -> 136.7 | H14: =G14*E14 -> 410.1 | I14: =G14*F14 -> 8202 | K14: 총 일수 | L14: 15 | M14: 일분
B15: 14 | C15: 사인 | E15: 4 | F15: =E15*$L$15 -> 80 | G15: =VLOOKUP($C15,약재관리!A:J,10,FALSE) -> 21.8 | H15: =G15*E15 -> 87.2 | I15: =G15*F15 -> 1744 | K15: 첩수 | L15: 20 | M15: 첩
B16: 15 | C16: 익지인 | E16: 4 | F16: =E16*$L$15 -> 80 | G16: =VLOOKUP($C16,약재관리!A:J,10,FALSE) -> 15.4 | H16: =G16*E16 -> 61.6 | I16: =G16*F16 -> 1232 | K16: 총 팩수 | L16: 45 | M16: 팩
B17: 16 | C17: 홍화 | E17: 2 | F17: =E17*$L$15 -> 40 | G17: =VLOOKUP($C17,약재관리!A:J,10,FALSE) -> 44.2 | H17: =G17*E17 -> 88.4 | I17: =G17*F17 -> 1768 | K17: 팩당 물량 | L17: 100 | M17: cc
B18: 17 | C18: 자충 | E18: 10 | F18: =E18*$L$15 -> 200 | G18: =VLOOKUP($C18,약재관리!A:J,10,FALSE) -> 52 | H18: =G18*E18 -> 520 | I18: =G18*F18 -> 10400 | K18: 1첩당약재 | L18: =SUM(E2:E31) -> 87 | M18: g
B19: 18 | C19: 반하 | E19: 4 | F19: =E19*$L$15 -> 80 | G19: =VLOOKUP($C19,약재관리!A:J,10,FALSE) -> 47 | H19: =G19*E19 -> 188 | I19: =G19*F19 -> 3760 | K19: 약재총량 | L19: =L15*L18 -> 1740 | M19: g
B20: 19 | C20: 삼릉 | E20: 2 | F20: =E20*$L$15 -> 40 | G20: =VLOOKUP($C20,약재관리!A:J,10,FALSE) -> 9.2 | H20: =G20*E20 -> 18.4 | I20: =G20*F20 -> 368 | K20: 총 물 양 | L20: =L16*L17+L19 -> 6240 | M20: cc
B21: 20 | C21: 봉출 | E21: 2 | F21: =E21*$L$15 -> 40 | G21: =VLOOKUP($C21,약재관리!A:J,10,FALSE) -> 10.8 | H21: =G21*E21 -> 21.6 | I21: =G21*F21 -> 432
B22: 21 | F22: =E22*$L$15 -> 0 | H22: =G22*E22 -> 0 | I22: =G22*F22 -> 0 | K22: 참고치
B23: 22 | F23: =E23*$L$15 -> 0 | H23: =G23*E23 -> 0 | I23: =G23*F23 -> 0 | K23: cross chk | L23: =SUM(F2:F31) -> 1740 | M23: g
B24: 23 | F24: =E24*$L$15 -> 0 | H24: =G24*E24 -> 0 | I24: =G24*F24 -> 0 | K24: 20첩물양 | L24: 5000 | M24: cc
B25: 24 | F25: =E25*$L$15 -> 0 | H25: =G25*E25 -> 0 | I25: =G25*F25 -> 0 | K25: 1첩당 | L25: 80-120 | M25: g
B26: 25 | F26: =E26*$L$15 -> 0 | H26: =G26*E26 -> 0 | I26: =G26*F26 -> 0 | K26: 20첩당 | L26: 1600 | M26: g
B27: 26 | F27: =E27*$L$15 -> 0 | H27: =G27*E27 -> 0 | I27: =G27*F27 -> 0 | K27: 1돈 환산 | L27: 4 | M27: g
B28: 27 | F28: =E28*$L$15 -> 0 | H28: =G28*E28 -> 0 | I28: =G28*F28 -> 0
B29: 28 | F29: =E29*$L$15 -> 0 | H29: =G29*E29 -> 0 | I29: =G29*F29 -> 0 | K29: 금액
B30: 29 | F30: =E30*$L$15 -> 0 | H30: =G30*E30 -> 0 | I30: =G30*F30 -> 0 | K30: 1첩당 | L30: =SUM(H2:H31) -> 2610.3 | M30: 원
B31: 30 | F31: =E31*$L$15 -> 0 | H31: =G31*E31 -> 0 | I31: =G31*F31 -> 0 | K31: 총 | L31: =SUM(I2:I31) -> 52206 | M31: 원

Sheet 처방전양식 (10)
B1: No. | C1: 약재명 | D1: 수치 | E1: 그램 | F1: 총용량 | G1: 1g 금액 | H1: 1첩 금액 | I1: 총 금액 | K1: 기본 정보
B2: 1 | C2: 백작약 | E2: 4 | F2: =E2*$L$15 -> 80 | G2: =VLOOKUP($C2,약재관리!A:J,10,FALSE) -> 19.6 | H2: =G2*E2 -> 78.4 | I2: =G2*F2 -> 1568 | K2: UNIT | L2: 47
B3: 2 | C3: 백출 | E3: 10 | F3: =E3*$L$15 -> 200 | G3: =VLOOKUP($C3,약재관리!A:J,10,FALSE) -> 28.3 | H3: =G3*E3 -> 283 | I3: =G3*F3 -> 5660 | K3: 처방명 | L3: 사물탕 합 소요산
B4: 3 | C4: 당귀1 | E4: 8 | F4: =E4*$L$15 -> 160 | G4: =VLOOKUP($C4,약재관리!A:J,10,FALSE) -> 25 | H4: =G4*E4 -> 200 | I4: =G4*F4 -> 4000 | K4: 날짜 | L4: 45756
B5: 4 | C5: 복령 | E5: 6 | F5: =E5*$L$15 -> 120 | G5: =VLOOKUP($C5,약재관리!A:J,10,FALSE) -> 11 | H5: =G5*E5 -> 66 | I5: =G5*F5 -> 1320 | K5: 이름 | L5: 박효진
B6: 5 | C6: 맥문동 | E6: 4 | F6: =E6*$L$15 -> 80 | G6: =VLOOKUP($C6,약재관리!A:J,10,FALSE) -> 44.3 | H6: =G6*E6 -> 177.2 | I6: =G6*F6 -> 3544 | K6: 나이 | L6: 41
B7: 6 | C7: 생지황 | E7: 4 | F7: =E7*$L$15 -> 80 | G7: =VLOOKUP($C7,약재관리!A:J,10,FALSE) -> 17.4 | H7: =G7*E7 -> 69.6 | I7: =G7*F7 -> 1392 | K7: 성별 | L7: F
B8: 7 | C8: 치자 | D8: 초 | E8: 2 | F8: =E8*$L$15 -> 40 | G8: =VLOOKUP($C8,약재관리!A:J,10,FALSE) -> 21.3 | H8: =G8*E8 -> 42.6 | I8: =G8*F8 -> 852 | K8: 메모
B9: 8 | C9: 지모 | E9: 3 | F9: =E9*$L$15 -> 60 | G9: =VLOOKUP($C9,약재관리!A:J,10,FALSE) -> 16.7 | H9: =G9*E9 -> 50.1 | I9: =G9*F9 -> 1002 | K9: 단치소요산 + 황련 지모 황백 지골피 + 홍화 목단피 자충(감량) + 사인 건강 익지인 반하
B10: 9 | C10: 건강 | E10: 4 | F10: =E10*$L$15 -> 80 | G10: =VLOOKUP($C10,약재관리!A:J,10,FALSE) -> 9.5 | H10: =G10*E10 -> 38 | I10: =G10*F10 -> 760
B11: 10 | C11: 감초 | E11: 2 | F11: =E11*$L$15 -> 40 | G11: =VLOOKUP($C11,약재관리!A:J,10,FALSE) -> 28.3 | H11: =G11*E11 -> 56.6 | I11: =G11*F11 -> 1132
B12: 11 | C12: 지골피 | E12: 4 | F12: =E12*$L$15 -> 80 | G12: =VLOOKUP($C12,약재관리!A:J,10,FALSE) -> 21.7 | H12: =G12*E12 -> 86.8 | I12: =G12*F12 -> 1736
B13: 12 | C13: 목단피 | E13: 4 | F13: =E13*$L$15 -> 80 | G13: =VLOOKUP($C13,약재관리!A:J,10,FALSE) -> 31.5 | H13: =G13*E13 -> 126 | I13: =G13*F13 -> 2520
B14: 13 | C14: 황련 | D14: 주초 | E14: 3 | F14: =E14*$L$15 -> 60 | G14: =VLOOKUP($C14,약재관리!A:J,10,FALSE) -> 136.7 | H14: =G14*E14 -> 410.1 | I14: =G14*F14 -> 8202 | K14: 총 일수 | L14: 15 | M14: 일분
B15: 14 | C15: 황백 | E15: 3 | F15: =E15*$L$15 -> 60 | G15: =VLOOKUP($C15,약재관리!A:J,10,FALSE) -> 27.7 | H15: =G15*E15 -> 83.1 | I15: =G15*F15 -> 1662 | K15: 첩수 | L15: 20 | M15: 첩
B16: 15 | C16: 사인 | E16: 4 | F16: =E16*$L$15 -> 80 | G16: =VLOOKUP($C16,약재관리!A:J,10,FALSE) -> 21.8 | H16: =G16*E16 -> 87.2 | I16: =G16*F16 -> 1744 | K16: 총 팩수 | L16: 45 | M16: 팩
B17: 16 | C17: 익지인 | E17: 4 | F17: =E17*$L$15 -> 80 | G17: =VLOOKUP($C17,약재관리!A:J,10,FALSE) -> 15.4 | H17: =G17*E17 -> 61.6 | I17: =G17*F17 -> 1232 | K17: 팩당 물량 | L17: 100 | M17: cc
B18: 17 | C18: 홍화 | E18: 2 | F18: =E18*$L$15 -> 40 | G18: =VLOOKUP($C18,약재관리!A:J,10,FALSE) -> 44.2 | H18: =G18*E18 -> 88.4 | I18: =G18*F18 -> 1768 | K18: 1첩당약재 | L18: =SUM(E2:E31) -> 83 | M18: g
B19: 18 | C19: 자충 | E19: 8 | F19: =E19*$L$15 -> 160 | G19: =VLOOKUP($C19,약재관리!A:J,10,FALSE) -> 52 | H19: =G19*E19 -> 416 | I19: =G19*F19 -> 8320 | K19: 약재총량 | L19: =L15*L18 -> 1660 | M19: g
B20: 19 | C20: 반하 | E20: 4 | F20: =E20*$L$15 -> 80 | G20: =VLOOKUP($C20,약재관리!A:J,10,FALSE) -> 47 | H20: =G20*E20 -> 188 | I20: =G20*F20 -> 3760 | K20: 총 물 양 | L20: =L16*L17+L19 -> 6160 | M20: cc
B21: 20 | F21: =E21*$L$15 -> 0 | H21: =G21*E21 -> 0 | I21: =G21*F21 -> 0
B22: 21 | F22: =E22*$L$15 -> 0 | H22: =G22*E22 -> 0 | I22: =G22*F22 -> 0 | K22: 참고치
B23: 22 | F23: =E23*$L$15 -> 0 | H23: =G23*E23 -> 0 | I23: =G23*F23 -> 0 | K23: cross chk | L23: =SUM(F2:F31) -> 1660 | M23: g
B24: 23 | F24: =E24*$L$15 -> 0 | H24: =G24*E24 -> 0 | I24: =G24*F24 -> 0 | K24: 20첩물양 | L24: 5000 | M24: cc
B25: 24 | F25: =E25*$L$15 -> 0 | H25: =G25*E25 -> 0 | I25: =G25*F25 -> 0 | K25: 1첩당 | L25: 80-120 | M25: g
B26: 25 | F26: =E26*$L$15 -> 0 | H26: =G26*E26 -> 0 | I26: =G26*F26 -> 0 | K26: 20첩당 | L26: 1600 | M26: g
B27: 26 | F27: =E27*$L$15 -> 0 | H27: =G27*E27 -> 0 | I27: =G27*F27 -> 0 | K27: 1돈 환산 | L27: 4 | M27: g
B28: 27 | F28: =E28*$L$15 -> 0 | H28: =G28*E28 -> 0 | I28: =G28*F28 -> 0
B29: 28 | F29: =E29*$L$15 -> 0 | H29: =G29*E29 -> 0 | I29: =G29*F29 -> 0 | K29: 금액
B30: 29 | F30: =E30*$L$15 -> 0 | H30: =G30*E30 -> 0 | I30: =G30*F30 -> 0 | K30: 1첩당 | L30: =SUM(H2:H31) -> 2608.7 | M30: 원
B31: 30 | F31: =E31*$L$15 -> 0 | H31: =G31*E31 -> 0 | I31: =G31*F31 -> 0 | K31: 총 | L31: =SUM(I2:I31) -> 52174 | M31: 원

Sheet 처방전양식 (9)
B1: No. | C1: 약재명 | D1: 수치 | E1: 그램 | F1: 총용량 | G1: 1g 금액 | H1: 1첩 금액 | I1: 총 금액 | K1: 기본 정보
B2: 1 | C2: 백작약 | E2: 4 | F2: =E2*$L$15 -> 80 | G2: =VLOOKUP($C2,약재관리!A:J,10,FALSE) -> 19.6 | H2: =G2*E2 -> 78.4 | I2: =G2*F2 -> 1568 | K2: UNIT | L2: 47
B3: 2 | C3: 창출1 | E3: 8 | F3: =E3*$L$15 -> 160 | G3: =VLOOKUP($C3,약재관리!A:J,10,FALSE) -> 24 | H3: =G3*E3 -> 192 | I3: =G3*F3 -> 3840 | K3: 처방명 | L3: 사물탕 합 소요산
B4: 3 | C4: 당귀1 | E4: 8 | F4: =E4*$L$15 -> 160 | G4: =VLOOKUP($C4,약재관리!A:J,10,FALSE) -> 25 | H4: =G4*E4 -> 200 | I4: =G4*F4 -> 4000 | K4: 날짜 | L4: 45756
B5: 4 | C5: 복령 | E5: 6 | F5: =E5*$L$15 -> 120 | G5: =VLOOKUP($C5,약재관리!A:J,10,FALSE) -> 11 | H5: =G5*E5 -> 66 | I5: =G5*F5 -> 1320 | K5: 이름 | L5: 박효진
B6: 5 | C6: 맥문동 | E6: 4 | F6: =E6*$L$15 -> 80 | G6: =VLOOKUP($C6,약재관리!A:J,10,FALSE) -> 44.3 | H6: =G6*E6 -> 177.2 | I6: =G6*F6 -> 3544 | K6: 나이 | L6: 41
B7: 6 | C7: 생지황 | E7: 8 | F7: =E7*$L$15 -> 160 | G7: =VLOOKUP($C7,약재관리!A:J,10,FALSE) -> 17.4 | H7: =G7*E7 -> 139.2 | I7: =G7*F7 -> 2784 | K7: 성별 | L7: F
B8: 7 | C8: 치자 | D8: 초 | E8: 2 | F8: =E8*$L$15 -> 40 | G8: =VLOOKUP($C8,약재관리!A:J,10,FALSE) -> 21.3 | H8: =G8*E8 -> 42.6 | I8: =G8*F8 -> 852 | K8: 메모
B9: 8 | C9: 지모 | E9: 3 | F9: =E9*$L$15 -> 60 | G9: =VLOOKUP($C9,약재관리!A:J,10,FALSE) -> 16.7 | H9: =G9*E9 -> 50.1 | I9: =G9*F9 -> 1002 | K9: 단치소요산 + 황련 지모 황백 지골피 + 홍화 목단피 삼릉 봉출 자충(감량) + 사인 건강 익지인
B10: 9 | C10: 건강 | E10: 3 | F10: =E10*$L$15 -> 60 | G10: =VLOOKUP($C10,약재관리!A:J,10,FALSE) -> 9.5 | H10: =G10*E10 -> 28.5 | I10: =G10*F10 -> 570
B11: 10 | C11: 감초 | E11: 2 | F11: =E11*$L$15 -> 40 | G11: =VLOOKUP($C11,약재관리!A:J,10,FALSE) -> 28.3 | H11: =G11*E11 -> 56.6 | I11: =G11*F11 -> 1132
B12: 11 | C12: 지골피 | E12: 4 | F12: =E12*$L$15 -> 80 | G12: =VLOOKUP($C12,약재관리!A:J,10,FALSE) -> 21.7 | H12: =G12*E12 -> 86.8 | I12: =G12*F12 -> 1736
B13: 12 | C13: 목단피 | E13: 4 | F13: =E13*$L$15 -> 80 | G13: =VLOOKUP($C13,약재관리!A:J,10,FALSE) -> 31.5 | H13: =G13*E13 -> 126 | I13: =G13*F13 -> 2520
B14: 13 | C14: 황련 | D14: 주초 | E14: 2 | F14: =E14*$L$15 -> 40 | G14: =VLOOKUP($C14,약재관리!A:J,10,FALSE) -> 136.7 | H14: =G14*E14 -> 273.4 | I14: =G14*F14 -> 5468 | K14: 총 일수 | L14: 15 | M14: 일분
B15: 14 | C15: 황백 | E15: 3 | F15: =E15*$L$15 -> 60 | G15: =VLOOKUP($C15,약재관리!A:J,10,FALSE) -> 27.7 | H15: =G15*E15 -> 83.1 | I15: =G15*F15 -> 1662 | K15: 첩수 | L15: 20 | M15: 첩
B16: 15 | C16: 사인 | E16: 4 | F16: =E16*$L$15 -> 80 | G16: =VLOOKUP($C16,약재관리!A:J,10,FALSE) -> 21.8 | H16: =G16*E16 -> 87.2 | I16: =G16*F16 -> 1744 | K16: 총 팩수 | L16: 45 | M16: 팩
B17: 16 | C17: 익지인 | E17: 4 | F17: =E17*$L$15 -> 80 | G17: =VLOOKUP($C17,약재관리!A:J,10,FALSE) -> 15.4 | H17: =G17*E17 -> 61.6 | I17: =G17*F17 -> 1232 | K17: 팩당 물량 | L17: 100 | M17: cc
B18: 17 | C18: 삼릉 | E18: 2 | F18: =E18*$L$15 -> 40 | G18: =VLOOKUP($C18,약재관리!A:J,10,FALSE) -> 9.2 | H18: =G18*E18 -> 18.4 | I18: =G18*F18 -> 368 | K18: 1첩당약재 | L18: =SUM(E2:E31) -> 85 | M18: g
B19: 18 | C19: 봉출 | E19: 2 | F19: =E19*$L$15 -> 40 | G19: =VLOOKUP($C19,약재관리!A:J,10,FALSE) -> 10.8 | H19: =G19*E19 -> 21.6 | I19: =G19*F19 -> 432 | K19: 약재총량 | L19: =L15*L18 -> 1700 | M19: g
B20: 19 | C20: 홍화 | E20: 4 | F20: =E20*$L$15 -> 80 | G20: =VLOOKUP($C20,약재관리!A:J,10,FALSE) -> 44.2 | H20: =G20*E20 -> 176.8 | I20: =G20*F20 -> 3536 | K20: 총 물 양 | L20: =L16*L17+L19 -> 6200 | M20: cc
B21: 20 | C21: 자충 | E21: 8 | F21: =E21*$L$15 -> 160 | G21: =VLOOKUP($C21,약재관리!A:J,10,FALSE) -> 52 | H21: =G21*E21 -> 416 | I21: =G21*F21 -> 8320
B22: 21 | F22: =E22*$L$15 -> 0 | H22: =G22*E22 -> 0 | I22: =G22*F22 -> 0 | K22: 참고치
B23: 22 | F23: =E23*$L$15 -> 0 | H23: =G23*E23 -> 0 | I23: =G23*F23 -> 0 | K23: cross chk | L23: =SUM(F2:F31) -> 1700 | M23: g
B24: 23 | F24: =E24*$L$15 -> 0 | H24: =G24*E24 -> 0 | I24: =G24*F24 -> 0 | K24: 20첩물양 | L24: 5000 | M24: cc
B25: 24 | F25: =E25*$L$15 -> 0 | H25: =G25*E25 -> 0 | I25: =G25*F25 -> 0 | K25: 1첩당 | L25: 80-120 | M25: g
B26: 25 | F26: =E26*$L$15 -> 0 | H26: =G26*E26 -> 0 | I26: =G26*F26 -> 0 | K26: 20첩당 | L26: 1600 | M26: g
B27: 26 | F27: =E27*$L$15 -> 0 | H27: =G27*E27 -> 0 | I27: =G27*F27 -> 0 | K27: 1돈 환산 | L27: 4 | M27: g
B28: 27 | F28: =E28*$L$15 -> 0 | H28: =G28*E28 -> 0 | I28: =G28*F28 -> 0
B29: 28 | F29: =E29*$L$15 -> 0 | H29: =G29*E29 -> 0 | I29: =G29*F29 -> 0 | K29: 금액
B30: 29 | F30: =E30*$L$15 -> 0 | H30: =G30*E30 -> 0 | I30: =G30*F30 -> 0 | K30: 1첩당 | L30: =SUM(H2:H31) -> 2381.5 | M30: 원
B31: 30 | F31: =E31*$L$15 -> 0 | H31: =G31*E31 -> 0 | I31: =G31*F31 -> 0 | K31: 총 | L31: =SUM(I2:I31) -> 47630 | M31: 원

Sheet 처방전양식 (8)
B1: No. | C1: 약재명 | D1: 수치 | E1: 그램 | F1: 총용량 | G1: 1g 금액 | H1: 1첩 금액 | I1: 총 금액 | K1: 기본 정보
B2: 1 | C2: 백작약 | E2: 4 | F2: =E2*$L$15 -> 80 | G2: =VLOOKUP($C2,약재관리!A:J,10,FALSE) -> 19.6 | H2: =G2*E2 -> 78.4 | I2: =G2*F2 -> 1568 | K2: UNIT | L2: 47
B3: 2 | C3: 창출1 | E3: 8 | F3: =E3*$L$15 -> 160 | G3: =VLOOKUP($C3,약재관리!A:J,10,FALSE) -> 24 | H3: =G3*E3 -> 192 | I3: =G3*F3 -> 3840 | K3: 처방명 | L3: 사물탕 합 소요산
B4: 3 | C4: 당귀1 | E4: 8 | F4: =E4*$L$15 -> 160 | G4: =VLOOKUP($C4,약재관리!A:J,10,FALSE) -> 25 | H4: =G4*E4 -> 200 | I4: =G4*F4 -> 4000 | K4: 날짜 | L4: 45742
B5: 4 | C5: 복령 | E5: 6 | F5: =E5*$L$15 -> 120 | G5: =VLOOKUP($C5,약재관리!A:J,10,FALSE) -> 11 | H5: =G5*E5 -> 66 | I5: =G5*F5 -> 1320 | K5: 이름 | L5: 박효진
B6: 5 | C6: 맥문동 | E6: 4 | F6: =E6*$L$15 -> 80 | G6: =VLOOKUP($C6,약재관리!A:J,10,FALSE) -> 44.3 | H6: =G6*E6 -> 177.2 | I6: =G6*F6 -> 3544 | K6: 나이 | L6: 41
B7: 6 | C7: 생지황 | E7: 8 | F7: =E7*$L$15 -> 160 | G7: =VLOOKUP($C7,약재관리!A:J,10,FALSE) -> 17.4 | H7: =G7*E7 -> 139.2 | I7: =G7*F7 -> 2784 | K7: 성별 | L7: F
B8: 7 | C8: 치자 | D8: 초 | E8: 2 | F8: =E8*$L$15 -> 40 | G8: =VLOOKUP($C8,약재관리!A:J,10,FALSE) -> 21.3 | H8: =G8*E8 -> 42.6 | I8: =G8*F8 -> 852 | K8: 메모
B9: 8 | C9: 지모 | E9: 3 | F9: =E9*$L$15 -> 60 | G9: =VLOOKUP($C9,약재관리!A:J,10,FALSE) -> 16.7 | H9: =G9*E9 -> 50.1 | I9: =G9*F9 -> 1002 | K9: 단치소요산 + 황련 지모 황백 지골피 + 홍화 목단피 삼릉 봉출 자충 + 사인 건강 익지인
B10: 9 | C10: 건강 | E10: 3 | F10: =E10*$L$15 -> 60 | G10: =VLOOKUP($C10,약재관리!A:J,10,FALSE) -> 9.5 | H10: =G10*E10 -> 28.5 | I10: =G10*F10 -> 570
B11: 10 | C11: 감초 | E11: 2 | F11: =E11*$L$15 -> 40 | G11: =VLOOKUP($C11,약재관리!A:J,10,FALSE) -> 28.3 | H11: =G11*E11 -> 56.6 | I11: =G11*F11 -> 1132
B12: 11 | C12: 홍화 | E12: 4 | F12: =E12*$L$15 -> 80 | G12: =VLOOKUP($C12,약재관리!A:J,10,FALSE) -> 44.2 | H12: =G12*E12 -> 176.8 | I12: =G12*F12 -> 3536
B13: 12 | C13: 목단피 | E13: 4 | F13: =E13*$L$15 -> 80 | G13: =VLOOKUP($C13,약재관리!A:J,10,FALSE) -> 31.5 | H13: =G13*E13 -> 126 | I13: =G13*F13 -> 2520
B14: 13 | C14: 황련 | D14: 주초 | E14: 2 | F14: =E14*$L$15 -> 40 | G14: =VLOOKUP($C14,약재관리!A:J,10,FALSE) -> 136.7 | H14: =G14*E14 -> 273.4 | I14: =G14*F14 -> 5468 | K14: 총 일수 | L14: 15 | M14: 일분
B15: 14 | C15: 황백 | E15: 3 | F15: =E15*$L$15 -> 60 | G15: =VLOOKUP($C15,약재관리!A:J,10,FALSE) -> 27.7 | H15: =G15*E15 -> 83.1 | I15: =G15*F15 -> 1662 | K15: 첩수 | L15: 20 | M15: 첩
B16: 15 | C16: 사인 | E16: 4 | F16: =E16*$L$15 -> 80 | G16: =VLOOKUP($C16,약재관리!A:J,10,FALSE) -> 21.8 | H16: =G16*E16 -> 87.2 | I16: =G16*F16 -> 1744 | K16: 총 팩수 | L16: 45 | M16: 팩
B17: 16 | C17: 익지인 | E17: 4 | F17: =E17*$L$15 -> 80 | G17: =VLOOKUP($C17,약재관리!A:J,10,FALSE) -> 15.4 | H17: =G17*E17 -> 61.6 | I17: =G17*F17 -> 1232 | K17: 팩당 물량 | L17: 100 | M17: cc
B18: 17 | C18: 삼릉 | E18: 2 | F18: =E18*$L$15 -> 40 | G18: =VLOOKUP($C18,약재관리!A:J,10,FALSE) -> 9.2 | H18: =G18*E18 -> 18.4 | I18: =G18*F18 -> 368 | K18: 1첩당약재 | L18: =SUM(E2:E31) -> 87 | M18: g
B19: 18 | C19: 봉출 | E19: 2 | F19: =E19*$L$15 -> 40 | G19: =VLOOKUP($C19,약재관리!A:J,10,FALSE) -> 10.8 | H19: =G19*E19 -> 21.6 | I19: =G19*F19 -> 432 | K19: 약재총량 | L19: =L15*L18 -> 1740 | M19: g
B20: 19 | C20: 지골피 | E20: 4 | F20: =E20*$L$15 -> 80 | G20: =VLOOKUP($C20,약재관리!A:J,10,FALSE) -> 21.7 | H20: =G20*E20 -> 86.8 | I20: =G20*F20 -> 1736 | K20: 총 물 양 | L20: =L16*L17+L19 -> 6240 | M20: cc
B21: 20 | C21: 자충 | E21: 10 | F21: =E21*$L$15 -> 200 | G21: =VLOOKUP($C21,약재관리!A:J,10,FALSE) -> 52 | H21: =G21*E21 -> 520 | I21: =G21*F21 -> 10400
B22: 21 | F22: =E22*$L$15 -> 0 | H22: =G22*E22 -> 0 | I22: =G22*F22 -> 0 | K22: 참고치
B23: 22 | F23: =E23*$L$15 -> 0 | H23: =G23*E23 -> 0 | I23: =G23*F23 -> 0 | K23: cross chk | L23: =SUM(F2:F31) -> 1740 | M23: g
B24: 23 | F24: =E24*$L$15 -> 0 | H24: =G24*E24 -> 0 | I24: =G24*F24 -> 0 | K24: 20첩물양 | L24: 5000 | M24: cc
B25: 24 | F25: =E25*$L$15 -> 0 | H25: =G25*E25 -> 0 | I25: =G25*F25 -> 0 | K25: 1첩당 | L25: 80-120 | M25: g
B26: 25 | F26: =E26*$L$15 -> 0 | H26: =G26*E26 -> 0 | I26: =G26*F26 -> 0 | K26: 20첩당 | L26: 1600 | M26: g
B27: 26 | F27: =E27*$L$15 -> 0 | H27: =G27*E27 -> 0 | I27: =G27*F27 -> 0 | K27: 1돈 환산 | L27: 4 | M27: g
B28: 27 | F28: =E28*$L$15 -> 0 | H28: =G28*E28 -> 0 | I28: =G28*F28 -> 0
B29: 28 | F29: =E29*$L$15 -> 0 | H29: =G29*E29 -> 0 | I29: =G29*F29 -> 0 | K29: 금액
B30: 29 | F30: =E30*$L$15 -> 0 | H30: =G30*E30 -> 0 | I30: =G30*F30 -> 0 | K30: 1첩당 | L30: =SUM(H2:H31) -> 2485.5 | M30: 원
B31: 30 | F31: =E31*$L$15 -> 0 | H31: =G31*E31 -> 0 | I31: =G31*F31 -> 0 | K31: 총 | L31: =SUM(I2:I31) -> 49710 | M31: 원

Sheet 처방전양식 (7)
B1: No. | C1: 약재명 | D1: 수치 | E1: 그램 | F1: 총용량 | G1: 1g 금액 | H1: 1첩 금액 | I1: 총 금액 | K1: 기본 정보
B2: 1 | C2: 백작약 | E2: 6 | F2: =E2*$L$15 -> 120 | G2: =VLOOKUP($C2,약재관리!A:J,10,FALSE) -> 19.6 | H2: =G2*E2 -> 117.6 | I2: =G2*F2 -> 2352 | K2: UNIT | L2: 47
B3: 2 | C3: 창출1 | E3: 6 | F3: =E3*$L$15 -> 120 | G3: =VLOOKUP($C3,약재관리!A:J,10,FALSE) -> 24 | H3: =G3*E3 -> 144 | I3: =G3*F3 -> 2880 | K3: 처방명 | L3: 소요산 가감
B4: 3 | C4: 당귀1 | E4: 8 | F4: =E4*$L$15 -> 160 | G4: =VLOOKUP($C4,약재관리!A:J,10,FALSE) -> 25 | H4: =G4*E4 -> 200 | I4: =G4*F4 -> 4000 | K4: 날짜 | L4: 45700
B5: 4 | C5: 복령 | E5: 6 | F5: =E5*$L$15 -> 120 | G5: =VLOOKUP($C5,약재관리!A:J,10,FALSE) -> 11 | H5: =G5*E5 -> 66 | I5: =G5*F5 -> 1320 | K5: 이름 | L5: 박효진
B6: 5 | C6: 맥문동 | E6: 4 | F6: =E6*$L$15 -> 80 | G6: =VLOOKUP($C6,약재관리!A:J,10,FALSE) -> 44.3 | H6: =G6*E6 -> 177.2 | I6: =G6*F6 -> 3544 | K6: 나이 | L6: 41
B7: 6 | C7: 생지황 | E7: 8 | F7: =E7*$L$15 -> 160 | G7: =VLOOKUP($C7,약재관리!A:J,10,FALSE) -> 17.4 | H7: =G7*E7 -> 139.2 | I7: =G7*F7 -> 2784 | K7: 성별 | L7: F
B8: 7 | C8: 치자 | D8: 초 | E8: 2 | F8: =E8*$L$15 -> 40 | G8: =VLOOKUP($C8,약재관리!A:J,10,FALSE) -> 21.3 | H8: =G8*E8 -> 42.6 | I8: =G8*F8 -> 852 | K8: 메모
B9: 8 | C9: 지모 | E9: 3 | F9: =E9*$L$15 -> 60 | G9: =VLOOKUP($C9,약재관리!A:J,10,FALSE) -> 16.7 | H9: =G9*E9 -> 50.1 | I9: =G9*F9 -> 1002 | K9: 단치소요산 + 황련 지모 황백 생지황 지골피 + 사인 건강 익지인
B10: 9 | C10: 건강 | E10: 2 | F10: =E10*$L$15 -> 40 | G10: =VLOOKUP($C10,약재관리!A:J,10,FALSE) -> 9.5 | H10: =G10*E10 -> 19 | I10: =G10*F10 -> 380
B11: 10 | C11: 감초 | E11: 2 | F11: =E11*$L$15 -> 40 | G11: =VLOOKUP($C11,약재관리!A:J,10,FALSE) -> 28.3 | H11: =G11*E11 -> 56.6 | I11: =G11*F11 -> 1132
B12: 11 | C12: 지골피 | E12: 4 | F12: =E12*$L$15 -> 80 | G12: =VLOOKUP($C12,약재관리!A:J,10,FALSE) -> 21.7 | H12: =G12*E12 -> 86.8 | I12: =G12*F12 -> 1736
B13: 12 | C13: 목단피 | E13: 6 | F13: =E13*$L$15 -> 120 | G13: =VLOOKUP($C13,약재관리!A:J,10,FALSE) -> 31.5 | H13: =G13*E13 -> 189 | I13: =G13*F13 -> 3780
B14: 13 | C14: 황련 | D14: 주초 | E14: 2 | F14: =E14*$L$15 -> 40 | G14: =VLOOKUP($C14,약재관리!A:J,10,FALSE) -> 136.7 | H14: =G14*E14 -> 273.4 | I14: =G14*F14 -> 5468 | K14: 총 일수 | L14: 15 | M14: 일분
B15: 14 | C15: 황백 | E15: 3 | F15: =E15*$L$15 -> 60 | G15: =VLOOKUP($C15,약재관리!A:J,10,FALSE) -> 27.7 | H15: =G15*E15 -> 83.1 | I15: =G15*F15 -> 1662 | K15: 첩수 | L15: 20 | M15: 첩
B16: 15 | C16: 사인 | E16: 4 | F16: =E16*$L$15 -> 80 | G16: =VLOOKUP($C16,약재관리!A:J,10,FALSE) -> 21.8 | H16: =G16*E16 -> 87.2 | I16: =G16*F16 -> 1744 | K16: 총 팩수 | L16: 45 | M16: 팩
B17: 16 | C17: 익지인 | E17: 3 | F17: =E17*$L$15 -> 60 | G17: =VLOOKUP($C17,약재관리!A:J,10,FALSE) -> 15.4 | H17: =G17*E17 -> 46.2 | I17: =G17*F17 -> 924 | K17: 팩당 물량 | L17: 100 | M17: cc
B18: 17 | C18: 시호1 | E18: 4 | F18: =E18*$L$15 -> 80 | G18: =VLOOKUP($C18,약재관리!A:J,10,FALSE) -> 72.7 | H18: =G18*E18 -> 290.8 | I18: =G18*F18 -> 5816 | K18: 1첩당약재 | L18: =SUM(E2:E31) -> 79 | M18: g
B19: 18 | C19: 박하 | E19: 2 | F19: =E19*$L$15 -> 40 | G19: =VLOOKUP($C19,약재관리!A:J,10,FALSE) -> 21.8 | H19: =G19*E19 -> 43.6 | I19: =G19*F19 -> 872 | K19: 약재총량 | L19: =L15*L18 -> 1580 | M19: g
B20: 19 | C20: 반하 | E20: 4 | F20: =E20*$L$15 -> 80 | G20: =VLOOKUP($C20,약재관리!A:J,10,FALSE) -> 47 | H20: =G20*E20 -> 188 | I20: =G20*F20 -> 3760 | K20: 총 물 양 | L20: =L16*L17+L19 -> 6080 | M20: cc
B21: 20 | F21: =E21*$L$15 -> 0 | H21: =G21*E21 -> 0 | I21: =G21*F21 -> 0
B22: 21 | F22: =E22*$L$15 -> 0 | H22: =G22*E22 -> 0 | I22: =G22*F22 -> 0 | K22: 참고치
B23: 22 | F23: =E23*$L$15 -> 0 | H23: =G23*E23 -> 0 | I23: =G23*F23 -> 0 | K23: cross chk | L23: =SUM(F2:F31) -> 1580 | M23: g
B24: 23 | F24: =E24*$L$15 -> 0 | H24: =G24*E24 -> 0 | I24: =G24*F24 -> 0 | K24: 20첩물양 | L24: 5000 | M24: cc
B25: 24 | F25: =E25*$L$15 -> 0 | H25: =G25*E25 -> 0 | I25: =G25*F25 -> 0 | K25: 1첩당 | L25: 80-120 | M25: g
B26: 25 | F26: =E26*$L$15 -> 0 | H26: =G26*E26 -> 0 | I26: =G26*F26 -> 0 | K26: 20첩당 | L26: 1600 | M26: g
B27: 26 | F27: =E27*$L$15 -> 0 | H27: =G27*E27 -> 0 | I27: =G27*F27 -> 0 | K27: 1돈 환산 | L27: 4 | M27: g
B28: 27 | F28: =E28*$L$15 -> 0 | H28: =G28*E28 -> 0 | I28: =G28*F28 -> 0
B29: 28 | F29: =E29*$L$15 -> 0 | H29: =G29*E29 -> 0 | I29: =G29*F29 -> 0 | K29: 금액
B30: 29 | F30: =E30*$L$15 -> 0 | H30: =G30*E30 -> 0 | I30: =G30*F30 -> 0 | K30: 1첩당 | L30: =SUM(H2:H31) -> 2300.4 | M30: 원
B31: 30 | F31: =E31*$L$15 -> 0 | H31: =G31*E31 -> 0 | I31: =G31*F31 -> 0 | K31: 총 | L31: =SUM(I2:I31) -> 46008 | M31: 원

Sheet 처방전양식 (6)
B1: No. | C1: 약재명 | D1: 수치 | E1: 그램 | F1: 총용량 | G1: 1g 금액 | H1: 1첩 금액 | I1: 총 금액 | K1: 기본 정보
B2: 1 | C2: 백작약 | E2: 6 | F2: =E2*$L$15 -> 120 | G2: =VLOOKUP($C2,약재관리!A:J,10,FALSE) -> 19.6 | H2: =G2*E2 -> 117.6 | I2: =G2*F2 -> 2352 | K2: UNIT | L2: 47
B3: 2 | C3: 창출1 | E3: 8 | F3: =E3*$L$15 -> 160 | G3: =VLOOKUP($C3,약재관리!A:J,10,FALSE) -> 24 | H3: =G3*E3 -> 192 | I3: =G3*F3 -> 3840 | K3: 처방명 | L3: 소요산 가감
B4: 3 | C4: 당귀1 | E4: 8 | F4: =E4*$L$15 -> 160 | G4: =VLOOKUP($C4,약재관리!A:J,10,FALSE) -> 25 | H4: =G4*E4 -> 200 | I4: =G4*F4 -> 4000 | K4: 날짜 | L4: 45700
B5: 4 | C5: 복령 | E5: 6 | F5: =E5*$L$15 -> 120 | G5: =VLOOKUP($C5,약재관리!A:J,10,FALSE) -> 11 | H5: =G5*E5 -> 66 | I5: =G5*F5 -> 1320 | K5: 이름 | L5: 박효진
B6: 5 | C6: 맥문동 | E6: 4 | F6: =E6*$L$15 -> 80 | G6: =VLOOKUP($C6,약재관리!A:J,10,FALSE) -> 44.3 | H6: =G6*E6 -> 177.2 | I6: =G6*F6 -> 3544 | K6: 나이 | L6: 41
B7: 6 | C7: 생지황 | E7: 8 | F7: =E7*$L$15 -> 160 | G7: =VLOOKUP($C7,약재관리!A:J,10,FALSE) -> 17.4 | H7: =G7*E7 -> 139.2 | I7: =G7*F7 -> 2784 | K7: 성별 | L7: F
B8: 7 | C8: 치자 | D8: 초 | E8: 2 | F8: =E8*$L$15 -> 40 | G8: =VLOOKUP($C8,약재관리!A:J,10,FALSE) -> 21.3 | H8: =G8*E8 -> 42.6 | I8: =G8*F8 -> 852 | K8: 메모
B9: 8 | C9: 지모 | E9: 3 | F9: =E9*$L$15 -> 60 | G9: =VLOOKUP($C9,약재관리!A:J,10,FALSE) -> 16.7 | H9: =G9*E9 -> 50.1 | I9: =G9*F9 -> 1002 | K9: 단치소요산 + 황련 지모 황백 생지황 지골피 + 사인 건강 익지인
B10: 9 | C10: 건강 | E10: 2 | F10: =E10*$L$15 -> 40 | G10: =VLOOKUP($C10,약재관리!A:J,10,FALSE) -> 9.5 | H10: =G10*E10 -> 19 | I10: =G10*F10 -> 380
B11: 10 | C11: 감초 | E11: 2 | F11: =E11*$L$15 -> 40 | G11: =VLOOKUP($C11,약재관리!A:J,10,FALSE) -> 28.3 | H11: =G11*E11 -> 56.6 | I11: =G11*F11 -> 1132
B12: 11 | C12: 지골피 | E12: 4 | F12: =E12*$L$15 -> 80 | G12: =VLOOKUP($C12,약재관리!A:J,10,FALSE) -> 21.7 | H12: =G12*E12 -> 86.8 | I12: =G12*F12 -> 1736
B13: 12 | C13: 목단피 | E13: 4 | F13: =E13*$L$15 -> 80 | G13: =VLOOKUP($C13,약재관리!A:J,10,FALSE) -> 31.5 | H13: =G13*E13 -> 126 | I13: =G13*F13 -> 2520
B14: 13 | C14: 황련 | D14: 주초 | E14: 2 | F14: =E14*$L$15 -> 40 | G14: =VLOOKUP($C14,약재관리!A:J,10,FALSE) -> 136.7 | H14: =G14*E14 -> 273.4 | I14: =G14*F14 -> 5468 | K14: 총 일수 | L14: 15 | M14: 일분
B15: 14 | C15: 황백 | E15: 3 | F15: =E15*$L$15 -> 60 | G15: =VLOOKUP($C15,약재관리!A:J,10,FALSE) -> 27.7 | H15: =G15*E15 -> 83.1 | I15: =G15*F15 -> 1662 | K15: 첩수 | L15: 20 | M15: 첩
B16: 15 | C16: 사인 | E16: 4 | F16: =E16*$L$15 -> 80 | G16: =VLOOKUP($C16,약재관리!A:J,10,FALSE) -> 21.8 | H16: =G16*E16 -> 87.2 | I16: =G16*F16 -> 1744 | K16: 총 팩수 | L16: 45 | M16: 팩
B17: 16 | C17: 익지인 | E17: 4 | F17: =E17*$L$15 -> 80 | G17: =VLOOKUP($C17,약재관리!A:J,10,FALSE) -> 15.4 | H17: =G17*E17 -> 61.6 | I17: =G17*F17 -> 1232 | K17: 팩당 물량 | L17: 100 | M17: cc
B18: 17 | C18: 시호1 | E18: 4 | F18: =E18*$L$15 -> 80 | G18: =VLOOKUP($C18,약재관리!A:J,10,FALSE) -> 72.7 | H18: =G18*E18 -> 290.8 | I18: =G18*F18 -> 5816 | K18: 1첩당약재 | L18: =SUM(E2:E31) -> 76 | M18: g
B19: 18 | C19: 박하 | E19: 2 | F19: =E19*$L$15 -> 40 | G19: =VLOOKUP($C19,약재관리!A:J,10,FALSE) -> 21.8 | H19: =G19*E19 -> 43.6 | I19: =G19*F19 -> 872 | K19: 약재총량 | L19: =L15*L18 -> 1520 | M19: g
B20: 19 | F20: =E20*$L$15 -> 0 | H20: =G20*E20 -> 0 | I20: =G20*F20 -> 0 | K20: 총 물 양 | L20: =L16*L17+L19 -> 6020 | M20: cc
B21: 20 | F21: =E21*$L$15 -> 0 | H21: =G21*E21 -> 0 | I21: =G21*F21 -> 0
B22: 21 | F22: =E22*$L$15 -> 0 | H22: =G22*E22 -> 0 | I22: =G22*F22 -> 0 | K22: 참고치
B23: 22 | F23: =E23*$L$15 -> 0 | H23: =G23*E23 -> 0 | I23: =G23*F23 -> 0 | K23: cross chk | L23: =SUM(F2:F31) -> 1520 | M23: g
B24: 23 | F24: =E24*$L$15 -> 0 | H24: =G24*E24 -> 0 | I24: =G24*F24 -> 0 | K24: 20첩물양 | L24: 5000 | M24: cc
B25: 24 | F25: =E25*$L$15 -> 0 | H25: =G25*E25 -> 0 | I25: =G25*F25 -> 0 | K25: 1첩당 | L25: 80-120 | M25: g
B26: 25 | F26: =E26*$L$15 -> 0 | H26: =G26*E26 -> 0 | I26: =G26*F26 -> 0 | K26: 20첩당 | L26: 1600 | M26: g
B27: 26 | F27: =E27*$L$15 -> 0 | H27: =G27*E27 -> 0 | I27: =G27*F27 -> 0 | K27: 1돈 환산 | L27: 4 | M27: g
B28: 27 | F28: =E28*$L$15 -> 0 | H28: =G28*E28 -> 0 | I28: =G28*F28 -> 0
B29: 28 | F29: =E29*$L$15 -> 0 | H29: =G29*E29 -> 0 | I29: =G29*F29 -> 0 | K29: 금액
B30: 29 | F30: =E30*$L$15 -> 0 | H30: =G30*E30 -> 0 | I30: =G30*F30 -> 0 | K30: 1첩당 | L30: =SUM(H2:H31) -> 2112.8 | M30: 원
B31: 30 | F31: =E31*$L$15 -> 0 | H31: =G31*E31 -> 0 | I31: =G31*F31 -> 0 | K31: 총 | L31: =SUM(I2:I31) -> 42256 | M31: 원

Sheet 처방전양식 (5)
B1: No. | C1: 약재명 | D1: 수치 | E1: 그램 | F1: 총용량 | G1: 1g 금액 | H1: 1첩 금액 | I1: 총 금액 | K1: 기본 정보
B2: 1 | C2: 백작약 | E2: 6 | F2: =E2*$L$15 -> 120 | G2: =VLOOKUP($C2,약재관리!A:J,10,FALSE) -> 19.6 | H2: =G2*E2 -> 117.6 | I2: =G2*F2 -> 2352 | K2: UNIT | L2: 47
B3: 2 | C3: 창출1 | E3: 8 | F3: =E3*$L$15 -> 160 | G3: =VLOOKUP($C3,약재관리!A:J,10,FALSE) -> 24 | H3: =G3*E3 -> 192 | I3: =G3*F3 -> 3840 | K3: 처방명 | L3: 사물탕 합 소요산
B4: 3 | C4: 당귀1 | E4: 8 | F4: =E4*$L$15 -> 160 | G4: =VLOOKUP($C4,약재관리!A:J,10,FALSE) -> 25 | H4: =G4*E4 -> 200 | I4: =G4*F4 -> 4000 | K4: 날짜 | L4: 45680
B5: 4 | C5: 복령 | E5: 6 | F5: =E5*$L$15 -> 120 | G5: =VLOOKUP($C5,약재관리!A:J,10,FALSE) -> 11 | H5: =G5*E5 -> 66 | I5: =G5*F5 -> 1320 | K5: 이름 | L5: 박효진
B6: 5 | C6: 맥문동 | E6: 4 | F6: =E6*$L$15 -> 80 | G6: =VLOOKUP($C6,약재관리!A:J,10,FALSE) -> 44.3 | H6: =G6*E6 -> 177.2 | I6: =G6*F6 -> 3544 | K6: 나이 | L6: 41
B7: 6 | C7: 생지황 | E7: 8 | F7: =E7*$L$15 -> 160 | G7: =VLOOKUP($C7,약재관리!A:J,10,FALSE) -> 17.4 | H7: =G7*E7 -> 139.2 | I7: =G7*F7 -> 2784 | K7: 성별 | L7: F
B8: 7 | C8: 치자 | D8: 초 | E8: 2 | F8: =E8*$L$15 -> 40 | G8: =VLOOKUP($C8,약재관리!A:J,10,FALSE) -> 21.3 | H8: =G8*E8 -> 42.6 | I8: =G8*F8 -> 852 | K8: 메모
B9: 8 | C9: 지모 | E9: 3 | F9: =E9*$L$15 -> 60 | G9: =VLOOKUP($C9,약재관리!A:J,10,FALSE) -> 16.7 | H9: =G9*E9 -> 50.1 | I9: =G9*F9 -> 1002 | K9: 단치소요산 + 황련 지모 황백 + 홍화 목단피 삼릉 봉출 현호색 자충 + 사인 건강 익지인
B10: 9 | C10: 건강 | E10: 2 | F10: =E10*$L$15 -> 40 | G10: =VLOOKUP($C10,약재관리!A:J,10,FALSE) -> 9.5 | H10: =G10*E10 -> 19 | I10: =G10*F10 -> 380
B11: 10 | C11: 감초 | E11: 2 | F11: =E11*$L$15 -> 40 | G11: =VLOOKUP($C11,약재관리!A:J,10,FALSE) -> 28.3 | H11: =G11*E11 -> 56.6 | I11: =G11*F11 -> 1132
B12: 11 | C12: 홍화 | E12: 4 | F12: =E12*$L$15 -> 80 | G12: =VLOOKUP($C12,약재관리!A:J,10,FALSE) -> 44.2 | H12: =G12*E12 -> 176.8 | I12: =G12*F12 -> 3536
B13: 12 | C13: 목단피 | E13: 4 | F13: =E13*$L$15 -> 80 | G13: =VLOOKUP($C13,약재관리!A:J,10,FALSE) -> 31.5 | H13: =G13*E13 -> 126 | I13: =G13*F13 -> 2520
B14: 13 | C14: 황련 | D14: 주초 | E14: 2 | F14: =E14*$L$15 -> 40 | G14: =VLOOKUP($C14,약재관리!A:J,10,FALSE) -> 136.7 | H14: =G14*E14 -> 273.4 | I14: =G14*F14 -> 5468 | K14: 총 일수 | L14: 15 | M14: 일분
B15: 14 | C15: 황백 | E15: 3 | F15: =E15*$L$15 -> 60 | G15: =VLOOKUP($C15,약재관리!A:J,10,FALSE) -> 27.7 | H15: =G15*E15 -> 83.1 | I15: =G15*F15 -> 1662 | K15: 첩수 | L15: 20 | M15: 첩
B16: 15 | C16: 사인 | E16: 4 | F16: =E16*$L$15 -> 80 | G16: =VLOOKUP($C16,약재관리!A:J,10,FALSE) -> 21.8 | H16: =G16*E16 -> 87.2 | I16: =G16*F16 -> 1744 | K16: 총 팩수 | L16: 45 | M16: 팩
B17: 16 | C17: 익지인 | E17: 4 | F17: =E17*$L$15 -> 80 | G17: =VLOOKUP($C17,약재관리!A:J,10,FALSE) -> 15.4 | H17: =G17*E17 -> 61.6 | I17: =G17*F17 -> 1232 | K17: 팩당 물량 | L17: 100 | M17: cc
B18: 17 | C18: 삼릉 | E18: 2 | F18: =E18*$L$15 -> 40 | G18: =VLOOKUP($C18,약재관리!A:J,10,FALSE) -> 9.2 | H18: =G18*E18 -> 18.4 | I18: =G18*F18 -> 368 | K18: 1첩당약재 | L18: =SUM(E2:E31) -> 86 | M18: g
B19: 18 | C19: 봉출 | E19: 2 | F19: =E19*$L$15 -> 40 | G19: =VLOOKUP($C19,약재관리!A:J,10,FALSE) -> 10.8 | H19: =G19*E19 -> 21.6 | I19: =G19*F19 -> 432 | K19: 약재총량 | L19: =L15*L18 -> 1720 | M19: g
B20: 19 | C20: 현호색 | E20: 2 | F20: =E20*$L$15 -> 40 | G20: =VLOOKUP($C20,약재관리!A:J,10,FALSE) -> 46.7 | H20: =G20*E20 -> 93.4 | I20: =G20*F20 -> 1868 | K20: 총 물 양 | L20: =L16*L17+L19 -> 6220 | M20: cc
B21: 20 | C21: 자충 | E21: 10 | F21: =E21*$L$15 -> 200 | G21: =VLOOKUP($C21,약재관리!A:J,10,FALSE) -> 52 | H21: =G21*E21 -> 520 | I21: =G21*F21 -> 10400
B22: 21 | F22: =E22*$L$15 -> 0 | H22: =G22*E22 -> 0 | I22: =G22*F22 -> 0 | K22: 참고치
B23: 22 | F23: =E23*$L$15 -> 0 | H23: =G23*E23 -> 0 | I23: =G23*F23 -> 0 | K23: cross chk | L23: =SUM(F2:F31) -> 1720 | M23: g
B24: 23 | F24: =E24*$L$15 -> 0 | H24: =G24*E24 -> 0 | I24: =G24*F24 -> 0 | K24: 20첩물양 | L24: 5000 | M24: cc
B25: 24 | F25: =E25*$L$15 -> 0 | H25: =G25*E25 -> 0 | I25: =G25*F25 -> 0 | K25: 1첩당 | L25: 80-120 | M25: g
B26: 25 | F26: =E26*$L$15 -> 0 | H26: =G26*E26 -> 0 | I26: =G26*F26 -> 0 | K26: 20첩당 | L26: 1600 | M26: g
B27: 26 | F27: =E27*$L$15 -> 0 | H27: =G27*E27 -> 0 | I27: =G27*F27 -> 0 | K27: 1돈 환산 | L27: 4 | M27: g
B28: 27 | F28: =E28*$L$15 -> 0 | H28: =G28*E28 -> 0 | I28: =G28*F28 -> 0
B29: 28 | F29: =E29*$L$15 -> 0 | H29: =G29*E29 -> 0 | I29: =G29*F29 -> 0 | K29: 금액
B30: 29 | F30: =E30*$L$15 -> 0 | H30: =G30*E30 -> 0 | I30: =G30*F30 -> 0 | K30: 1첩당 | L30: =SUM(H2:H31) -> 2521.8 | M30: 원
B31: 30 | F31: =E31*$L$15 -> 0 | H31: =G31*E31 -> 0 | I31: =G31*F31 -> 0 | K31: 총 | L31: =SUM(I2:I31) -> 50436 | M31: 원

Sheet 처방전양식 (4)
B1: No. | C1: 약재명 | D1: 수치 | E1: 그램 | F1: 총용량 | G1: 1g 금액 | H1: 1첩 금액 | I1: 총 금액 | K1: 기본 정보
B2: 1 | C2: 백작약 | E2: 6 | F2: =E2*$L$15 -> 120 | G2: =VLOOKUP($C2,약재관리!A:J,10,FALSE) -> 19.6 | H2: =G2*E2 -> 117.6 | I2: =G2*F2 -> 2352 | K2: UNIT | L2: 47
B3: 2 | C3: 창출1 | E3: 8 | F3: =E3*$L$15 -> 160 | G3: =VLOOKUP($C3,약재관리!A:J,10,FALSE) -> 24 | H3: =G3*E3 -> 192 | I3: =G3*F3 -> 3840 | K3: 처방명 | L3: 사물탕 합 소요산
B4: 3 | C4: 당귀1 | E4: 8 | F4: =E4*$L$15 -> 160 | G4: =VLOOKUP($C4,약재관리!A:J,10,FALSE) -> 25 | H4: =G4*E4 -> 200 | I4: =G4*F4 -> 4000 | K4: 날짜 | L4: 45666
B5: 4 | C5: 복령 | E5: 6 | F5: =E5*$L$15 -> 120 | G5: =VLOOKUP($C5,약재관리!A:J,10,FALSE) -> 11 | H5: =G5*E5 -> 66 | I5: =G5*F5 -> 1320 | K5: 이름 | L5: 박효진
B6: 5 | C6: 맥문동 | E6: 4 | F6: =E6*$L$15 -> 80 | G6: =VLOOKUP($C6,약재관리!A:J,10,FALSE) -> 44.3 | H6: =G6*E6 -> 177.2 | I6: =G6*F6 -> 3544 | K6: 나이 | L6: 41
B7: 6 | C7: 생지황 | E7: 8 | F7: =E7*$L$15 -> 160 | G7: =VLOOKUP($C7,약재관리!A:J,10,FALSE) -> 17.4 | H7: =G7*E7 -> 139.2 | I7: =G7*F7 -> 2784 | K7: 성별 | L7: F
B8: 7 | C8: 치자 | D8: 초 | E8: 2 | F8: =E8*$L$15 -> 40 | G8: =VLOOKUP($C8,약재관리!A:J,10,FALSE) -> 21.3 | H8: =G8*E8 -> 42.6 | I8: =G8*F8 -> 852 | K8: 메모
B9: 8 | C9: 지모 | E9: 3 | F9: =E9*$L$15 -> 60 | G9: =VLOOKUP($C9,약재관리!A:J,10,FALSE) -> 16.7 | H9: =G9*E9 -> 50.1 | I9: =G9*F9 -> 1002 | K9: 단치소요산 + 황련 지모 황백 + 홍화 목단피 삼릉 봉출 현호색 자충 + 사인 토사자 건강
B10: 9 | C10: 건강 | E10: 2 | F10: =E10*$L$15 -> 40 | G10: =VLOOKUP($C10,약재관리!A:J,10,FALSE) -> 9.5 | H10: =G10*E10 -> 19 | I10: =G10*F10 -> 380
B11: 10 | C11: 감초 | E11: 2 | F11: =E11*$L$15 -> 40 | G11: =VLOOKUP($C11,약재관리!A:J,10,FALSE) -> 28.3 | H11: =G11*E11 -> 56.6 | I11: =G11*F11 -> 1132
B12: 11 | C12: 홍화 | E12: 4 | F12: =E12*$L$15 -> 80 | G12: =VLOOKUP($C12,약재관리!A:J,10,FALSE) -> 44.2 | H12: =G12*E12 -> 176.8 | I12: =G12*F12 -> 3536
B13: 12 | C13: 목단피 | E13: 4 | F13: =E13*$L$15 -> 80 | G13: =VLOOKUP($C13,약재관리!A:J,10,FALSE) -> 31.5 | H13: =G13*E13 -> 126 | I13: =G13*F13 -> 2520
B14: 13 | C14: 황련 | D14: 주초 | E14: 2 | F14: =E14*$L$15 -> 40 | G14: =VLOOKUP($C14,약재관리!A:J,10,FALSE) -> 136.7 | H14: =G14*E14 -> 273.4 | I14: =G14*F14 -> 5468 | K14: 총 일수 | L14: 15 | M14: 일분
B15: 14 | C15: 황백 | E15: 3 | F15: =E15*$L$15 -> 60 | G15: =VLOOKUP($C15,약재관리!A:J,10,FALSE) -> 27.7 | H15: =G15*E15 -> 83.1 | I15: =G15*F15 -> 1662 | K15: 첩수 | L15: 20 | M15: 첩
B16: 15 | C16: 사인 | E16: 4 | F16: =E16*$L$15 -> 80 | G16: =VLOOKUP($C16,약재관리!A:J,10,FALSE) -> 21.8 | H16: =G16*E16 -> 87.2 | I16: =G16*F16 -> 1744 | K16: 총 팩수 | L16: 45 | M16: 팩
B17: 16 | C17: 토사자 | E17: 3 | F17: =E17*$L$15 -> 60 | G17: =VLOOKUP($C17,약재관리!A:J,10,FALSE) -> 16.7 | H17: =G17*E17 -> 50.1 | I17: =G17*F17 -> 1002 | K17: 팩당 물량 | L17: 100 | M17: cc
B18: 17 | C18: 삼릉 | E18: 2 | F18: =E18*$L$15 -> 40 | G18: =VLOOKUP($C18,약재관리!A:J,10,FALSE) -> 9.2 | H18: =G18*E18 -> 18.4 | I18: =G18*F18 -> 368 | K18: 1첩당약재 | L18: =SUM(E2:E31) -> 85 | M18: g
B19: 18 | C19: 봉출 | E19: 2 | F19: =E19*$L$15 -> 40 | G19: =VLOOKUP($C19,약재관리!A:J,10,FALSE) -> 10.8 | H19: =G19*E19 -> 21.6 | I19: =G19*F19 -> 432 | K19: 약재총량 | L19: =L15*L18 -> 1700 | M19: g
B20: 19 | C20: 현호색 | E20: 2 | F20: =E20*$L$15 -> 40 | G20: =VLOOKUP($C20,약재관리!A:J,10,FALSE) -> 46.7 | H20: =G20*E20 -> 93.4 | I20: =G20*F20 -> 1868 | K20: 총 물 양 | L20: =L16*L17+L19 -> 6200 | M20: cc
B21: 20 | C21: 자충 | E21: 10 | F21: =E21*$L$15 -> 200 | G21: =VLOOKUP($C21,약재관리!A:J,10,FALSE) -> 52 | H21: =G21*E21 -> 520 | I21: =G21*F21 -> 10400
B22: 21 | F22: =E22*$L$15 -> 0 | H22: =G22*E22 -> 0 | I22: =G22*F22 -> 0 | K22: 참고치
B23: 22 | F23: =E23*$L$15 -> 0 | H23: =G23*E23 -> 0 | I23: =G23*F23 -> 0 | K23: cross chk | L23: =SUM(F2:F31) -> 1700 | M23: g
B24: 23 | F24: =E24*$L$15 -> 0 | H24: =G24*E24 -> 0 | I24: =G24*F24 -> 0 | K24: 20첩물양 | L24: 5000 | M24: cc
B25: 24 | F25: =E25*$L$15 -> 0 | H25: =G25*E25 -> 0 | I25: =G25*F25 -> 0 | K25: 1첩당 | L25: 80-120 | M25: g
B26: 25 | F26: =E26*$L$15 -> 0 | H26: =G26*E26 -> 0 | I26: =G26*F26 -> 0 | K26: 20첩당 | L26: 1600 | M26: g
B27: 26 | F27: =E27*$L$15 -> 0 | H27: =G27*E27 -> 0 | I27: =G27*F27 -> 0 | K27: 1돈 환산 | L27: 4 | M27: g
B28: 27 | F28: =E28*$L$15 -> 0 | H28: =G28*E28 -> 0 | I28: =G28*F28 -> 0
B29: 28 | F29: =E29*$L$15 -> 0 | H29: =G29*E29 -> 0 | I29: =G29*F29 -> 0 | K29: 금액
B30: 29 | F30: =E30*$L$15 -> 0 | H30: =G30*E30 -> 0 | I30: =G30*F30 -> 0 | K30: 1첩당 | L30: =SUM(H2:H31) -> 2510.3 | M30: 원
B31: 30 | F31: =E31*$L$15 -> 0 | H31: =G31*E31 -> 0 | I31: =G31*F31 -> 0 | K31: 총 | L31: =SUM(I2:I31) -> 50206 | M31: 원

Sheet 처방전양식 (3)
B1: No. | C1: 약재명 | D1: 수치 | E1: 그램 | F1: 총용량 | G1: 1g 금액 | H1: 1첩 금액 | I1: 총 금액 | K1: 기본 정보
B2: 1 | C2: 백작약 | E2: 6 | F2: =E2*$L$15 -> 120 | G2: =VLOOKUP($C2,약재관리!A:J,10,FALSE) -> 19.6 | H2: =G2*E2 -> 117.6 | I2: =G2*F2 -> 2352 | K2: UNIT | L2: 47
B3: 2 | C3: 창출1 | E3: 8 | F3: =E3*$L$15 -> 160 | G3: =VLOOKUP($C3,약재관리!A:J,10,FALSE) -> 24 | H3: =G3*E3 -> 192 | I3: =G3*F3 -> 3840 | K3: 처방명 | L3: 사물탕 합 소요산
B4: 3 | C4: 당귀1 | E4: 8 | F4: =E4*$L$15 -> 160 | G4: =VLOOKUP($C4,약재관리!A:J,10,FALSE) -> 25 | H4: =G4*E4 -> 200 | I4: =G4*F4 -> 4000 | K4: 날짜 | L4: 45652
B5: 4 | C5: 복령 | E5: 6 | F5: =E5*$L$15 -> 120 | G5: =VLOOKUP($C5,약재관리!A:J,10,FALSE) -> 11 | H5: =G5*E5 -> 66 | I5: =G5*F5 -> 1320 | K5: 이름 | L5: 박효진
B6: 5 | C6: 맥문동 | E6: 4 | F6: =E6*$L$15 -> 80 | G6: =VLOOKUP($C6,약재관리!A:J,10,FALSE) -> 44.3 | H6: =G6*E6 -> 177.2 | I6: =G6*F6 -> 3544 | K6: 나이 | L6: 41
B7: 6 | C7: 생지황 | E7: 8 | F7: =E7*$L$15 -> 160 | G7: =VLOOKUP($C7,약재관리!A:J,10,FALSE) -> 17.4 | H7: =G7*E7 -> 139.2 | I7: =G7*F7 -> 2784 | K7: 성별 | L7: F
B8: 7 | C8: 치자 | D8: 초 | E8: 2 | F8: =E8*$L$15 -> 40 | G8: =VLOOKUP($C8,약재관리!A:J,10,FALSE) -> 21.3 | H8: =G8*E8 -> 42.6 | I8: =G8*F8 -> 852 | K8: 메모
B9: 8 | C9: 산약 | E9: 4 | F9: =E9*$L$15 -> 80 | G9: =VLOOKUP($C9,약재관리!A:J,10,FALSE) -> 18.3 | H9: =G9*E9 -> 73.2 | I9: =G9*F9 -> 1464 | K9: 단치소요산 + 황련 + 홍화 목단피 삼릉 봉출 현호색 자충 + 사인 소회향 산약 건강
B10: 9 | C10: 건강 | E10: 2 | F10: =E10*$L$15 -> 40 | G10: =VLOOKUP($C10,약재관리!A:J,10,FALSE) -> 9.5 | H10: =G10*E10 -> 19 | I10: =G10*F10 -> 380
B11: 10 | C11: 감초 | E11: 2 | F11: =E11*$L$15 -> 40 | G11: =VLOOKUP($C11,약재관리!A:J,10,FALSE) -> 28.3 | H11: =G11*E11 -> 56.6 | I11: =G11*F11 -> 1132
B12: 11 | C12: 홍화 | E12: 4 | F12: =E12*$L$15 -> 80 | G12: =VLOOKUP($C12,약재관리!A:J,10,FALSE) -> 44.2 | H12: =G12*E12 -> 176.8 | I12: =G12*F12 -> 3536
B13: 12 | C13: 목단피 | E13: 4 | F13: =E13*$L$15 -> 80 | G13: =VLOOKUP($C13,약재관리!A:J,10,FALSE) -> 31.5 | H13: =G13*E13 -> 126 | I13: =G13*F13 -> 2520
B14: 13 | C14: 황련 | D14: 주초 | E14: 2 | F14: =E14*$L$15 -> 40 | G14: =VLOOKUP($C14,약재관리!A:J,10,FALSE) -> 136.7 | H14: =G14*E14 -> 273.4 | I14: =G14*F14 -> 5468 | K14: 총 일수 | L14: 15 | M14: 일분
B15: 14 | K15: 첩수 | L15: 20 | M15: 첩
B16: 15 | C16: 사인 | E16: 4 | F16: =E16*$L$15 -> 80 | G16: =VLOOKUP($C16,약재관리!A:J,10,FALSE) -> 21.8 | H16: =G16*E16 -> 87.2 | I16: =G16*F16 -> 1744 | K16: 총 팩수 | L16: 45 | M16: 팩
B17: 16 | C17: 소회향 | E17: 3 | F17: =E17*$L$15 -> 60 | G17: =VLOOKUP($C17,약재관리!A:J,10,FALSE) -> 10 | H17: =G17*E17 -> 30 | I17: =G17*F17 -> 600 | K17: 팩당 물량 | L17: 100 | M17: cc
B18: 17 | C18: 삼릉 | E18: 2 | F18: =E18*$L$15 -> 40 | G18: =VLOOKUP($C18,약재관리!A:J,10,FALSE) -> 9.2 | H18: =G18*E18 -> 18.4 | I18: =G18*F18 -> 368 | K18: 1첩당약재 | L18: =SUM(E2:E31) -> 83 | M18: g
B19: 18 | C19: 봉출 | E19: 2 | F19: =E19*$L$15 -> 40 | G19: =VLOOKUP($C19,약재관리!A:J,10,FALSE) -> 10.8 | H19: =G19*E19 -> 21.6 | I19: =G19*F19 -> 432 | K19: 약재총량 | L19: =L15*L18 -> 1660 | M19: g
B20: 19 | C20: 현호색 | E20: 2 | F20: =E20*$L$15 -> 40 | G20: =VLOOKUP($C20,약재관리!A:J,10,FALSE) -> 46.7 | H20: =G20*E20 -> 93.4 | I20: =G20*F20 -> 1868 | K20: 총 물 양 | L20: =L16*L17+L19 -> 6160 | M20: cc
B21: 20 | C21: 자충 | E21: 10 | F21: =E21*$L$15 -> 200 | G21: =VLOOKUP($C21,약재관리!A:J,10,FALSE) -> 52 | H21: =G21*E21 -> 520 | I21: =G21*F21 -> 10400
B22: 21 | F22: =E22*$L$15 -> 0 | H22: =G22*E22 -> 0 | I22: =G22*F22 -> 0 | K22: 참고치
B23: 22 | F23: =E23*$L$15 -> 0 | H23: =G23*E23 -> 0 | I23: =G23*F23 -> 0 | K23: cross chk | L23: =SUM(F2:F31) -> 1660 | M23: g
B24: 23 | F24: =E24*$L$15 -> 0 | H24: =G24*E24 -> 0 | I24: =G24*F24 -> 0 | K24: 20첩물양 | L24: 5000 | M24: cc
B25: 24 | F25: =E25*$L$15 -> 0 | H25: =G25*E25 -> 0 | I25: =G25*F25 -> 0 | K25: 1첩당 | L25: 80-120 | M25: g
B26: 25 | F26: =E26*$L$15 -> 0 | H26: =G26*E26 -> 0 | I26: =G26*F26 -> 0 | K26: 20첩당 | L26: 1600 | M26: g
B27: 26 | F27: =E27*$L$15 -> 0 | H27: =G27*E27 -> 0 | I27: =G27*F27 -> 0 | K27: 1돈 환산 | L27: 4 | M27: g
B28: 27 | F28: =E28*$L$15 -> 0 | H28: =G28*E28 -> 0 | I28: =G28*F28 -> 0
B29: 28 | F29: =E29*$L$15 -> 0 | H29: =G29*E29 -> 0 | I29: =G29*F29 -> 0 | K29: 금액
B30: 29 | F30: =E30*$L$15 -> 0 | H30: =G30*E30 -> 0 | I30: =G30*F30 -> 0 | K30: 1첩당 | L30: =SUM(H2:H31) -> 2430.2 | M30: 원
B31: 30 | F31: =E31*$L$15 -> 0 | H31: =G31*E31 -> 0 | I31: =G31*F31 -> 0 | K31: 총 | L31: =SUM(I2:I31) -> 48604 | M31: 원

Sheet 처방전양식 (2)
B1: No. | C1: 약재명 | D1: 수치 | E1: 그램 | F1: 총용량 | G1: 1g 금액 | H1: 1첩 금액 | I1: 총 금액 | K1: 기본 정보
B2: 1 | C2: 백작약 | E2: 6 | F2: =E2*$L$15 -> 120 | G2: =VLOOKUP($C2,약재관리!A:J,10,FALSE) -> 19.6 | H2: =G2*E2 -> 117.6 | I2: =G2*F2 -> 2352 | K2: UNIT | L2: 47
B3: 2 | C3: 창출1 | E3: 6 | F3: =E3*$L$15 -> 120 | G3: =VLOOKUP($C3,약재관리!A:J,10,FALSE) -> 24 | H3: =G3*E3 -> 144 | I3: =G3*F3 -> 2880 | K3: 처방명 | L3: 사물탕 합 소요산
B4: 3 | C4: 당귀1 | E4: 6 | F4: =E4*$L$15 -> 120 | G4: =VLOOKUP($C4,약재관리!A:J,10,FALSE) -> 25 | H4: =G4*E4 -> 150 | I4: =G4*F4 -> 3000 | K4: 날짜 | L4: 45636
B5: 4 | C5: 복령 | E5: 4 | F5: =E5*$L$15 -> 80 | G5: =VLOOKUP($C5,약재관리!A:J,10,FALSE) -> 11 | H5: =G5*E5 -> 44 | I5: =G5*F5 -> 880 | K5: 이름 | L5: 박효진
B6: 5 | C6: 맥문동 | E6: 4 | F6: =E6*$L$15 -> 80 | G6: =VLOOKUP($C6,약재관리!A:J,10,FALSE) -> 44.3 | H6: =G6*E6 -> 177.2 | I6: =G6*F6 -> 3544 | K6: 나이 | L6: 41
B7: 6 | C7: 생지황 | E7: 6 | F7: =E7*$L$15 -> 120 | G7: =VLOOKUP($C7,약재관리!A:J,10,FALSE) -> 17.4 | H7: =G7*E7 -> 104.4 | I7: =G7*F7 -> 2088 | K7: 성별 | L7: F
B8: 7 | C8: 치자 | D8: 초 | E8: 2 | F8: =E8*$L$15 -> 40 | G8: =VLOOKUP($C8,약재관리!A:J,10,FALSE) -> 21.3 | H8: =G8*E8 -> 42.6 | I8: =G8*F8 -> 852 | K8: 메모
B9: 8 | C9: 지모 | E9: 3 | F9: =E9*$L$15 -> 60 | G9: =VLOOKUP($C9,약재관리!A:J,10,FALSE) -> 16.7 | H9: =G9*E9 -> 50.1 | I9: =G9*F9 -> 1002 | K9: 단치소요산 + 지모 황백 황련 + 천궁 홍화 목단피 삼릉 봉출 현호색 + 사인 오수유
B10: 9 | C10: 황백 | E10: 3 | F10: =E10*$L$15 -> 60 | G10: =VLOOKUP($C10,약재관리!A:J,10,FALSE) -> 27.7 | H10: =G10*E10 -> 83.1 | I10: =G10*F10 -> 1662
B11: 10 | C11: 감초 | E11: 2 | F11: =E11*$L$15 -> 40 | G11: =VLOOKUP($C11,약재관리!A:J,10,FALSE) -> 28.3 | H11: =G11*E11 -> 56.6 | I11: =G11*F11 -> 1132
B12: 11 | C12: 홍화 | E12: 4 | F12: =E12*$L$15 -> 80 | G12: =VLOOKUP($C12,약재관리!A:J,10,FALSE) -> 44.2 | H12: =G12*E12 -> 176.8 | I12: =G12*F12 -> 3536
B13: 12 | C13: 목단피 | E13: 4 | F13: =E13*$L$15 -> 80 | G13: =VLOOKUP($C13,약재관리!A:J,10,FALSE) -> 31.5 | H13: =G13*E13 -> 126 | I13: =G13*F13 -> 2520
B14: 13 | C14: 황련 | D14: 주초 | E14: 2 | F14: =E14*$L$15 -> 40 | G14: =VLOOKUP($C14,약재관리!A:J,10,FALSE) -> 136.7 | H14: =G14*E14 -> 273.4 | I14: =G14*F14 -> 5468 | K14: 총 일수 | L14: 15 | M14: 일분
B15: 14 | C15: 천궁1 | E15: 4 | F15: =E15*$L$15 -> 80 | G15: =VLOOKUP($C15,약재관리!A:J,10,FALSE) -> 10.8 | H15: =G15*E15 -> 43.2 | I15: =G15*F15 -> 864 | K15: 첩수 | L15: 20 | M15: 첩
B16: 15 | C16: 사인 | E16: 2 | F16: =E16*$L$15 -> 40 | G16: =VLOOKUP($C16,약재관리!A:J,10,FALSE) -> 21.8 | H16: =G16*E16 -> 43.6 | I16: =G16*F16 -> 872 | K16: 총 팩수 | L16: 45 | M16: 팩
B17: 16 | C17: 오수유 | E17: 2 | F17: 40 | G17: =VLOOKUP($C17,약재관리!A:J,10,FALSE) -> 16.8 | H17: =G17*E17 -> 33.6 | I17: =G17*F17 -> 672 | K17: 팩당 물량 | L17: 100 | M17: cc
B18: 17 | C18: 삼릉 | E18: 2 | F18: =E18*$L$15 -> 40 | G18: =VLOOKUP($C18,약재관리!A:J,10,FALSE) -> 9.2 | H18: =G18*E18 -> 18.4 | I18: =G18*F18 -> 368 | K18: 1첩당약재 | L18: =SUM(E2:E31) -> 66 | M18: g
B19: 18 | C19: 봉출 | E19: 2 | F19: =E19*$L$15 -> 40 | G19: =VLOOKUP($C19,약재관리!A:J,10,FALSE) -> 10.8 | H19: =G19*E19 -> 21.6 | I19: =G19*F19 -> 432 | K19: 약재총량 | L19: =L15*L18 -> 1320 | M19: g
B20: 19 | C20: 현호색 | E20: 2 | F20: =E20*$L$15 -> 40 | G20: =VLOOKUP($C20,약재관리!A:J,10,FALSE) -> 46.7 | H20: =G20*E20 -> 93.4 | I20: =G20*F20 -> 1868 | K20: 총 물 양 | L20: =L16*L17+L19 -> 5820 | M20: cc
B21: 20 | F21: =E21*$L$15 -> 0 | H21: =G21*E21 -> 0 | I21: =G21*F21 -> 0
B22: 21 | F22: =E22*$L$15 -> 0 | H22: =G22*E22 -> 0 | I22: =G22*F22 -> 0 | K22: 참고치
B23: 22 | F23: =E23*$L$15 -> 0 | H23: =G23*E23 -> 0 | I23: =G23*F23 -> 0 | K23: cross chk | L23: =SUM(F2:F31) -> 1320 | M23: g
B24: 23 | F24: =E24*$L$15 -> 0 | H24: =G24*E24 -> 0 | I24: =G24*F24 -> 0 | K24: 20첩물양 | L24: 5000 | M24: cc
B25: 24 | F25: =E25*$L$15 -> 0 | H25: =G25*E25 -> 0 | I25: =G25*F25 -> 0 | K25: 1첩당 | L25: 80-120 | M25: g
B26: 25 | F26: =E26*$L$15 -> 0 | H26: =G26*E26 -> 0 | I26: =G26*F26 -> 0 | K26: 20첩당 | L26: 1600 | M26: g
B27: 26 | F27: =E27*$L$15 -> 0 | H27: =G27*E27 -> 0 | I27: =G27*F27 -> 0 | K27: 1돈 환산 | L27: 4 | M27: g
B28: 27 | F28: =E28*$L$15 -> 0 | H28: =G28*E28 -> 0 | I28: =G28*F28 -> 0
B29: 28 | F29: =E29*$L$15 -> 0 | H29: =G29*E29 -> 0 | I29: =G29*F29 -> 0 | K29: 금액
B30: 29 | F30: =E30*$L$15 -> 0 | H30: =G30*E30 -> 0 | I30: =G30*F30 -> 0 | K30: 1첩당 | L30: =SUM(H2:H31) -> 1799.6 | M30: 원
B31: 30 | F31: =E31*$L$15 -> 0 | H31: =G31*E31 -> 0 | I31: =G31*F31 -> 0 | K31: 총 | L31: =SUM(I2:I31) -> 35992 | M31: 원

Sheet 처방전양식
B1: No. | C1: 약재명 | D1: 수치 | E1: 그램 | F1: 총용량 | G1: 1g 금액 | H1: 1첩 금액 | I1: 총 금액 | K1: 기본 정보
B2: 1 | C2: 백작약 | E2: 6 | F2: =E2*$L$15 -> 120 | G2: =VLOOKUP($C2,약재관리!A:J,10,FALSE) -> 19.6 | H2: =G2*E2 -> 117.6 | I2: =G2*F2 -> 2352 | K2: UNIT | L2: 47
B3: 2 | C3: 창출1 | E3: 6 | F3: =E3*$L$15 -> 120 | G3: =VLOOKUP($C3,약재관리!A:J,10,FALSE) -> 24 | H3: =G3*E3 -> 144 | I3: =G3*F3 -> 2880 | K3: 처방명 | L3: 사물합소요산
B4: 3 | C4: 당귀1 | E4: 6 | F4: =E4*$L$15 -> 120 | G4: =VLOOKUP($C4,약재관리!A:J,10,FALSE) -> 25 | H4: =G4*E4 -> 150 | I4: =G4*F4 -> 3000 | K4: 날짜 | L4: 45621
B5: 4 | C5: 복령 | E5: 4 | F5: =E5*$L$15 -> 80 | G5: =VLOOKUP($C5,약재관리!A:J,10,FALSE) -> 11 | H5: =G5*E5 -> 44 | I5: =G5*F5 -> 880 | K5: 이름 | L5: 박효진
B6: 5 | C6: 맥문동 | E6: 4 | F6: =E6*$L$15 -> 80 | G6: =VLOOKUP($C6,약재관리!A:J,10,FALSE) -> 44.3 | H6: =G6*E6 -> 177.2 | I6: =G6*F6 -> 3544 | K6: 나이 | L6: 41
B7: 6 | C7: 생지황 | E7: 6 | F7: =E7*$L$15 -> 120 | G7: =VLOOKUP($C7,약재관리!A:J,10,FALSE) -> 17.4 | H7: =G7*E7 -> 104.4 | I7: =G7*F7 -> 2088 | K7: 성별 | L7: F
B8: 7 | C8: 치자 | D8: 초 | E8: 2 | F8: =E8*$L$15 -> 40 | G8: =VLOOKUP($C8,약재관리!A:J,10,FALSE) -> 21.3 | H8: =G8*E8 -> 42.6 | I8: =G8*F8 -> 852 | K8: 메모
B9: 8 | C9: 지모 | E9: 4 | F9: =E9*$L$15 -> 80 | G9: =VLOOKUP($C9,약재관리!A:J,10,FALSE) -> 16.7 | H9: =G9*E9 -> 66.8 | I9: =G9*F9 -> 1336 | K9: #심계 정충 맥삽
B10: 9 | C10: 황백 | E10: 2 | F10: =E10*$L$15 -> 40 | G10: =VLOOKUP($C10,약재관리!A:J,10,FALSE) -> 27.7 | H10: =G10*E10 -> 55.4 | I10: =G10*F10 -> 1108
B11: 10 | C11: 길경 | E11: 1.2 | F11: =E11*$L$15 -> 24 | G11: =VLOOKUP($C11,약재관리!A:J,10,FALSE) -> 11.2 | H11: =G11*E11 -> 13.44 | I11: =G11*F11 -> 268.8
B12: 11 | C12: 감초 | E12: 1.2 | F12: =E12*$L$15 -> 24 | G12: =VLOOKUP($C12,약재관리!A:J,10,FALSE) -> 28.3 | H12: =G12*E12 -> 33.96 | I12: =G12*F12 -> 679.2
B13: 12 | C13: 목단피 | E13: 4 | F13: =E13*$L$15 -> 80 | G13: =VLOOKUP($C13,약재관리!A:J,10,FALSE) -> 31.5 | H13: =G13*E13 -> 126 | I13: =G13*F13 -> 2520
B14: 13 | C14: 황련 | D14: 주초 | E14: 2 | F14: =E14*$L$15 -> 40 | G14: =VLOOKUP($C14,약재관리!A:J,10,FALSE) -> 136.7 | H14: =G14*E14 -> 273.4 | I14: =G14*F14 -> 5468 | K14: 총 일수 | L14: 15 | M14: 일분
B15: 14 | C15: 천궁1 | E15: 4 | F15: =E15*$L$15 -> 80 | G15: =VLOOKUP($C15,약재관리!A:J,10,FALSE) -> 10.8 | H15: =G15*E15 -> 43.2 | I15: =G15*F15 -> 864 | K15: 첩수 | L15: 20 | M15: 첩
B16: 15 | C16: 익모초 | E16: 2 | F16: =E16*$L$15 -> 40 | G16: =VLOOKUP($C16,약재관리!A:J,10,FALSE) -> 12.5 | H16: =G16*E16 -> 25 | I16: =G16*F16 -> 500 | K16: 총 팩수 | L16: 45 | M16: 팩
B17: 16 | F17: =E17*$L$15 -> 0 | H17: =G17*E17 -> 0 | I17: =G17*F17 -> 0 | K17: 팩당 물량 | L17: 100 | M17: cc
B18: 17 | F18: =E18*$L$15 -> 0 | H18: =G18*E18 -> 0 | I18: =G18*F18 -> 0 | K18: 1첩당약재 | L18: =SUM(E2:E31) -> 54.4 | M18: g
B19: 18 | F19: =E19*$L$15 -> 0 | H19: =G19*E19 -> 0 | I19: =G19*F19 -> 0 | K19: 약재총량 | L19: =L15*L18 -> 1088 | M19: g
B20: 19 | F20: =E20*$L$15 -> 0 | H20: =G20*E20 -> 0 | I20: =G20*F20 -> 0 | K20: 총 물 양 | L20: =L16*L17+L19 -> 5588 | M20: cc
B21: 20 | F21: =E21*$L$15 -> 0 | H21: =G21*E21 -> 0 | I21: =G21*F21 -> 0
B22: 21 | F22: =E22*$L$15 -> 0 | H22: =G22*E22 -> 0 | I22: =G22*F22 -> 0 | K22: 참고치
B23: 22 | F23: =E23*$L$15 -> 0 | H23: =G23*E23 -> 0 | I23: =G23*F23 -> 0 | K23: cross chk | L23: =SUM(F2:F31) -> 1088 | M23: g
B24: 23 | F24: =E24*$L$15 -> 0 | H24: =G24*E24 -> 0 | I24: =G24*F24 -> 0 | K24: 20첩물양 | L24: 5000 | M24: cc
B25: 24 | F25: =E25*$L$15 -> 0 | H25: =G25*E25 -> 0 | I25: =G25*F25 -> 0 | K25: 1첩당 | L25: 80-120 | M25: g
B26: 25 | F26: =E26*$L$15 -> 0 | H26: =G26*E26 -> 0 | I26: =G26*F26 -> 0 | K26: 20첩당 | L26: 1600 | M26: g
B27: 26 | F27: =E27*$L$15 -> 0 | H27: =G27*E27 -> 0 | I27: =G27*F27 -> 0 | K27: 1돈 환산 | L27: 4 | M27: g
B28: 27 | F28: =E28*$L$15 -> 0 | H28: =G28*E28 -> 0 | I28: =G28*F28 -> 0
B29: 28 | F29: =E29*$L$15 -> 0 | H29: =G29*E29 -> 0 | I29: =G29*F29 -> 0 | K29: 금액
B30: 29 | F30: =E30*$L$15 -> 0 | H30: =G30*E30 -> 0 | I30: =G30*F30 -> 0 | K30: 1첩당 | L30: =SUM(H2:H31) -> 1417 | M30: 원
B31: 30 | F31: =E31*$L$15 -> 0 | H31: =G31*E31 -> 0 | I31: =G31*F31 -> 0 | K31: 총 | L31: =SUM(I2:I31) -> 28340 | M31: 원

Sheet 약재관리
A1: 약재 이름 | B1: 옴니허브 | C1: 한퓨어 | D1: 신우한방 | E1: 바른한약 | F1: 옴니허브 | G1: 한퓨어 | H1: 신우한방 | I1: 바른한약 | J1: 최종 | K1: 옴니허브 | L1: 한퓨어 | M1: 신우한방 | N1: 바른한약
A2: 45602 | B2: 구입단가 | C2: 구입단가 | D2: 구입단가 | E2: 구입단가 | F2: 1g | G2: 1g | H2: 1g | I2: 1g | J2: 1g | K2: 500g | L2: 500g | M2: 600g | N2: 600g
A3: 갈근1 | B3: 9900 | C3: 9000 | D3: 10500 | E3: 9900 | F3: =B3/500 -> 19.8 | G3: =C3/500 -> 18 | H3: =D3/600 -> 17.5 | I3: =E3/600 -> 16.5 | J3: 16.5 | L3: 선일국산 | M3: 토 | N3: 퓨어마인드국산
A4: 갈근2 | C4: 2700 | F4: =B4/500 -> 0 | G4: =C4/500 -> 5.4 | H4: =D4/600 -> 0 | I4: =E4/600 -> 0 | L4: 이풀잎중국
A5: 감국 | F5: =B5/500 -> 0 | G5: =C5/500 -> 0 | H5: =D5/600 -> 0 | I5: =E5/600 -> 0
A6: 감수 | C6: 23400 | E6: 27100 | F6: =B6/500 -> 0 | G6: =C6/600 -> 39 | H6: =D6/600 -> 0 | I6: =E6/600 -> 45.166667 | J6: 45.2 | L6: 600g씨케이중국 | N6: 씨케이중국
A7: 감초 | D7: 17000 | E7: 25500 | F7: =B7/500 -> 0 | G7: =C7/500 -> 0 | H7: =D7/600 -> 28.333333 | I7: =E7/600 -> 42.5 | J7: 28.3 | M7: 양외2 | N7: 양외1
A8: 강활1 | B8: 27200 | C8: 20500 | D8: 24000 | F8: =B8/500 -> 54.4 | G8: =C8/500 -> 41 | H8: =D8/600 -> 40 | I8: =E8/600 -> 0 | J8: 40 | L8: 선일국산 | M8: 토
A9: 강활2 | C9: 18700 | D9: 21000 | E9: 23300 | F9: =B9/500 -> 0 | G9: =C9/500 -> 37.4 | H9: =D9/600 -> 35 | I9: =E9/600 -> 38.833333 | J9: 38.8 | L9: 태극인국산 | N9: 선일국산
A10: 강황 | C10: 3300 | D10: 5000 | F10: =B10/500 -> 0 | G10: =C10/500 -> 6.6 | H10: =D10/600 -> 8.3333333 | I10: =E10/600 -> 0 | J10: 8.3 | M10: 인도
A11: 건강 | C11: 4500 | D11: 8000 | E11: 5700 | F11: =B11/500 -> 0 | G11: =C11/500 -> 9 | H11: =D11/600 -> 13.333333 | I11: =E11/600 -> 9.5 | J11: 9.5
A12: 건율 | C12: 13500 | D12: 16500 | E12: 16700 | F12: =B12/500 -> 0 | G12: =C12/500 -> 27 | H12: =D12/600 -> 27.5 | I12: =E12/600 -> 27.833333 | J12: 27.5 | M12: 토 | N12: (절, 토)
A13: 건지황 | B13: 19900 | C13: 7200 | D13: 11000 | E13: 8900 | F13: =B13/500 -> 39.8 | G13: =C13/500 -> 14.4 | H13: =D13/600 -> 18.333333 | I13: =E13/600 -> 14.833333 | J13: 14.4 | L13: 허브팜중국
A14: 검인 | F14: =B14/500 -> 0 | G14: =C14/500 -> 0 | H14: =D14/600 -> 0 | I14: =E14/600 -> 0
A15: 결명자 | F15: =B15/500 -> 0 | G15: =C15/500 -> 0 | H15: =D15/600 -> 0 | I15: =E15/600 -> 0
A16: 계지 | B16: 4500 | C16: 2000 | D16: 3500 | E16: 2900 | F16: =B16/500 -> 9 | G16: =C16/500 -> 4 | H16: =D16/600 -> 5.8333333 | I16: =E16/600 -> 4.8333333 | J16: 4.8 | L16: 씨케이베트남 | M16: 세 | N16: 엔탭베트남
A17: 고량강 | C17: 10200 | E17: 11100 | F17: =B17/500 -> 0 | G17: =C17/600 -> 17 | H17: =D17/600 -> 0 | I17: =E17/600 -> 18.5 | J17: 17 | L17: 600g 씨케이중국 | N17: 씨케이중국
A18: 고본 | C18: 32000 | E18: 36800 | F18: =B18/500 -> 0 | G18: =C18/500 -> 64 | H18: =D18/600 -> 0 | I18: =E18/600 -> 61.333333 | J18: 61.3 | N18: 퓨어마인드국산
A19: 고삼 | C19: 4500 | F19: =B19/500 -> 0 | G19: =C19/500 -> 9 | H19: =D19/600 -> 0 | I19: =E19/600 -> 0 | J19: 9 | L19: 한솔중국
A20: 골쇄보 | F20: =B20/500 -> 0 | G20: =C20/500 -> 0 | H20: =D20/600 -> 0 | I20: =E20/600 -> 0
A21: 과루인 | C21: 3500 | D21: 6500 | F21: =B21/500 -> 0 | G21: =C21/500 -> 7 | H21: =D21/600 -> 10.833333 | I21: =E21/600 -> 0 | J21: 10.8 | M21: (추)
A22: 곽향1 | B22: 6900 | C22: 5600 | E22: 6900 | F22: =B22/500 -> 13.8 | G22: =C22/500 -> 11.2 | H22: =D22/600 -> 0 | I22: =E22/600 -> 11.5 | J22: 13.8 | L22: 선일국산 | N22: 씨케이국산
A23: 곽향2 | B23: 4600 | C23: 3500 | E23: 4800 | F23: =B23/500 -> 9.2 | G23: =C23/500 -> 7 | H23: =D23/600 -> 0 | I23: =E23/600 -> 8 | J23: 7 | K23: 인도네시아 | L23: 올본인도네시아 | N23: 엔탭인도네시아
A24: 관동화 | C24: 46000 | D24: 70000 | E24: 75400 | F24: =B24/500 -> 0 | G24: =C24/300 -> 153.33333 | H24: =D24/600 -> 116.66667 | I24: =E24/600 -> 125.66667 | J24: 116.7 | L24: 300g | N24: 엔탭중국
A25: 괴화 | F25: =B25/500 -> 0 | G25: =C25/500 -> 0 | H25: =D25/600 -> 0 | I25: =E25/600 -> 0
A26: 교이 | F26: =B26/500 -> 0 | G26: =C26/500 -> 0 | H26: =D26/600 -> 0 | I26: =E26/600 -> 0 | J26: 5.3
A27: 구기자 | B27: 14900 | C27: 8700 | D27: 9000 | E27: 8000 | F27: =B27/500 -> 29.8 | G27: =C27/500 -> 17.4 | H27: =D27/600 -> 15 | I27: =E27/600 -> 13.333333 | J27: 13.3 | N27: 엔탭중국영하
A28: 구맥 | F28: =B28/500 -> 0 | G28: =C28/500 -> 0 | H28: =D28/600 -> 0 | I28: =E28/600 -> 0
A29: 구척 | F29: =B29/500 -> 0 | G29: =C29/500 -> 0 | H29: =D29/600 -> 0 | I29: =E29/600 -> 0
A30: 귀판 | C30: 20500 | D30: 19000 | F30: =B30/500 -> 0 | G30: =C30/600 -> 34.166667 | H30: =D30/600 -> 31.666667 | I30: =E30/600 -> 0 | J30: 31.7 | L30: 600g추말/자연세상인도네시아
A31: 금은화 | C31: 22000 | E31: 30800 | F31: =B31/500 -> 0 | G31: =C31/500 -> 44 | H31: =D31/600 -> 0 | I31: =E31/600 -> 51.333333 | J31: 44 | L31: 한솔중국 | N31: 엔탭중국
A32: 길경 | B32: 11500 | C32: 12900 | D32: 7500 | E32: 6700 | F32: =B32/500 -> 23 | G32: =C32/500 -> 25.8 | H32: =D32/600 -> 12.5 | I32: =E32/600 -> 11.166667 | J32: 11.2 | K32: (중국4-5년) | L32: 선일국산 | M32: (편) | N32: 엔탭중국야생3년
A33: 나복자 | C33: 3000 | D33: 4000 | F33: =B33/500 -> 0 | G33: =C33/500 -> 6 | H33: =D33/600 -> 6.6666667 | I33: =E33/600 -> 0 | J33: 6.7 | L33: 올본인도/추말 | M33: 추
A34: 남성 | C34: 13000 | D34: 13000 | F34: =B34/500 -> 0 | G34: =C34/500 -> 26 | H34: =D34/500 -> 26 | I34: =E34/600 -> 0 | J34: 26 | L34: 생강백반제/신흥중국 | M34: 500g생강백반제/신흥중국
A35: 녹용 | C35: 278000 | F35: =B35/500 -> 0 | G35: =C35/600 -> 463.33333 | H35: =D35/600 -> 0 | I35: =E35/600 -> 0 | J35: 463.3 | L35: 600g
A36: 단삼 | C36: 6600 | E36: 8900 | F36: =B36/500 -> 0 | G36: =C36/500 -> 13.2 | H36: =D36/600 -> 0 | I36: =E36/600 -> 14.833333 | J36: 14.8 | L36: 허브팜중국 | N36: 엔탭중국
A37: 담두시 | D37: 8000 | F37: =B37/500 -> 0 | G37: =C37/500 -> 0 | H37: =D37/600 -> 13.333333 | I37: =E37/600 -> 0 | J37: 13.3
A38: 당귀1 | B38: 14900 | C38: 12000 | D38: 15000 | E38: 15000 | F38: =B38/500 -> 29.8 | G38: =C38/500 -> 24 | H38: =D38/600 -> 25 | I38: =E38/600 -> 25 | J38: 25 | L38: 선일국산 | N38: 선일국산
A39: 당귀2 | C39: 12700 | E39: 13800 | F39: =B39/500 -> 0 | G39: =C39/500 -> 25.4 | H39: =D39/600 -> 0 | I39: =E39/600 -> 23 | J39: 23 | L39: 선일국산 | N39: 선일국산
A40: 당삼 | C40: 31200 | D40: 32000 | E40: 35500 | F40: =B40/500 -> 0 | G40: =C40/600 -> 52 | H40: =D40/600 -> 53.333333 | I40: =E40/600 -> 59.166667 | J40: 53.3 | L40: 600g씨케이중국 | N40: 엔탭중국
...
