Workbook

Sheet 처방전양식 (6)
B1: No. | F1: 총용량 | G1: 1g 금액 | H1: 1첩 금액 | I1: 총 금액 | J1: 1일당 | K1: 기본 정보
B2: 1 | C2: 백출 | E2: 6 | F2: =E2*$L$15 -> 120 | G2: =VLOOKUP($C2,[1]약재관리!$A:$J,10,FALSE) -> 13 | H2: =G2*E2 -> 78 | I2: =G2*F2 -> 1560 | J2: =F2/$L$14 -> 12 | K2: UNIT | L2: 84
B3: 2 | C3: 백작약 | E3: 6 | F3: =E3*$L$15 -> 120 | G3: =VLOOKUP($C3,[1]약재관리!$A:$J,10,FALSE) -> 19.6 | H3: =G3*E3 -> 117.6 | I3: =G3*F3 -> 2352 | J3: =F3/$L$14 -> 12 | K3: 처방명 | L3: 소요산가감
B4: 3 | C4: 복령 | E4: 6 | F4: =E4*$L$15 -> 120 | G4: =VLOOKUP($C4,[1]약재관리!$A:$J,10,FALSE) -> 8.7 | H4: =G4*E4 -> 52.2 | I4: =G4*F4 -> 1044 | J4: =F4/$L$14 -> 12 | K4: 날짜 | L4: 46120
B5: 4 | C5: 시호2 | E5: 4 | F5: =E5*$L$15 -> 80 | G5: =VLOOKUP($C5,[1]약재관리!$A:$J,10,FALSE) -> 15.3 | H5: =G5*E5 -> 61.2 | I5: =G5*F5 -> 1224 | J5: =F5/$L$14 -> 8 | K5: 이름 | L5: 김수정
B6: 5 | C6: 당귀1 | E6: 4 | F6: =E6*$L$15 -> 80 | G6: =VLOOKUP($C6,[1]약재관리!$A:$J,10,FALSE) -> 31.7 | H6: =G6*E6 -> 126.8 | I6: =G6*F6 -> 2536 | J6: =F6/$L$14 -> 8 | K6: 나이 | L6: 21
B7: 6 | C7: 목단피 | E7: 4 | F7: =E7*$L$15 -> 80 | G7: =VLOOKUP($C7,[1]약재관리!$A:$J,10,FALSE) -> 33.7 | H7: =G7*E7 -> 134.8 | I7: =G7*F7 -> 2696 | J7: =F7/$L$14 -> 8 | K7: 성별 | L7: F
B8: 7 | C8: 감초 | E8: 2 | F8: =E8*$L$15 -> 40 | G8: =VLOOKUP($C8,[1]약재관리!$A:$J,10,FALSE) -> 30 | H8: =G8*E8 -> 60 | I8: =G8*F8 -> 1200 | J8: =F8/$L$14 -> 4 | K8: 메모
B9: 8 | C9: 생강 | E9: 4 | F9: =E9*$L$15 -> 80 | G9: =VLOOKUP($C9,[1]약재관리!$A:$J,10,FALSE) -> 20 | H9: =G9*E9 -> 80 | I9: =G9*F9 -> 1600 | J9: =F9/$L$14 -> 8 | K9: 소요산가미 + 석창포 울금 황련 향부자 원육 인삼 건지황
B10: 9 | C10: 지각 | E10: 4 | F10: =E10*$L$15 -> 80 | G10: =VLOOKUP($C10,[1]약재관리!$A:$J,10,FALSE) -> 10 | H10: =G10*E10 -> 40 | I10: =G10*F10 -> 800 | J10: =F10/$L$14 -> 8
B11: 10 | C11: 석창포 | E11: 4 | F11: =E11*$L$15 -> 80 | G11: =VLOOKUP($C11,[1]약재관리!$A:$J,10,FALSE) -> 31.3 | H11: =G11*E11 -> 125.2 | I11: =G11*F11 -> 2504 | J11: =F11/$L$14 -> 8
B12: 11 | C12: 울금 | E12: 4 | F12: =E12*$L$15 -> 80 | G12: =VLOOKUP($C12,[1]약재관리!$A:$J,10,FALSE) -> 11.2 | H12: =G12*E12 -> 44.8 | I12: =G12*F12 -> 896 | J12: =F12/$L$14 -> 8
B13: 12 | C13: 향부자 | E13: 8 | F13: =E13*$L$15 -> 160 | G13: =VLOOKUP($C13,[1]약재관리!$A:$J,10,FALSE) -> 14.7 | H13: =G13*E13 -> 117.6 | I13: =G13*F13 -> 2352 | J13: =F13/$L$14 -> 16
B14: 13 | C14: 치자 | E14: 3 | F14: =E14*$L$15 -> 60 | G14: =VLOOKUP($C14,[1]약재관리!$A:$J,10,FALSE) -> 26 | H14: =G14*E14 -> 78 | I14: =G14*F14 -> 1560 | J14: =F14/$L$14 -> 6 | K14: 총 일수 | L14: 10 | M14: 일분
B15: 14 | C15: 황련 | D15: 주초 | E15: 2 | F15: =E15*$L$15 -> 40 | G15: =VLOOKUP($C15,[1]약재관리!$A:$J,10,FALSE) -> 136.8 | H15: =G15*E15 -> 273.6 | I15: =G15*F15 -> 5472 | J15: =F15/$L$14 -> 4 | K15: 첩수 | L15: 20 | M15: 첩
B16: 15 | C16: 원육 | E16: 6 | F16: =E16*$L$15 -> 120 | G16: =VLOOKUP($C16,[1]약재관리!$A:$J,10,FALSE) -> 20.5 | H16: =G16*E16 -> 123 | I16: =G16*F16 -> 2460 | J16: =F16/$L$14 -> 12 | K16: 총 팩수 | L16: 41 | M16: 팩
B17: 16 | C17: 인삼 | E17: 4 | F17: =E17*$L$15 -> 80 | G17: =VLOOKUP($C17,[1]약재관리!$A:$J,10,FALSE) -> 120 | H17: =G17*E17 -> 480 | I17: =G17*F17 -> 9600 | J17: =F17/$L$14 -> 8 | K17: 팩당 물량 | L17: 110 | M17: cc
B18: 17 | C18: 건지황 | E18: 4 | F18: =E18*$L$15 -> 80 | G18: =VLOOKUP($C18,[1]약재관리!$A:$J,10,FALSE) -> 18.3 | H18: =G18*E18 -> 73.2 | I18: =G18*F18 -> 1464 | J18: =F18/$L$14 -> 8 | K18: 1첩당약재 | L18: =SUM(E2:E31) -> 75 | M18: g
B19: 18 | F19: =E19*$L$15 -> 0 | H19: =G19*E19 -> 0 | I19: =G19*F19 -> 0 | K19: 약재총량 | L19: =L15*L18 -> 1500 | M19: g
B20: 19 | F20: =E20*$L$15 -> 0 | H20: =G20*E20 -> 0 | I20: =G20*F20 -> 0 | K20: 총 물 양 | L20: =L16*L17+L19*1.3+400 -> 6860 | M20: cc
B21: 20 | F21: =E21*$L$15 -> 0 | H21: =G21*E21 -> 0 | I21: =G21*F21 -> 0
B22: 21 | F22: =E22*$L$15 -> 0 | H22: =G22*E22 -> 0 | I22: =G22*F22 -> 0 | K22: 참고치
B23: 22 | F23: =E23*$L$15 -> 0 | H23: =G23*E23 -> 0 | I23: =G23*F23 -> 0 | K23: cross chk | L23: =SUM(F2:F31) -> 1500 | M23: g
B24: 23 | F24: =E24*$L$15 -> 0 | H24: =G24*E24 -> 0 | I24: =G24*F24 -> 0 | K24: 20첩물양 | L24: 5000 | M24: cc
B25: 24 | F25: =E25*$L$15 -> 0 | H25: =G25*E25 -> 0 | I25: =G25*F25 -> 0 | K25: 1첩당 | L25: 80-120 | M25: g
B26: 25 | F26: =E26*$L$15 -> 0 | I26: =G26*F26 -> 0 | K26: 20첩당 | L26: 1600 | M26: g
B27: 26 | F27: =E27*$L$15 -> 0 | H27: =G27*E27 -> 0 | I27: =G27*F27 -> 0 | K27: 1돈 환산 | L27: 4 | M27: g
B28: 27 | F28: =E28*$L$15 -> 0 | H28: =G28*E28 -> 0 | I28: =G28*F28 -> 0
B29: 28 | F29: =E29*$L$15 -> 0 | H29: =G29*E29 -> 0 | I29: =G29*F29 -> 0 | K29: 금액
B30: 29 | F30: =E30*$L$15 -> 0 | H30: =G30*E30 -> 0 | I30: =G30*F30 -> 0 | K30: 1첩당 | L30: =SUM(H2:H31) -> 2066 | M30: 원
B31: 30 | F31: =E31*$L$15 -> 0 | H31: =G31*E31 -> 0 | I31: =G31*F31 -> 0 | K31: 총 | L31: =SUM(I2:I31) -> 41320 | M31: 원

Sheet 처방전양식 (5)
B1: No. | F1: 총용량 | G1: 1g 금액 | H1: 1첩 금액 | I1: 총 금액 | J1: 1일당 | K1: 기본 정보
B2: 1 | C2: 백출 | E2: 6 | F2: =E2*$L$15 -> 60 | G2: =VLOOKUP($C2,[1]약재관리!$A:$J,10,FALSE) -> 13 | H2: =G2*E2 -> 78 | I2: =G2*F2 -> 780 | J2: =F2/$L$14 -> 6 | K2: UNIT | L2: 84
B3: 2 | C3: 백작약 | E3: 6 | F3: =E3*$L$15 -> 60 | G3: =VLOOKUP($C3,[1]약재관리!$A:$J,10,FALSE) -> 19.6 | H3: =G3*E3 -> 117.6 | I3: =G3*F3 -> 1176 | J3: =F3/$L$14 -> 6 | K3: 처방명 | L3: 소요산가감
B4: 3 | C4: 복령 | E4: 6 | F4: =E4*$L$15 -> 60 | G4: =VLOOKUP($C4,[1]약재관리!$A:$J,10,FALSE) -> 8.7 | H4: =G4*E4 -> 52.2 | I4: =G4*F4 -> 522 | J4: =F4/$L$14 -> 6 | K4: 날짜 | L4: 46097
B5: 4 | C5: 시호2 | E5: 4 | F5: =E5*$L$15 -> 40 | G5: =VLOOKUP($C5,[1]약재관리!$A:$J,10,FALSE) -> 15.3 | H5: =G5*E5 -> 61.2 | I5: =G5*F5 -> 612 | J5: =F5/$L$14 -> 4 | K5: 이름 | L5: 김수정
B6: 5 | C6: 당귀1 | E6: 4 | F6: =E6*$L$15 -> 40 | G6: =VLOOKUP($C6,[1]약재관리!$A:$J,10,FALSE) -> 31.7 | H6: =G6*E6 -> 126.8 | I6: =G6*F6 -> 1268 | J6: =F6/$L$14 -> 4 | K6: 나이 | L6: 21
B7: 6 | C7: 목단피 | E7: 4 | F7: =E7*$L$15 -> 40 | G7: =VLOOKUP($C7,[1]약재관리!$A:$J,10,FALSE) -> 33.7 | H7: =G7*E7 -> 134.8 | I7: =G7*F7 -> 1348 | J7: =F7/$L$14 -> 4 | K7: 성별 | L7: F
B8: 7 | C8: 감초 | E8: 2 | F8: =E8*$L$15 -> 20 | G8: =VLOOKUP($C8,[1]약재관리!$A:$J,10,FALSE) -> 30 | H8: =G8*E8 -> 60 | I8: =G8*F8 -> 600 | J8: =F8/$L$14 -> 2 | K8: 메모
B9: 8 | C9: 생강 | E9: 4 | F9: =E9*$L$15 -> 40 | G9: =VLOOKUP($C9,[1]약재관리!$A:$J,10,FALSE) -> 20 | H9: =G9*E9 -> 80 | I9: =G9*F9 -> 800 | J9: =F9/$L$14 -> 4 | K9: 소요산가미 + 석창포 울금 황련 향부자 원육 인삼 건지황
B10: 9 | C10: 지각 | E10: 4 | F10: =E10*$L$15 -> 40 | G10: =VLOOKUP($C10,[1]약재관리!$A:$J,10,FALSE) -> 10 | H10: =G10*E10 -> 40 | I10: =G10*F10 -> 400 | J10: =F10/$L$14 -> 4
B11: 10 | C11: 석창포 | E11: 4 | F11: =E11*$L$15 -> 40 | G11: =VLOOKUP($C11,[1]약재관리!$A:$J,10,FALSE) -> 31.3 | H11: =G11*E11 -> 125.2 | I11: =G11*F11 -> 1252 | J11: =F11/$L$14 -> 4
B12: 11 | C12: 울금 | E12: 4 | F12: =E12*$L$15 -> 40 | G12: =VLOOKUP($C12,[1]약재관리!$A:$J,10,FALSE) -> 11.2 | H12: =G12*E12 -> 44.8 | I12: =G12*F12 -> 448 | J12: =F12/$L$14 -> 4
B13: 12 | C13: 향부자 | E13: 8 | F13: =E13*$L$15 -> 80 | G13: =VLOOKUP($C13,[1]약재관리!$A:$J,10,FALSE) -> 14.7 | H13: =G13*E13 -> 117.6 | I13: =G13*F13 -> 1176 | J13: =F13/$L$14 -> 8
B14: 13 | C14: 치자 | E14: 3 | F14: =E14*$L$15 -> 30 | G14: =VLOOKUP($C14,[1]약재관리!$A:$J,10,FALSE) -> 26 | H14: =G14*E14 -> 78 | I14: =G14*F14 -> 780 | J14: =F14/$L$14 -> 3 | K14: 총 일수 | L14: 10 | M14: 일분
B15: 14 | C15: 황련 | D15: 주초 | E15: 2 | F15: =E15*$L$15 -> 20 | G15: =VLOOKUP($C15,[1]약재관리!$A:$J,10,FALSE) -> 136.8 | H15: =G15*E15 -> 273.6 | I15: =G15*F15 -> 2736 | J15: =F15/$L$14 -> 2 | K15: 첩수 | L15: 10 | M15: 첩
B16: 15 | C16: 원육 | E16: 6 | F16: =E16*$L$15 -> 60 | G16: =VLOOKUP($C16,[1]약재관리!$A:$J,10,FALSE) -> 20.5 | H16: =G16*E16 -> 123 | I16: =G16*F16 -> 1230 | J16: =F16/$L$14 -> 6 | K16: 총 팩수 | L16: 22 | M16: 팩
B17: 16 | C17: 인삼 | E17: 4 | F17: =E17*$L$15 -> 40 | G17: =VLOOKUP($C17,[1]약재관리!$A:$J,10,FALSE) -> 120 | H17: =G17*E17 -> 480 | I17: =G17*F17 -> 4800 | J17: =F17/$L$14 -> 4 | K17: 팩당 물량 | L17: 110 | M17: cc
B18: 17 | C18: 건지황 | E18: 4 | F18: =E18*$L$15 -> 40 | G18: =VLOOKUP($C18,[1]약재관리!$A:$J,10,FALSE) -> 18.3 | H18: =G18*E18 -> 73.2 | I18: =G18*F18 -> 732 | J18: =F18/$L$14 -> 4 | K18: 1첩당약재 | L18: =SUM(E2:E31) -> 75 | M18: g
B19: 18 | F19: =E19*$L$15 -> 0 | H19: =G19*E19 -> 0 | I19: =G19*F19 -> 0 | K19: 약재총량 | L19: =L15*L18 -> 750 | M19: g
B20: 19 | F20: =E20*$L$15 -> 0 | H20: =G20*E20 -> 0 | I20: =G20*F20 -> 0 | K20: 총 물 양 | L20: =L16*L17+L19*1.3+400 -> 3795 | M20: cc
B21: 20 | F21: =E21*$L$15 -> 0 | H21: =G21*E21 -> 0 | I21: =G21*F21 -> 0
B22: 21 | F22: =E22*$L$15 -> 0 | H22: =G22*E22 -> 0 | I22: =G22*F22 -> 0 | K22: 참고치
B23: 22 | F23: =E23*$L$15 -> 0 | H23: =G23*E23 -> 0 | I23: =G23*F23 -> 0 | K23: cross chk | L23: =SUM(F2:F31) -> 750 | M23: g
B24: 23 | F24: =E24*$L$15 -> 0 | H24: =G24*E24 -> 0 | I24: =G24*F24 -> 0 | K24: 20첩물양 | L24: 5000 | M24: cc
B25: 24 | F25: =E25*$L$15 -> 0 | H25: =G25*E25 -> 0 | I25: =G25*F25 -> 0 | K25: 1첩당 | L25: 80-120 | M25: g
B26: 25 | F26: =E26*$L$15 -> 0 | H26: =G26*E26 -> 0 | I26: =G26*F26 -> 0 | K26: 20첩당 | L26: 1600 | M26: g
B27: 26 | F27: =E27*$L$15 -> 0 | H27: =G27*E27 -> 0 | I27: =G27*F27 -> 0 | K27: 1돈 환산 | L27: 4 | M27: g
B28: 27 | F28: =E28*$L$15 -> 0 | H28: =G28*E28 -> 0 | I28: =G28*F28 -> 0
B29: 28 | F29: =E29*$L$15 -> 0 | H29: =G29*E29 -> 0 | I29: =G29*F29 -> 0 | K29: 금액
B30: 29 | F30: =E30*$L$15 -> 0 | H30: =G30*E30 -> 0 | I30: =G30*F30 -> 0 | K30: 1첩당 | L30: =SUM(H2:H31) -> 2066 | M30: 원
B31: 30 | F31: =E31*$L$15 -> 0 | H31: =G31*E31 -> 0 | I31: =G31*F31 -> 0 | K31: 총 | L31: =SUM(I2:I31) -> 20660 | M31: 원

Sheet 처방전양식 (4)
B1: No. | F1: 총용량 | G1: 1g 금액 | H1: 1첩 금액 | I1: 총 금액 | J1: 1일당 | K1: 기본 정보
B2: 1 | C2: 백출 | E2: 6 | F2: =E2*$L$15 -> 60 | G2: =VLOOKUP($C2,[1]약재관리!$A:$J,10,FALSE) -> 13 | H2: =G2*E2 -> 78 | I2: =G2*F2 -> 780 | J2: =F2/$L$14 -> 6 | K2: UNIT | L2: 84
B3: 2 | C3: 백작약 | E3: 6 | F3: =E3*$L$15 -> 60 | G3: =VLOOKUP($C3,[1]약재관리!$A:$J,10,FALSE) -> 19.6 | H3: =G3*E3 -> 117.6 | I3: =G3*F3 -> 1176 | J3: =F3/$L$14 -> 6 | K3: 처방명 | L3: 소요산가감
B4: 3 | C4: 복령 | E4: 6 | F4: =E4*$L$15 -> 60 | G4: =VLOOKUP($C4,[1]약재관리!$A:$J,10,FALSE) -> 8.7 | H4: =G4*E4 -> 52.2 | I4: =G4*F4 -> 522 | J4: =F4/$L$14 -> 6 | K4: 날짜 | L4: 46065
B5: 4 | C5: 시호2 | E5: 4 | F5: =E5*$L$15 -> 40 | G5: =VLOOKUP($C5,[1]약재관리!$A:$J,10,FALSE) -> 15.3 | H5: =G5*E5 -> 61.2 | I5: =G5*F5 -> 612 | J5: =F5/$L$14 -> 4 | K5: 이름 | L5: 김수정
B6: 5 | C6: 당귀1 | E6: 4 | F6: =E6*$L$15 -> 40 | G6: =VLOOKUP($C6,[1]약재관리!$A:$J,10,FALSE) -> 31.7 | H6: =G6*E6 -> 126.8 | I6: =G6*F6 -> 1268 | J6: =F6/$L$14 -> 4 | K6: 나이 | L6: 21
B7: 6 | C7: 목단피 | E7: 4 | F7: =E7*$L$15 -> 40 | G7: =VLOOKUP($C7,[1]약재관리!$A:$J,10,FALSE) -> 33.7 | H7: =G7*E7 -> 134.8 | I7: =G7*F7 -> 1348 | J7: =F7/$L$14 -> 4 | K7: 성별 | L7: F
B8: 7 | C8: 감초 | E8: 2 | F8: =E8*$L$15 -> 20 | G8: =VLOOKUP($C8,[1]약재관리!$A:$J,10,FALSE) -> 30 | H8: =G8*E8 -> 60 | I8: =G8*F8 -> 600 | J8: =F8/$L$14 -> 2 | K8: 메모
B9: 8 | C9: 생강 | E9: 4 | F9: =E9*$L$15 -> 40 | G9: =VLOOKUP($C9,[1]약재관리!$A:$J,10,FALSE) -> 20 | H9: =G9*E9 -> 80 | I9: =G9*F9 -> 800 | J9: =F9/$L$14 -> 4 | K9: 소요산가미 + 석창포 황금 황련 향부자 원육 인삼 건지황
B10: 9 | C10: 지각 | E10: 4 | F10: =E10*$L$15 -> 40 | G10: =VLOOKUP($C10,[1]약재관리!$A:$J,10,FALSE) -> 10 | H10: =G10*E10 -> 40 | I10: =G10*F10 -> 400 | J10: =F10/$L$14 -> 4
B11: 10 | C11: 석창포 | E11: 4 | F11: =E11*$L$15 -> 40 | G11: =VLOOKUP($C11,[1]약재관리!$A:$J,10,FALSE) -> 31.3 | H11: =G11*E11 -> 125.2 | I11: =G11*F11 -> 1252 | J11: =F11/$L$14 -> 4
B12: 11 | C12: 황금 | D12: 주초 | E12: 2 | F12: =E12*$L$15 -> 20 | G12: =VLOOKUP($C12,[1]약재관리!$A:$J,10,FALSE) -> 22.5 | H12: =G12*E12 -> 45 | I12: =G12*F12 -> 450 | J12: =F12/$L$14 -> 2
B13: 12 | C13: 향부자 | E13: 8 | F13: =E13*$L$15 -> 80 | G13: =VLOOKUP($C13,[1]약재관리!$A:$J,10,FALSE) -> 14.7 | H13: =G13*E13 -> 117.6 | I13: =G13*F13 -> 1176 | J13: =F13/$L$14 -> 8
B14: 13 | C14: 치자 | E14: 3 | F14: =E14*$L$15 -> 30 | G14: =VLOOKUP($C14,[1]약재관리!$A:$J,10,FALSE) -> 26 | H14: =G14*E14 -> 78 | I14: =G14*F14 -> 780 | J14: =F14/$L$14 -> 3 | K14: 총 일수 | L14: 10 | M14: 일분
B15: 14 | C15: 황련 | D15: 주초 | E15: 2 | F15: =E15*$L$15 -> 20 | G15: =VLOOKUP($C15,[1]약재관리!$A:$J,10,FALSE) -> 136.8 | H15: =G15*E15 -> 273.6 | I15: =G15*F15 -> 2736 | J15: =F15/$L$14 -> 2 | K15: 첩수 | L15: 10 | M15: 첩
B16: 15 | C16: 원육 | E16: 6 | F16: =E16*$L$15 -> 60 | G16: =VLOOKUP($C16,[1]약재관리!$A:$J,10,FALSE) -> 20.5 | H16: =G16*E16 -> 123 | I16: =G16*F16 -> 1230 | J16: =F16/$L$14 -> 6 | K16: 총 팩수 | L16: 20 | M16: 팩
B17: 16 | C17: 인삼 | E17: 4 | F17: =E17*$L$15 -> 40 | G17: =VLOOKUP($C17,[1]약재관리!$A:$J,10,FALSE) -> 120 | H17: =G17*E17 -> 480 | I17: =G17*F17 -> 4800 | J17: =F17/$L$14 -> 4 | K17: 팩당 물량 | L17: 70 | M17: cc
B18: 17 | C18: 건지황 | E18: 4 | F18: =E18*$L$15 -> 40 | G18: =VLOOKUP($C18,[1]약재관리!$A:$J,10,FALSE) -> 18.3 | H18: =G18*E18 -> 73.2 | I18: =G18*F18 -> 732 | J18: =F18/$L$14 -> 4 | K18: 1첩당약재 | L18: =SUM(E2:E31) -> 73 | M18: g
B19: 18 | F19: =E19*$L$15 -> 0 | H19: =G19*E19 -> 0 | I19: =G19*F19 -> 0 | K19: 약재총량 | L19: =L15*L18 -> 730 | M19: g
B20: 19 | F20: =E20*$L$15 -> 0 | H20: =G20*E20 -> 0 | I20: =G20*F20 -> 0 | K20: 총 물 양 | L20: =L16*L17+L19 -> 2130 | M20: cc
B21: 20 | F21: =E21*$L$15 -> 0 | H21: =G21*E21 -> 0 | I21: =G21*F21 -> 0
B22: 21 | F22: =E22*$L$15 -> 0 | H22: =G22*E22 -> 0 | I22: =G22*F22 -> 0 | K22: 참고치
B23: 22 | F23: =E23*$L$15 -> 0 | H23: =G23*E23 -> 0 | I23: =G23*F23 -> 0 | K23: cross chk | L23: =SUM(F2:F31) -> 730 | M23: g
B24: 23 | F24: =E24*$L$15 -> 0 | H24: =G24*E24 -> 0 | I24: =G24*F24 -> 0 | K24: 20첩물양 | L24: 5000 | M24: cc
B25: 24 | F25: =E25*$L$15 -> 0 | H25: =G25*E25 -> 0 | I25: =G25*F25 -> 0 | K25: 1첩당 | L25: 80-120 | M25: g
B26: 25 | F26: =E26*$L$15 -> 0 | H26: =G26*E26 -> 0 | I26: =G26*F26 -> 0 | K26: 20첩당 | L26: 1600 | M26: g
B27: 26 | F27: =E27*$L$15 -> 0 | H27: =G27*E27 -> 0 | I27: =G27*F27 -> 0 | K27: 1돈 환산 | L27: 4 | M27: g
B28: 27 | F28: =E28*$L$15 -> 0 | H28: =G28*E28 -> 0 | I28: =G28*F28 -> 0
B29: 28 | F29: =E29*$L$15 -> 0 | H29: =G29*E29 -> 0 | I29: =G29*F29 -> 0 | K29: 금액
B30: 29 | F30: =E30*$L$15 -> 0 | H30: =G30*E30 -> 0 | I30: =G30*F30 -> 0 | K30: 1첩당 | L30: =SUM(H2:H31) -> 2066.2 | M30: 원
B31: 30 | F31: =E31*$L$15 -> 0 | H31: =G31*E31 -> 0 | I31: =G31*F31 -> 0 | K31: 총 | L31: =SUM(I2:I31) -> 20662 | M31: 원

Sheet 처방전양식 (3)
B1: No. | F1: 총용량 | G1: 1g 금액 | H1: 1첩 금액 | I1: 총 금액 | J1: 1일당 | K1: 기본 정보
B2: 1 | C2: 백출 | E2: 6 | F2: =E2*$L$15 -> 120 | G2: =VLOOKUP($C2,[1]약재관리!$A:$J,10,FALSE) -> 13 | H2: =G2*E2 -> 78 | I2: =G2*F2 -> 1560 | J2: =F2/$L$14 -> 6 | K2: UNIT | L2: 84
B3: 2 | C3: 백작약 | E3: 4 | F3: =E3*$L$15 -> 80 | G3: =VLOOKUP($C3,[1]약재관리!$A:$J,10,FALSE) -> 19.6 | H3: =G3*E3 -> 78.4 | I3: =G3*F3 -> 1568 | J3: =F3/$L$14 -> 4 | K3: 처방명 | L3: 소요산가감
B4: 3 | C4: 복령 | E4: 4 | F4: =E4*$L$15 -> 80 | G4: =VLOOKUP($C4,[1]약재관리!$A:$J,10,FALSE) -> 8.7 | H4: =G4*E4 -> 34.8 | I4: =G4*F4 -> 696 | J4: =F4/$L$14 -> 4 | K4: 날짜 | L4: 45789
B5: 4 | C5: 시호2 | E5: 4 | F5: =E5*$L$15 -> 80 | G5: =VLOOKUP($C5,[1]약재관리!$A:$J,10,FALSE) -> 15.3 | H5: =G5*E5 -> 61.2 | I5: =G5*F5 -> 1224 | J5: =F5/$L$14 -> 4 | K5: 이름 | L5: 김수정
B6: 5 | C6: 당귀1 | E6: 4 | F6: =E6*$L$15 -> 80 | G6: =VLOOKUP($C6,[1]약재관리!$A:$J,10,FALSE) -> 31.7 | H6: =G6*E6 -> 126.8 | I6: =G6*F6 -> 2536 | J6: =F6/$L$14 -> 4 | K6: 나이 | L6: 21
B7: 6 | C7: 맥문동 | E7: 4 | F7: =E7*$L$15 -> 80 | G7: =VLOOKUP($C7,[1]약재관리!$A:$J,10,FALSE) -> 39.2 | H7: =G7*E7 -> 156.8 | I7: =G7*F7 -> 3136 | J7: =F7/$L$14 -> 4 | K7: 성별 | L7: F
B8: 7 | C8: 감초 | E8: 2 | F8: =E8*$L$15 -> 40 | G8: =VLOOKUP($C8,[1]약재관리!$A:$J,10,FALSE) -> 30 | H8: =G8*E8 -> 60 | I8: =G8*F8 -> 1200 | J8: =F8/$L$14 -> 2 | K8: 메모
B9: 8 | C9: 생강 | E9: 4 | F9: =E9*$L$15 -> 80 | G9: =VLOOKUP($C9,[1]약재관리!$A:$J,10,FALSE) -> 20 | H9: =G9*E9 -> 80 | I9: =G9*F9 -> 1600 | J9: =F9/$L$14 -> 4
B10: 9 | C10: 천궁1 | E10: 4 | F10: =E10*$L$15 -> 80 | G10: =VLOOKUP($C10,[1]약재관리!$A:$J,10,FALSE) -> 10.8 | H10: =G10*E10 -> 43.2 | I10: =G10*F10 -> 864 | J10: =F10/$L$14 -> 4
B11: 10 | C11: 생지황 | E11: 4 | F11: =E11*$L$15 -> 80 | G11: =VLOOKUP($C11,[1]약재관리!$A:$J,10,FALSE) -> 19 | H11: =G11*E11 -> 76 | I11: =G11*F11 -> 1520 | J11: =F11/$L$14 -> 4
B12: 11 | C12: 사인 | E12: 3 | F12: =E12*$L$15 -> 60 | G12: =VLOOKUP($C12,[1]약재관리!$A:$J,10,FALSE) -> 21.8 | H12: =G12*E12 -> 65.4 | I12: =G12*F12 -> 1308 | J12: =F12/$L$14 -> 3
B13: 12 | C13: 황백 | E13: 2 | F13: =E13*$L$15 -> 40 | G13: =VLOOKUP($C13,[1]약재관리!$A:$J,10,FALSE) -> 30.8 | H13: =G13*E13 -> 61.6 | I13: =G13*F13 -> 1232 | J13: =F13/$L$14 -> 2
B14: 13 | C14: 감초 | E14: 2 | F14: =E14*$L$15 -> 40 | G14: =VLOOKUP($C14,[1]약재관리!$A:$J,10,FALSE) -> 30 | H14: =G14*E14 -> 60 | I14: =G14*F14 -> 1200 | J14: =F14/$L$14 -> 2 | K14: 총 일수 | L14: 20 | M14: 일분
B15: 14 | C15: 별갑 | E15: 4 | F15: =E15*$L$15 -> 80 | G15: =VLOOKUP($C15,[1]약재관리!$A:$J,10,FALSE) -> 0 | H15: =G15*E15 -> 0 | I15: =G15*F15 -> 0 | J15: =F15/$L$14 -> 4 | K15: 첩수 | L15: 20 | M15: 첩
B16: 15 | C16: 현호색 | E16: 4 | F16: =E16*$L$15 -> 80 | G16: =VLOOKUP($C16,[1]약재관리!$A:$J,10,FALSE) -> 59.7 | H16: =G16*E16 -> 238.8 | I16: =G16*F16 -> 4776 | J16: =F16/$L$14 -> 4 | K16: 총 팩수 | L16: 45 | M16: 팩
B17: 16 | C17: 목단피 | E17: 4 | F17: =E17*$L$15 -> 80 | G17: =VLOOKUP($C17,[1]약재관리!$A:$J,10,FALSE) -> 33.7 | H17: =G17*E17 -> 134.8 | I17: =G17*F17 -> 2696 | J17: =F17/$L$14 -> 4 | K17: 팩당 물량 | L17: 70 | M17: cc
B18: 17 | C18: 치자 | E18: 2 | F18: =E18*$L$15 -> 40 | G18: =VLOOKUP($C18,[1]약재관리!$A:$J,10,FALSE) -> 26 | H18: =G18*E18 -> 52 | I18: =G18*F18 -> 1040 | J18: =F18/$L$14 -> 2 | K18: 1첩당약재 | L18: =SUM(E2:E31) -> 61 | M18: g
B19: 18 | F19: =E19*$L$15 -> 0 | H19: =G19*E19 -> 0 | I19: =G19*F19 -> 0 | K19: 약재총량 | L19: =L15*L18 -> 1220 | M19: g
B20: 19 | F20: =E20*$L$15 -> 0 | H20: =G20*E20 -> 0 | I20: =G20*F20 -> 0 | K20: 총 물 양 | L20: =L16*L17+L19 -> 4370 | M20: cc
B21: 20 | F21: =E21*$L$15 -> 0 | H21: =G21*E21 -> 0 | I21: =G21*F21 -> 0
B22: 21 | F22: =E22*$L$15 -> 0 | H22: =G22*E22 -> 0 | I22: =G22*F22 -> 0 | K22: 참고치
B23: 22 | F23: =E23*$L$15 -> 0 | H23: =G23*E23 -> 0 | I23: =G23*F23 -> 0 | K23: cross chk | L23: =SUM(F2:F31) -> 1220 | M23: g
B24: 23 | F24: =E24*$L$15 -> 0 | H24: =G24*E24 -> 0 | I24: =G24*F24 -> 0 | K24: 20첩물양 | L24: 5000 | M24: cc
B25: 24 | F25: =E25*$L$15 -> 0 | H25: =G25*E25 -> 0 | I25: =G25*F25 -> 0 | K25: 1첩당 | L25: 80-120 | M25: g
B26: 25 | F26: =E26*$L$15 -> 0 | H26: =G26*E26 -> 0 | I26: =G26*F26 -> 0 | K26: 20첩당 | L26: 1600 | M26: g
B27: 26 | F27: =E27*$L$15 -> 0 | H27: =G27*E27 -> 0 | I27: =G27*F27 -> 0 | K27: 1돈 환산 | L27: 4 | M27: g
B28: 27 | F28: =E28*$L$15 -> 0 | H28: =G28*E28 -> 0 | I28: =G28*F28 -> 0
B29: 28 | F29: =E29*$L$15 -> 0 | H29: =G29*E29 -> 0 | I29: =G29*F29 -> 0 | K29: 금액
B30: 29 | F30: =E30*$L$15 -> 0 | H30: =G30*E30 -> 0 | I30: =G30*F30 -> 0 | K30: 1첩당 | L30: =SUM(H2:H31) -> 1407.8 | M30: 원
B31: 30 | F31: =E31*$L$15 -> 0 | H31: =G31*E31 -> 0 | I31: =G31*F31 -> 0 | K31: 총 | L31: =SUM(I2:I31) -> 28156 | M31: 원

Sheet 처방전양식 (2)
B1: No. | C1: 약재명 | D1: 수치 | E1: 그램 | F1: 총용량 | G1: 1g 금액 | H1: 1첩 금액 | I1: 총 금액 | K1: 기본 정보
B2: 1 | C2: 백출 | E2: 4 | F2: =E2*$L$15 -> 40 | G2: =VLOOKUP($C2,약재관리!A:J,10,FALSE) -> 30.3 | H2: =G2*E2 -> 121.2 | I2: =G2*F2 -> 1212 | K2: UNIT | L2: 84
B3: 2 | C3: 백작약 | E3: 4 | F3: =E3*$L$15 -> 40 | G3: =VLOOKUP($C3,약재관리!A:J,10,FALSE) -> 19.6 | H3: =G3*E3 -> 78.4 | I3: =G3*F3 -> 784 | K3: 처방명 | L3: 소요산가감
B4: 3 | C4: 복령 | E4: 6 | F4: =E4*$L$15 -> 60 | G4: =VLOOKUP($C4,약재관리!A:J,10,FALSE) -> 11 | H4: =G4*E4 -> 66 | I4: =G4*F4 -> 660 | K4: 날짜 | L4: 45757
B5: 4 | C5: 시호2 | E5: 4 | F5: =E5*$L$15 -> 40 | G5: =VLOOKUP($C5,약재관리!A:J,10,FALSE) -> 15.3 | H5: =G5*E5 -> 61.2 | I5: =G5*F5 -> 612 | K5: 이름 | L5: 김수정
B6: 5 | C6: 당귀1 | E6: 4 | F6: =E6*$L$15 -> 40 | G6: =VLOOKUP($C6,약재관리!A:J,10,FALSE) -> 25.3 | H6: =G6*E6 -> 101.2 | I6: =G6*F6 -> 1012 | K6: 나이 | L6: 21
B7: 6 | C7: 맥문동 | E7: 4 | F7: =E7*$L$15 -> 40 | G7: =VLOOKUP($C7,약재관리!A:J,10,FALSE) -> 44.3 | H7: =G7*E7 -> 177.2 | I7: =G7*F7 -> 1772 | K7: 성별 | L7: F
B8: 7 | C8: 감초 | E8: 2 | F8: =E8*$L$15 -> 20 | G8: =VLOOKUP($C8,약재관리!A:J,10,FALSE) -> 28.3 | H8: =G8*E8 -> 56.6 | I8: =G8*F8 -> 566 | K8: 메모
B9: 8 | C9: 생강 | E9: 4 | F9: =E9*$L$15 -> 40 | G9: =VLOOKUP($C9,약재관리!A:J,10,FALSE) -> 15 | H9: =G9*E9 -> 60 | I9: =G9*F9 -> 600
B10: 9 | C10: 천궁1 | E10: 4 | F10: =E10*$L$15 -> 40 | G10: =VLOOKUP($C10,약재관리!A:J,10,FALSE) -> 10.8 | H10: =G10*E10 -> 43.2 | I10: =G10*F10 -> 432
B11: 10 | C11: 생지황 | E11: 4 | F11: =E11*$L$15 -> 40 | G11: =VLOOKUP($C11,약재관리!A:J,10,FALSE) -> 17.4 | H11: =G11*E11 -> 69.6 | I11: =G11*F11 -> 696
B12: 11 | C12: 사인 | E12: 3 | F12: =E12*$L$15 -> 30 | G12: =VLOOKUP($C12,약재관리!A:J,10,FALSE) -> 21.8 | H12: =G12*E12 -> 65.4 | I12: =G12*F12 -> 654
B13: 12 | C13: 황백 | E13: 2 | F13: =E13*$L$15 -> 20 | G13: =VLOOKUP($C13,약재관리!A:J,10,FALSE) -> 27.7 | H13: =G13*E13 -> 55.4 | I13: =G13*F13 -> 554
B14: 13 | C14: 감초 | E14: 2 | F14: =E14*$L$15 -> 20 | G14: =VLOOKUP($C14,약재관리!A:J,10,FALSE) -> 28.3 | H14: =G14*E14 -> 56.6 | I14: =G14*F14 -> 566 | K14: 총 일수 | L14: 10 | M14: 일분
B15: 14 | C15: 별갑 | E15: 4 | F15: =E15*$L$15 -> 40 | G15: =VLOOKUP($C15,약재관리!A:J,10,FALSE) -> 29.7 | H15: =G15*E15 -> 118.8 | I15: =G15*F15 -> 1188 | K15: 첩수 | L15: 10 | M15: 첩
B16: 15 | C16: 현호색 | E16: 4 | F16: =E16*$L$15 -> 40 | G16: =VLOOKUP($C16,약재관리!A:J,10,FALSE) -> 61.7 | H16: =G16*E16 -> 246.8 | I16: =G16*F16 -> 2468 | K16: 총 팩수 | L16: 20 | M16: 팩
B17: 16 | C17: 목단피 | E17: 4 | F17: =E17*$L$15 -> 40 | G17: =VLOOKUP($C17,약재관리!A:J,10,FALSE) -> 31.5 | H17: =G17*E17 -> 126 | I17: =G17*F17 -> 1260 | K17: 팩당 물량 | L17: 100 | M17: cc
B18: 17 | F18: =E18*$L$15 -> 0 | H18: =G18*E18 -> 0 | I18: =G18*F18 -> 0 | K18: 1첩당약재 | L18: =SUM(E2:E31) -> 59 | M18: g
B19: 18 | F19: =E19*$L$15 -> 0 | H19: =G19*E19 -> 0 | I19: =G19*F19 -> 0 | K19: 약재총량 | L19: =L15*L18 -> 590 | M19: g
B20: 19 | F20: =E20*$L$15 -> 0 | H20: =G20*E20 -> 0 | I20: =G20*F20 -> 0 | K20: 총 물 양 | L20: =L16*L17+L19 -> 2590 | M20: cc
B21: 20 | F21: =E21*$L$15 -> 0 | H21: =G21*E21 -> 0 | I21: =G21*F21 -> 0
B22: 21 | F22: =E22*$L$15 -> 0 | H22: =G22*E22 -> 0 | I22: =G22*F22 -> 0 | K22: 참고치
B23: 22 | F23: =E23*$L$15 -> 0 | H23: =G23*E23 -> 0 | I23: =G23*F23 -> 0 | K23: cross chk | L23: =SUM(F2:F31) -> 590 | M23: g
B24: 23 | F24: =E24*$L$15 -> 0 | H24: =G24*E24 -> 0 | I24: =G24*F24 -> 0 | K24: 20첩물양 | L24: 5000 | M24: cc
B25: 24 | F25: =E25*$L$15 -> 0 | H25: =G25*E25 -> 0 | I25: =G25*F25 -> 0 | K25: 1첩당 | L25: 80-120 | M25: g
B26: 25 | F26: =E26*$L$15 -> 0 | H26: =G26*E26 -> 0 | I26: =G26*F26 -> 0 | K26: 20첩당 | L26: 1600 | M26: g
B27: 26 | F27: =E27*$L$15 -> 0 | H27: =G27*E27 -> 0 | I27: =G27*F27 -> 0 | K27: 1돈 환산 | L27: 4 | M27: g
B28: 27 | F28: =E28*$L$15 -> 0 | H28: =G28*E28 -> 0 | I28: =G28*F28 -> 0
B29: 28 | F29: =E29*$L$15 -> 0 | H29: =G29*E29 -> 0 | I29: =G29*F29 -> 0 | K29: 금액
B30: 29 | F30: =E30*$L$15 -> 0 | H30: =G30*E30 -> 0 | I30: =G30*F30 -> 0 | K30: 1첩당 | L30: =SUM(H2:H31) -> 1503.6 | M30: 원
B31: 30 | F31: =E31*$L$15 -> 0 | H31: =G31*E31 -> 0 | I31: =G31*F31 -> 0 | K31: 총 | L31: =SUM(I2:I31) -> 15036 | M31: 원

Sheet 처방전양식
B1: No. | C1: 약재명 | D1: 수치 | E1: 그램 | F1: 총용량 | G1: 1g 금액 | H1: 1첩 금액 | I1: 총 금액 | K1: 기본 정보
B2: 1 | C2: 인삼 | E2: 4 | F2: =E2*$L$15 -> 40 | G2: =VLOOKUP($C2,약재관리!A:J,10,FALSE) -> 106.7 | H2: =G2*E2 -> 426.8 | I2: =G2*F2 -> 4268 | K2: UNIT | L2: 84
B3: 2 | C3: 백출 | E3: 6 | F3: =E3*$L$15 -> 60 | G3: =VLOOKUP($C3,약재관리!A:J,10,FALSE) -> 30.3 | H3: =G3*E3 -> 181.8 | I3: =G3*F3 -> 1818 | K3: 처방명 | L3: 보중익기탕가감
B4: 3 | C4: 진피1 | E4: 4 | F4: =E4*$L$15 -> 40 | G4: =VLOOKUP($C4,약재관리!A:J,10,FALSE) -> 17.6 | H4: =G4*E4 -> 70.4 | I4: =G4*F4 -> 704 | K4: 날짜 | L4: 45716
B5: 4 | C5: 감초 | E5: 4 | F5: =E5*$L$15 -> 40 | G5: =VLOOKUP($C5,약재관리!A:J,10,FALSE) -> 28.3 | H5: =G5*E5 -> 113.2 | I5: =G5*F5 -> 1132 | K5: 이름 | L5: 김수정
B6: 5 | C6: 황기 | E6: 6 | F6: =E6*$L$15 -> 60 | G6: =VLOOKUP($C6,약재관리!A:J,10,FALSE) -> 22 | H6: =G6*E6 -> 132 | I6: =G6*F6 -> 1320 | K6: 나이 | L6: 21
B7: 6 | C7: 당귀1 | E7: 4 | F7: =E7*$L$15 -> 40 | G7: =VLOOKUP($C7,약재관리!A:J,10,FALSE) -> 25.3 | H7: =G7*E7 -> 101.2 | I7: =G7*F7 -> 1012 | K7: 성별 | L7: F
B8: 7 | C8: 천궁1 | E8: 3 | F8: =E8*$L$15 -> 30 | G8: =VLOOKUP($C8,약재관리!A:J,10,FALSE) -> 10.8 | H8: =G8*E8 -> 32.4 | I8: =G8*F8 -> 324 | K8: 메모
B9: 8 | C9: 홍화 | E9: 2 | F9: =E9*$L$15 -> 20 | G9: =VLOOKUP($C9,약재관리!A:J,10,FALSE) -> 44.2 | H9: =G9*E9 -> 88.4 | I9: =G9*F9 -> 884 | K9: 보중익기탕+천궁, 홍화, 황백, 원육, 향부자, 목향
B10: 9 | C10: 시호2 | E10: 2 | F10: =E10*$L$15 -> 20 | G10: =VLOOKUP($C10,약재관리!A:J,10,FALSE) -> 15.3 | H10: =G10*E10 -> 30.6 | I10: =G10*F10 -> 306
B11: 10 | C11: 승마 | E11: 2 | F11: =E11*$L$15 -> 20 | G11: =VLOOKUP($C11,약재관리!A:J,10,FALSE) -> 34.7 | H11: =G11*E11 -> 69.4 | I11: =G11*F11 -> 694
B12: 11 | C12: 황백 | E12: 2 | F12: =E12*$L$15 -> 20 | G12: =VLOOKUP($C12,약재관리!A:J,10,FALSE) -> 27.7 | H12: =G12*E12 -> 55.4 | I12: =G12*F12 -> 554
B13: 12 | C13: 원육 | E13: 6 | F13: =E13*$L$15 -> 60 | G13: =VLOOKUP($C13,약재관리!A:J,10,FALSE) -> 19.2 | H13: =G13*E13 -> 115.2 | I13: =G13*F13 -> 1152
B14: 13 | C14: 향부자 | E14: 4 | F14: =E14*$L$15 -> 40 | G14: =VLOOKUP($C14,약재관리!A:J,10,FALSE) -> 14.7 | H14: =G14*E14 -> 58.8 | I14: =G14*F14 -> 588 | K14: 총 일수 | L14: 10 | M14: 일분
B15: 14 | C15: 목향 | E15: 2 | F15: =E15*$L$15 -> 20 | G15: =VLOOKUP($C15,약재관리!A:J,10,FALSE) -> 12.2 | H15: =G15*E15 -> 24.4 | I15: =G15*F15 -> 244 | K15: 첩수 | L15: 10 | M15: 첩
B16: 15 | F16: =E16*$L$15 -> 0 | H16: =G16*E16 -> 0 | I16: =G16*F16 -> 0 | K16: 총 팩수 | L16: 20 | M16: 팩
B17: 16 | F17: =E17*$L$15 -> 0 | H17: =G17*E17 -> 0 | I17: =G17*F17 -> 0 | K17: 팩당 물량 | L17: 100 | M17: cc
B18: 17 | F18: =E18*$L$15 -> 0 | H18: =G18*E18 -> 0 | I18: =G18*F18 -> 0 | K18: 1첩당약재 | L18: =SUM(E2:E31) -> 51 | M18: g
B19: 18 | F19: =E19*$L$15 -> 0 | H19: =G19*E19 -> 0 | I19: =G19*F19 -> 0 | K19: 약재총량 | L19: =L15*L18 -> 510 | M19: g
B20: 19 | F20: =E20*$L$15 -> 0 | H20: =G20*E20 -> 0 | I20: =G20*F20 -> 0 | K20: 총 물 양 | L20: =L16*L17+L19 -> 2510 | M20: cc
B21: 20 | F21: =E21*$L$15 -> 0 | H21: =G21*E21 -> 0 | I21: =G21*F21 -> 0
B22: 21 | F22: =E22*$L$15 -> 0 | H22: =G22*E22 -> 0 | I22: =G22*F22 -> 0 | K22: 참고치
B23: 22 | F23: =E23*$L$15 -> 0 | H23: =G23*E23 -> 0 | I23: =G23*F23 -> 0 | K23: cross chk | L23: =SUM(F2:F31) -> 510 | M23: g
B24: 23 | F24: =E24*$L$15 -> 0 | H24: =G24*E24 -> 0 | I24: =G24*F24 -> 0 | K24: 20첩물양 | L24: 5000 | M24: cc
B25: 24 | F25: =E25*$L$15 -> 0 | H25: =G25*E25 -> 0 | I25: =G25*F25 -> 0 | K25: 1첩당 | L25: 80-120 | M25: g
B26: 25 | F26: =E26*$L$15 -> 0 | H26: =G26*E26 -> 0 | I26: =G26*F26 -> 0 | K26: 20첩당 | L26: 1600 | M26: g
B27: 26 | F27: =E27*$L$15 -> 0 | H27: =G27*E27 -> 0 | I27: =G27*F27 -> 0 | K27: 1돈 환산 | L27: 4 | M27: g
B28: 27 | F28: =E28*$L$15 -> 0 | H28: =G28*E28 -> 0 | I28: =G28*F28 -> 0
B29: 28 | F29: =E29*$L$15 -> 0 | H29: =G29*E29 -> 0 | I29: =G29*F29 -> 0 | K29: 금액
B30: 29 | F30: =E30*$L$15 -> 0 | H30: =G30*E30 -> 0 | I30: =G30*F30 -> 0 | K30: 1첩당 | L30: =SUM(H2:H31) -> 1500 | M30: 원
B31: 30 | F31: =E31*$L$15 -> 0 | H31: =G31*E31 -> 0 | I31: =G31*F31 -> 0 | K31: 총 | L31: =SUM(I2:I31) -> 15000 | M31: 원

Sheet 약재관리
A1: 약재 이름 | B1: 옴니허브 | C1: 한퓨어 | D1: 신우한방 | E1: 바른한약 | F1: 옴니허브 | G1: 한퓨어 | H1: 신우한방 | I1: 바른한약 | J1: 최종 | K1: 옴니허브 | L1: 한퓨어 | M1: 신우한방 | N1: 바른한약
A2: 45674 | B2: 구입단가 | C2: 구입단가 | D2: 구입단가 | E2: 구입단가 | F2: 1g | G2: 1g | H2: 1g | I2: 1g | J2: 1g | K2: 500g | L2: 500g | M2: 600g | N2: 600g
A3: 갈근1 | B3: 9900 | C3: 9000 | D3: 10500 | E3: 9900 | F3: =B3/500 -> 19.8 | G3: =C3/500 -> 18 | H3: =D3/600 -> 17.5 | I3: =E3/600 -> 16.5 | J3: 16.5 | L3: 선일국산 | M3: 토 | N3: 퓨어마인드국산
A4: 갈근2 | C4: 2700 | F4: =B4/500 -> 0 | G4: =C4/500 -> 5.4 | H4: =D4/600 -> 0 | I4: =E4/600 -> 0 | L4: 이풀잎중국
A5: 감국 | F5: =B5/500 -> 0 | G5: =C5/500 -> 0 | H5: =D5/600 -> 0 | I5: =E5/600 -> 0
A6: 감수 | C6: 23400 | E6: 27100 | F6: =B6/500 -> 0 | G6: =C6/600 -> 39 | H6: =D6/600 -> 0 | I6: =E6/600 -> 45.166667 | J6: 45.2 | L6: 600g씨케이중국 | N6: 씨케이중국
A7: 감초 | B7: 15800 | D7: 17000 | E7: 25500 | F7: =B7/500 -> 31.6 | G7: =C7/500 -> 0 | H7: =D7/600 -> 28.333333 | I7: =E7/600 -> 42.5 | J7: 28.3 | M7: 양외2 | N7: 양외1
A8: 강활1 | B8: 27200 | C8: 20500 | D8: 24000 | F8: =B8/500 -> 54.4 | G8: =C8/500 -> 41 | H8: =D8/600 -> 40 | I8: =E8/600 -> 0 | J8: 40 | L8: 선일국산 | M8: 토
A9: 강활2 | C9: 18700 | D9: 21000 | E9: 23300 | F9: =B9/500 -> 0 | G9: =C9/500 -> 37.4 | H9: =D9/600 -> 35 | I9: =E9/600 -> 38.833333 | J9: 38.8 | L9: 태극인국산 | N9: 선일국산
A10: 강황 | C10: 3300 | D10: 5000 | F10: =B10/500 -> 0 | G10: =C10/500 -> 6.6 | H10: =D10/600 -> 8.3333333 | I10: =E10/600 -> 0 | J10: 8.3 | M10: 인도
A11: 건강 | C11: 5200 | D11: 8000 | E11: 5900 | F11: =B11/500 -> 0 | G11: =C11/500 -> 10.4 | H11: =D11/600 -> 13.333333 | I11: =E11/600 -> 9.8333333 | J11: 9.5 | L11: 페루 | N11: 페루
A12: 건율 | C12: 13500 | D12: 16500 | E12: 16700 | F12: =B12/500 -> 0 | G12: =C12/500 -> 27 | H12: =D12/600 -> 27.5 | I12: =E12/600 -> 27.833333 | J12: 27.5 | M12: 토 | N12: (절, 토)
A13: 건지황 | B13: 19900 | C13: 7200 | D13: 11000 | E13: 8900 | F13: =B13/500 -> 39.8 | G13: =C13/500 -> 14.4 | H13: =D13/600 -> 18.333333 | I13: =E13/600 -> 14.833333 | J13: 14.4 | L13: 허브팜중국
A14: 검인 | F14: =B14/500 -> 0 | G14: =C14/500 -> 0 | H14: =D14/600 -> 0 | I14: =E14/600 -> 0
A15: 결명자 | F15: =B15/500 -> 0 | G15: =C15/500 -> 0 | H15: =D15/600 -> 0 | I15: =E15/600 -> 0
A16: 계지 | B16: 4500 | C16: 2000 | D16: 3500 | E16: 2900 | F16: =B16/500 -> 9 | G16: =C16/500 -> 4 | H16: =D16/600 -> 5.8333333 | I16: =E16/600 -> 4.8333333 | J16: 4.8 | L16: 씨케이베트남 | M16: 세 | N16: 엔탭베트남
A17: 고량강 | C17: 10200 | E17: 11100 | F17: =B17/500 -> 0 | G17: =C17/600 -> 17 | H17: =D17/600 -> 0 | I17: =E17/600 -> 18.5 | J17: 17 | L17: 600g 씨케이중국 | N17: 씨케이중국
A18: 고본 | C18: 32000 | E18: 41600 | F18: =B18/500 -> 0 | G18: =C18/500 -> 64 | H18: =D18/600 -> 0 | I18: =E18/600 -> 69.333333 | J18: 64 | L18: 선일국산 | N18: 퓨어마인드국산
A19: 고삼 | C19: 4500 | F19: =B19/500 -> 0 | G19: =C19/500 -> 9 | H19: =D19/600 -> 0 | I19: =E19/600 -> 0 | J19: 9 | L19: 한솔중국
A20: 골쇄보 | F20: =B20/500 -> 0 | G20: =C20/500 -> 0 | H20: =D20/600 -> 0 | I20: =E20/600 -> 0
A21: 과루인 | C21: 3500 | D21: 6500 | F21: =B21/500 -> 0 | G21: =C21/500 -> 7 | H21: =D21/600 -> 10.833333 | I21: =E21/600 -> 0 | J21: 10.8 | M21: (추)
A22: 곽향1 | B22: 6900 | C22: 5600 | E22: 6900 | F22: =B22/500 -> 13.8 | G22: =C22/500 -> 11.2 | H22: =D22/600 -> 0 | I22: =E22/600 -> 11.5 | J22: 13.8 | L22: 선일국산 | N22: 씨케이국산
A23: 곽향2 | B23: 4600 | C23: 3500 | E23: 4800 | F23: =B23/500 -> 9.2 | G23: =C23/500 -> 7 | H23: =D23/600 -> 0 | I23: =E23/600 -> 8 | J23: 7 | K23: 인도네시아 | L23: 올본인도네시아 | N23: 엔탭인도네시아
A24: 관동화 | C24: 46000 | D24: 70000 | E24: 75400 | F24: =B24/500 -> 0 | G24: =C24/300 -> 153.33333 | H24: =D24/600 -> 116.66667 | I24: =E24/600 -> 125.66667 | J24: 116.7 | L24: 300g | N24: 엔탭중국
A25: 괴화 | F25: =B25/500 -> 0 | G25: =C25/500 -> 0 | H25: =D25/600 -> 0 | I25: =E25/600 -> 0
A26: 교이 | F26: =B26/500 -> 0 | G26: =C26/500 -> 0 | H26: =D26/600 -> 0 | I26: =E26/600 -> 0 | J26: 5.3
A27: 구기자 | B27: 14900 | C27: 8700 | D27: 9000 | E27: 8200 | F27: =B27/500 -> 29.8 | G27: =C27/500 -> 17.4 | H27: =D27/600 -> 15 | I27: =E27/600 -> 13.666667 | J27: 13.7 | N27: 엔탭중국영하
A28: 구맥 | F28: =B28/500 -> 0 | G28: =C28/500 -> 0 | H28: =D28/600 -> 0 | I28: =E28/600 -> 0
A29: 구척 | F29: =B29/500 -> 0 | G29: =C29/500 -> 0 | H29: =D29/600 -> 0 | I29: =E29/600 -> 0
A30: 귀판 | C30: 20500 | D30: 19000 | F30: =B30/500 -> 0 | G30: =C30/600 -> 34.166667 | H30: =D30/600 -> 31.666667 | I30: =E30/600 -> 0 | J30: 31.7 | L30: 600g추말/자연세상인도네시아
A31: 금은화 | C31: 21500 | E31: 30800 | F31: =B31/500 -> 0 | G31: =C31/500 -> 43 | H31: =D31/600 -> 0 | I31: =E31/600 -> 51.333333 | J31: 44 | L31: 한솔중국 | N31: 엔탭중국
A32: 길경 | B32: 11500 | C32: 12900 | D32: 7500 | E32: 6900 | F32: =B32/500 -> 23 | G32: =C32/500 -> 25.8 | H32: =D32/600 -> 12.5 | I32: =E32/600 -> 11.5 | J32: 11.5 | K32: (중국4-5년) | L32: 선일국산 | M32: (편) | N32: 엔탭중국야생3년
A33: 나복자 | C33: 3000 | D33: 4000 | F33: =B33/500 -> 0 | G33: =C33/500 -> 6 | H33: =D33/600 -> 6.6666667 | I33: =E33/600 -> 0 | J33: 6.7 | L33: 올본인도/추말 | M33: 추
A34: 남성 | C34: 13000 | D34: 13000 | F34: =B34/500 -> 0 | G34: =C34/500 -> 26 | H34: =D34/500 -> 26 | I34: =E34/600 -> 0 | J34: 26 | L34: 생강백반제/신흥중국 | M34: 500g생강백반제/신흥중국
A35: 녹용 | C35: 278000 | F35: =B35/500 -> 0 | G35: =C35/600 -> 463.33333 | H35: =D35/600 -> 0 | I35: =E35/600 -> 0 | J35: 463.3 | L35: 600g
A36: 단삼 | C36: 6600 | E36: 8900 | F36: =B36/500 -> 0 | G36: =C36/500 -> 13.2 | H36: =D36/600 -> 0 | I36: =E36/600 -> 14.833333 | J36: 14.8 | L36: 허브팜중국 | N36: 엔탭중국
A37: 담두시 | D37: 8000 | F37: =B37/500 -> 0 | G37: =C37/500 -> 0 | H37: =D37/600 -> 13.333333 | I37: =E37/600 -> 0 | J37: 13.3
A38: 당귀1 | B38: 14900 | C38: 12700 | D38: 15000 | E38: 15200 | F38: =B38/500 -> 29.8 | G38: =C38/500 -> 25.4 | H38: =D38/600 -> 25 | I38: =E38/600 -> 25.333333 | J38: 25.3 | L38: 선일국산 | N38: 선일국산
A39: 당귀2 | C39: 12700 | E39: 13800 | F39: =B39/500 -> 0 | G39: =C39/500 -> 25.4 | H39: =D39/600 -> 0 | I39: =E39/600 -> 23 | J39: 23 | L39: 선일국산 | N39: 선일국산
A40: 당삼 | C40: 26000 | D40: 32000 | E40: 35500 | F40: =B40/500 -> 0 | G40: =C40/600 -> 43.333333 | H40: =D40/600 -> 53.333333 | I40: =E40/600 -> 59.166667 | J40: 43.3 | L40: 600g씨케이중국 | N40: 엔탭중국
...
