Workbook

Sheet 처방전양식 (12)
B1: No. | C1: 약재명 | D1: 수치 | E1: 그램 | F1: 총용량 | G1: 1g 금액 | H1: 1첩 금액 | I1: 총 금액 | K1: 기본 정보
B2: 1 | C2: 향부자 | E2: 8 | F2: =E2*$L$15 -> 160 | G2: =VLOOKUP($C2,[1]약재관리!$A:$J,10,FALSE) -> 14.7 | H2: =G2*E2 -> 117.6 | I2: =G2*F2 -> 2352 | K2: UNIT | L2: 85
B3: 2 | C3: 숙지황 | E3: 6 | F3: =E3*$L$15 -> 120 | G3: =VLOOKUP($C3,[1]약재관리!$A:$J,10,FALSE) -> 20 | H3: =G3*E3 -> 120 | I3: =G3*F3 -> 2400 | K3: 처방명 | L3: 조경종옥탕
B4: 3 | C4: 당귀1 | E4: 6 | F4: =E4*$L$15 -> 120 | G4: =VLOOKUP($C4,[1]약재관리!$A:$J,10,FALSE) -> 31.7 | H4: =G4*E4 -> 190.2 | I4: =G4*F4 -> 3804 | K4: 날짜 | L4: 46155
B5: 4 | C5: 천궁1 | E5: 4 | F5: =E5*$L$15 -> 80 | G5: =VLOOKUP($C5,[1]약재관리!$A:$J,10,FALSE) -> 10.8 | H5: =G5*E5 -> 43.2 | I5: =G5*F5 -> 864 | K5: 이름 | L5: 차현아
B6: 5 | C6: 백작약 | E6: 4 | F6: =E6*$L$15 -> 80 | G6: =VLOOKUP($C6,[1]약재관리!$A:$J,10,FALSE) -> 19.6 | H6: =G6*E6 -> 78.4 | I6: =G6*F6 -> 1568 | K6: 나이 | L6: 42
B7: 6 | C7: 오수유 | E7: 4 | F7: =E7*$L$15 -> 80 | G7: =VLOOKUP($C7,[1]약재관리!$A:$J,10,FALSE) -> 15.2 | H7: =G7*E7 -> 60.8 | I7: =G7*F7 -> 1216 | K7: 성별 | L7: F
B8: 7 | C8: 진피1 | E8: 4 | F8: =E8*$L$15 -> 80 | G8: =VLOOKUP($C8,[1]약재관리!$A:$J,10,FALSE) -> 17.6 | H8: =G8*E8 -> 70.4 | I8: =G8*F8 -> 1408 | K8: 메모
B9: 8 | C9: 복령 | E9: 4 | F9: =E9*$L$15 -> 80 | G9: =VLOOKUP($C9,[1]약재관리!$A:$J,10,FALSE) -> 8.7 | H9: =G9*E9 -> 34.8 | I9: =G9*F9 -> 696 | K9: 조경종옥탕 + 황기 인삼 백출 목향 후박 지각 삼사
B10: 9 | C10: 후박 | E10: 6 | F10: =E10*$L$15 -> 120 | G10: =VLOOKUP($C10,[1]약재관리!$A:$J,10,FALSE) -> 8.8 | H10: =G10*E10 -> 52.8 | I10: =G10*F10 -> 1056
B11: 10 | C11: 목단피 | E11: 3 | F11: =E11*$L$15 -> 60 | G11: =VLOOKUP($C11,[1]약재관리!$A:$J,10,FALSE) -> 33.7 | H11: =G11*E11 -> 101.1 | I11: =G11*F11 -> 2022
B12: 11 | C12: 건강 | E12: 3 | F12: =E12*$L$15 -> 60 | G12: =VLOOKUP($C12,[1]약재관리!$A:$J,10,FALSE) -> 9.5 | H12: =G12*E12 -> 28.5 | I12: =G12*F12 -> 570
B13: 12 | C13: 육계 | E13: 2 | F13: =E13*$L$15 -> 40 | G13: =VLOOKUP($C13,[1]약재관리!$A:$J,10,FALSE) -> 14.8 | H13: =G13*E13 -> 29.6 | I13: =G13*F13 -> 592
B14: 13 | C14: 애엽 | E14: 2 | F14: =E14*$L$15 -> 40 | G14: =VLOOKUP($C14,[1]약재관리!$A:$J,10,FALSE) -> 24.7 | H14: =G14*E14 -> 49.4 | I14: =G14*F14 -> 988 | K14: 총 일수 | L14: 20 | M14: 일분
B15: 14 | C15: 생강 | E15: 4 | F15: =E15*$L$15 -> 80 | G15: =VLOOKUP($C15,[1]약재관리!$A:$J,10,FALSE) -> 20 | H15: =G15*E15 -> 80 | I15: =G15*F15 -> 1600 | K15: 첩수 | L15: 20 | M15: 첩
B16: 15 | C16: 황기 | E16: 8 | F16: =E16*$L$15 -> 160 | G16: =VLOOKUP($C16,[1]약재관리!$A:$J,10,FALSE) -> 16.8 | H16: =G16*E16 -> 134.4 | I16: =G16*F16 -> 2688 | K16: 총 팩수 | L16: 46 | M16: 팩
B17: 16 | C17: 인삼 | E17: 4 | F17: =E17*$L$15 -> 80 | G17: =VLOOKUP($C17,[1]약재관리!$A:$J,10,FALSE) -> 120 | H17: =G17*E17 -> 480 | I17: =G17*F17 -> 9600 | K17: 팩당 물량 | L17: 110 | M17: cc
B18: 17 | C18: 백출 | E18: 6 | F18: =E18*$L$15 -> 120 | G18: =VLOOKUP($C18,[1]약재관리!$A:$J,10,FALSE) -> 13 | H18: =G18*E18 -> 78 | I18: =G18*F18 -> 1560 | K18: 1첩당약재 | L18: =SUM(E2:E31) -> 97 | M18: g
B19: 18 | C19: 녹용 | E19: 2 | F19: =E19*$L$15 -> 40 | G19: =VLOOKUP($C19,[1]약재관리!$A:$J,10,FALSE) -> 550 | H19: =G19*E19 -> 1100 | I19: =G19*F19 -> 22000 | K19: 약재총량 | L19: =L15*L18 -> 1940 | M19: g
B20: 19 | C20: 목향 | E20: 4 | F20: =E20*$L$15 -> 80 | G20: =VLOOKUP($C20,[1]약재관리!$A:$J,10,FALSE) -> 12.2 | H20: =G20*E20 -> 48.8 | I20: =G20*F20 -> 976 | K20: 총 물 양 | L20: =L16*L17+L19*1.3+400 -> 7982 | M20: cc
B21: 20 | C21: 지각 | E21: 4 | F21: =E21*$L$15 -> 80 | G21: =VLOOKUP($C21,[1]약재관리!$A:$J,10,FALSE) -> 10 | H21: =G21*E21 -> 40 | I21: =G21*F21 -> 800
B22: 21 | C22: 신곡 | E22: 3 | F22: =E22*$L$15 -> 60 | G22: =VLOOKUP($C22,[1]약재관리!$A:$J,10,FALSE) -> 8 | H22: =G22*E22 -> 24 | I22: =G22*F22 -> 480 | K22: 참고치
B23: 22 | C23: 맥아 | E23: 3 | F23: =E23*$L$15 -> 60 | G23: =VLOOKUP($C23,[1]약재관리!$A:$J,10,FALSE) -> 7.5 | H23: =G23*E23 -> 22.5 | I23: =G23*F23 -> 450 | K23: cross chk | L23: =SUM(F2:F31) -> 1940 | M23: g
B24: 23 | C24: 산사 | E24: 3 | F24: =E24*$L$15 -> 60 | G24: =VLOOKUP($C24,[1]약재관리!$A:$J,10,FALSE) -> 7 | H24: =G24*E24 -> 21 | I24: =G24*F24 -> 420 | K24: 20첩물양 | L24: 5000 | M24: cc
B25: 24 | F25: =E25*$L$15 -> 0 | H25: =G25*E25 -> 0 | I25: =G25*F25 -> 0 | K25: 1첩당 | L25: 80-120 | M25: g
B26: 25 | F26: =E26*$L$15 -> 0 | H26: =G26*E26 -> 0 | I26: =G26*F26 -> 0 | K26: 20첩당 | L26: 1600 | M26: g
B27: 26 | F27: =E27*$L$15 -> 0 | H27: =G27*E27 -> 0 | I27: =G27*F27 -> 0 | K27: 1돈 환산 | L27: 4 | M27: g
B28: 27 | F28: =E28*$L$15 -> 0 | H28: =G28*E28 -> 0 | I28: =G28*F28 -> 0
B29: 28 | F29: =E29*$L$15 -> 0 | H29: =G29*E29 -> 0 | I29: =G29*F29 -> 0 | K29: 금액
B30: 29 | F30: =E30*$L$15 -> 0 | H30: =G30*E30 -> 0 | I30: =G30*F30 -> 0 | K30: 1첩당 | L30: =SUM(H2:H31) -> 3005.5 | M30: 원
B31: 30 | F31: =E31*$L$15 -> 0 | H31: =G31*E31 -> 0 | I31: =G31*F31 -> 0 | K31: 총 | L31: =SUM(I2:I31) -> 60110 | M31: 원

Sheet 처방전양식 (11)
B1: No. | C1: 약재명 | D1: 수치 | E1: 그램 | F1: 총용량 | G1: 1g 금액 | H1: 1첩 금액 | I1: 총 금액 | K1: 기본 정보
B2: 1 | C2: 향부자 | E2: 8 | F2: =E2*$L$15 -> 160 | G2: =VLOOKUP($C2,[1]약재관리!$A:$J,10,FALSE) -> 14.7 | H2: =G2*E2 -> 117.6 | I2: =G2*F2 -> 2352 | K2: UNIT | L2: 85
B3: 2 | C3: 숙지황 | E3: 6 | F3: =E3*$L$15 -> 120 | G3: =VLOOKUP($C3,[1]약재관리!$A:$J,10,FALSE) -> 20 | H3: =G3*E3 -> 120 | I3: =G3*F3 -> 2400 | K3: 처방명 | L3: 조경종옥탕
B4: 3 | C4: 당귀1 | E4: 6 | F4: =E4*$L$15 -> 120 | G4: =VLOOKUP($C4,[1]약재관리!$A:$J,10,FALSE) -> 31.7 | H4: =G4*E4 -> 190.2 | I4: =G4*F4 -> 3804 | K4: 날짜 | L4: 46132
B5: 4 | C5: 천궁1 | E5: 4 | F5: =E5*$L$15 -> 80 | G5: =VLOOKUP($C5,[1]약재관리!$A:$J,10,FALSE) -> 10.8 | H5: =G5*E5 -> 43.2 | I5: =G5*F5 -> 864 | K5: 이름 | L5: 차현아
B6: 5 | C6: 백작약 | E6: 4 | F6: =E6*$L$15 -> 80 | G6: =VLOOKUP($C6,[1]약재관리!$A:$J,10,FALSE) -> 19.6 | H6: =G6*E6 -> 78.4 | I6: =G6*F6 -> 1568 | K6: 나이 | L6: 42
B7: 6 | C7: 오수유 | E7: 4 | F7: =E7*$L$15 -> 80 | G7: =VLOOKUP($C7,[1]약재관리!$A:$J,10,FALSE) -> 15.2 | H7: =G7*E7 -> 60.8 | I7: =G7*F7 -> 1216 | K7: 성별 | L7: F
B8: 7 | C8: 진피1 | E8: 4 | F8: =E8*$L$15 -> 80 | G8: =VLOOKUP($C8,[1]약재관리!$A:$J,10,FALSE) -> 17.6 | H8: =G8*E8 -> 70.4 | I8: =G8*F8 -> 1408 | K8: 메모
B9: 8 | C9: 복령 | E9: 6 | F9: =E9*$L$15 -> 120 | G9: =VLOOKUP($C9,[1]약재관리!$A:$J,10,FALSE) -> 8.7 | H9: =G9*E9 -> 52.2 | I9: =G9*F9 -> 1044 | K9: 조경종옥탕 + 황기 인삼 백출 목향 후박 지각 곽향 사인
B10: 9 | C10: 후박 | E10: 6 | F10: =E10*$L$15 -> 120 | G10: =VLOOKUP($C10,[1]약재관리!$A:$J,10,FALSE) -> 8.8 | H10: =G10*E10 -> 52.8 | I10: =G10*F10 -> 1056
B11: 10 | C11: 목단피 | E11: 3 | F11: =E11*$L$15 -> 60 | G11: =VLOOKUP($C11,[1]약재관리!$A:$J,10,FALSE) -> 33.7 | H11: =G11*E11 -> 101.1 | I11: =G11*F11 -> 2022
B12: 11 | C12: 건강 | E12: 3 | F12: =E12*$L$15 -> 60 | G12: =VLOOKUP($C12,[1]약재관리!$A:$J,10,FALSE) -> 9.5 | H12: =G12*E12 -> 28.5 | I12: =G12*F12 -> 570
B13: 12 | C13: 육계 | E13: 2 | F13: =E13*$L$15 -> 40 | G13: =VLOOKUP($C13,[1]약재관리!$A:$J,10,FALSE) -> 14.8 | H13: =G13*E13 -> 29.6 | I13: =G13*F13 -> 592
B14: 13 | C14: 애엽 | E14: 2 | F14: =E14*$L$15 -> 40 | G14: =VLOOKUP($C14,[1]약재관리!$A:$J,10,FALSE) -> 24.7 | H14: =G14*E14 -> 49.4 | I14: =G14*F14 -> 988 | K14: 총 일수 | L14: 20 | M14: 일분
B15: 14 | C15: 생강 | E15: 4 | F15: =E15*$L$15 -> 80 | G15: =VLOOKUP($C15,[1]약재관리!$A:$J,10,FALSE) -> 20 | H15: =G15*E15 -> 80 | I15: =G15*F15 -> 1600 | K15: 첩수 | L15: 20 | M15: 첩
B16: 15 | C16: 황기 | E16: 8 | F16: =E16*$L$15 -> 160 | G16: =VLOOKUP($C16,[1]약재관리!$A:$J,10,FALSE) -> 16.8 | H16: =G16*E16 -> 134.4 | I16: =G16*F16 -> 2688 | K16: 총 팩수 | L16: 46 | M16: 팩
B17: 16 | C17: 인삼 | E17: 4 | F17: =E17*$L$15 -> 80 | G17: =VLOOKUP($C17,[1]약재관리!$A:$J,10,FALSE) -> 120 | H17: =G17*E17 -> 480 | I17: =G17*F17 -> 9600 | K17: 팩당 물량 | L17: 110 | M17: cc
B18: 17 | C18: 백출 | E18: 6 | F18: =E18*$L$15 -> 120 | G18: =VLOOKUP($C18,[1]약재관리!$A:$J,10,FALSE) -> 13 | H18: =G18*E18 -> 78 | I18: =G18*F18 -> 1560 | K18: 1첩당약재 | L18: =SUM(E2:E31) -> 96 | M18: g
B19: 18 | C19: 녹용 | E19: 2 | F19: =E19*$L$15 -> 40 | G19: =VLOOKUP($C19,[1]약재관리!$A:$J,10,FALSE) -> 550 | H19: =G19*E19 -> 1100 | I19: =G19*F19 -> 22000 | K19: 약재총량 | L19: =L15*L18 -> 1920 | M19: g
B20: 19 | C20: 목향 | E20: 4 | F20: =E20*$L$15 -> 80 | G20: =VLOOKUP($C20,[1]약재관리!$A:$J,10,FALSE) -> 12.2 | H20: =G20*E20 -> 48.8 | I20: =G20*F20 -> 976 | K20: 총 물 양 | L20: =L16*L17+L19*1.3+400 -> 7956 | M20: cc
B21: 20 | C21: 지각 | E21: 4 | F21: =E21*$L$15 -> 80 | G21: =VLOOKUP($C21,[1]약재관리!$A:$J,10,FALSE) -> 10 | H21: =G21*E21 -> 40 | I21: =G21*F21 -> 800
B22: 21 | C22: 곽향1 | E22: 4 | F22: =E22*$L$15 -> 80 | G22: =VLOOKUP($C22,[1]약재관리!$A:$J,10,FALSE) -> 13.8 | H22: =G22*E22 -> 55.2 | I22: =G22*F22 -> 1104 | K22: 참고치
B23: 22 | C23: 사인 | E23: 2 | F23: =E23*$L$15 -> 40 | G23: =VLOOKUP($C23,[1]약재관리!$A:$J,10,FALSE) -> 21.8 | H23: =G23*E23 -> 43.6 | I23: =G23*F23 -> 872 | K23: cross chk | L23: =SUM(F2:F31) -> 1920 | M23: g
B24: 23 | F24: =E24*$L$15 -> 0 | H24: =G24*E24 -> 0 | I24: =G24*F24 -> 0 | K24: 20첩물양 | L24: 5000 | M24: cc
B25: 24 | F25: =E25*$L$15 -> 0 | H25: =G25*E25 -> 0 | I25: =G25*F25 -> 0 | K25: 1첩당 | L25: 80-120 | M25: g
B26: 25 | F26: =E26*$L$15 -> 0 | H26: =G26*E26 -> 0 | I26: =G26*F26 -> 0 | K26: 20첩당 | L26: 1600 | M26: g
B27: 26 | F27: =E27*$L$15 -> 0 | H27: =G27*E27 -> 0 | I27: =G27*F27 -> 0 | K27: 1돈 환산 | L27: 4 | M27: g
B28: 27 | F28: =E28*$L$15 -> 0 | H28: =G28*E28 -> 0 | I28: =G28*F28 -> 0
B29: 28 | F29: =E29*$L$15 -> 0 | H29: =G29*E29 -> 0 | I29: =G29*F29 -> 0 | K29: 금액
B30: 29 | F30: =E30*$L$15 -> 0 | H30: =G30*E30 -> 0 | I30: =G30*F30 -> 0 | K30: 1첩당 | L30: =SUM(H2:H31) -> 3054.2 | M30: 원
B31: 30 | F31: =E31*$L$15 -> 0 | H31: =G31*E31 -> 0 | I31: =G31*F31 -> 0 | K31: 총 | L31: =SUM(I2:I31) -> 61084 | M31: 원

Sheet 처방전양식 (10)
B1: No. | C1: 약재명 | D1: 수치 | E1: 그램 | F1: 총용량 | G1: 1g 금액 | H1: 1첩 금액 | I1: 총 금액 | K1: 기본 정보
B2: 1 | C2: 향부자 | E2: 8 | F2: =E2*$L$15 -> 160 | G2: =VLOOKUP($C2,[1]약재관리!$A:$J,10,FALSE) -> 14.7 | H2: =G2*E2 -> 117.6 | I2: =G2*F2 -> 2352 | K2: UNIT | L2: 85
B3: 2 | C3: 숙지황 | E3: 6 | F3: =E3*$L$15 -> 120 | G3: =VLOOKUP($C3,[1]약재관리!$A:$J,10,FALSE) -> 20 | H3: =G3*E3 -> 120 | I3: =G3*F3 -> 2400 | K3: 처방명 | L3: 조경종옥탕
B4: 3 | C4: 당귀1 | E4: 6 | F4: =E4*$L$15 -> 120 | G4: =VLOOKUP($C4,[1]약재관리!$A:$J,10,FALSE) -> 31.7 | H4: =G4*E4 -> 190.2 | I4: =G4*F4 -> 3804 | K4: 날짜 | L4: 46094
B5: 4 | C5: 천궁1 | E5: 4 | F5: =E5*$L$15 -> 80 | G5: =VLOOKUP($C5,[1]약재관리!$A:$J,10,FALSE) -> 10.8 | H5: =G5*E5 -> 43.2 | I5: =G5*F5 -> 864 | K5: 이름 | L5: 차현아
B6: 5 | C6: 백작약 | E6: 4 | F6: =E6*$L$15 -> 80 | G6: =VLOOKUP($C6,[1]약재관리!$A:$J,10,FALSE) -> 19.6 | H6: =G6*E6 -> 78.4 | I6: =G6*F6 -> 1568 | K6: 나이 | L6: 42
B7: 6 | C7: 오수유 | E7: 4 | F7: =E7*$L$15 -> 80 | G7: =VLOOKUP($C7,[1]약재관리!$A:$J,10,FALSE) -> 15.2 | H7: =G7*E7 -> 60.8 | I7: =G7*F7 -> 1216 | K7: 성별 | L7: F
B8: 7 | C8: 진피1 | E8: 4 | F8: =E8*$L$15 -> 80 | G8: =VLOOKUP($C8,[1]약재관리!$A:$J,10,FALSE) -> 17.6 | H8: =G8*E8 -> 70.4 | I8: =G8*F8 -> 1408 | K8: 메모
B9: 8 | C9: 복령 | E9: 6 | F9: =E9*$L$15 -> 120 | G9: =VLOOKUP($C9,[1]약재관리!$A:$J,10,FALSE) -> 8.7 | H9: =G9*E9 -> 52.2 | I9: =G9*F9 -> 1044 | K9: 조경종옥탕 + 구기자 음양곽 토사자 창출 반하 목향 - 현호색
B10: 9 | F10: =E10*$L$15 -> 0 | H10: =G10*E10 -> 0 | I10: =G10*F10 -> 0
B11: 10 | C11: 목단피 | E11: 4 | F11: =E11*$L$15 -> 80 | G11: =VLOOKUP($C11,[1]약재관리!$A:$J,10,FALSE) -> 33.7 | H11: =G11*E11 -> 134.8 | I11: =G11*F11 -> 2696
B12: 11 | C12: 건강 | E12: 3 | F12: =E12*$L$15 -> 60 | G12: =VLOOKUP($C12,[1]약재관리!$A:$J,10,FALSE) -> 9.5 | H12: =G12*E12 -> 28.5 | I12: =G12*F12 -> 570
B13: 12 | C13: 육계 | E13: 2 | F13: =E13*$L$15 -> 40 | G13: =VLOOKUP($C13,[1]약재관리!$A:$J,10,FALSE) -> 14.8 | H13: =G13*E13 -> 29.6 | I13: =G13*F13 -> 592
B14: 13 | C14: 애엽 | E14: 2 | F14: =E14*$L$15 -> 40 | G14: =VLOOKUP($C14,[1]약재관리!$A:$J,10,FALSE) -> 24.7 | H14: =G14*E14 -> 49.4 | I14: =G14*F14 -> 988 | K14: 총 일수 | L14: 15 | M14: 일분
B15: 14 | C15: 생강 | E15: 4 | F15: =E15*$L$15 -> 80 | G15: =VLOOKUP($C15,[1]약재관리!$A:$J,10,FALSE) -> 20 | H15: =G15*E15 -> 80 | I15: =G15*F15 -> 1600 | K15: 첩수 | L15: 20 | M15: 첩
B16: 15 | C16: 목향 | E16: 4 | F16: =E16*$L$15 -> 80 | G16: =VLOOKUP($C16,[1]약재관리!$A:$J,10,FALSE) -> 12.2 | H16: =G16*E16 -> 48.8 | I16: =G16*F16 -> 976 | K16: 총 팩수 | L16: 32 | M16: 팩
B17: 16 | C17: 창출1 | E17: 4 | F17: =E17*$L$15 -> 80 | G17: =VLOOKUP($C17,[1]약재관리!$A:$J,10,FALSE) -> 25 | H17: =G17*E17 -> 100 | I17: =G17*F17 -> 2000 | K17: 팩당 물량 | L17: 100 | M17: cc
B18: 17 | C18: 반하 | E18: 4 | F18: =E18*$L$15 -> 80 | G18: =VLOOKUP($C18,[1]약재관리!$A:$J,10,FALSE) -> 41 | H18: =G18*E18 -> 164 | I18: =G18*F18 -> 3280 | K18: 1첩당약재 | L18: =SUM(E2:E31) -> 89 | M18: g
B19: 18 | C19: 구기자 | E19: 6 | F19: =E19*$L$15 -> 120 | G19: =VLOOKUP($C19,[1]약재관리!$A:$J,10,FALSE) -> 13.7 | H19: =G19*E19 -> 82.2 | I19: =G19*F19 -> 1644 | K19: 약재총량 | L19: =L15*L18 -> 1780 | M19: g
B20: 19 | C20: 음양곽 | E20: 6 | F20: =E20*$L$15 -> 120 | G20: =VLOOKUP($C20,[1]약재관리!$A:$J,10,FALSE) -> 31 | H20: =G20*E20 -> 186 | I20: =G20*F20 -> 3720 | K20: 총 물 양 | L20: =L16*L17+L19*1.3+400 -> 5914 | M20: cc
B21: 20 | C21: 토사자 | E21: 8 | F21: =E21*$L$15 -> 160 | G21: =VLOOKUP($C21,[1]약재관리!$A:$J,10,FALSE) -> 17.2 | H21: =G21*E21 -> 137.6 | I21: =G21*F21 -> 2752
B22: 21 | F22: =E22*$L$15 -> 0 | H22: =G22*E22 -> 0 | I22: =G22*F22 -> 0 | K22: 참고치
B23: 22 | F23: =E23*$L$15 -> 0 | H23: =G23*E23 -> 0 | I23: =G23*F23 -> 0 | K23: cross chk | L23: =SUM(F2:F31) -> 1780 | M23: g
B24: 23 | F24: =E24*$L$15 -> 0 | H24: =G24*E24 -> 0 | I24: =G24*F24 -> 0 | K24: 20첩물양 | L24: 5000 | M24: cc
B25: 24 | F25: =E25*$L$15 -> 0 | H25: =G25*E25 -> 0 | I25: =G25*F25 -> 0 | K25: 1첩당 | L25: 80-120 | M25: g
B26: 25 | F26: =E26*$L$15 -> 0 | H26: =G26*E26 -> 0 | I26: =G26*F26 -> 0 | K26: 20첩당 | L26: 1600 | M26: g
B27: 26 | F27: =E27*$L$15 -> 0 | H27: =G27*E27 -> 0 | I27: =G27*F27 -> 0 | K27: 1돈 환산 | L27: 4 | M27: g
B28: 27 | F28: =E28*$L$15 -> 0 | H28: =G28*E28 -> 0 | I28: =G28*F28 -> 0
B29: 28 | F29: =E29*$L$15 -> 0 | H29: =G29*E29 -> 0 | I29: =G29*F29 -> 0 | K29: 금액
B30: 29 | F30: =E30*$L$15 -> 0 | H30: =G30*E30 -> 0 | I30: =G30*F30 -> 0 | K30: 1첩당 | L30: =SUM(H2:H31) -> 1773.7 | M30: 원
B31: 30 | F31: =E31*$L$15 -> 0 | H31: =G31*E31 -> 0 | I31: =G31*F31 -> 0 | K31: 총 | L31: =SUM(I2:I31) -> 35474 | M31: 원

Sheet 처방전양식 (9)
B1: No. | C1: 약재명 | D1: 수치 | E1: 그램 | F1: 총용량 | G1: 1g 금액 | H1: 1첩 금액 | I1: 총 금액 | K1: 기본 정보
B2: 1 | C2: 향부자 | E2: 8 | F2: =E2*$L$15 -> 160 | G2: =VLOOKUP($C2,[1]약재관리!$A:$J,10,FALSE) -> 14.7 | H2: =G2*E2 -> 117.6 | I2: =G2*F2 -> 2352 | K2: UNIT | L2: 85
B3: 2 | C3: 숙지황 | E3: 6 | F3: =E3*$L$15 -> 120 | G3: =VLOOKUP($C3,[1]약재관리!$A:$J,10,FALSE) -> 20 | H3: =G3*E3 -> 120 | I3: =G3*F3 -> 2400 | K3: 처방명 | L3: 조경종옥탕
B4: 3 | C4: 당귀1 | E4: 6 | F4: =E4*$L$15 -> 120 | G4: =VLOOKUP($C4,[1]약재관리!$A:$J,10,FALSE) -> 31.7 | H4: =G4*E4 -> 190.2 | I4: =G4*F4 -> 3804 | K4: 날짜 | L4: 46017
B5: 4 | C5: 천궁1 | E5: 4 | F5: =E5*$L$15 -> 80 | G5: =VLOOKUP($C5,[1]약재관리!$A:$J,10,FALSE) -> 10.8 | H5: =G5*E5 -> 43.2 | I5: =G5*F5 -> 864 | K5: 이름 | L5: 차현아
B6: 5 | C6: 백작약 | E6: 4 | F6: =E6*$L$15 -> 80 | G6: =VLOOKUP($C6,[1]약재관리!$A:$J,10,FALSE) -> 19.6 | H6: =G6*E6 -> 78.4 | I6: =G6*F6 -> 1568 | K6: 나이 | L6: 42
B7: 6 | C7: 오수유 | E7: 4 | F7: =E7*$L$15 -> 80 | G7: =VLOOKUP($C7,[1]약재관리!$A:$J,10,FALSE) -> 15.2 | H7: =G7*E7 -> 60.8 | I7: =G7*F7 -> 1216 | K7: 성별 | L7: F
B8: 7 | C8: 진피1 | E8: 4 | F8: =E8*$L$15 -> 80 | G8: =VLOOKUP($C8,[1]약재관리!$A:$J,10,FALSE) -> 17.6 | H8: =G8*E8 -> 70.4 | I8: =G8*F8 -> 1408 | K8: 메모
B9: 8 | C9: 복령 | E9: 6 | F9: =E9*$L$15 -> 120 | G9: =VLOOKUP($C9,[1]약재관리!$A:$J,10,FALSE) -> 8.7 | H9: =G9*E9 -> 52.2 | I9: =G9*F9 -> 1044 | K9: 조경종옥탕 + 황기 인삼 백출 목향 구기자 음양곽 저근백피
B10: 9 | C10: 현호색 | E10: 3 | F10: =E10*$L$15 -> 60 | G10: =VLOOKUP($C10,[1]약재관리!$A:$J,10,FALSE) -> 59.7 | H10: =G10*E10 -> 179.1 | I10: =G10*F10 -> 3582
B11: 10 | C11: 목단피 | E11: 3 | F11: =E11*$L$15 -> 60 | G11: =VLOOKUP($C11,[1]약재관리!$A:$J,10,FALSE) -> 33.7 | H11: =G11*E11 -> 101.1 | I11: =G11*F11 -> 2022
B12: 11 | C12: 건강 | E12: 3 | F12: =E12*$L$15 -> 60 | G12: =VLOOKUP($C12,[1]약재관리!$A:$J,10,FALSE) -> 9.5 | H12: =G12*E12 -> 28.5 | I12: =G12*F12 -> 570
B13: 12 | C13: 육계 | E13: 2 | F13: =E13*$L$15 -> 40 | G13: =VLOOKUP($C13,[1]약재관리!$A:$J,10,FALSE) -> 14.8 | H13: =G13*E13 -> 29.6 | I13: =G13*F13 -> 592
B14: 13 | C14: 애엽 | E14: 2 | F14: =E14*$L$15 -> 40 | G14: =VLOOKUP($C14,[1]약재관리!$A:$J,10,FALSE) -> 24.7 | H14: =G14*E14 -> 49.4 | I14: =G14*F14 -> 988 | K14: 총 일수 | L14: 15 | M14: 일분
B15: 14 | C15: 생강 | E15: 4 | F15: =E15*$L$15 -> 80 | G15: =VLOOKUP($C15,[1]약재관리!$A:$J,10,FALSE) -> 20 | H15: =G15*E15 -> 80 | I15: =G15*F15 -> 1600 | K15: 첩수 | L15: 20 | M15: 첩
B16: 15 | C16: 황기 | E16: 8 | F16: =E16*$L$15 -> 160 | G16: =VLOOKUP($C16,[1]약재관리!$A:$J,10,FALSE) -> 16.8 | H16: =G16*E16 -> 134.4 | I16: =G16*F16 -> 2688 | K16: 총 팩수 | L16: 30 | M16: 팩
B17: 16 | C17: 인삼 | E17: 4 | F17: =E17*$L$15 -> 80 | G17: =VLOOKUP($C17,[1]약재관리!$A:$J,10,FALSE) -> 120 | H17: =G17*E17 -> 480 | I17: =G17*F17 -> 9600 | K17: 팩당 물량 | L17: 100 | M17: cc
B18: 17 | C18: 백출 | E18: 6 | F18: =E18*$L$15 -> 120 | G18: =VLOOKUP($C18,[1]약재관리!$A:$J,10,FALSE) -> 13 | H18: =G18*E18 -> 78 | I18: =G18*F18 -> 1560 | K18: 1첩당약재 | L18: =SUM(E2:E31) -> 99 | M18: g
B19: 18 | C19: 녹용 | E19: 2 | F19: =E19*$L$15 -> 40 | G19: =VLOOKUP($C19,[1]약재관리!$A:$J,10,FALSE) -> 550 | H19: =G19*E19 -> 1100 | I19: =G19*F19 -> 22000 | K19: 약재총량 | L19: =L15*L18 -> 1980 | M19: g
B20: 19 | C20: 목향 | E20: 4 | F20: =E20*$L$15 -> 80 | G20: =VLOOKUP($C20,[1]약재관리!$A:$J,10,FALSE) -> 12.2 | H20: =G20*E20 -> 48.8 | I20: =G20*F20 -> 976 | K20: 총 물 양 | L20: =L16*L17+L19 -> 4980 | M20: cc
B21: 20 | C21: 저근백피 | E21: 4 | F21: =E21*$L$15 -> 80 | G21: =VLOOKUP($C21,[1]약재관리!$A:$J,10,FALSE) -> 23.3 | H21: =G21*E21 -> 93.2 | I21: =G21*F21 -> 1864
B22: 21 | C22: 구기자 | E22: 6 | F22: =E22*$L$15 -> 120 | G22: =VLOOKUP($C22,[1]약재관리!$A:$J,10,FALSE) -> 13.7 | H22: =G22*E22 -> 82.2 | I22: =G22*F22 -> 1644 | K22: 참고치
B23: 22 | C23: 음양곽 | E23: 6 | F23: =E23*$L$15 -> 120 | G23: =VLOOKUP($C23,[1]약재관리!$A:$J,10,FALSE) -> 31 | H23: =G23*E23 -> 186 | I23: =G23*F23 -> 3720 | K23: cross chk | L23: =SUM(F2:F31) -> 1980 | M23: g
B24: 23 | F24: =E24*$L$15 -> 0 | H24: =G24*E24 -> 0 | I24: =G24*F24 -> 0 | K24: 20첩물양 | L24: 5000 | M24: cc
B25: 24 | F25: =E25*$L$15 -> 0 | H25: =G25*E25 -> 0 | I25: =G25*F25 -> 0 | K25: 1첩당 | L25: 80-120 | M25: g
B26: 25 | F26: =E26*$L$15 -> 0 | H26: =G26*E26 -> 0 | I26: =G26*F26 -> 0 | K26: 20첩당 | L26: 1600 | M26: g
B27: 26 | F27: =E27*$L$15 -> 0 | H27: =G27*E27 -> 0 | I27: =G27*F27 -> 0 | K27: 1돈 환산 | L27: 4 | M27: g
B28: 27 | F28: =E28*$L$15 -> 0 | H28: =G28*E28 -> 0 | I28: =G28*F28 -> 0
B29: 28 | F29: =E29*$L$15 -> 0 | H29: =G29*E29 -> 0 | I29: =G29*F29 -> 0 | K29: 금액
B30: 29 | F30: =E30*$L$15 -> 0 | H30: =G30*E30 -> 0 | I30: =G30*F30 -> 0 | K30: 1첩당 | L30: =SUM(H2:H31) -> 3403.1 | M30: 원
B31: 30 | F31: =E31*$L$15 -> 0 | H31: =G31*E31 -> 0 | I31: =G31*F31 -> 0 | K31: 총 | L31: =SUM(I2:I31) -> 68062 | M31: 원

Sheet 처방전양식 (8)
B1: No. | C1: 약재명 | D1: 수치 | E1: 그램 | F1: 총용량 | G1: 1g 금액 | H1: 1첩 금액 | I1: 총 금액 | K1: 기본 정보
B2: 1 | C2: 향부자 | E2: 8 | F2: =E2*$L$15 -> 160 | G2: =VLOOKUP($C2,약재관리!A:J,10,FALSE) -> 14.7 | H2: =G2*E2 -> 117.6 | I2: =G2*F2 -> 2352 | K2: UNIT | L2: 85
B3: 2 | C3: 숙지황 | E3: 6 | F3: =E3*$L$15 -> 120 | G3: =VLOOKUP($C3,약재관리!A:J,10,FALSE) -> 20 | H3: =G3*E3 -> 120 | I3: =G3*F3 -> 2400 | K3: 처방명 | L3: 조경종옥탕
B4: 3 | C4: 당귀1 | E4: 6 | F4: =E4*$L$15 -> 120 | G4: =VLOOKUP($C4,약재관리!A:J,10,FALSE) -> 25.3 | H4: =G4*E4 -> 151.8 | I4: =G4*F4 -> 3036 | K4: 날짜 | L4: 46017
B5: 4 | C5: 천궁1 | E5: 4 | F5: =E5*$L$15 -> 80 | G5: =VLOOKUP($C5,약재관리!A:J,10,FALSE) -> 10.8 | H5: =G5*E5 -> 43.2 | I5: =G5*F5 -> 864 | K5: 이름 | L5: 차현아
B6: 5 | C6: 백작약 | E6: 4 | F6: =E6*$L$15 -> 80 | G6: =VLOOKUP($C6,약재관리!A:J,10,FALSE) -> 19.6 | H6: =G6*E6 -> 78.4 | I6: =G6*F6 -> 1568 | K6: 나이 | L6: 42
B7: 6 | C7: 오수유 | E7: 4 | F7: =E7*$L$15 -> 80 | G7: =VLOOKUP($C7,약재관리!A:J,10,FALSE) -> 16.8 | H7: =G7*E7 -> 67.2 | I7: =G7*F7 -> 1344 | K7: 성별 | L7: F
B8: 7 | C8: 진피1 | E8: 4 | F8: =E8*$L$15 -> 80 | G8: =VLOOKUP($C8,약재관리!A:J,10,FALSE) -> 17.6 | H8: =G8*E8 -> 70.4 | I8: =G8*F8 -> 1408 | K8: 메모
B9: 8 | C9: 복령 | E9: 6 | F9: =E9*$L$15 -> 120 | G9: =VLOOKUP($C9,약재관리!A:J,10,FALSE) -> 11 | H9: =G9*E9 -> 66 | I9: =G9*F9 -> 1320 | K9: 조경종옥탕 + 황기 인삼 백출 목향 구기자 음양곽
B10: 9 | C10: 현호색 | E10: 3 | F10: =E10*$L$15 -> 60 | G10: =VLOOKUP($C10,약재관리!A:J,10,FALSE) -> 61.7 | H10: =G10*E10 -> 185.1 | I10: =G10*F10 -> 3702
B11: 10 | C11: 목단피 | E11: 3 | F11: =E11*$L$15 -> 60 | G11: =VLOOKUP($C11,약재관리!A:J,10,FALSE) -> 31.5 | H11: =G11*E11 -> 94.5 | I11: =G11*F11 -> 1890
B12: 11 | C12: 건강 | E12: 3 | F12: =E12*$L$15 -> 60 | G12: =VLOOKUP($C12,약재관리!A:J,10,FALSE) -> 9.5 | H12: =G12*E12 -> 28.5 | I12: =G12*F12 -> 570
B13: 12 | C13: 육계 | E13: 2 | F13: =E13*$L$15 -> 40 | G13: =VLOOKUP($C13,약재관리!A:J,10,FALSE) -> 14.8 | H13: =G13*E13 -> 29.6 | I13: =G13*F13 -> 592
B14: 13 | C14: 애엽 | E14: 2 | F14: =E14*$L$15 -> 40 | G14: =VLOOKUP($C14,약재관리!A:J,10,FALSE) -> 12.5 | H14: =G14*E14 -> 25 | I14: =G14*F14 -> 500 | K14: 총 일수 | L14: 15 | M14: 일분
B15: 14 | C15: 생강 | E15: 4 | F15: =E15*$L$15 -> 80 | G15: =VLOOKUP($C15,약재관리!A:J,10,FALSE) -> 15 | H15: =G15*E15 -> 60 | I15: =G15*F15 -> 1200 | K15: 첩수 | L15: 20 | M15: 첩
B16: 15 | C16: 황기 | E16: 8 | F16: =E16*$L$15 -> 160 | G16: =VLOOKUP($C16,약재관리!A:J,10,FALSE) -> 22 | H16: =G16*E16 -> 176 | I16: =G16*F16 -> 3520 | K16: 총 팩수 | L16: 30 | M16: 팩
B17: 16 | C17: 인삼 | E17: 4 | F17: =E17*$L$15 -> 80 | G17: =VLOOKUP($C17,약재관리!A:J,10,FALSE) -> 106.7 | H17: =G17*E17 -> 426.8 | I17: =G17*F17 -> 8536 | K17: 팩당 물량 | L17: 100 | M17: cc
B18: 17 | C18: 백출 | E18: 6 | F18: =E18*$L$15 -> 120 | G18: =VLOOKUP($C18,약재관리!A:J,10,FALSE) -> 30.3 | H18: =G18*E18 -> 181.8 | I18: =G18*F18 -> 3636 | K18: 1첩당약재 | L18: =SUM(E2:E31) -> 101 | M18: g
B19: 18 | C19: 녹용 | E19: 2 | F19: =E19*$L$15 -> 40 | G19: =VLOOKUP($C19,약재관리!A:J,10,FALSE) -> 463.3 | H19: =G19*E19 -> 926.6 | I19: =G19*F19 -> 18532 | K19: 약재총량 | L19: =L15*L18 -> 2020 | M19: g
B20: 19 | C20: 목향 | E20: 4 | F20: =E20*$L$15 -> 80 | G20: =VLOOKUP($C20,약재관리!A:J,10,FALSE) -> 12.2 | H20: =G20*E20 -> 48.8 | I20: =G20*F20 -> 976 | K20: 총 물 양 | L20: =L16*L17+L19 -> 5020 | M20: cc
B21: 20 | C21: 산약 | E21: 6 | F21: =E21*$L$15 -> 120 | G21: =VLOOKUP($C21,약재관리!A:J,10,FALSE) -> 18.3 | H21: =G21*E21 -> 109.8 | I21: =G21*F21 -> 2196
B22: 21 | C22: 구기자 | E22: 6 | F22: =E22*$L$15 -> 120 | G22: =VLOOKUP($C22,약재관리!A:J,10,FALSE) -> 13.7 | H22: =G22*E22 -> 82.2 | I22: =G22*F22 -> 1644 | K22: 참고치
B23: 22 | C23: 음양곽 | E23: 6 | F23: =E23*$L$15 -> 120 | G23: =VLOOKUP($C23,약재관리!A:J,10,FALSE) -> 23.8 | H23: =G23*E23 -> 142.8 | I23: =G23*F23 -> 2856 | K23: cross chk | L23: =SUM(F2:F31) -> 2020 | M23: g
B24: 23 | F24: =E24*$L$15 -> 0 | H24: =G24*E24 -> 0 | I24: =G24*F24 -> 0 | K24: 20첩물양 | L24: 5000 | M24: cc
B25: 24 | F25: =E25*$L$15 -> 0 | H25: =G25*E25 -> 0 | I25: =G25*F25 -> 0 | K25: 1첩당 | L25: 80-120 | M25: g
B26: 25 | F26: =E26*$L$15 -> 0 | H26: =G26*E26 -> 0 | I26: =G26*F26 -> 0 | K26: 20첩당 | L26: 1600 | M26: g
B27: 26 | F27: =E27*$L$15 -> 0 | H27: =G27*E27 -> 0 | I27: =G27*F27 -> 0 | K27: 1돈 환산 | L27: 4 | M27: g
B28: 27 | F28: =E28*$L$15 -> 0 | H28: =G28*E28 -> 0 | I28: =G28*F28 -> 0
B29: 28 | F29: =E29*$L$15 -> 0 | H29: =G29*E29 -> 0 | I29: =G29*F29 -> 0 | K29: 금액
B30: 29 | F30: =E30*$L$15 -> 0 | H30: =G30*E30 -> 0 | I30: =G30*F30 -> 0 | K30: 1첩당 | L30: =SUM(H2:H31) -> 3232.1 | M30: 원
B31: 30 | F31: =E31*$L$15 -> 0 | H31: =G31*E31 -> 0 | I31: =G31*F31 -> 0 | K31: 총 | L31: =SUM(I2:I31) -> 64642 | M31: 원

Sheet 처방전양식 (7)
B1: No. | C1: 약재명 | D1: 수치 | E1: 그램 | F1: 총용량 | G1: 1g 금액 | H1: 1첩 금액 | I1: 총 금액 | K1: 기본 정보
B2: 1 | C2: 황기 | E2: 12 | F2: =E2*$L$15 -> 240 | G2: =VLOOKUP($C2,약재관리!A:J,10,FALSE) -> 22 | H2: =G2*E2 -> 264 | I2: =G2*F2 -> 5280 | K2: UNIT | L2: 85
B3: 2 | C3: 구기자 | E3: 6 | F3: =E3*$L$15 -> 120 | G3: =VLOOKUP($C3,약재관리!A:J,10,FALSE) -> 13.7 | H3: =G3*E3 -> 82.2 | I3: =G3*F3 -> 1644 | K3: 처방명 | L3: 십전대보탕가감
B4: 3 | C4: 음양곽 | E4: 6 | F4: =E4*$L$15 -> 120 | G4: =VLOOKUP($C4,약재관리!A:J,10,FALSE) -> 23.8 | H4: =G4*E4 -> 142.8 | I4: =G4*F4 -> 2856 | K4: 날짜 | L4: 45986
B5: 4 | C5: 백출 | E5: 6 | F5: =E5*$L$15 -> 120 | G5: =VLOOKUP($C5,약재관리!A:J,10,FALSE) -> 30.3 | H5: =G5*E5 -> 181.8 | I5: =G5*F5 -> 3636 | K5: 이름 | L5: 차현아
B6: 5 | C6: 당귀1 | E6: 5 | F6: =E6*$L$15 -> 100 | G6: =VLOOKUP($C6,약재관리!A:J,10,FALSE) -> 25.3 | H6: =G6*E6 -> 126.5 | I6: =G6*F6 -> 2530 | K6: 나이 | L6: 42
B7: 6 | C7: 천궁1 | E7: 5 | F7: =E7*$L$15 -> 100 | G7: =VLOOKUP($C7,약재관리!A:J,10,FALSE) -> 10.8 | H7: =G7*E7 -> 54 | I7: =G7*F7 -> 1080 | K7: 성별 | L7: F
B8: 7 | C8: 백작약 | E8: 5 | F8: =E8*$L$15 -> 100 | G8: =VLOOKUP($C8,약재관리!A:J,10,FALSE) -> 19.6 | H8: =G8*E8 -> 98 | I8: =G8*F8 -> 1960 | K8: 메모
B9: 8 | C9: 숙지황 | E9: 5 | F9: =E9*$L$15 -> 100 | G9: =VLOOKUP($C9,약재관리!A:J,10,FALSE) -> 20 | H9: =G9*E9 -> 100 | I9: =G9*F9 -> 2000 | K9: 십전대보탕 + 구기자 음양곽 익모초 후박 지각 목향
B10: 9 | C10: 복령 | E10: 6 | F10: =E10*$L$15 -> 120 | G10: =VLOOKUP($C10,약재관리!A:J,10,FALSE) -> 11 | H10: =G10*E10 -> 66 | I10: =G10*F10 -> 1320
B11: 10 | C11: 인삼 | E11: 4 | F11: =E11*$L$15 -> 80 | G11: =VLOOKUP($C11,약재관리!A:J,10,FALSE) -> 106.7 | H11: =G11*E11 -> 426.8 | I11: =G11*F11 -> 8536
B12: 11 | C12: 감초 | E12: 2 | F12: =E12*$L$15 -> 40 | G12: =VLOOKUP($C12,약재관리!A:J,10,FALSE) -> 28.3 | H12: =G12*E12 -> 56.6 | I12: =G12*F12 -> 1132
B13: 12 | C13: 녹용 | E13: 2 | F13: =E13*$L$15 -> 40 | G13: =VLOOKUP($C13,약재관리!A:J,10,FALSE) -> 463.3 | H13: =G13*E13 -> 926.6 | I13: =G13*F13 -> 18532
B14: 13 | C14: 건강 | E14: 4 | F14: =E14*$L$15 -> 80 | G14: =VLOOKUP($C14,약재관리!A:J,10,FALSE) -> 9.5 | H14: =G14*E14 -> 38 | I14: =G14*F14 -> 760 | K14: 총 일수 | L14: 15 | M14: 일분
B15: 14 | C15: 육계 | E15: 2 | F15: =E15*$L$15 -> 40 | G15: =VLOOKUP($C15,약재관리!A:J,10,FALSE) -> 14.8 | H15: =G15*E15 -> 29.6 | I15: =G15*F15 -> 592 | K15: 첩수 | L15: 20 | M15: 첩
B16: 15 | C16: 익모초 | E16: 6 | F16: =E16*$L$15 -> 120 | G16: =VLOOKUP($C16,약재관리!A:J,10,FALSE) -> 12.5 | H16: =G16*E16 -> 75 | I16: =G16*F16 -> 1500 | K16: 총 팩수 | L16: 45 | M16: 팩
B17: 16 | C17: 후박 | E17: 4 | F17: =E17*$L$15 -> 80 | G17: =VLOOKUP($C17,약재관리!A:J,10,FALSE) -> 9 | H17: =G17*E17 -> 36 | I17: =G17*F17 -> 720 | K17: 팩당 물량 | L17: 100 | M17: cc
B18: 17 | C18: 지각 | E18: 4 | F18: =E18*$L$15 -> 80 | G18: =VLOOKUP($C18,약재관리!A:J,10,FALSE) -> 10 | H18: =G18*E18 -> 40 | I18: =G18*F18 -> 800 | K18: 1첩당약재 | L18: =SUM(E2:E31) -> 89 | M18: g
B19: 18 | C19: 목향 | E19: 2 | F19: =E19*$L$15 -> 40 | G19: =VLOOKUP($C19,약재관리!A:J,10,FALSE) -> 12.2 | H19: =G19*E19 -> 24.4 | I19: =G19*F19 -> 488 | K19: 약재총량 | L19: =L15*L18 -> 1780 | M19: g
B20: 19 | C20: 사인 | E20: 3 | F20: =E20*$L$15 -> 60 | G20: =VLOOKUP($C20,약재관리!A:J,10,FALSE) -> 21.8 | H20: =G20*E20 -> 65.4 | I20: =G20*F20 -> 1308 | K20: 총 물 양 | L20: =L16*L17+L19 -> 6280 | M20: cc
B21: 20 | F21: =E21*$L$15 -> 0 | H21: =G21*E21 -> 0 | I21: =G21*F21 -> 0
B22: 21 | F22: =E22*$L$15 -> 0 | H22: =G22*E22 -> 0 | I22: =G22*F22 -> 0 | K22: 참고치
B23: 22 | F23: =E23*$L$15 -> 0 | H23: =G23*E23 -> 0 | I23: =G23*F23 -> 0 | K23: cross chk | L23: =SUM(F2:F31) -> 1780 | M23: g
B24: 23 | F24: =E24*$L$15 -> 0 | H24: =G24*E24 -> 0 | I24: =G24*F24 -> 0 | K24: 20첩물양 | L24: 5000 | M24: cc
B25: 24 | F25: =E25*$L$15 -> 0 | H25: =G25*E25 -> 0 | I25: =G25*F25 -> 0 | K25: 1첩당 | L25: 80-120 | M25: g
B26: 25 | F26: =E26*$L$15 -> 0 | H26: =G26*E26 -> 0 | I26: =G26*F26 -> 0 | K26: 20첩당 | L26: 1600 | M26: g
B27: 26 | F27: =E27*$L$15 -> 0 | H27: =G27*E27 -> 0 | I27: =G27*F27 -> 0 | K27: 1돈 환산 | L27: 4 | M27: g
B28: 27 | F28: =E28*$L$15 -> 0 | H28: =G28*E28 -> 0 | I28: =G28*F28 -> 0
B29: 28 | F29: =E29*$L$15 -> 0 | H29: =G29*E29 -> 0 | I29: =G29*F29 -> 0 | K29: 금액
B30: 29 | F30: =E30*$L$15 -> 0 | H30: =G30*E30 -> 0 | I30: =G30*F30 -> 0 | K30: 1첩당 | L30: =SUM(H2:H31) -> 2833.7 | M30: 원
B31: 30 | F31: =E31*$L$15 -> 0 | H31: =G31*E31 -> 0 | I31: =G31*F31 -> 0 | K31: 총 | L31: =SUM(I2:I31) -> 56674 | M31: 원

Sheet 처방전양식 (6)
B1: No. | C1: 약재명 | D1: 수치 | E1: 그램 | F1: 총용량 | G1: 1g 금액 | H1: 1첩 금액 | I1: 총 금액 | K1: 기본 정보
B2: 1 | C2: 향부자 | E2: 8 | F2: =E2*$L$15 -> 160 | G2: =VLOOKUP($C2,약재관리!A:J,10,FALSE) -> 14.7 | H2: =G2*E2 -> 117.6 | I2: =G2*F2 -> 2352 | K2: UNIT | L2: 85
B3: 2 | C3: 숙지황 | E3: 6 | F3: =E3*$L$15 -> 120 | G3: =VLOOKUP($C3,약재관리!A:J,10,FALSE) -> 20 | H3: =G3*E3 -> 120 | I3: =G3*F3 -> 2400 | K3: 처방명 | L3: 조경종옥탕
B4: 3 | C4: 당귀1 | E4: 6 | F4: =E4*$L$15 -> 120 | G4: =VLOOKUP($C4,약재관리!A:J,10,FALSE) -> 25.3 | H4: =G4*E4 -> 151.8 | I4: =G4*F4 -> 3036 | K4: 날짜 | L4: 45951
B5: 4 | C5: 천궁1 | E5: 4 | F5: =E5*$L$15 -> 80 | G5: =VLOOKUP($C5,약재관리!A:J,10,FALSE) -> 10.8 | H5: =G5*E5 -> 43.2 | I5: =G5*F5 -> 864 | K5: 이름 | L5: 차현아
B6: 5 | C6: 백작약 | E6: 4 | F6: =E6*$L$15 -> 80 | G6: =VLOOKUP($C6,약재관리!A:J,10,FALSE) -> 19.6 | H6: =G6*E6 -> 78.4 | I6: =G6*F6 -> 1568 | K6: 나이 | L6: 42
B7: 6 | C7: 오수유 | E7: 4 | F7: =E7*$L$15 -> 80 | G7: =VLOOKUP($C7,약재관리!A:J,10,FALSE) -> 16.8 | H7: =G7*E7 -> 67.2 | I7: =G7*F7 -> 1344 | K7: 성별 | L7: F
B8: 7 | C8: 진피1 | E8: 4 | F8: =E8*$L$15 -> 80 | G8: =VLOOKUP($C8,약재관리!A:J,10,FALSE) -> 17.6 | H8: =G8*E8 -> 70.4 | I8: =G8*F8 -> 1408 | K8: 메모
B9: 8 | C9: 복령 | E9: 6 | F9: =E9*$L$15 -> 120 | G9: =VLOOKUP($C9,약재관리!A:J,10,FALSE) -> 11 | H9: =G9*E9 -> 66 | I9: =G9*F9 -> 1320 | K9: 조경종옥탕 + 황기 인삼 백출 목향 구기자 음양곽
B10: 9 | C10: 현호색 | E10: 3 | F10: =E10*$L$15 -> 60 | G10: =VLOOKUP($C10,약재관리!A:J,10,FALSE) -> 61.7 | H10: =G10*E10 -> 185.1 | I10: =G10*F10 -> 3702
B11: 10 | C11: 목단피 | E11: 3 | F11: =E11*$L$15 -> 60 | G11: =VLOOKUP($C11,약재관리!A:J,10,FALSE) -> 31.5 | H11: =G11*E11 -> 94.5 | I11: =G11*F11 -> 1890
B12: 11 | C12: 건강 | E12: 3 | F12: =E12*$L$15 -> 60 | G12: =VLOOKUP($C12,약재관리!A:J,10,FALSE) -> 9.5 | H12: =G12*E12 -> 28.5 | I12: =G12*F12 -> 570
B13: 12 | C13: 육계 | E13: 2 | F13: =E13*$L$15 -> 40 | G13: =VLOOKUP($C13,약재관리!A:J,10,FALSE) -> 14.8 | H13: =G13*E13 -> 29.6 | I13: =G13*F13 -> 592
B14: 13 | C14: 애엽 | E14: 2 | F14: =E14*$L$15 -> 40 | G14: =VLOOKUP($C14,약재관리!A:J,10,FALSE) -> 12.5 | H14: =G14*E14 -> 25 | I14: =G14*F14 -> 500 | K14: 총 일수 | L14: 15 | M14: 일분
B15: 14 | C15: 생강 | E15: 4 | F15: =E15*$L$15 -> 80 | G15: =VLOOKUP($C15,약재관리!A:J,10,FALSE) -> 15 | H15: =G15*E15 -> 60 | I15: =G15*F15 -> 1200 | K15: 첩수 | L15: 20 | M15: 첩
B16: 15 | C16: 황기 | E16: 8 | F16: =E16*$L$15 -> 160 | G16: =VLOOKUP($C16,약재관리!A:J,10,FALSE) -> 22 | H16: =G16*E16 -> 176 | I16: =G16*F16 -> 3520 | K16: 총 팩수 | L16: 30 | M16: 팩
B17: 16 | C17: 인삼 | E17: 4 | F17: =E17*$L$15 -> 80 | G17: =VLOOKUP($C17,약재관리!A:J,10,FALSE) -> 106.7 | H17: =G17*E17 -> 426.8 | I17: =G17*F17 -> 8536 | K17: 팩당 물량 | L17: 100 | M17: cc
B18: 17 | C18: 백출 | E18: 4 | F18: =E18*$L$15 -> 80 | G18: =VLOOKUP($C18,약재관리!A:J,10,FALSE) -> 30.3 | H18: =G18*E18 -> 121.2 | I18: =G18*F18 -> 2424 | K18: 1첩당약재 | L18: =SUM(E2:E31) -> 97 | M18: g
B19: 18 | C19: 녹용 | E19: 2 | F19: =E19*$L$15 -> 40 | G19: =VLOOKUP($C19,약재관리!A:J,10,FALSE) -> 463.3 | H19: =G19*E19 -> 926.6 | I19: =G19*F19 -> 18532 | K19: 약재총량 | L19: =L15*L18 -> 1940 | M19: g
B20: 19 | C20: 목향 | E20: 4 | F20: =E20*$L$15 -> 80 | G20: =VLOOKUP($C20,약재관리!A:J,10,FALSE) -> 12.2 | H20: =G20*E20 -> 48.8 | I20: =G20*F20 -> 976 | K20: 총 물 양 | L20: =L16*L17+L19 -> 4940 | M20: cc
B21: 20 | C21: 구기자 | E21: 8 | F21: =E21*$L$15 -> 160 | G21: =VLOOKUP($C21,약재관리!A:J,10,FALSE) -> 13.7 | H21: =G21*E21 -> 109.6 | I21: =G21*F21 -> 2192
B22: 21 | C22: 음양곽 | E22: 8 | F22: =E22*$L$15 -> 160 | G22: =VLOOKUP($C22,약재관리!A:J,10,FALSE) -> 23.8 | H22: =G22*E22 -> 190.4 | I22: =G22*F22 -> 3808 | K22: 참고치
B23: 22 | F23: =E23*$L$15 -> 0 | H23: =G23*E23 -> 0 | I23: =G23*F23 -> 0 | K23: cross chk | L23: =SUM(F2:F31) -> 1940 | M23: g
B24: 23 | F24: =E24*$L$15 -> 0 | H24: =G24*E24 -> 0 | I24: =G24*F24 -> 0 | K24: 20첩물양 | L24: 5000 | M24: cc
B25: 24 | F25: =E25*$L$15 -> 0 | H25: =G25*E25 -> 0 | I25: =G25*F25 -> 0 | K25: 1첩당 | L25: 80-120 | M25: g
B26: 25 | F26: =E26*$L$15 -> 0 | H26: =G26*E26 -> 0 | I26: =G26*F26 -> 0 | K26: 20첩당 | L26: 1600 | M26: g
B27: 26 | F27: =E27*$L$15 -> 0 | H27: =G27*E27 -> 0 | I27: =G27*F27 -> 0 | K27: 1돈 환산 | L27: 4 | M27: g
B28: 27 | F28: =E28*$L$15 -> 0 | H28: =G28*E28 -> 0 | I28: =G28*F28 -> 0
B29: 28 | F29: =E29*$L$15 -> 0 | H29: =G29*E29 -> 0 | I29: =G29*F29 -> 0 | K29: 금액
B30: 29 | F30: =E30*$L$15 -> 0 | H30: =G30*E30 -> 0 | I30: =G30*F30 -> 0 | K30: 1첩당 | L30: =SUM(H2:H31) -> 3136.7 | M30: 원
B31: 30 | F31: =E31*$L$15 -> 0 | H31: =G31*E31 -> 0 | I31: =G31*F31 -> 0 | K31: 총 | L31: =SUM(I2:I31) -> 62734 | M31: 원

Sheet 처방전양식 (5)
B1: No. | C1: 약재명 | D1: 수치 | E1: 그램 | F1: 총용량 | G1: 1g 금액 | H1: 1첩 금액 | I1: 총 금액 | K1: 기본 정보
B2: 1 | C2: 향부자 | E2: 8 | F2: =E2*$L$15 -> 160 | G2: =VLOOKUP($C2,약재관리!A:J,10,FALSE) -> 14.7 | H2: =G2*E2 -> 117.6 | I2: =G2*F2 -> 2352 | K2: UNIT | L2: 85
B3: 2 | C3: 숙지황 | E3: 6 | F3: =E3*$L$15 -> 120 | G3: =VLOOKUP($C3,약재관리!A:J,10,FALSE) -> 20 | H3: =G3*E3 -> 120 | I3: =G3*F3 -> 2400 | K3: 처방명 | L3: 조경종옥탕
B4: 3 | C4: 당귀1 | E4: 6 | F4: =E4*$L$15 -> 120 | G4: =VLOOKUP($C4,약재관리!A:J,10,FALSE) -> 25.3 | H4: =G4*E4 -> 151.8 | I4: =G4*F4 -> 3036 | K4: 날짜 | L4: 45924
B5: 4 | C5: 천궁1 | E5: 6 | F5: =E5*$L$15 -> 120 | G5: =VLOOKUP($C5,약재관리!A:J,10,FALSE) -> 10.8 | H5: =G5*E5 -> 64.8 | I5: =G5*F5 -> 1296 | K5: 이름 | L5: 차현아
B6: 5 | C6: 백작약 | E6: 6 | F6: =E6*$L$15 -> 120 | G6: =VLOOKUP($C6,약재관리!A:J,10,FALSE) -> 19.6 | H6: =G6*E6 -> 117.6 | I6: =G6*F6 -> 2352 | K6: 나이 | L6: 42
B7: 6 | C7: 오수유 | E7: 4 | F7: =E7*$L$15 -> 80 | G7: =VLOOKUP($C7,약재관리!A:J,10,FALSE) -> 16.8 | H7: =G7*E7 -> 67.2 | I7: =G7*F7 -> 1344 | K7: 성별 | L7: F
B8: 7 | C8: 진피1 | E8: 4 | F8: =E8*$L$15 -> 80 | G8: =VLOOKUP($C8,약재관리!A:J,10,FALSE) -> 17.6 | H8: =G8*E8 -> 70.4 | I8: =G8*F8 -> 1408 | K8: 메모
B9: 8 | C9: 복령 | E9: 4 | F9: =E9*$L$15 -> 80 | G9: =VLOOKUP($C9,약재관리!A:J,10,FALSE) -> 11 | H9: =G9*E9 -> 44 | I9: =G9*F9 -> 880 | K9: 조경종옥탕 + 백출 산약 황백 인삼 사인 맥문동 녹용
B10: 9 | C10: 현호색 | E10: 3 | F10: =E10*$L$15 -> 60 | G10: =VLOOKUP($C10,약재관리!A:J,10,FALSE) -> 61.7 | H10: =G10*E10 -> 185.1 | I10: =G10*F10 -> 3702
B11: 10 | C11: 목단피 | E11: 3 | F11: =E11*$L$15 -> 60 | G11: =VLOOKUP($C11,약재관리!A:J,10,FALSE) -> 31.5 | H11: =G11*E11 -> 94.5 | I11: =G11*F11 -> 1890
B12: 11 | C12: 건강 | E12: 3 | F12: =E12*$L$15 -> 60 | G12: =VLOOKUP($C12,약재관리!A:J,10,FALSE) -> 9.5 | H12: =G12*E12 -> 28.5 | I12: =G12*F12 -> 570
B13: 12 | C13: 육계 | E13: 2 | F13: =E13*$L$15 -> 40 | G13: =VLOOKUP($C13,약재관리!A:J,10,FALSE) -> 14.8 | H13: =G13*E13 -> 29.6 | I13: =G13*F13 -> 592
B14: 13 | C14: 애엽 | E14: 2 | F14: =E14*$L$15 -> 40 | G14: =VLOOKUP($C14,약재관리!A:J,10,FALSE) -> 12.5 | H14: =G14*E14 -> 25 | I14: =G14*F14 -> 500 | K14: 총 일수 | L14: 15 | M14: 일분
B15: 14 | C15: 생강 | E15: 4 | F15: =E15*$L$15 -> 80 | G15: =VLOOKUP($C15,약재관리!A:J,10,FALSE) -> 15 | H15: =G15*E15 -> 60 | I15: =G15*F15 -> 1200 | K15: 첩수 | L15: 20 | M15: 첩
B16: 15 | C16: 백출 | E16: 6 | F16: =E16*$L$15 -> 120 | G16: =VLOOKUP($C16,약재관리!A:J,10,FALSE) -> 30.3 | H16: =G16*E16 -> 181.8 | I16: =G16*F16 -> 3636 | K16: 총 팩수 | L16: 30 | M16: 팩
B17: 16 | C17: 산약 | E17: 6 | F17: =E17*$L$15 -> 120 | G17: =VLOOKUP($C17,약재관리!A:J,10,FALSE) -> 18.3 | H17: =G17*E17 -> 109.8 | I17: =G17*F17 -> 2196 | K17: 팩당 물량 | L17: 100 | M17: cc
B18: 17 | C18: 인삼 | E18: 4 | F18: =E18*$L$15 -> 80 | G18: =VLOOKUP($C18,약재관리!A:J,10,FALSE) -> 106.7 | H18: =G18*E18 -> 426.8 | I18: =G18*F18 -> 8536 | K18: 1첩당약재 | L18: =SUM(E2:E31) -> 88 | M18: g
B19: 18 | C19: 사인 | E19: 2 | F19: =E19*$L$15 -> 40 | G19: =VLOOKUP($C19,약재관리!A:J,10,FALSE) -> 21.8 | H19: =G19*E19 -> 43.6 | I19: =G19*F19 -> 872 | K19: 약재총량 | L19: =L15*L18 -> 1760 | M19: g
B20: 19 | C20: 맥문동 | E20: 4 | F20: =E20*$L$15 -> 80 | G20: =VLOOKUP($C20,약재관리!A:J,10,FALSE) -> 44.3 | H20: =G20*E20 -> 177.2 | I20: =G20*F20 -> 3544 | K20: 총 물 양 | L20: =L16*L17+L19 -> 4760 | M20: cc
B21: 20 | C21: 녹용 | E21: 2 | F21: =E21*$L$15 -> 40 | G21: =VLOOKUP($C21,약재관리!A:J,10,FALSE) -> 463.3 | H21: =G21*E21 -> 926.6 | I21: =G21*F21 -> 18532
B22: 21 | C22: 황백 | E22: 3 | F22: =E22*$L$15 -> 60 | G22: =VLOOKUP($C22,약재관리!A:J,10,FALSE) -> 27.7 | H22: =G22*E22 -> 83.1 | I22: =G22*F22 -> 1662 | K22: 참고치
B23: 22 | F23: =E23*$L$15 -> 0 | H23: =G23*E23 -> 0 | I23: =G23*F23 -> 0 | K23: cross chk | L23: =SUM(F2:F31) -> 1760 | M23: g
B24: 23 | F24: =E24*$L$15 -> 0 | H24: =G24*E24 -> 0 | I24: =G24*F24 -> 0 | K24: 20첩물양 | L24: 5000 | M24: cc
B25: 24 | F25: =E25*$L$15 -> 0 | H25: =G25*E25 -> 0 | I25: =G25*F25 -> 0 | K25: 1첩당 | L25: 80-120 | M25: g
B26: 25 | F26: =E26*$L$15 -> 0 | H26: =G26*E26 -> 0 | I26: =G26*F26 -> 0 | K26: 20첩당 | L26: 1600 | M26: g
B27: 26 | F27: =E27*$L$15 -> 0 | H27: =G27*E27 -> 0 | I27: =G27*F27 -> 0 | K27: 1돈 환산 | L27: 4 | M27: g
B28: 27 | F28: =E28*$L$15 -> 0 | H28: =G28*E28 -> 0 | I28: =G28*F28 -> 0
B29: 28 | F29: =E29*$L$15 -> 0 | H29: =G29*E29 -> 0 | I29: =G29*F29 -> 0 | K29: 금액
B30: 29 | F30: =E30*$L$15 -> 0 | H30: =G30*E30 -> 0 | I30: =G30*F30 -> 0 | K30: 1첩당 | L30: =SUM(H2:H31) -> 3125 | M30: 원
B31: 30 | F31: =E31*$L$15 -> 0 | H31: =G31*E31 -> 0 | I31: =G31*F31 -> 0 | K31: 총 | L31: =SUM(I2:I31) -> 62500 | M31: 원

Sheet 처방전양식 (4)
B1: No. | C1: 약재명 | D1: 수치 | E1: 그램 | F1: 총용량 | G1: 1g 금액 | H1: 1첩 금액 | I1: 총 금액 | K1: 기본 정보
B2: 1 | C2: 향부자 | E2: 8 | F2: =E2*$L$15 -> 160 | G2: =VLOOKUP($C2,약재관리!A:J,10,FALSE) -> 14.7 | H2: =G2*E2 -> 117.6 | I2: =G2*F2 -> 2352 | K2: UNIT | L2: 85
B3: 2 | C3: 창출1 | E3: 6 | F3: =E3*$L$15 -> 120 | G3: =VLOOKUP($C3,약재관리!A:J,10,FALSE) -> 22 | H3: =G3*E3 -> 132 | I3: =G3*F3 -> 2640 | K3: 처방명 | L3: 증손오화음
B4: 3 | C4: 진피1 | E4: 4 | F4: =E4*$L$15 -> 80 | G4: =VLOOKUP($C4,약재관리!A:J,10,FALSE) -> 17.6 | H4: =G4*E4 -> 70.4 | I4: =G4*F4 -> 1408 | K4: 날짜 | L4: 45890
B5: 4 | C5: 후박 | E5: 4 | F5: =E5*$L$15 -> 80 | G5: =VLOOKUP($C5,약재관리!A:J,10,FALSE) -> 9 | H5: =G5*E5 -> 36 | I5: =G5*F5 -> 720 | K5: 이름 | L5: 차현아
B6: 5 | C6: 반하 | E6: 4 | F6: =E6*$L$15 -> 80 | G6: =VLOOKUP($C6,약재관리!A:J,10,FALSE) -> 47 | H6: =G6*E6 -> 188 | I6: =G6*F6 -> 3760 | K6: 나이 | L6: 42
B7: 6 | C7: 복령 | E7: 4 | F7: =E7*$L$15 -> 80 | G7: =VLOOKUP($C7,약재관리!A:J,10,FALSE) -> 11 | H7: =G7*E7 -> 44 | I7: =G7*F7 -> 880 | K7: 성별 | L7: F
B8: 7 | C8: 당귀1 | E8: 3 | F8: =E8*$L$15 -> 60 | G8: =VLOOKUP($C8,약재관리!A:J,10,FALSE) -> 25.3 | H8: =G8*E8 -> 75.9 | I8: =G8*F8 -> 1518 | K8: 메모
B9: 8 | C9: 천궁1 | E9: 3 | F9: =E9*$L$15 -> 60 | G9: =VLOOKUP($C9,약재관리!A:J,10,FALSE) -> 10.8 | H9: =G9*E9 -> 32.4 | I9: =G9*F9 -> 648 | K9: 증손오화음-현호색,목향,백지 +신곡 맥아 홍화 인삼 오수유 황백 녹용
B10: 9 | C10: 백작약 | E10: 3 | F10: =E10*$L$15 -> 60 | G10: =VLOOKUP($C10,약재관리!A:J,10,FALSE) -> 19.6 | H10: =G10*E10 -> 58.8 | I10: =G10*F10 -> 1176
B11: 10 | C11: 오약 | E11: 3 | F11: =E11*$L$15 -> 60 | G11: =VLOOKUP($C11,약재관리!A:J,10,FALSE) -> 9.2 | H11: =G11*E11 -> 27.6 | I11: =G11*F11 -> 552
B12: 11 | C12: 길경 | E12: 3 | F12: =E12*$L$15 -> 60 | G12: =VLOOKUP($C12,약재관리!A:J,10,FALSE) -> 11.5 | H12: =G12*E12 -> 34.5 | I12: =G12*F12 -> 690
B13: 12 | C13: 지각 | E13: 3 | F13: =E13*$L$15 -> 60 | G13: =VLOOKUP($C13,약재관리!A:J,10,FALSE) -> 10 | H13: =G13*E13 -> 30 | I13: =G13*F13 -> 600
B14: 13 | C14: 육계 | E14: 3 | F14: =E14*$L$15 -> 60 | G14: =VLOOKUP($C14,약재관리!A:J,10,FALSE) -> 14.8 | H14: =G14*E14 -> 44.4 | I14: =G14*F14 -> 888 | K14: 총 일수 | L14: 15 | M14: 일분
B15: 14 | C15: 건강 | E15: 3 | F15: =E15*$L$15 -> 60 | G15: =VLOOKUP($C15,약재관리!A:J,10,FALSE) -> 9.5 | H15: =G15*E15 -> 28.5 | I15: =G15*F15 -> 570 | K15: 첩수 | L15: 20 | M15: 첩
B16: 15 | C16: 감초 | E16: 2 | F16: =E16*$L$15 -> 40 | G16: =VLOOKUP($C16,약재관리!A:J,10,FALSE) -> 28.3 | H16: =G16*E16 -> 56.6 | I16: =G16*F16 -> 1132 | K16: 총 팩수 | L16: 30 | M16: 팩
B17: 16 | C17: 생강 | E17: 4 | F17: =E17*$L$15 -> 80 | G17: =VLOOKUP($C17,약재관리!A:J,10,FALSE) -> 15 | H17: =G17*E17 -> 60 | I17: =G17*F17 -> 1200 | K17: 팩당 물량 | L17: 100 | M17: cc
B18: 17 | C18: 신곡 | E18: 4 | F18: =E18*$L$15 -> 80 | G18: =VLOOKUP($C18,약재관리!A:J,10,FALSE) -> 8 | H18: =G18*E18 -> 32 | I18: =G18*F18 -> 640 | K18: 1첩당약재 | L18: =SUM(E2:E31) -> 84 | M18: g
B19: 18 | C19: 맥아 | E19: 4 | F19: =E19*$L$15 -> 80 | G19: =VLOOKUP($C19,약재관리!A:J,10,FALSE) -> 7.5 | H19: =G19*E19 -> 30 | I19: =G19*F19 -> 600 | K19: 약재총량 | L19: =L15*L18 -> 1680 | M19: g
B20: 19 | C20: 홍화 | E20: 2 | F20: =E20*$L$15 -> 40 | G20: =VLOOKUP($C20,약재관리!A:J,10,FALSE) -> 44.2 | H20: =G20*E20 -> 88.4 | I20: =G20*F20 -> 1768 | K20: 총 물 양 | L20: =L16*L17+L19 -> 4680 | M20: cc
B21: 20 | C21: 인삼 | E21: 4 | F21: =E21*$L$15 -> 80 | G21: =VLOOKUP($C21,약재관리!A:J,10,FALSE) -> 106.7 | H21: =G21*E21 -> 426.8 | I21: =G21*F21 -> 8536
B22: 21 | C22: 오수유 | E22: 4 | F22: =E22*$L$15 -> 80 | G22: =VLOOKUP($C22,약재관리!A:J,10,FALSE) -> 16.8 | H22: =G22*E22 -> 67.2 | I22: =G22*F22 -> 1344 | K22: 참고치
B23: 22 | C23: 황백 | E23: 4 | F23: =E23*$L$15 -> 80 | G23: =VLOOKUP($C23,약재관리!A:J,10,FALSE) -> 27.7 | H23: =G23*E23 -> 110.8 | I23: =G23*F23 -> 2216 | K23: cross chk | L23: =SUM(F2:F31) -> 1680 | M23: g
B24: 23 | C24: 녹용 | E24: 2 | F24: =E24*$L$15 -> 40 | G24: =VLOOKUP($C24,약재관리!A:J,10,FALSE) -> 463.3 | H24: =G24*E24 -> 926.6 | I24: =G24*F24 -> 18532 | K24: 20첩물양 | L24: 5000 | M24: cc
B25: 24 | F25: =E25*$L$15 -> 0 | H25: =G25*E25 -> 0 | I25: =G25*F25 -> 0 | K25: 1첩당 | L25: 80-120 | M25: g
B26: 25 | F26: =E26*$L$15 -> 0 | H26: =G26*E26 -> 0 | I26: =G26*F26 -> 0 | K26: 20첩당 | L26: 1600 | M26: g
B27: 26 | F27: =E27*$L$15 -> 0 | H27: =G27*E27 -> 0 | I27: =G27*F27 -> 0 | K27: 1돈 환산 | L27: 4 | M27: g
B28: 27 | F28: =E28*$L$15 -> 0 | H28: =G28*E28 -> 0 | I28: =G28*F28 -> 0
B29: 28 | F29: =E29*$L$15 -> 0 | H29: =G29*E29 -> 0 | I29: =G29*F29 -> 0 | K29: 금액
B30: 29 | F30: =E30*$L$15 -> 0 | H30: =G30*E30 -> 0 | I30: =G30*F30 -> 0 | K30: 1첩당 | L30: =SUM(H2:H31) -> 2718.5 | M30: 원
B31: 30 | F31: =E31*$L$15 -> 0 | H31: =G31*E31 -> 0 | I31: =G31*F31 -> 0 | K31: 총 | L31: =SUM(I2:I31) -> 54370 | M31: 원

Sheet 처방전양식 (3)
B1: No. | C1: 약재명 | D1: 수치 | E1: 그램 | F1: 총용량 | G1: 1g 금액 | H1: 1첩 금액 | I1: 총 금액 | K1: 기본 정보
B2: 1 | C2: 향부자 | E2: 8 | F2: =E2*$L$15 -> 160 | G2: =VLOOKUP($C2,약재관리!A:J,10,FALSE) -> 14.7 | H2: =G2*E2 -> 117.6 | I2: =G2*F2 -> 2352 | K2: UNIT | L2: 85
B3: 2 | C3: 숙지황 | E3: 6 | F3: =E3*$L$15 -> 120 | G3: =VLOOKUP($C3,약재관리!A:J,10,FALSE) -> 20 | H3: =G3*E3 -> 120 | I3: =G3*F3 -> 2400 | K3: 처방명 | L3: 조경종옥탕
B4: 3 | C4: 당귀1 | E4: 6 | F4: =E4*$L$15 -> 120 | G4: =VLOOKUP($C4,약재관리!A:J,10,FALSE) -> 25.3 | H4: =G4*E4 -> 151.8 | I4: =G4*F4 -> 3036 | K4: 날짜 | L4: 45779
B5: 4 | C5: 천궁1 | E5: 4 | F5: =E5*$L$15 -> 80 | G5: =VLOOKUP($C5,약재관리!A:J,10,FALSE) -> 10.8 | H5: =G5*E5 -> 43.2 | I5: =G5*F5 -> 864 | K5: 이름 | L5: 차현아
B6: 5 | C6: 백작약 | E6: 4 | F6: =E6*$L$15 -> 80 | G6: =VLOOKUP($C6,약재관리!A:J,10,FALSE) -> 19.6 | H6: =G6*E6 -> 78.4 | I6: =G6*F6 -> 1568 | K6: 나이 | L6: 42
B7: 6 | C7: 진피1 | E7: 4 | F7: =E7*$L$15 -> 80 | G7: =VLOOKUP($C7,약재관리!A:J,10,FALSE) -> 17.6 | H7: =G7*E7 -> 70.4 | I7: =G7*F7 -> 1408 | K7: 성별 | L7: F
B8: 7 | C8: 현호색 | E8: 4 | F8: =E8*$L$15 -> 80 | G8: =VLOOKUP($C8,약재관리!A:J,10,FALSE) -> 61.7 | H8: =G8*E8 -> 246.8 | I8: =G8*F8 -> 4936 | K8: 메모
B9: 8 | C9: 목단피 | E9: 4 | F9: =E9*$L$15 -> 80 | G9: =VLOOKUP($C9,약재관리!A:J,10,FALSE) -> 31.5 | H9: =G9*E9 -> 126 | I9: =G9*F9 -> 2520 | K9: 조경종옥탕+인삼, 반하,생강,창출,사인,녹용+황백,산약(백대하)
B10: 9 | C10: 건강 | E10: 2 | F10: =E10*$L$15 -> 40 | G10: =VLOOKUP($C10,약재관리!A:J,10,FALSE) -> 9.5 | H10: =G10*E10 -> 19 | I10: =G10*F10 -> 380
B11: 10 | C11: 육계 | E11: 4 | F11: =E11*$L$15 -> 80 | G11: =VLOOKUP($C11,약재관리!A:J,10,FALSE) -> 14.8 | H11: =G11*E11 -> 59.2 | I11: =G11*F11 -> 1184
B12: 11 | C12: 애엽 | E12: 4 | F12: =E12*$L$15 -> 80 | G12: =VLOOKUP($C12,약재관리!A:J,10,FALSE) -> 12.5 | H12: =G12*E12 -> 50 | I12: =G12*F12 -> 1000
B13: 12 | C13: 복령 | E13: 6 | F13: =E13*$L$15 -> 120 | G13: =VLOOKUP($C13,약재관리!A:J,10,FALSE) -> 11 | H13: =G13*E13 -> 66 | I13: =G13*F13 -> 1320
B14: 13 | C14: 인삼 | E14: 4 | F14: =E14*$L$15 -> 80 | G14: =VLOOKUP($C14,약재관리!A:J,10,FALSE) -> 106.7 | H14: =G14*E14 -> 426.8 | I14: =G14*F14 -> 8536 | K14: 총 일수 | L14: 15 | M14: 일분
B15: 14 | C15: 오수유 | E15: 4 | F15: =E15*$L$15 -> 80 | G15: =VLOOKUP($C15,약재관리!A:J,10,FALSE) -> 16.8 | H15: =G15*E15 -> 67.2 | I15: =G15*F15 -> 1344 | K15: 첩수 | L15: 20 | M15: 첩
B16: 15 | C16: 반하 | E16: 4 | F16: =E16*$L$15 -> 80 | G16: =VLOOKUP($C16,약재관리!A:J,10,FALSE) -> 47 | H16: =G16*E16 -> 188 | I16: =G16*F16 -> 3760 | K16: 총 팩수 | L16: 30 | M16: 팩
B17: 16 | C17: 생강 | E17: 4 | F17: =E17*$L$15 -> 80 | G17: =VLOOKUP($C17,약재관리!A:J,10,FALSE) -> 15 | H17: =G17*E17 -> 60 | I17: =G17*F17 -> 1200 | K17: 팩당 물량 | L17: 100 | M17: cc
B18: 17 | C18: 창출1 | E18: 6 | F18: =E18*$L$15 -> 120 | G18: =VLOOKUP($C18,약재관리!A:J,10,FALSE) -> 22 | H18: =G18*E18 -> 132 | I18: =G18*F18 -> 2640 | K18: 1첩당약재 | L18: =SUM(E2:E31) -> 92 | M18: g
B19: 18 | C19: 사인 | E19: 2 | F19: =E19*$L$15 -> 40 | G19: =VLOOKUP($C19,약재관리!A:J,10,FALSE) -> 21.8 | H19: =G19*E19 -> 43.6 | I19: =G19*F19 -> 872 | K19: 약재총량 | L19: =L15*L18 -> 1840 | M19: g
B20: 19 | C20: 녹용 | E20: 2 | F20: =E20*$L$15 -> 40 | G20: =VLOOKUP($C20,약재관리!A:J,10,FALSE) -> 463.3 | H20: =G20*E20 -> 926.6 | I20: =G20*F20 -> 18532 | K20: 총 물 양 | L20: =L16*L17+L19 -> 4840 | M20: cc
B21: 20 | C21: 황백 | E21: 4 | F21: =E21*$L$15 -> 80 | G21: =VLOOKUP($C21,약재관리!A:J,10,FALSE) -> 27.7 | H21: =G21*E21 -> 110.8 | I21: =G21*F21 -> 2216
B22: 21 | C22: 산약 | E22: 6 | F22: =E22*$L$15 -> 120 | G22: =VLOOKUP($C22,약재관리!A:J,10,FALSE) -> 18.3 | H22: =G22*E22 -> 109.8 | I22: =G22*F22 -> 2196 | K22: 참고치
B23: 22 | F23: =E23*$L$15 -> 0 | H23: =G23*E23 -> 0 | I23: =G23*F23 -> 0 | K23: cross chk | L23: =SUM(F2:F31) -> 1840 | M23: g
B24: 23 | F24: =E24*$L$15 -> 0 | H24: =G24*E24 -> 0 | I24: =G24*F24 -> 0 | K24: 20첩물양 | L24: 5000 | M24: cc
B25: 24 | F25: =E25*$L$15 -> 0 | H25: =G25*E25 -> 0 | I25: =G25*F25 -> 0 | K25: 1첩당 | L25: 80-120 | M25: g
B26: 25 | F26: =E26*$L$15 -> 0 | H26: =G26*E26 -> 0 | I26: =G26*F26 -> 0 | K26: 20첩당 | L26: 1600 | M26: g
B27: 26 | F27: =E27*$L$15 -> 0 | H27: =G27*E27 -> 0 | I27: =G27*F27 -> 0 | K27: 1돈 환산 | L27: 4 | M27: g
B28: 27 | F28: =E28*$L$15 -> 0 | H28: =G28*E28 -> 0 | I28: =G28*F28 -> 0
B29: 28 | F29: =E29*$L$15 -> 0 | H29: =G29*E29 -> 0 | I29: =G29*F29 -> 0 | K29: 금액
B30: 29 | F30: =E30*$L$15 -> 0 | H30: =G30*E30 -> 0 | I30: =G30*F30 -> 0 | K30: 1첩당 | L30: =SUM(H2:H31) -> 3213.2 | M30: 원
B31: 30 | F31: =E31*$L$15 -> 0 | H31: =G31*E31 -> 0 | I31: =G31*F31 -> 0 | K31: 총 | L31: =SUM(I2:I31) -> 64264 | M31: 원

Sheet 처방전양식 (2)
B1: No. | C1: 약재명 | D1: 수치 | E1: 그램 | F1: 총용량 | G1: 1g 금액 | H1: 1첩 금액 | I1: 총 금액 | K1: 기본 정보
B2: 1 | C2: 향부자 | E2: 8 | F2: =E2*$L$15 -> 160 | G2: =VLOOKUP($C2,약재관리!A:J,10,FALSE) -> 14.7 | H2: =G2*E2 -> 117.6 | I2: =G2*F2 -> 2352 | K2: UNIT | L2: 85
B3: 2 | C3: 숙지황 | E3: 6 | F3: =E3*$L$15 -> 120 | G3: =VLOOKUP($C3,약재관리!A:J,10,FALSE) -> 20 | H3: =G3*E3 -> 120 | I3: =G3*F3 -> 2400 | K3: 처방명 | L3: 조경종옥탕
B4: 3 | C4: 당귀1 | E4: 6 | F4: =E4*$L$15 -> 120 | G4: =VLOOKUP($C4,약재관리!A:J,10,FALSE) -> 25.3 | H4: =G4*E4 -> 151.8 | I4: =G4*F4 -> 3036 | K4: 날짜 | L4: 45747
B5: 4 | C5: 천궁1 | E5: 4 | F5: =E5*$L$15 -> 80 | G5: =VLOOKUP($C5,약재관리!A:J,10,FALSE) -> 10.8 | H5: =G5*E5 -> 43.2 | I5: =G5*F5 -> 864 | K5: 이름 | L5: 차현아
B6: 5 | C6: 백작약 | E6: 4 | F6: =E6*$L$15 -> 80 | G6: =VLOOKUP($C6,약재관리!A:J,10,FALSE) -> 19.6 | H6: =G6*E6 -> 78.4 | I6: =G6*F6 -> 1568 | K6: 나이 | L6: 42
B7: 6 | C7: 진피1 | E7: 4 | F7: =E7*$L$15 -> 80 | G7: =VLOOKUP($C7,약재관리!A:J,10,FALSE) -> 17.6 | H7: =G7*E7 -> 70.4 | I7: =G7*F7 -> 1408 | K7: 성별 | L7: F
B8: 7 | C8: 현호색 | E8: 4 | F8: =E8*$L$15 -> 80 | G8: =VLOOKUP($C8,약재관리!A:J,10,FALSE) -> 61.7 | H8: =G8*E8 -> 246.8 | I8: =G8*F8 -> 4936 | K8: 메모
B9: 8 | C9: 목단피 | E9: 4 | F9: =E9*$L$15 -> 80 | G9: =VLOOKUP($C9,약재관리!A:J,10,FALSE) -> 31.5 | H9: =G9*E9 -> 126 | I9: =G9*F9 -> 2520 | K9: 조경종옥탕+인삼, 반하,생강,창출,후박,신곡,사인,녹용
B10: 9 | C10: 건강 | E10: 2 | F10: =E10*$L$15 -> 40 | G10: =VLOOKUP($C10,약재관리!A:J,10,FALSE) -> 9.5 | H10: =G10*E10 -> 19 | I10: =G10*F10 -> 380
B11: 10 | C11: 육계 | E11: 4 | F11: =E11*$L$15 -> 80 | G11: =VLOOKUP($C11,약재관리!A:J,10,FALSE) -> 14.8 | H11: =G11*E11 -> 59.2 | I11: =G11*F11 -> 1184
B12: 11 | C12: 애엽 | E12: 4 | F12: =E12*$L$15 -> 80 | G12: =VLOOKUP($C12,약재관리!A:J,10,FALSE) -> 12.5 | H12: =G12*E12 -> 50 | I12: =G12*F12 -> 1000
B13: 12 | C13: 복령 | E13: 6 | F13: =E13*$L$15 -> 120 | G13: =VLOOKUP($C13,약재관리!A:J,10,FALSE) -> 11 | H13: =G13*E13 -> 66 | I13: =G13*F13 -> 1320
B14: 13 | C14: 인삼 | E14: 4 | F14: =E14*$L$15 -> 80 | G14: =VLOOKUP($C14,약재관리!A:J,10,FALSE) -> 106.7 | H14: =G14*E14 -> 426.8 | I14: =G14*F14 -> 8536 | K14: 총 일수 | L14: 15 | M14: 일분
B15: 14 | C15: 오수유 | E15: 4 | F15: =E15*$L$15 -> 80 | G15: =VLOOKUP($C15,약재관리!A:J,10,FALSE) -> 16.8 | H15: =G15*E15 -> 67.2 | I15: =G15*F15 -> 1344 | K15: 첩수 | L15: 20 | M15: 첩
B16: 15 | C16: 반하 | E16: 4 | F16: =E16*$L$15 -> 80 | G16: =VLOOKUP($C16,약재관리!A:J,10,FALSE) -> 47 | H16: =G16*E16 -> 188 | I16: =G16*F16 -> 3760 | K16: 총 팩수 | L16: 45 | M16: 팩
B17: 16 | C17: 생강 | E17: 4 | F17: =E17*$L$15 -> 80 | G17: =VLOOKUP($C17,약재관리!A:J,10,FALSE) -> 15 | H17: =G17*E17 -> 60 | I17: =G17*F17 -> 1200 | K17: 팩당 물량 | L17: 100 | M17: cc
B18: 17 | C18: 창출1 | E18: 6 | F18: =E18*$L$15 -> 120 | G18: =VLOOKUP($C18,약재관리!A:J,10,FALSE) -> 22 | H18: =G18*E18 -> 132 | I18: =G18*F18 -> 2640 | K18: 1첩당약재 | L18: =SUM(E2:E31) -> 90 | M18: g
B19: 18 | C19: 사인 | E19: 2 | F19: =E19*$L$15 -> 40 | G19: =VLOOKUP($C19,약재관리!A:J,10,FALSE) -> 21.8 | H19: =G19*E19 -> 43.6 | I19: =G19*F19 -> 872 | K19: 약재총량 | L19: =L15*L18 -> 1800 | M19: g
B20: 19 | C20: 녹용 | E20: 2 | F20: =E20*$L$15 -> 40 | G20: =VLOOKUP($C20,약재관리!A:J,10,FALSE) -> 463.3 | H20: =G20*E20 -> 926.6 | I20: =G20*F20 -> 18532 | K20: 총 물 양 | L20: =L16*L17+L19 -> 6300 | M20: cc
B21: 20 | C21: 후박 | E21: 4 | F21: =E21*$L$15 -> 80 | G21: =VLOOKUP($C21,약재관리!A:J,10,FALSE) -> 9 | H21: =G21*E21 -> 36 | I21: =G21*F21 -> 720
B22: 21 | C22: 신곡 | E22: 4 | F22: =E22*$L$15 -> 80 | G22: =VLOOKUP($C22,약재관리!A:J,10,FALSE) -> 8 | H22: =G22*E22 -> 32 | I22: =G22*F22 -> 640 | K22: 참고치
B23: 22 | F23: =E23*$L$15 -> 0 | H23: =G23*E23 -> 0 | I23: =G23*F23 -> 0 | K23: cross chk | L23: =SUM(F2:F31) -> 1800 | M23: g
B24: 23 | F24: =E24*$L$15 -> 0 | H24: =G24*E24 -> 0 | I24: =G24*F24 -> 0 | K24: 20첩물양 | L24: 5000 | M24: cc
B25: 24 | F25: =E25*$L$15 -> 0 | H25: =G25*E25 -> 0 | I25: =G25*F25 -> 0 | K25: 1첩당 | L25: 80-120 | M25: g
B26: 25 | F26: =E26*$L$15 -> 0 | H26: =G26*E26 -> 0 | I26: =G26*F26 -> 0 | K26: 20첩당 | L26: 1600 | M26: g
B27: 26 | F27: =E27*$L$15 -> 0 | H27: =G27*E27 -> 0 | I27: =G27*F27 -> 0 | K27: 1돈 환산 | L27: 4 | M27: g
B28: 27 | F28: =E28*$L$15 -> 0 | H28: =G28*E28 -> 0 | I28: =G28*F28 -> 0
B29: 28 | F29: =E29*$L$15 -> 0 | H29: =G29*E29 -> 0 | I29: =G29*F29 -> 0 | K29: 금액
B30: 29 | F30: =E30*$L$15 -> 0 | H30: =G30*E30 -> 0 | I30: =G30*F30 -> 0 | K30: 1첩당 | L30: =SUM(H2:H31) -> 3060.6 | M30: 원
B31: 30 | F31: =E31*$L$15 -> 0 | H31: =G31*E31 -> 0 | I31: =G31*F31 -> 0 | K31: 총 | L31: =SUM(I2:I31) -> 61212 | M31: 원

Sheet 처방전양식
B1: No. | C1: 약재명 | D1: 수치 | E1: 그램 | F1: 총용량 | G1: 1g 금액 | H1: 1첩 금액 | I1: 총 금액 | K1: 기본 정보
B2: 1 | C2: 반하 | E2: 8 | F2: =E2*$L$15 -> 160 | G2: =VLOOKUP($C2,약재관리!A:J,10,FALSE) -> 47 | H2: =G2*E2 -> 376 | I2: =G2*F2 -> 7520 | K2: UNIT | L2: 85
B3: 2 | C3: 맥문동 | E3: 8 | F3: =E3*$L$15 -> 160 | G3: =VLOOKUP($C3,약재관리!A:J,10,FALSE) -> 44.3 | H3: =G3*E3 -> 354.4 | I3: =G3*F3 -> 7088 | K3: 처방명 | L3: 온경탕
B4: 3 | C4: 당귀1 | E4: 6 | F4: =E4*$L$15 -> 120 | G4: =VLOOKUP($C4,약재관리!A:J,10,FALSE) -> 25.3 | H4: =G4*E4 -> 151.8 | I4: =G4*F4 -> 3036 | K4: 날짜 | L4: 45717
B5: 4 | C5: 천궁1 | E5: 6 | F5: =E5*$L$15 -> 120 | G5: =VLOOKUP($C5,약재관리!A:J,10,FALSE) -> 10.8 | H5: =G5*E5 -> 64.8 | I5: =G5*F5 -> 1296 | K5: 이름 | L5: 차현아
B6: 5 | C6: 백작약 | E6: 4 | F6: =E6*$L$15 -> 80 | G6: =VLOOKUP($C6,약재관리!A:J,10,FALSE) -> 19.6 | H6: =G6*E6 -> 78.4 | I6: =G6*F6 -> 1568 | K6: 나이 | L6: 42
B7: 6 | C7: 인삼 | E7: 4 | F7: =E7*$L$15 -> 80 | G7: =VLOOKUP($C7,약재관리!A:J,10,FALSE) -> 106.7 | H7: =G7*E7 -> 426.8 | I7: =G7*F7 -> 8536 | K7: 성별 | L7: F
B8: 7 | C8: 육계 | E8: 4 | F8: =E8*$L$15 -> 80 | G8: =VLOOKUP($C8,약재관리!A:J,10,FALSE) -> 14.8 | H8: =G8*E8 -> 59.2 | I8: =G8*F8 -> 1184 | K8: 메모
B9: 8 | C9: 아교 | E9: 4 | F9: =E9*$L$15 -> 80 | G9: =VLOOKUP($C9,약재관리!A:J,10,FALSE) -> 26.7 | H9: =G9*E9 -> 106.8 | I9: =G9*F9 -> 2136 | K9: 온경탕+향부자, 창출, 소회향, 익모초, 복령
B10: 9 | C10: 목단피 | E10: 4 | F10: =E10*$L$15 -> 80 | G10: =VLOOKUP($C10,약재관리!A:J,10,FALSE) -> 31.5 | H10: =G10*E10 -> 126 | I10: =G10*F10 -> 2520
B11: 10 | C11: 생강 | E11: 4 | F11: =E11*$L$15 -> 80 | G11: =VLOOKUP($C11,약재관리!A:J,10,FALSE) -> 15 | H11: =G11*E11 -> 60 | I11: =G11*F11 -> 1200
B12: 11 | C12: 감초 | E12: 4 | F12: =E12*$L$15 -> 80 | G12: =VLOOKUP($C12,약재관리!A:J,10,FALSE) -> 28.3 | H12: =G12*E12 -> 113.2 | I12: =G12*F12 -> 2264
B13: 12 | C13: 오수유 | E13: 3 | F13: =E13*$L$15 -> 60 | G13: =VLOOKUP($C13,약재관리!A:J,10,FALSE) -> 16.8 | H13: =G13*E13 -> 50.4 | I13: =G13*F13 -> 1008
B14: 13 | C14: 향부자 | E14: 8 | F14: =E14*$L$15 -> 160 | G14: =VLOOKUP($C14,약재관리!A:J,10,FALSE) -> 14.7 | H14: =G14*E14 -> 117.6 | I14: =G14*F14 -> 2352 | K14: 총 일수 | L14: 15 | M14: 일분
B15: 14 | C15: 창출1 | E15: 4 | F15: =E15*$L$15 -> 80 | G15: =VLOOKUP($C15,약재관리!A:J,10,FALSE) -> 22 | H15: =G15*E15 -> 88 | I15: =G15*F15 -> 1760 | K15: 첩수 | L15: 20 | M15: 첩
B16: 15 | C16: 소회향 | E16: 3 | F16: =E16*$L$15 -> 60 | G16: =VLOOKUP($C16,약재관리!A:J,10,FALSE) -> 10 | H16: =G16*E16 -> 30 | I16: =G16*F16 -> 600 | K16: 총 팩수 | L16: 45 | M16: 팩
B17: 16 | C17: 복령 | E17: 6 | F17: =E17*$L$15 -> 120 | G17: =VLOOKUP($C17,약재관리!A:J,10,FALSE) -> 11 | H17: =G17*E17 -> 66 | I17: =G17*F17 -> 1320 | K17: 팩당 물량 | L17: 100 | M17: cc
B18: 17 | C18: 익모초 | E18: 4 | F18: =E18*$L$15 -> 80 | G18: =VLOOKUP($C18,약재관리!A:J,10,FALSE) -> 12.5 | H18: =G18*E18 -> 50 | I18: =G18*F18 -> 1000 | K18: 1첩당약재 | L18: =SUM(E2:E31) -> 86 | M18: g
B19: 18 | C19: 녹용 | E19: 2 | F19: =E19*$L$15 -> 40 | G19: =VLOOKUP($C19,약재관리!A:J,10,FALSE) -> 463.3 | H19: =G19*E19 -> 926.6 | I19: =G19*F19 -> 18532 | K19: 약재총량 | L19: =L15*L18 -> 1720 | M19: g
B20: 19 | F20: =E20*$L$15 -> 0 | H20: =G20*E20 -> 0 | I20: =G20*F20 -> 0 | K20: 총 물 양 | L20: =L16*L17+L19 -> 6220 | M20: cc
B21: 20 | F21: =E21*$L$15 -> 0 | H21: =G21*E21 -> 0 | I21: =G21*F21 -> 0
B22: 21 | F22: =E22*$L$15 -> 0 | H22: =G22*E22 -> 0 | I22: =G22*F22 -> 0 | K22: 참고치
B23: 22 | F23: =E23*$L$15 -> 0 | H23: =G23*E23 -> 0 | I23: =G23*F23 -> 0 | K23: cross chk | L23: =SUM(F2:F31) -> 1720 | M23: g
B24: 23 | F24: =E24*$L$15 -> 0 | H24: =G24*E24 -> 0 | I24: =G24*F24 -> 0 | K24: 20첩물양 | L24: 5000 | M24: cc
B25: 24 | F25: =E25*$L$15 -> 0 | H25: =G25*E25 -> 0 | I25: =G25*F25 -> 0 | K25: 1첩당 | L25: 80-120 | M25: g
B26: 25 | F26: =E26*$L$15 -> 0 | H26: =G26*E26 -> 0 | I26: =G26*F26 -> 0 | K26: 20첩당 | L26: 1600 | M26: g
B27: 26 | F27: =E27*$L$15 -> 0 | H27: =G27*E27 -> 0 | I27: =G27*F27 -> 0 | K27: 1돈 환산 | L27: 4 | M27: g
B28: 27 | F28: =E28*$L$15 -> 0 | H28: =G28*E28 -> 0 | I28: =G28*F28 -> 0
B29: 28 | F29: =E29*$L$15 -> 0 | H29: =G29*E29 -> 0 | I29: =G29*F29 -> 0 | K29: 금액
B30: 29 | F30: =E30*$L$15 -> 0 | H30: =G30*E30 -> 0 | I30: =G30*F30 -> 0 | K30: 1첩당 | L30: =SUM(H2:H31) -> 3246 | M30: 원
B31: 30 | F31: =E31*$L$15 -> 0 | H31: =G31*E31 -> 0 | I31: =G31*F31 -> 0 | K31: 총 | L31: =SUM(I2:I31) -> 64920 | M31: 원

Sheet 약재관리
A1: 약재 이름 | B1: 옴니허브 | C1: 한퓨어 | D1: 신우한방 | E1: 바른한약 | F1: 옴니허브 | G1: 한퓨어 | H1: 신우한방 | I1: 바른한약 | J1: 최종 | K1: 옴니허브 | L1: 한퓨어 | M1: 신우한방 | N1: 바른한약
A2: 45674 | B2: 구입단가 | C2: 구입단가 | D2: 구입단가 | E2: 구입단가 | F2: 1g | G2: 1g | H2: 1g | I2: 1g | J2: 1g | K2: 500g | L2: 500g | M2: 600g | N2: 600g
A3: 갈근1 | B3: 9900 | C3: 9000 | D3: 10500 | E3: 9900 | F3: =B3/500 -> 19.8 | G3: =C3/500 -> 18 | H3: =D3/600 -> 17.5 | I3: =E3/600 -> 16.5 | J3: 16.5 | L3: 선일국산 | M3: 토 | N3: 퓨어마인드국산
A4: 갈근2 | C4: 2700 | F4: =B4/500 -> 0 | G4: =C4/500 -> 5.4 | H4: =D4/600 -> 0 | I4: =E4/600 -> 0 | L4: 이풀잎중국
A5: 감국 | F5: =B5/500 -> 0 | G5: =C5/500 -> 0 | H5: =D5/600 -> 0 | I5: =E5/600 -> 0
A6: 감수 | C6: 23400 | E6: 27100 | F6: =B6/500 -> 0 | G6: =C6/600 -> 39 | H6: =D6/600 -> 0 | I6: =E6/600 -> 45.166667 | J6: 45.2 | L6: 600g씨케이중국 | N6: 씨케이중국
A7: 감초 | B7: 15800 | D7: 17000 | E7: 25500 | F7: =B7/500 -> 31.6 | G7: =C7/500 -> 0 | H7: =D7/600 -> 28.333333 | I7: =E7/600 -> 42.5 | J7: 28.3 | M7: 양외2 | N7: 양외1
A8: 강활1 | B8: 27200 | C8: 20500 | D8: 24000 | F8: =B8/500 -> 54.4 | G8: =C8/500 -> 41 | H8: =D8/600 -> 40 | I8: =E8/600 -> 0 | J8: 40 | L8: 선일국산 | M8: 토
A9: 강활2 | C9: 18700 | D9: 21000 | E9: 23300 | F9: =B9/500 -> 0 | G9: =C9/500 -> 37.4 | H9: =D9/600 -> 35 | I9: =E9/600 -> 38.833333 | J9: 38.8 | L9: 태극인국산 | N9: 선일국산
A10: 강황 | C10: 3300 | D10: 5000 | F10: =B10/500 -> 0 | G10: =C10/500 -> 6.6 | H10: =D10/600 -> 8.3333333 | I10: =E10/600 -> 0 | J10: 8.3 | M10: 인도
A11: 건강 | C11: 5200 | D11: 8000 | E11: 5900 | F11: =B11/500 -> 0 | G11: =C11/500 -> 10.4 | H11: =D11/600 -> 13.333333 | I11: =E11/600 -> 9.8333333 | J11: 9.5 | L11: 페루 | N11: 페루
A12: 건율 | C12: 13500 | D12: 16500 | E12: 16700 | F12: =B12/500 -> 0 | G12: =C12/500 -> 27 | H12: =D12/600 -> 27.5 | I12: =E12/600 -> 27.833333 | J12: 27.5 | M12: 토 | N12: (절, 토)
A13: 건지황 | B13: 19900 | C13: 7200 | D13: 11000 | E13: 8900 | F13: =B13/500 -> 39.8 | G13: =C13/500 -> 14.4 | H13: =D13/600 -> 18.333333 | I13: =E13/600 -> 14.833333 | J13: 14.4 | L13: 허브팜중국
A14: 검인 | F14: =B14/500 -> 0 | G14: =C14/500 -> 0 | H14: =D14/600 -> 0 | I14: =E14/600 -> 0
A15: 결명자 | F15: =B15/500 -> 0 | G15: =C15/500 -> 0 | H15: =D15/600 -> 0 | I15: =E15/600 -> 0
A16: 계지 | B16: 4500 | C16: 2000 | D16: 3500 | E16: 2900 | F16: =B16/500 -> 9 | G16: =C16/500 -> 4 | H16: =D16/600 -> 5.8333333 | I16: =E16/600 -> 4.8333333 | J16: 4.8 | L16: 씨케이베트남 | M16: 세 | N16: 엔탭베트남
A17: 고량강 | C17: 10200 | E17: 11100 | F17: =B17/500 -> 0 | G17: =C17/600 -> 17 | H17: =D17/600 -> 0 | I17: =E17/600 -> 18.5 | J17: 17 | L17: 600g 씨케이중국 | N17: 씨케이중국
A18: 고본 | C18: 32000 | E18: 41600 | F18: =B18/500 -> 0 | G18: =C18/500 -> 64 | H18: =D18/600 -> 0 | I18: =E18/600 -> 69.333333 | J18: 64 | L18: 선일국산 | N18: 퓨어마인드국산
A19: 고삼 | C19: 4500 | F19: =B19/500 -> 0 | G19: =C19/500 -> 9 | H19: =D19/600 -> 0 | I19: =E19/600 -> 0 | J19: 9 | L19: 한솔중국
A20: 골쇄보 | F20: =B20/500 -> 0 | G20: =C20/500 -> 0 | H20: =D20/600 -> 0 | I20: =E20/600 -> 0
A21: 과루인 | C21: 3500 | D21: 6500 | F21: =B21/500 -> 0 | G21: =C21/500 -> 7 | H21: =D21/600 -> 10.833333 | I21: =E21/600 -> 0 | J21: 10.8 | M21: (추)
A22: 곽향1 | B22: 6900 | C22: 5600 | E22: 6900 | F22: =B22/500 -> 13.8 | G22: =C22/500 -> 11.2 | H22: =D22/600 -> 0 | I22: =E22/600 -> 11.5 | J22: 13.8 | L22: 선일국산 | N22: 씨케이국산
A23: 곽향2 | B23: 4600 | C23: 3500 | E23: 4800 | F23: =B23/500 -> 9.2 | G23: =C23/500 -> 7 | H23: =D23/600 -> 0 | I23: =E23/600 -> 8 | J23: 7 | K23: 인도네시아 | L23: 올본인도네시아 | N23: 엔탭인도네시아
A24: 관동화 | C24: 46000 | D24: 70000 | E24: 75400 | F24: =B24/500 -> 0 | G24: =C24/300 -> 153.33333 | H24: =D24/600 -> 116.66667 | I24: =E24/600 -> 125.66667 | J24: 116.7 | L24: 300g | N24: 엔탭중국
A25: 괴화 | F25: =B25/500 -> 0 | G25: =C25/500 -> 0 | H25: =D25/600 -> 0 | I25: =E25/600 -> 0
A26: 교이 | F26: =B26/500 -> 0 | G26: =C26/500 -> 0 | H26: =D26/600 -> 0 | I26: =E26/600 -> 0 | J26: 5.3
A27: 구기자 | B27: 14900 | C27: 8700 | D27: 9000 | E27: 8200 | F27: =B27/500 -> 29.8 | G27: =C27/500 -> 17.4 | H27: =D27/600 -> 15 | I27: =E27/600 -> 13.666667 | J27: 13.7 | N27: 엔탭중국영하
A28: 구맥 | F28: =B28/500 -> 0 | G28: =C28/500 -> 0 | H28: =D28/600 -> 0 | I28: =E28/600 -> 0
A29: 구척 | F29: =B29/500 -> 0 | G29: =C29/500 -> 0 | H29: =D29/600 -> 0 | I29: =E29/600 -> 0
A30: 귀판 | C30: 20500 | D30: 19000 | F30: =B30/500 -> 0 | G30: =C30/600 -> 34.166667 | H30: =D30/600 -> 31.666667 | I30: =E30/600 -> 0 | J30: 31.7 | L30: 600g추말/자연세상인도네시아
A31: 금은화 | C31: 21500 | E31: 30800 | F31: =B31/500 -> 0 | G31: =C31/500 -> 43 | H31: =D31/600 -> 0 | I31: =E31/600 -> 51.333333 | J31: 44 | L31: 한솔중국 | N31: 엔탭중국
A32: 길경 | B32: 11500 | C32: 12900 | D32: 7500 | E32: 6900 | F32: =B32/500 -> 23 | G32: =C32/500 -> 25.8 | H32: =D32/600 -> 12.5 | I32: =E32/600 -> 11.5 | J32: 11.5 | K32: (중국4-5년) | L32: 선일국산 | M32: (편) | N32: 엔탭중국야생3년
A33: 나복자 | C33: 3000 | D33: 4000 | F33: =B33/500 -> 0 | G33: =C33/500 -> 6 | H33: =D33/600 -> 6.6666667 | I33: =E33/600 -> 0 | J33: 6.7 | L33: 올본인도/추말 | M33: 추
A34: 남성 | C34: 13000 | D34: 13000 | F34: =B34/500 -> 0 | G34: =C34/500 -> 26 | H34: =D34/500 -> 26 | I34: =E34/600 -> 0 | J34: 26 | L34: 생강백반제/신흥중국 | M34: 500g생강백반제/신흥중국
A35: 녹용 | C35: 278000 | F35: =B35/500 -> 0 | G35: =C35/600 -> 463.33333 | H35: =D35/600 -> 0 | I35: =E35/600 -> 0 | J35: 463.3 | L35: 600g
A36: 단삼 | C36: 6600 | E36: 8900 | F36: =B36/500 -> 0 | G36: =C36/500 -> 13.2 | H36: =D36/600 -> 0 | I36: =E36/600 -> 14.833333 | J36: 14.8 | L36: 허브팜중국 | N36: 엔탭중국
A37: 담두시 | D37: 8000 | F37: =B37/500 -> 0 | G37: =C37/500 -> 0 | H37: =D37/600 -> 13.333333 | I37: =E37/600 -> 0 | J37: 13.3
A38: 당귀1 | B38: 14900 | C38: 12700 | D38: 15000 | E38: 15200 | F38: =B38/500 -> 29.8 | G38: =C38/500 -> 25.4 | H38: =D38/600 -> 25 | I38: =E38/600 -> 25.333333 | J38: 25.3 | L38: 선일국산 | N38: 선일국산
