Workbook

Sheet 처방전양식 (6)
B1: No. | C1: 약재명 | D1: 수치 | E1: 그램 | F1: 총용량 | G1: 1g 금액 | H1: 1첩 금액 | I1: 총 금액 | K1: 기본 정보
B2: 1 | C2: 자소엽 | E2: 5 | F2: =E2*$L$15 -> 100 | G2: =VLOOKUP($C2,약재관리!A:J,10,FALSE) -> 12 | H2: =G2*E2 -> 60 | I2: =G2*F2 -> 1200 | K2: UNIT | L2: 96
B3: 2 | C3: 감초 | E3: 2 | F3: =E3*$L$15 -> 40 | G3: =VLOOKUP($C3,약재관리!A:J,10,FALSE) -> 28.3 | H3: =G3*E3 -> 56.6 | I3: =G3*F3 -> 1132 | K3: 처방명 | L3: 분심기음
B4: 3 | C4: 반하 | E4: 4 | F4: =E4*$L$15 -> 80 | G4: =VLOOKUP($C4,약재관리!A:J,10,FALSE) -> 47 | H4: =G4*E4 -> 188 | I4: =G4*F4 -> 3760 | K4: 날짜 | L4: 45862
B5: 4 | C5: 지각 | E5: 4 | F5: =E5*$L$15 -> 80 | G5: =VLOOKUP($C5,약재관리!A:J,10,FALSE) -> 10 | H5: =G5*E5 -> 40 | I5: =G5*F5 -> 800 | K5: 이름 | L5: 김남순
B6: 5 | C6: 진피1 | E6: 4 | F6: =E6*$L$15 -> 80 | G6: =VLOOKUP($C6,약재관리!A:J,10,FALSE) -> 17.6 | H6: =G6*E6 -> 70.4 | I6: =G6*F6 -> 1408 | K6: 나이 | L6: 60
B7: 6 | C7: 백출 | E7: 4 | F7: =E7*$L$15 -> 80 | G7: =VLOOKUP($C7,약재관리!A:J,10,FALSE) -> 30.3 | H7: =G7*E7 -> 121.2 | I7: =G7*F7 -> 2424 | K7: 성별 | L7: F
B8: 7 | C8: 목통 | E8: 3 | F8: =E8*$L$15 -> 60 | G8: =VLOOKUP($C8,약재관리!A:J,10,FALSE) -> 10.7 | H8: =G8*E8 -> 32.1 | I8: =G8*F8 -> 642 | K8: 메모
B9: 8 | C9: 저령 | E9: 4 | F9: =E9*$L$15 -> 80 | G9: =VLOOKUP($C9,약재관리!A:J,10,FALSE) -> 46.7 | H9: =G9*E9 -> 186.8 | I9: =G9*F9 -> 3736 | K9: 대전대처방집 참고 (5차 처방 - 나복자, 신곡, 산사, 박하, 당귀 +백출 목향 빈랑 사인 황련 황백 건지황) - 수면 / 변실금 / 뇨불리
B10: 9 | C10: 상백피 | E10: 4 | F10: =E10*$L$15 -> 80 | G10: =VLOOKUP($C10,약재관리!A:J,10,FALSE) -> 35 | H10: =G10*E10 -> 140 | I10: =G10*F10 -> 2800
B11: 10 | C11: 목향 | E11: 2 | F11: =E11*$L$15 -> 40 | G11: =VLOOKUP($C11,약재관리!A:J,10,FALSE) -> 12.2 | H11: =G11*E11 -> 24.4 | I11: =G11*F11 -> 488
B12: 11 | C12: 복령 | E12: 6 | F12: =E12*$L$15 -> 120 | G12: =VLOOKUP($C12,약재관리!A:J,10,FALSE) -> 11 | H12: =G12*E12 -> 66 | I12: =G12*F12 -> 1320
B13: 12 | C13: 빈랑 | E13: 2 | F13: =E13*$L$15 -> 40 | G13: =VLOOKUP($C13,약재관리!A:J,10,FALSE) -> 8.3 | H13: =G13*E13 -> 16.6 | I13: =G13*F13 -> 332
B14: 13 | C14: 택사1 | E14: 6 | F14: =E14*$L$15 -> 120 | G14: =VLOOKUP($C14,약재관리!A:J,10,FALSE) -> 23.7 | H14: =G14*E14 -> 142.2 | I14: =G14*F14 -> 2844 | K14: 총 일수 | L14: 15 | M14: 일분
B15: 14 | C15: 사인 | E15: 3 | F15: =E15*$L$15 -> 60 | G15: =VLOOKUP($C15,약재관리!A:J,10,FALSE) -> 21.8 | H15: =G15*E15 -> 65.4 | I15: =G15*F15 -> 1308 | K15: 첩수 | L15: 20 | M15: 첩
B16: 15 | C16: 길경 | E16: 4 | F16: =E16*$L$15 -> 80 | G16: =VLOOKUP($C16,약재관리!A:J,10,FALSE) -> 11.5 | H16: =G16*E16 -> 46 | I16: =G16*F16 -> 920 | K16: 총 팩수 | L16: 45 | M16: 팩
B17: 16 | C17: 계지 | E17: 4 | F17: =E17*$L$15 -> 80 | G17: =VLOOKUP($C17,약재관리!A:J,10,FALSE) -> 4.8 | H17: =G17*E17 -> 19.2 | I17: =G17*F17 -> 384 | K17: 팩당 물량 | L17: 110 | M17: cc
B18: 17 | C18: 향부자 | E18: 4 | F18: =E18*$L$15 -> 80 | G18: =VLOOKUP($C18,약재관리!A:J,10,FALSE) -> 14.7 | H18: =G18*E18 -> 58.8 | I18: =G18*F18 -> 1176 | K18: 1첩당약재 | L18: =SUM(E2:E31) -> 80 | M18: g
B19: 18 | C19: 곽향1 | E19: 4 | F19: =E19*$L$15 -> 80 | G19: =VLOOKUP($C19,약재관리!A:J,10,FALSE) -> 13.8 | H19: =G19*E19 -> 55.2 | I19: =G19*F19 -> 1104 | K19: 약재총량 | L19: =L15*L18 -> 1600 | M19: g
B20: 19 | C20: 등심초 | E20: 1 | F20: =E20*$L$15 -> 20 | G20: =VLOOKUP($C20,약재관리!A:J,10,FALSE) -> 65 | H20: =G20*E20 -> 65 | I20: =G20*F20 -> 1300 | K20: 총 물 양 | L20: =L16*L17+L19 -> 6550 | M20: cc
B21: 20 | C21: 치자 | D21: 초 | E21: 2 | F21: =E21*$L$15 -> 40 | G21: =VLOOKUP($C21,약재관리!A:J,10,FALSE) -> 26 | H21: =G21*E21 -> 52 | I21: =G21*F21 -> 1040
B22: 21 | C22: 황백 | E22: 2 | F22: =E22*$L$15 -> 40 | G22: =VLOOKUP($C22,약재관리!A:J,10,FALSE) -> 27.7 | H22: =G22*E22 -> 55.4 | I22: =G22*F22 -> 1108 | K22: 참고치
B23: 22 | C23: 황련 | E23: 2 | F23: =E23*$L$15 -> 40 | G23: =VLOOKUP($C23,약재관리!A:J,10,FALSE) -> 136.8 | H23: =G23*E23 -> 273.6 | I23: =G23*F23 -> 5472 | K23: cross chk | L23: =SUM(F2:F31) -> 1600 | M23: g
B24: 23 | C24: 건지황 | E24: 4 | F24: =E24*$L$15 -> 80 | G24: =VLOOKUP($C24,약재관리!A:J,10,FALSE) -> 14.4 | H24: =G24*E24 -> 57.6 | I24: =G24*F24 -> 1152 | K24: 20첩물양 | L24: 5000 | M24: cc
B25: 24 | F25: =E25*$L$15 -> 0 | H25: =G25*E25 -> 0 | I25: =G25*F25 -> 0 | K25: 1첩당 | L25: 80-120 | M25: g
B26: 25 | F26: =E26*$L$15 -> 0 | H26: =G26*E26 -> 0 | I26: =G26*F26 -> 0 | K26: 20첩당 | L26: 1600 | M26: g
B27: 26 | F27: =E27*$L$15 -> 0 | H27: =G27*E27 -> 0 | I27: =G27*F27 -> 0 | K27: 1돈 환산 | L27: 4 | M27: g
B28: 27 | F28: =E28*$L$15 -> 0 | H28: =G28*E28 -> 0 | I28: =G28*F28 -> 0
B29: 28 | F29: =E29*$L$15 -> 0 | H29: =G29*E29 -> 0 | I29: =G29*F29 -> 0 | K29: 금액
B30: 29 | F30: =E30*$L$15 -> 0 | H30: =G30*E30 -> 0 | I30: =G30*F30 -> 0 | K30: 1첩당 | L30: =SUM(H2:H31) -> 1892.5 | M30: 원
B31: 30 | F31: =E31*$L$15 -> 0 | H31: =G31*E31 -> 0 | I31: =G31*F31 -> 0 | K31: 총 | L31: =SUM(I2:I31) -> 37850 | M31: 원

Sheet 처방전양식 (5)
B1: No. | C1: 약재명 | D1: 수치 | E1: 그램 | F1: 총용량 | G1: 1g 금액 | H1: 1첩 금액 | I1: 총 금액 | K1: 기본 정보
B2: 1 | C2: 자소엽 | E2: 8 | F2: =E2*$L$15 -> 160 | G2: =VLOOKUP($C2,약재관리!A:J,10,FALSE) -> 12 | H2: =G2*E2 -> 96 | I2: =G2*F2 -> 1920 | K2: UNIT | L2: 96
B3: 2 | C3: 복령 | E3: 6 | F3: =E3*$L$15 -> 120 | G3: =VLOOKUP($C3,약재관리!A:J,10,FALSE) -> 11 | H3: =G3*E3 -> 66 | I3: =G3*F3 -> 1320 | K3: 처방명 | L3: 분심기음
B4: 3 | C4: 택사1 | E4: 6 | F4: =E4*$L$15 -> 120 | G4: =VLOOKUP($C4,약재관리!A:J,10,FALSE) -> 23.7 | H4: =G4*E4 -> 142.2 | I4: =G4*F4 -> 2844 | K4: 날짜 | L4: 45842
B5: 4 | C5: 반하 | E5: 4 | F5: =E5*$L$15 -> 80 | G5: =VLOOKUP($C5,약재관리!A:J,10,FALSE) -> 47 | H5: =G5*E5 -> 188 | I5: =G5*F5 -> 3760 | K5: 이름 | L5: 김남순
B6: 5 | C6: 나복자 | E6: 4 | F6: =E6*$L$15 -> 80 | G6: =VLOOKUP($C6,약재관리!A:J,10,FALSE) -> 6.7 | H6: =G6*E6 -> 26.8 | I6: =G6*F6 -> 536 | K6: 나이 | L6: 60
B7: 6 | C7: 신곡 | E7: 4 | F7: =E7*$L$15 -> 80 | G7: =VLOOKUP($C7,약재관리!A:J,10,FALSE) -> 8 | H7: =G7*E7 -> 32 | I7: =G7*F7 -> 640 | K7: 성별 | L7: F
B8: 7 | C8: 산사 | E8: 4 | F8: =E8*$L$15 -> 80 | G8: =VLOOKUP($C8,약재관리!A:J,10,FALSE) -> 7 | H8: =G8*E8 -> 28 | I8: =G8*F8 -> 560 | K8: 메모
B9: 8 | C9: 곽향1 | E9: 4 | F9: =E9*$L$15 -> 80 | G9: =VLOOKUP($C9,약재관리!A:J,10,FALSE) -> 13.8 | H9: =G9*E9 -> 55.2 | I9: =G9*F9 -> 1104 | K9: 대전대처방집 + 치자 당귀 저령 - 사인 (4차 처방 - 사인 황백 + 등심 저령 산사)
B10: 9 | C10: 지각 | E10: 4 | F10: =E10*$L$15 -> 80 | G10: =VLOOKUP($C10,약재관리!A:J,10,FALSE) -> 10 | H10: =G10*E10 -> 40 | I10: =G10*F10 -> 800
B11: 10 | C11: 향부자 | E11: 4 | F11: =E11*$L$15 -> 80 | G11: =VLOOKUP($C11,약재관리!A:J,10,FALSE) -> 14.7 | H11: =G11*E11 -> 58.8 | I11: =G11*F11 -> 1176
B12: 11 | C12: 길경 | E12: 4 | F12: =E12*$L$15 -> 80 | G12: =VLOOKUP($C12,약재관리!A:J,10,FALSE) -> 11.5 | H12: =G12*E12 -> 46 | I12: =G12*F12 -> 920
B13: 12 | C13: 상백피 | E13: 4 | F13: =E13*$L$15 -> 80 | G13: =VLOOKUP($C13,약재관리!A:J,10,FALSE) -> 35 | H13: =G13*E13 -> 140 | I13: =G13*F13 -> 2800
B14: 13 | C14: 계지 | E14: 4 | F14: =E14*$L$15 -> 80 | G14: =VLOOKUP($C14,약재관리!A:J,10,FALSE) -> 4.8 | H14: =G14*E14 -> 19.2 | I14: =G14*F14 -> 384 | K14: 총 일수 | L14: 15 | M14: 일분
B15: 14 | C15: 진피1 | E15: 4 | F15: =E15*$L$15 -> 80 | G15: =VLOOKUP($C15,약재관리!A:J,10,FALSE) -> 17.6 | H15: =G15*E15 -> 70.4 | I15: =G15*F15 -> 1408 | K15: 첩수 | L15: 20 | M15: 첩
B16: 15 | C16: 치자 | E16: 3 | F16: =E16*$L$15 -> 60 | G16: =VLOOKUP($C16,약재관리!A:J,10,FALSE) -> 26 | H16: =G16*E16 -> 78 | I16: =G16*F16 -> 1560 | K16: 총 팩수 | L16: 45 | M16: 팩
B17: 16 | C17: 목통 | E17: 3 | F17: =E17*$L$15 -> 60 | G17: =VLOOKUP($C17,약재관리!A:J,10,FALSE) -> 10.7 | H17: =G17*E17 -> 32.1 | I17: =G17*F17 -> 642 | K17: 팩당 물량 | L17: 110 | M17: cc
B18: 17 | C18: 등심초 | E18: 2 | F18: =E18*$L$15 -> 40 | G18: =VLOOKUP($C18,약재관리!A:J,10,FALSE) -> 65 | H18: =G18*E18 -> 130 | I18: =G18*F18 -> 2600 | K18: 1첩당약재 | L18: =SUM(E2:E31) -> 84 | M18: g
B19: 18 | C19: 감초 | E19: 2 | F19: =E19*$L$15 -> 40 | G19: =VLOOKUP($C19,약재관리!A:J,10,FALSE) -> 28.3 | H19: =G19*E19 -> 56.6 | I19: =G19*F19 -> 1132 | K19: 약재총량 | L19: =L15*L18 -> 1680 | M19: g
B20: 19 | C20: 박하 | E20: 2 | F20: =E20*$L$15 -> 40 | G20: =VLOOKUP($C20,약재관리!A:J,10,FALSE) -> 21.8 | H20: =G20*E20 -> 43.6 | I20: =G20*F20 -> 872 | K20: 총 물 양 | L20: =L16*L17+L19 -> 6630 | M20: cc
B21: 20 | C21: 당귀1 | E21: 4 | F21: =E21*$L$15 -> 80 | G21: =VLOOKUP($C21,약재관리!A:J,10,FALSE) -> 27.2 | H21: =G21*E21 -> 108.8 | I21: =G21*F21 -> 2176
B22: 21 | C22: 저령 | E22: 4 | F22: =E22*$L$15 -> 80 | G22: =VLOOKUP($C22,약재관리!A:J,10,FALSE) -> 46.7 | H22: =G22*E22 -> 186.8 | I22: =G22*F22 -> 3736 | K22: 참고치
B23: 22 | F23: =E23*$L$15 -> 0 | H23: =G23*E23 -> 0 | I23: =G23*F23 -> 0 | K23: cross chk | L23: =SUM(F2:F31) -> 1680 | M23: g
B24: 23 | F24: =E24*$L$15 -> 0 | H24: =G24*E24 -> 0 | I24: =G24*F24 -> 0 | K24: 20첩물양 | L24: 5000 | M24: cc
B25: 24 | F25: =E25*$L$15 -> 0 | H25: =G25*E25 -> 0 | I25: =G25*F25 -> 0 | K25: 1첩당 | L25: 80-120 | M25: g
B26: 25 | F26: =E26*$L$15 -> 0 | H26: =G26*E26 -> 0 | I26: =G26*F26 -> 0 | K26: 20첩당 | L26: 1600 | M26: g
B27: 26 | F27: =E27*$L$15 -> 0 | H27: =G27*E27 -> 0 | I27: =G27*F27 -> 0 | K27: 1돈 환산 | L27: 4 | M27: g
B28: 27 | F28: =E28*$L$15 -> 0 | H28: =G28*E28 -> 0 | I28: =G28*F28 -> 0
B29: 28 | F29: =E29*$L$15 -> 0 | H29: =G29*E29 -> 0 | I29: =G29*F29 -> 0 | K29: 금액
B30: 29 | F30: =E30*$L$15 -> 0 | H30: =G30*E30 -> 0 | I30: =G30*F30 -> 0 | K30: 1첩당 | L30: =SUM(H2:H31) -> 1644.5 | M30: 원
B31: 30 | F31: =E31*$L$15 -> 0 | H31: =G31*E31 -> 0 | I31: =G31*F31 -> 0 | K31: 총 | L31: =SUM(I2:I31) -> 32890 | M31: 원

Sheet 처방전양식 (4)
B1: No. | C1: 약재명 | D1: 수치 | E1: 그램 | F1: 총용량 | G1: 1g 금액 | H1: 1첩 금액 | I1: 총 금액 | K1: 기본 정보
B2: 1 | C2: 자소엽 | E2: 8 | F2: =E2*$L$15 -> 160 | G2: =VLOOKUP($C2,약재관리!A:J,10,FALSE) -> 12 | H2: =G2*E2 -> 96 | I2: =G2*F2 -> 1920 | K2: UNIT | L2: 96
B3: 2 | C3: 복령 | E3: 6 | F3: =E3*$L$15 -> 120 | G3: =VLOOKUP($C3,약재관리!A:J,10,FALSE) -> 11 | H3: =G3*E3 -> 66 | I3: =G3*F3 -> 1320 | K3: 처방명 | L3: 분심기음
B4: 3 | C4: 택사1 | E4: 6 | F4: =E4*$L$15 -> 120 | G4: =VLOOKUP($C4,약재관리!A:J,10,FALSE) -> 23.7 | H4: =G4*E4 -> 142.2 | I4: =G4*F4 -> 2844 | K4: 날짜 | L4: 45825
B5: 4 | C5: 반하 | E5: 4 | F5: =E5*$L$15 -> 80 | G5: =VLOOKUP($C5,약재관리!A:J,10,FALSE) -> 47 | H5: =G5*E5 -> 188 | I5: =G5*F5 -> 3760 | K5: 이름 | L5: 김남순
B6: 5 | C6: 나복자 | E6: 4 | F6: =E6*$L$15 -> 80 | G6: =VLOOKUP($C6,약재관리!A:J,10,FALSE) -> 6.7 | H6: =G6*E6 -> 26.8 | I6: =G6*F6 -> 536 | K6: 나이 | L6: 60
B7: 6 | C7: 신곡 | E7: 4 | F7: =E7*$L$15 -> 80 | G7: =VLOOKUP($C7,약재관리!A:J,10,FALSE) -> 8 | H7: =G7*E7 -> 32 | I7: =G7*F7 -> 640 | K7: 성별 | L7: F
B8: 7 | C8: 사인 | E8: 3 | F8: =E8*$L$15 -> 60 | G8: =VLOOKUP($C8,약재관리!A:J,10,FALSE) -> 21.8 | H8: =G8*E8 -> 65.4 | I8: =G8*F8 -> 1308 | K8: 메모
B9: 8 | C9: 곽향1 | E9: 4 | F9: =E9*$L$15 -> 80 | G9: =VLOOKUP($C9,약재관리!A:J,10,FALSE) -> 13.8 | H9: =G9*E9 -> 55.2 | I9: =G9*F9 -> 1104 | K9: 대전대처방집 + 치자 당귀 황백 - 등심 산사
B10: 9 | C10: 지각 | E10: 4 | F10: =E10*$L$15 -> 80 | G10: =VLOOKUP($C10,약재관리!A:J,10,FALSE) -> 10 | H10: =G10*E10 -> 40 | I10: =G10*F10 -> 800
B11: 10 | C11: 향부자 | E11: 4 | F11: =E11*$L$15 -> 80 | G11: =VLOOKUP($C11,약재관리!A:J,10,FALSE) -> 14.7 | H11: =G11*E11 -> 58.8 | I11: =G11*F11 -> 1176
B12: 11 | C12: 길경 | E12: 4 | F12: =E12*$L$15 -> 80 | G12: =VLOOKUP($C12,약재관리!A:J,10,FALSE) -> 11.5 | H12: =G12*E12 -> 46 | I12: =G12*F12 -> 920
B13: 12 | C13: 상백피 | E13: 4 | F13: =E13*$L$15 -> 80 | G13: =VLOOKUP($C13,약재관리!A:J,10,FALSE) -> 35 | H13: =G13*E13 -> 140 | I13: =G13*F13 -> 2800
B14: 13 | C14: 계지 | E14: 4 | F14: =E14*$L$15 -> 80 | G14: =VLOOKUP($C14,약재관리!A:J,10,FALSE) -> 4.8 | H14: =G14*E14 -> 19.2 | I14: =G14*F14 -> 384 | K14: 총 일수 | L14: 15 | M14: 일분
B15: 14 | C15: 진피1 | E15: 4 | F15: =E15*$L$15 -> 80 | G15: =VLOOKUP($C15,약재관리!A:J,10,FALSE) -> 17.6 | H15: =G15*E15 -> 70.4 | I15: =G15*F15 -> 1408 | K15: 첩수 | L15: 20 | M15: 첩
B16: 15 | C16: 치자 | E16: 3 | F16: =E16*$L$15 -> 60 | G16: =VLOOKUP($C16,약재관리!A:J,10,FALSE) -> 26 | H16: =G16*E16 -> 78 | I16: =G16*F16 -> 1560 | K16: 총 팩수 | L16: 45 | M16: 팩
B17: 16 | C17: 목통 | E17: 3 | F17: =E17*$L$15 -> 60 | G17: =VLOOKUP($C17,약재관리!A:J,10,FALSE) -> 10.7 | H17: =G17*E17 -> 32.1 | I17: =G17*F17 -> 642 | K17: 팩당 물량 | L17: 110 | M17: cc
B18: 17 | C18: 황백 | E18: 2 | F18: =E18*$L$15 -> 40 | G18: =VLOOKUP($C18,약재관리!A:J,10,FALSE) -> 27.7 | H18: =G18*E18 -> 55.4 | I18: =G18*F18 -> 1108 | K18: 1첩당약재 | L18: =SUM(E2:E31) -> 79 | M18: g
B19: 18 | C19: 감초 | E19: 2 | F19: =E19*$L$15 -> 40 | G19: =VLOOKUP($C19,약재관리!A:J,10,FALSE) -> 28.3 | H19: =G19*E19 -> 56.6 | I19: =G19*F19 -> 1132 | K19: 약재총량 | L19: =L15*L18 -> 1580 | M19: g
B20: 19 | C20: 박하 | E20: 2 | F20: =E20*$L$15 -> 40 | G20: =VLOOKUP($C20,약재관리!A:J,10,FALSE) -> 21.8 | H20: =G20*E20 -> 43.6 | I20: =G20*F20 -> 872 | K20: 총 물 양 | L20: =L16*L17+L19 -> 6530 | M20: cc
B21: 20 | C21: 당귀1 | E21: 4 | F21: =E21*$L$15 -> 80 | G21: =VLOOKUP($C21,약재관리!A:J,10,FALSE) -> 27.2 | H21: =G21*E21 -> 108.8 | I21: =G21*F21 -> 2176
B22: 21 | F22: =E22*$L$15 -> 0 | H22: =G22*E22 -> 0 | I22: =G22*F22 -> 0 | K22: 참고치
B23: 22 | F23: =E23*$L$15 -> 0 | H23: =G23*E23 -> 0 | I23: =G23*F23 -> 0 | K23: cross chk | L23: =SUM(F2:F31) -> 1580 | M23: g
B24: 23 | F24: =E24*$L$15 -> 0 | H24: =G24*E24 -> 0 | I24: =G24*F24 -> 0 | K24: 20첩물양 | L24: 5000 | M24: cc
B25: 24 | F25: =E25*$L$15 -> 0 | H25: =G25*E25 -> 0 | I25: =G25*F25 -> 0 | K25: 1첩당 | L25: 80-120 | M25: g
B26: 25 | F26: =E26*$L$15 -> 0 | H26: =G26*E26 -> 0 | I26: =G26*F26 -> 0 | K26: 20첩당 | L26: 1600 | M26: g
B27: 26 | F27: =E27*$L$15 -> 0 | H27: =G27*E27 -> 0 | I27: =G27*F27 -> 0 | K27: 1돈 환산 | L27: 4 | M27: g
B28: 27 | F28: =E28*$L$15 -> 0 | H28: =G28*E28 -> 0 | I28: =G28*F28 -> 0
B29: 28 | F29: =E29*$L$15 -> 0 | H29: =G29*E29 -> 0 | I29: =G29*F29 -> 0 | K29: 금액
B30: 29 | F30: =E30*$L$15 -> 0 | H30: =G30*E30 -> 0 | I30: =G30*F30 -> 0 | K30: 1첩당 | L30: =SUM(H2:H31) -> 1420.5 | M30: 원
B31: 30 | F31: =E31*$L$15 -> 0 | H31: =G31*E31 -> 0 | I31: =G31*F31 -> 0 | K31: 총 | L31: =SUM(I2:I31) -> 28410 | M31: 원

Sheet 처방전양식 (3)
B1: No. | C1: 약재명 | D1: 수치 | E1: 그램 | F1: 총용량 | G1: 1g 금액 | H1: 1첩 금액 | I1: 총 금액 | K1: 기본 정보
B2: 1 | C2: 향부자 | E2: 8 | F2: =E2*$L$15 -> 160 | G2: =VLOOKUP($C2,약재관리!A:J,10,FALSE) -> 14.7 | H2: =G2*E2 -> 117.6 | I2: =G2*F2 -> 2352 | K2: UNIT | L2: 96
B3: 2 | C3: 대복피 | E3: 6 | F3: =E3*$L$15 -> 120 | G3: =VLOOKUP($C3,약재관리!A:J,10,FALSE) -> 5.3 | H3: =G3*E3 -> 31.8 | I3: =G3*F3 -> 636 | K3: 처방명 | L3: 가감유기음자
B4: 3 | C4: 진피1 | E4: 6 | F4: =E4*$L$15 -> 120 | G4: =VLOOKUP($C4,약재관리!A:J,10,FALSE) -> 17.6 | H4: =G4*E4 -> 105.6 | I4: =G4*F4 -> 2112 | K4: 날짜 | L4: 45796
B5: 4 | C5: 복령 | E5: 4 | F5: =E5*$L$15 -> 80 | G5: =VLOOKUP($C5,약재관리!A:J,10,FALSE) -> 11 | H5: =G5*E5 -> 44 | I5: =G5*F5 -> 880 | K5: 이름 | L5: 김남순
B6: 5 | C6: 반하 | E6: 4 | F6: =E6*$L$15 -> 80 | G6: =VLOOKUP($C6,약재관리!A:J,10,FALSE) -> 47 | H6: =G6*E6 -> 188 | I6: =G6*F6 -> 3760 | K6: 나이 | L6: 60
B7: 6 | C7: 창출1 | E7: 4 | F7: =E7*$L$15 -> 80 | G7: =VLOOKUP($C7,약재관리!A:J,10,FALSE) -> 22 | H7: =G7*E7 -> 88 | I7: =G7*F7 -> 1760 | K7: 성별 | L7: F
B8: 7 | C8: 지실 | E8: 6 | F8: =E8*$L$15 -> 120 | G8: =VLOOKUP($C8,약재관리!A:J,10,FALSE) -> 16.7 | H8: =G8*E8 -> 100.2 | I8: =G8*F8 -> 2004 | K8: 메모
B9: 8 | C9: 목통 | E9: 4 | F9: =E9*$L$15 -> 80 | G9: =VLOOKUP($C9,약재관리!A:J,10,FALSE) -> 10.7 | H9: =G9*E9 -> 42.8 | I9: =G9*F9 -> 856 | K9: 가감유기음자+치자 황련 대황 저령 차전자 (소엽 대 맥문동)
B10: 9 | C10: 택사1 | E10: 4 | F10: =E10*$L$15 -> 80 | G10: =VLOOKUP($C10,약재관리!A:J,10,FALSE) -> 23.7 | H10: =G10*E10 -> 94.8 | I10: =G10*F10 -> 1896
B11: 10 | C11: 오약 | E11: 4 | F11: =E11*$L$15 -> 80 | G11: =VLOOKUP($C11,약재관리!A:J,10,FALSE) -> 9.2 | H11: =G11*E11 -> 36.8 | I11: =G11*F11 -> 736
B12: 11 | C12: 청피 | E12: 4 | F12: =E12*$L$15 -> 80 | G12: =VLOOKUP($C12,약재관리!A:J,10,FALSE) -> 7.3 | H12: =G12*E12 -> 29.2 | I12: =G12*F12 -> 584
B13: 12 | C13: 맥문동 | E13: 4 | F13: =E13*$L$15 -> 80 | G13: =VLOOKUP($C13,약재관리!A:J,10,FALSE) -> 44.3 | H13: =G13*E13 -> 177.2 | I13: =G13*F13 -> 3544
B14: 13 | C14: 길경 | E14: 3 | F14: =E14*$L$15 -> 60 | G14: =VLOOKUP($C14,약재관리!A:J,10,FALSE) -> 11.5 | H14: =G14*E14 -> 34.5 | I14: =G14*F14 -> 690 | K14: 총 일수 | L14: 15 | M14: 일분
B15: 14 | C15: 목향 | E15: 2 | F15: =E15*$L$15 -> 40 | G15: =VLOOKUP($C15,약재관리!A:J,10,FALSE) -> 12.2 | H15: =G15*E15 -> 24.4 | I15: =G15*F15 -> 488 | K15: 첩수 | L15: 20 | M15: 첩
B16: 15 | C16: 생강 | E16: 4 | F16: =E16*$L$15 -> 80 | G16: =VLOOKUP($C16,약재관리!A:J,10,FALSE) -> 15 | H16: =G16*E16 -> 60 | I16: =G16*F16 -> 1200 | K16: 총 팩수 | L16: 45 | M16: 팩
B17: 16 | C17: 치자 | E17: 6 | F17: =E17*$L$15 -> 120 | G17: =VLOOKUP($C17,약재관리!A:J,10,FALSE) -> 26 | H17: =G17*E17 -> 156 | I17: =G17*F17 -> 3120 | K17: 팩당 물량 | L17: 110 | M17: cc
B18: 17 | C18: 황련 | E18: 2 | F18: =E18*$L$15 -> 40 | G18: =VLOOKUP($C18,약재관리!A:J,10,FALSE) -> 136.8 | H18: =G18*E18 -> 273.6 | I18: =G18*F18 -> 5472 | K18: 1첩당약재 | L18: =SUM(E2:E31) -> 85 | M18: g
B19: 18 | C19: 대황 | E19: 4 | F19: =E19*$L$15 -> 80 | G19: =VLOOKUP($C19,약재관리!A:J,10,FALSE) -> 13 | H19: =G19*E19 -> 52 | I19: =G19*F19 -> 1040 | K19: 약재총량 | L19: =L15*L18 -> 1700 | M19: g
B20: 19 | C20: 저령 | E20: 4 | F20: =E20*$L$15 -> 80 | G20: =VLOOKUP($C20,약재관리!A:J,10,FALSE) -> 46.7 | H20: =G20*E20 -> 186.8 | I20: =G20*F20 -> 3736 | K20: 총 물 양 | L20: =L16*L17+L19 -> 6650 | M20: cc
B21: 20 | C21: 차전자 | E21: 2 | F21: =E21*$L$15 -> 40 | G21: =VLOOKUP($C21,약재관리!A:J,10,FALSE) -> 23.3 | H21: =G21*E21 -> 46.6 | I21: =G21*F21 -> 932
B22: 21 | F22: =E22*$L$15 -> 0 | H22: =G22*E22 -> 0 | I22: =G22*F22 -> 0 | K22: 참고치
B23: 22 | F23: =E23*$L$15 -> 0 | H23: =G23*E23 -> 0 | I23: =G23*F23 -> 0 | K23: cross chk | L23: =SUM(F2:F31) -> 1700 | M23: g
B24: 23 | F24: =E24*$L$15 -> 0 | H24: =G24*E24 -> 0 | I24: =G24*F24 -> 0 | K24: 20첩물양 | L24: 5000 | M24: cc
B25: 24 | F25: =E25*$L$15 -> 0 | H25: =G25*E25 -> 0 | I25: =G25*F25 -> 0 | K25: 1첩당 | L25: 80-120 | M25: g
B26: 25 | F26: =E26*$L$15 -> 0 | H26: =G26*E26 -> 0 | I26: =G26*F26 -> 0 | K26: 20첩당 | L26: 1600 | M26: g
B27: 26 | F27: =E27*$L$15 -> 0 | H27: =G27*E27 -> 0 | I27: =G27*F27 -> 0 | K27: 1돈 환산 | L27: 4 | M27: g
B28: 27 | F28: =E28*$L$15 -> 0 | H28: =G28*E28 -> 0 | I28: =G28*F28 -> 0
B29: 28 | F29: =E29*$L$15 -> 0 | H29: =G29*E29 -> 0 | I29: =G29*F29 -> 0 | K29: 금액
B30: 29 | F30: =E30*$L$15 -> 0 | H30: =G30*E30 -> 0 | I30: =G30*F30 -> 0 | K30: 1첩당 | L30: =SUM(H2:H31) -> 1889.9 | M30: 원
B31: 30 | F31: =E31*$L$15 -> 0 | H31: =G31*E31 -> 0 | I31: =G31*F31 -> 0 | K31: 총 | L31: =SUM(I2:I31) -> 37798 | M31: 원

Sheet 처방전양식 (2)
B1: No. | C1: 약재명 | D1: 수치 | E1: 그램 | F1: 총용량 | G1: 1g 금액 | H1: 1첩 금액 | I1: 총 금액 | K1: 기본 정보
B2: 1 | C2: 향부자 | E2: 8 | F2: =E2*$L$15 -> 160 | G2: =VLOOKUP($C2,약재관리!A:J,10,FALSE) -> 14.7 | H2: =G2*E2 -> 117.6 | I2: =G2*F2 -> 2352 | K2: UNIT | L2: 96
B3: 2 | C3: 대복피 | E3: 6 | F3: =E3*$L$15 -> 120 | G3: =VLOOKUP($C3,약재관리!A:J,10,FALSE) -> 5.3 | H3: =G3*E3 -> 31.8 | I3: =G3*F3 -> 636 | K3: 처방명 | L3: 가감유기음자
B4: 3 | C4: 진피1 | E4: 6 | F4: =E4*$L$15 -> 120 | G4: =VLOOKUP($C4,약재관리!A:J,10,FALSE) -> 17.6 | H4: =G4*E4 -> 105.6 | I4: =G4*F4 -> 2112 | K4: 날짜 | L4: 45777
B5: 4 | C5: 복령 | E5: 4 | F5: =E5*$L$15 -> 80 | G5: =VLOOKUP($C5,약재관리!A:J,10,FALSE) -> 11 | H5: =G5*E5 -> 44 | I5: =G5*F5 -> 880 | K5: 이름 | L5: 김남순
B6: 5 | C6: 반하 | E6: 4 | F6: =E6*$L$15 -> 80 | G6: =VLOOKUP($C6,약재관리!A:J,10,FALSE) -> 47 | H6: =G6*E6 -> 188 | I6: =G6*F6 -> 3760 | K6: 나이 | L6: 60
B7: 6 | C7: 창출1 | E7: 4 | F7: =E7*$L$15 -> 80 | G7: =VLOOKUP($C7,약재관리!A:J,10,FALSE) -> 22 | H7: =G7*E7 -> 88 | I7: =G7*F7 -> 1760 | K7: 성별 | L7: F
B8: 7 | C8: 지실 | E8: 6 | F8: =E8*$L$15 -> 120 | G8: =VLOOKUP($C8,약재관리!A:J,10,FALSE) -> 16.7 | H8: =G8*E8 -> 100.2 | I8: =G8*F8 -> 2004 | K8: 메모
B9: 8 | C9: 목통 | E9: 4 | F9: =E9*$L$15 -> 80 | G9: =VLOOKUP($C9,약재관리!A:J,10,FALSE) -> 10.7 | H9: =G9*E9 -> 42.8 | I9: =G9*F9 -> 856 | K9: 가감유기음자+치자 황련 대황
B10: 9 | C10: 택사1 | E10: 4 | F10: =E10*$L$15 -> 80 | G10: =VLOOKUP($C10,약재관리!A:J,10,FALSE) -> 23.7 | H10: =G10*E10 -> 94.8 | I10: =G10*F10 -> 1896
B11: 10 | C11: 오약 | E11: 4 | F11: =E11*$L$15 -> 80 | G11: =VLOOKUP($C11,약재관리!A:J,10,FALSE) -> 9.2 | H11: =G11*E11 -> 36.8 | I11: =G11*F11 -> 736
B12: 11 | C12: 청피 | E12: 4 | F12: =E12*$L$15 -> 80 | G12: =VLOOKUP($C12,약재관리!A:J,10,FALSE) -> 7.3 | H12: =G12*E12 -> 29.2 | I12: =G12*F12 -> 584
B13: 12 | C13: 자소엽 | E13: 3 | F13: =E13*$L$15 -> 60 | G13: =VLOOKUP($C13,약재관리!A:J,10,FALSE) -> 12 | H13: =G13*E13 -> 36 | I13: =G13*F13 -> 720
B14: 13 | C14: 길경 | E14: 3 | F14: =E14*$L$15 -> 60 | G14: =VLOOKUP($C14,약재관리!A:J,10,FALSE) -> 11.5 | H14: =G14*E14 -> 34.5 | I14: =G14*F14 -> 690 | K14: 총 일수 | L14: 15 | M14: 일분
B15: 14 | C15: 목향 | E15: 2 | F15: =E15*$L$15 -> 40 | G15: =VLOOKUP($C15,약재관리!A:J,10,FALSE) -> 12.2 | H15: =G15*E15 -> 24.4 | I15: =G15*F15 -> 488 | K15: 첩수 | L15: 20 | M15: 첩
B16: 15 | C16: 생강 | E16: 4 | F16: =E16*$L$15 -> 80 | G16: =VLOOKUP($C16,약재관리!A:J,10,FALSE) -> 15 | H16: =G16*E16 -> 60 | I16: =G16*F16 -> 1200 | K16: 총 팩수 | L16: 45 | M16: 팩
B17: 16 | C17: 치자 | E17: 6 | F17: =E17*$L$15 -> 120 | G17: =VLOOKUP($C17,약재관리!A:J,10,FALSE) -> 26 | H17: =G17*E17 -> 156 | I17: =G17*F17 -> 3120 | K17: 팩당 물량 | L17: 110 | M17: cc
B18: 17 | C18: 황련 | E18: 2 | F18: =E18*$L$15 -> 40 | G18: =VLOOKUP($C18,약재관리!A:J,10,FALSE) -> 136.8 | H18: =G18*E18 -> 273.6 | I18: =G18*F18 -> 5472 | K18: 1첩당약재 | L18: =SUM(E2:E31) -> 81 | M18: g
B19: 18 | C19: 대황 | E19: 4 | F19: =E19*$L$15 -> 80 | G19: =VLOOKUP($C19,약재관리!A:J,10,FALSE) -> 13 | H19: =G19*E19 -> 52 | I19: =G19*F19 -> 1040 | K19: 약재총량 | L19: =L15*L18 -> 1620 | M19: g
B20: 19 | C20: 목단피 | E20: 3 | F20: =E20*$L$15 -> 60 | G20: =VLOOKUP($C20,약재관리!A:J,10,FALSE) -> 31.5 | H20: =G20*E20 -> 94.5 | I20: =G20*F20 -> 1890 | K20: 총 물 양 | L20: =L16*L17+L19 -> 6570 | M20: cc
B21: 20 | F21: =E21*$L$15 -> 0 | H21: =G21*E21 -> 0 | I21: =G21*F21 -> 0
B22: 21 | F22: =E22*$L$15 -> 0 | H22: =G22*E22 -> 0 | I22: =G22*F22 -> 0 | K22: 참고치
B23: 22 | F23: =E23*$L$15 -> 0 | H23: =G23*E23 -> 0 | I23: =G23*F23 -> 0 | K23: cross chk | L23: =SUM(F2:F31) -> 1620 | M23: g
B24: 23 | F24: =E24*$L$15 -> 0 | H24: =G24*E24 -> 0 | I24: =G24*F24 -> 0 | K24: 20첩물양 | L24: 5000 | M24: cc
B25: 24 | F25: =E25*$L$15 -> 0 | H25: =G25*E25 -> 0 | I25: =G25*F25 -> 0 | K25: 1첩당 | L25: 80-120 | M25: g
B26: 25 | F26: =E26*$L$15 -> 0 | H26: =G26*E26 -> 0 | I26: =G26*F26 -> 0 | K26: 20첩당 | L26: 1600 | M26: g
B27: 26 | F27: =E27*$L$15 -> 0 | H27: =G27*E27 -> 0 | I27: =G27*F27 -> 0 | K27: 1돈 환산 | L27: 4 | M27: g
B28: 27 | F28: =E28*$L$15 -> 0 | H28: =G28*E28 -> 0 | I28: =G28*F28 -> 0
B29: 28 | F29: =E29*$L$15 -> 0 | H29: =G29*E29 -> 0 | I29: =G29*F29 -> 0 | K29: 금액
B30: 29 | F30: =E30*$L$15 -> 0 | H30: =G30*E30 -> 0 | I30: =G30*F30 -> 0 | K30: 1첩당 | L30: =SUM(H2:H31) -> 1609.8 | M30: 원
B31: 30 | F31: =E31*$L$15 -> 0 | H31: =G31*E31 -> 0 | I31: =G31*F31 -> 0 | K31: 총 | L31: =SUM(I2:I31) -> 32196 | M31: 원

Sheet 처방전양식
B1: No. | C1: 약재명 | D1: 수치 | E1: 그램 | F1: 총용량 | G1: 1g 금액 | H1: 1첩 금액 | I1: 총 금액 | K1: 기본 정보
B2: 1 | C2: 향부자 | E2: 8 | F2: =E2*$L$15 -> 120 | G2: =VLOOKUP($C2,약재관리!A:J,10,FALSE) -> 14.7 | H2: =G2*E2 -> 117.6 | I2: =G2*F2 -> 1764 | K2: UNIT | L2: 96
B3: 2 | C3: 대복피 | E3: 6 | F3: =E3*$L$15 -> 90 | G3: =VLOOKUP($C3,약재관리!A:J,10,FALSE) -> 5.3 | H3: =G3*E3 -> 31.8 | I3: =G3*F3 -> 477 | K3: 처방명 | L3: 가감유기음자
B4: 3 | C4: 진피1 | E4: 6 | F4: =E4*$L$15 -> 90 | G4: =VLOOKUP($C4,약재관리!A:J,10,FALSE) -> 17.6 | H4: =G4*E4 -> 105.6 | I4: =G4*F4 -> 1584 | K4: 날짜 | L4: 45749
B5: 4 | C5: 복령 | E5: 4 | F5: =E5*$L$15 -> 60 | G5: =VLOOKUP($C5,약재관리!A:J,10,FALSE) -> 11 | H5: =G5*E5 -> 44 | I5: =G5*F5 -> 660 | K5: 이름 | L5: 김남순
B6: 5 | C6: 반하 | E6: 4 | F6: =E6*$L$15 -> 60 | G6: =VLOOKUP($C6,약재관리!A:J,10,FALSE) -> 47 | H6: =G6*E6 -> 188 | I6: =G6*F6 -> 2820 | K6: 나이 | L6: 60
B7: 6 | C7: 창출1 | E7: 4 | F7: =E7*$L$15 -> 60 | G7: =VLOOKUP($C7,약재관리!A:J,10,FALSE) -> 22 | H7: =G7*E7 -> 88 | I7: =G7*F7 -> 1320 | K7: 성별 | L7: F
B8: 7 | C8: 지실 | E8: 6 | F8: =E8*$L$15 -> 90 | G8: =VLOOKUP($C8,약재관리!A:J,10,FALSE) -> 16.7 | H8: =G8*E8 -> 100.2 | I8: =G8*F8 -> 1503 | K8: 메모
B9: 8 | C9: 목통 | E9: 4 | F9: =E9*$L$15 -> 60 | G9: =VLOOKUP($C9,약재관리!A:J,10,FALSE) -> 10.7 | H9: =G9*E9 -> 42.8 | I9: =G9*F9 -> 642 | K9: 가감유기음자+치자 황련 대황 향시
B10: 9 | C10: 택사1 | E10: 4 | F10: =E10*$L$15 -> 60 | G10: =VLOOKUP($C10,약재관리!A:J,10,FALSE) -> 23.7 | H10: =G10*E10 -> 94.8 | I10: =G10*F10 -> 1422
B11: 10 | C11: 오약 | E11: 4 | F11: =E11*$L$15 -> 60 | G11: =VLOOKUP($C11,약재관리!A:J,10,FALSE) -> 9.2 | H11: =G11*E11 -> 36.8 | I11: =G11*F11 -> 552
B12: 11 | C12: 청피 | E12: 4 | F12: =E12*$L$15 -> 60 | G12: =VLOOKUP($C12,약재관리!A:J,10,FALSE) -> 7.3 | H12: =G12*E12 -> 29.2 | I12: =G12*F12 -> 438
B13: 12 | C13: 자소엽 | E13: 3 | F13: =E13*$L$15 -> 45 | G13: =VLOOKUP($C13,약재관리!A:J,10,FALSE) -> 12 | H13: =G13*E13 -> 36 | I13: =G13*F13 -> 540
B14: 13 | C14: 길경 | E14: 3 | F14: =E14*$L$15 -> 45 | G14: =VLOOKUP($C14,약재관리!A:J,10,FALSE) -> 11.5 | H14: =G14*E14 -> 34.5 | I14: =G14*F14 -> 517.5 | K14: 총 일수 | L14: 15 | M14: 일분
B15: 14 | C15: 목향 | E15: 2 | F15: =E15*$L$15 -> 30 | G15: =VLOOKUP($C15,약재관리!A:J,10,FALSE) -> 12.2 | H15: =G15*E15 -> 24.4 | I15: =G15*F15 -> 366 | K15: 첩수 | L15: 15 | M15: 첩
B16: 15 | C16: 생강 | E16: 4 | F16: =E16*$L$15 -> 60 | G16: =VLOOKUP($C16,약재관리!A:J,10,FALSE) -> 15 | H16: =G16*E16 -> 60 | I16: =G16*F16 -> 900 | K16: 총 팩수 | L16: 45 | M16: 팩
B17: 16 | C17: 치자 | E17: 6 | F17: =E17*$L$15 -> 90 | G17: =VLOOKUP($C17,약재관리!A:J,10,FALSE) -> 26 | H17: =G17*E17 -> 156 | I17: =G17*F17 -> 2340 | K17: 팩당 물량 | L17: 110 | M17: cc
B18: 17 | C18: 황련 | E18: 2 | F18: =E18*$L$15 -> 30 | G18: =VLOOKUP($C18,약재관리!A:J,10,FALSE) -> 136.8 | H18: =G18*E18 -> 273.6 | I18: =G18*F18 -> 4104 | K18: 1첩당약재 | L18: =SUM(E2:E31) -> 108 | M18: g
B19: 18 | C19: 대황 | E19: 4 | F19: =E19*$L$15 -> 60 | G19: =VLOOKUP($C19,약재관리!A:J,10,FALSE) -> 13 | H19: =G19*E19 -> 52 | I19: =G19*F19 -> 780 | K19: 약재총량 | L19: =L15*L18 -> 1620 | M19: g
B20: 19 | C20: 향시 | E20: 30 | F20: =E20*$L$15 -> 450 | G20: =VLOOKUP($C20,약재관리!A:J,10,FALSE) -> 39 | H20: =G20*E20 -> 1170 | I20: =G20*F20 -> 17550 | K20: 총 물 양 | L20: =L16*L17+L19 -> 6570 | M20: cc
B21: 20 | F21: =E21*$L$15 -> 0 | H21: =G21*E21 -> 0 | I21: =G21*F21 -> 0
B22: 21 | F22: =E22*$L$15 -> 0 | H22: =G22*E22 -> 0 | I22: =G22*F22 -> 0 | K22: 참고치
B23: 22 | F23: =E23*$L$15 -> 0 | H23: =G23*E23 -> 0 | I23: =G23*F23 -> 0 | K23: cross chk | L23: =SUM(F2:F31) -> 1620 | M23: g
B24: 23 | F24: =E24*$L$15 -> 0 | H24: =G24*E24 -> 0 | I24: =G24*F24 -> 0 | K24: 20첩물양 | L24: 5000 | M24: cc
B25: 24 | F25: =E25*$L$15 -> 0 | H25: =G25*E25 -> 0 | I25: =G25*F25 -> 0 | K25: 1첩당 | L25: 80-120 | M25: g
B26: 25 | F26: =E26*$L$15 -> 0 | H26: =G26*E26 -> 0 | I26: =G26*F26 -> 0 | K26: 20첩당 | L26: 1600 | M26: g
B27: 26 | F27: =E27*$L$15 -> 0 | H27: =G27*E27 -> 0 | I27: =G27*F27 -> 0 | K27: 1돈 환산 | L27: 4 | M27: g
B28: 27 | F28: =E28*$L$15 -> 0 | H28: =G28*E28 -> 0 | I28: =G28*F28 -> 0
B29: 28 | F29: =E29*$L$15 -> 0 | H29: =G29*E29 -> 0 | I29: =G29*F29 -> 0 | K29: 금액
B30: 29 | F30: =E30*$L$15 -> 0 | H30: =G30*E30 -> 0 | I30: =G30*F30 -> 0 | K30: 1첩당 | L30: =SUM(H2:H31) -> 2685.3 | M30: 원
B31: 30 | F31: =E31*$L$15 -> 0 | H31: =G31*E31 -> 0 | I31: =G31*F31 -> 0 | K31: 총 | L31: =SUM(I2:I31) -> 40279.5 | M31: 원

Sheet 약재관리
A1: 약재 이름 | B1: 옴니허브 | C1: 한퓨어 | D1: 신우한방 | E1: 바른한약 | F1: 옴니허브 | G1: 한퓨어 | H1: 신우한방 | I1: 바른한약 | J1: 최종 | K1: 옴니허브 | L1: 한퓨어 | M1: 신우한방 | N1: 바른한약
A2: 45674 | B2: 구입단가 | C2: 구입단가 | D2: 구입단가 | E2: 구입단가 | F2: 1g | G2: 1g | H2: 1g | I2: 1g | J2: 1g | K2: 500g | L2: 500g | M2: 600g | N2: 600g
A3: 갈근1 | B3: 9900 | C3: 9000 | D3: 10500 | E3: 9900 | F3: =B3/500 -> 19.8 | G3: =C3/500 -> 18 | H3: =D3/600 -> 17.5 | I3: =E3/600 -> 16.5 | J3: 16.5 | L3: 선일국산 | M3: 토 | N3: 퓨어마인드국산
A4: 갈근2 | C4: 2700 | F4: =B4/500 -> 0 | G4: =C4/500 -> 5.4 | H4: =D4/600 -> 0 | I4: =E4/600 -> 0 | L4: 이풀잎중국
A5: 감국 | F5: =B5/500 -> 0 | G5: =C5/500 -> 0 | H5: =D5/600 -> 0 | I5: =E5/600 -> 0
A6: 감수 | C6: 23400 | E6: 27100 | F6: =B6/500 -> 0 | G6: =C6/600 -> 39 | H6: =D6/600 -> 0 | I6: =E6/600 -> 45.166667 | J6: 45.2 | L6: 600g씨케이중국 | N6: 씨케이중국
A7: 감초 | B7: 15800 | D7: 17000 | E7: 25500 | F7: =B7/500 -> 31.6 | G7: =C7/500 -> 0 | H7: =D7/600 -> 28.333333 | I7: =E7/600 -> 42.5 | J7: 28.3 | M7: 양외2 | N7: 양외1
A8: 강활1 | B8: 27200 | C8: 20500 | D8: 24000 | F8: =B8/500 -> 54.4 | G8: =C8/500 -> 41 | H8: =D8/600 -> 40 | I8: =E8/600 -> 0 | J8: 40 | L8: 선일국산 | M8: 토
A9: 강활2 | C9: 18700 | D9: 21000 | E9: 23300 | F9: =B9/500 -> 0 | G9: =C9/500 -> 37.4 | H9: =D9/600 -> 35 | I9: =E9/600 -> 38.833333 | J9: 38.8 | L9: 태극인국산 | N9: 선일국산
A10: 강황 | C10: 3300 | D10: 5000 | F10: =B10/500 -> 0 | G10: =C10/500 -> 6.6 | H10: =D10/600 -> 8.3333333 | I10: =E10/600 -> 0 | J10: 8.3 | M10: 인도
A11: 건강 | C11: 5200 | D11: 8000 | E11: 5900 | F11: =B11/500 -> 0 | G11: =C11/500 -> 10.4 | H11: =D11/600 -> 13.333333 | I11: =E11/600 -> 9.8333333 | J11: 9.5 | L11: 페루 | N11: 페루
A12: 건율 | C12: 13500 | D12: 16500 | E12: 16700 | F12: =B12/500 -> 0 | G12: =C12/500 -> 27 | H12: =D12/600 -> 27.5 | I12: =E12/600 -> 27.833333 | J12: 27.5 | M12: 토 | N12: (절, 토)
A13: 건지황 | B13: 19900 | C13: 5600 | D13: 11000 | E13: 8900 | F13: =B13/500 -> 39.8 | G13: =C13/500 -> 11.2 | H13: =D13/600 -> 18.333333 | I13: =E13/600 -> 14.833333 | J13: 14.4 | L13: 허브팜중국
A14: 검인 | F14: =B14/500 -> 0 | G14: =C14/500 -> 0 | H14: =D14/600 -> 0 | I14: =E14/600 -> 0
A15: 결명자 | F15: =B15/500 -> 0 | G15: =C15/500 -> 0 | H15: =D15/600 -> 0 | I15: =E15/600 -> 0
A16: 계지 | B16: 4500 | C16: 2000 | D16: 3500 | E16: 2900 | F16: =B16/500 -> 9 | G16: =C16/500 -> 4 | H16: =D16/600 -> 5.8333333 | I16: =E16/600 -> 4.8333333 | J16: 4.8 | L16: 씨케이베트남 | M16: 세 | N16: 엔탭베트남
A17: 고량강 | C17: 10200 | E17: 11100 | F17: =B17/500 -> 0 | G17: =C17/600 -> 17 | H17: =D17/600 -> 0 | I17: =E17/600 -> 18.5 | J17: 17 | L17: 600g 씨케이중국 | N17: 씨케이중국
A18: 고본 | C18: 32000 | E18: 41600 | F18: =B18/500 -> 0 | G18: =C18/500 -> 64 | H18: =D18/600 -> 0 | I18: =E18/600 -> 69.333333 | J18: 64 | L18: 선일국산 | N18: 퓨어마인드국산
A19: 고삼 | C19: 4500 | F19: =B19/500 -> 0 | G19: =C19/500 -> 9 | H19: =D19/600 -> 0 | I19: =E19/600 -> 0 | J19: 9 | L19: 한솔중국
A20: 골쇄보 | F20: =B20/500 -> 0 | G20: =C20/500 -> 0 | H20: =D20/600 -> 0 | I20: =E20/600 -> 0
A21: 과루인 | C21: 3500 | D21: 6500 | F21: =B21/500 -> 0 | G21: =C21/500 -> 7 | H21: =D21/600 -> 10.833333 | I21: =E21/600 -> 0 | J21: 10.8 | M21: (추)
A22: 곽향1 | B22: 6900 | C22: 5600 | E22: 6900 | F22: =B22/500 -> 13.8 | G22: =C22/500 -> 11.2 | H22: =D22/600 -> 0 | I22: =E22/600 -> 11.5 | J22: 13.8 | L22: 선일국산 | N22: 씨케이국산
A23: 곽향2 | B23: 4600 | C23: 3500 | E23: 4800 | F23: =B23/500 -> 9.2 | G23: =C23/500 -> 7 | H23: =D23/600 -> 0 | I23: =E23/600 -> 8 | J23: 7 | K23: 인도네시아 | L23: 올본인도네시아 | N23: 엔탭인도네시아
A24: 관동화 | C24: 46000 | D24: 70000 | E24: 75400 | F24: =B24/500 -> 0 | G24: =C24/300 -> 153.33333 | H24: =D24/600 -> 116.66667 | I24: =E24/600 -> 125.66667 | J24: 116.7 | L24: 300g | N24: 엔탭중국
A25: 괴화 | F25: =B25/500 -> 0 | G25: =C25/500 -> 0 | H25: =D25/600 -> 0 | I25: =E25/600 -> 0
A26: 교이 | F26: =B26/500 -> 0 | G26: =C26/500 -> 0 | H26: =D26/600 -> 0 | I26: =E26/600 -> 0 | J26: 5.3
A27: 구기자 | B27: 14900 | C27: 8700 | D27: 9000 | E27: 8200 | F27: =B27/500 -> 29.8 | G27: =C27/500 -> 17.4 | H27: =D27/600 -> 15 | I27: =E27/600 -> 13.666667 | J27: 13.7 | N27: 엔탭중국영하
A28: 구맥 | F28: =B28/500 -> 0 | G28: =C28/500 -> 0 | H28: =D28/600 -> 0 | I28: =E28/600 -> 0
A29: 구척 | F29: =B29/500 -> 0 | G29: =C29/500 -> 0 | H29: =D29/600 -> 0 | I29: =E29/600 -> 0
A30: 귀판 | C30: 20500 | D30: 19000 | F30: =B30/500 -> 0 | G30: =C30/600 -> 34.166667 | H30: =D30/600 -> 31.666667 | I30: =E30/600 -> 0 | J30: 31.7 | L30: 600g추말/자연세상인도네시아
A31: 금은화 | C31: 21500 | E31: 30800 | F31: =B31/500 -> 0 | G31: =C31/500 -> 43 | H31: =D31/600 -> 0 | I31: =E31/600 -> 51.333333 | J31: 43 | L31: 한솔중국 | N31: 엔탭중국
A32: 길경 | B32: 11500 | C32: 12900 | D32: 7500 | E32: 6900 | F32: =B32/500 -> 23 | G32: =C32/500 -> 25.8 | H32: =D32/600 -> 12.5 | I32: =E32/600 -> 11.5 | J32: 11.5 | K32: (중국4-5년) | L32: 선일국산 | M32: (편) | N32: 엔탭중국야생3년
A33: 나복자 | C33: 3000 | D33: 4000 | F33: =B33/500 -> 0 | G33: =C33/500 -> 6 | H33: =D33/600 -> 6.6666667 | I33: =E33/600 -> 0 | J33: 6.7 | L33: 올본인도/추말 | M33: 추
A34: 남성 | C34: 13000 | D34: 13000 | F34: =B34/500 -> 0 | G34: =C34/500 -> 26 | H34: =D34/500 -> 26 | I34: =E34/600 -> 0 | J34: 26 | L34: 생강백반제/신흥중국 | M34: 500g생강백반제/신흥중국
A35: 녹용 | C35: 278000 | F35: =B35/500 -> 0 | G35: =C35/600 -> 463.33333 | H35: =D35/600 -> 0 | I35: =E35/600 -> 0 | J35: 463.3 | L35: 600g
A36: 단삼 | C36: 6600 | E36: 8900 | F36: =B36/500 -> 0 | G36: =C36/500 -> 13.2 | H36: =D36/600 -> 0 | I36: =E36/600 -> 14.833333 | J36: 14.8 | L36: 허브팜중국 | N36: 엔탭중국
A37: 담두시 | D37: 8000 | F37: =B37/500 -> 0 | G37: =C37/500 -> 0 | H37: =D37/600 -> 13.333333 | I37: =E37/600 -> 0 | J37: 13.3
A38: 당귀1 | B38: 14900 | C38: 12700 | D38: 15000 | E38: 16300 | F38: =B38/500 -> 29.8 | G38: =C38/500 -> 25.4 | H38: =D38/600 -> 25 | I38: =E38/600 -> 27.166667 | J38: 27.2 | L38: 선일국산 | N38: 선일국산
A39: 당귀2 | C39: 12700 | E39: 13800 | F39: =B39/500 -> 0 | G39: =C39/500 -> 25.4 | H39: =D39/600 -> 0 | I39: =E39/600 -> 23 | J39: 23 | L39: 선일국산 | N39: 선일국산
A40: 당삼 | C40: 26000 | D40: 32000 | E40: 35500 | F40: =B40/500 -> 0 | G40: =C40/600 -> 43.333333 | H40: =D40/600 -> 53.333333 | I40: =E40/600 -> 59.166667 | J40: 43.3 | L40: 600g씨케이중국 | N40: 엔탭중국
...
